Workbook

Sheet Chart_Data
B2: Chart Data — plot-ready series
B3: One row per date. Green = computed on HD_Weighting / L5_New_Leases (mix-weighted); blue = extracted from models/statements. Quarterly HD points plotted at quarter midpoints.
B5: Date | C5: Seasons HD asking (mix-wtd) | D5: Seasons UW asking | E5: Seasons L5 / UW entry | F5: Prelude HD asking (mix-wtd) | G5: Prelude UW rent/occ | H5: Prelude actual in-place | I5: Prelude L5 (8/13/26)
B6: 45153 | F6: =HD_Weighting!D25 -> 1700.9571
B7: 45245 | F7: =HD_Weighting!E25 -> 1647.45
B8: 45337 | F8: =HD_Weighting!F25 -> 1631.1571
B9: 45427 | C9: =HD_Weighting!G16 -> 1807.1806 | F9: =HD_Weighting!G25 -> 1616.0571
B10: 45519 | C10: =HD_Weighting!H16 -> 1843.8333 | F10: =HD_Weighting!H25 -> 1692.0643
B11: 45611 | C11: =HD_Weighting!I16 -> 1729.2639 | F11: =HD_Weighting!I25 -> 1595.0857
B12: 45703 | C12: =HD_Weighting!J16 -> 1722.6667 | F12: =HD_Weighting!J25 -> 1616.2857
B13: 45792 | C13: =HD_Weighting!K16 -> 1800.6667 | F13: =HD_Weighting!K25 -> 1677.0357
B14: 45884 | C14: =HD_Weighting!L16 -> 1768.5694 | F14: =HD_Weighting!L25 -> 1726.4357
B15: 45976 | C15: =HD_Weighting!M16 -> 1676.8611 | F15: =HD_Weighting!M25 -> 1695.9
B16: 46037 | H16: 1668
B17: 46068 | C17: =HD_Weighting!N16 -> 1722.7917 | H17: 1670
B18: 46096 | H18: 1672
B19: 46127 | H19: 1675
B20: 46157 | C20: =HD_Weighting!O16 -> 1912.1528 | H20: 1675
B21: 46188 | H21: 1682
B22: 46204 | G22: 1668
B23: 46218 | C23: =HD_Weighting!P16 -> 1937.7361 | H23: 1684
B24: 46238 | D24: 1885 | E24: =L5_New_Leases!D57 -> 1884.6861
B25: 46247 | I25: =L5_New_Leases!D44 -> 1810.6186
B26: 46569 | G26: 1745
B27: 46692 | D27: 1960
B28: 46935 | G28: 1808
B29: 47058 | D29: 2038
B30: 47300 | G30: 1883
B31: 47423 | D31: 2110
B32: 47665 | G32: 1952
B33: 47788 | D33: 2184
B34: 48153 | D34: 2249
B36: Sources: Seasons TMG model Rent Analysis (HD 8/2026) & Assumptions (UW path: $1,885 flat Y1, then +4/4/3.5/3.5/3% annual Nov steps); Prelude model Market Rent Summary (HD 11/2025) & Unleveraged (UW rent/occupied); Prelude accrual statement (2026 in-place = potential rent net LTL /280); rent roll 8/13/26 (L5). Seasons Q3 23-Q1 24 HD backfill excluded.

Sheet HD_Weighting
B2: HelloData Mix-Weighted Asking Rent — methodology = Seasons model Cash Flow (Annual) row 304
B3: Per floor plan HelloData asking by period (blue, from each model), weighted by rent-roll unit counts: Weighted Avg = SUMPRODUCT(values x units) / SUM(units). Identical convention to CF(Annual)!AP304 and Rent Analysis row 59.
B5: SEASONS AT MERIDIAN — source: TMG model Rent Analysis K9:W17 (HD pull 8/2026)
B6: Floor plan | C6: Units | D6: Q3 23 | E6: Q4 23 | F6: Q1 24 | G6: Q2 24 | H6: Q3 24 | I6: Q4 24 | J6: Q1 25 | K6: Q2 25 | L6: Q3 25 | M6: Q4 25 | N6: Q1 26 | O6: Q2 26 | P6: T90 (Jun-Aug 26)
B7: S1_Seas | C7: 15 | D7: 1403 | E7: 1403 | F7: 1403 | G7: 1403 | H7: 1415 | I7: 1351 | J7: 1345 | K7: 1509 | L7: 1509 | M7: 1325 | N7: 1310 | O7: 1544 | P7: 1597
B8: A1_Seas | C8: 120 | D8: 1479 | E8: 1479 | F8: 1479 | G8: 1610 | H8: 1586 | I8: 1432 | J8: 1447 | K8: 1536 | L8: 1518 | M8: 1394 | N8: 1483 | O8: 1660 | P8: 1691
B9: A2_Seas | C9: 45 | D9: 1625 | E9: 1625 | F9: 1625 | G9: 1625 | H9: 1695 | I9: 1676 | J9: 1689 | K9: 1771 | L9: 1679 | M9: 1556 | N9: 1570 | O9: 1692 | P9: 1787
B10: B1_Seas | C10: 30 | D10: 1805 | E10: 1805 | F10: 1805 | G10: 1805 | H10: 1960 | I10: 1765 | J10: 1737 | K10: 1910 | L10: 1799 | M10: 1726 | N10: 1805 | O10: 2030 | P10: 2050
B11: B2_Seas | C11: 75 | D11: 1983 | E11: 1983 | F11: 1983 | G11: 2045 | H11: 2021 | I11: 1945 | J11: 2016 | K11: 2007 | L11: 1930 | M11: 1838 | N11: 1935 | O11: 2125 | P11: 2104
B12: B3a_Seas | C12: 15 | D12: 1934 | E12: 1934 | F12: 1934 | G12: 1934 | H12: 2173 | I12: 2173 | J12: 1898 | K12: 1807 | L12: 1945 | M12: 2135 | N12: 1978 | O12: 1978 | P12: 2075
B13: B3b_Seas | C13: 30 | D13: 1941 | E13: 1941 | F13: 1941 | G13: 1941 | H13: 2098 | I13: 2098 | J13: 1826 | K13: 1958 | L13: 1958 | M13: 1866 | N13: 1870 | O13: 2102 | P13: 2100
B14: C1a_Seas | C14: 10 | D14: 2371 | E14: 2371 | F14: 2371 | G14: 2371 | H14: 2355 | I14: 2355 | J14: 2132 | K14: 2296 | L14: 2186 | M14: 2326 | N14: 2344 | O14: 2579 | P14: 2579
B15: C1b_Seas | C15: 20 | D15: 2237 | E15: 2237 | F15: 2237 | G15: 2237 | H15: 2325 | I15: 1855 | J15: 2123 | K15: 2248 | L15: 2392 | M15: 2280 | N15: 2173 | O15: 2554 | P15: 2554
B16: WEIGHTED AVG | C16: =SUM(C7:C15) -> 360 | D16: =SUMPRODUCT(D7:D15,$C$7:$C$15)/SUM($C$7:$C$15) -> 1750.5972 | E16: =SUMPRODUCT(E7:E15,$C$7:$C$15)/SUM($C$7:$C$15) -> 1750.5972 | F16: =SUMPRODUCT(F7:F15,$C$7:$C$15)/SUM($C$7:$C$15) -> 1750.5972 | G16: =SUMPRODUCT(G7:G15,$C$7:$C$15)/SUM($C$7:$C$15) -> 1807.1806 | H16: =SUMPRODUCT(H7:H15,$C$7:$C$15)/SUM($C$7:$C$15) -> 1843.8333 | I16: =SUMPRODUCT(I7:I15,$C$7:$C$15)/SUM($C$7:$C$15) -> 1729.2639 | J16: =SUMPRODUCT(J7:J15,$C$7:$C$15)/SUM($C$7:$C$15) -> 1722.6667 | K16: =SUMPRODUCT(K7:K15,$C$7:$C$15)/SUM($C$7:$C$15) -> 1800.6667 | ... P16: =SUMPRODUCT(P7:P15,$C$7:$C$15)/SUM($C$7:$C$15) -> 1937.7361
B17: Note: Q3 23–Q1 24 are rent-roll backfill (pre-delivery), not real HelloData — excluded from Chart_Data.
B19: PRELUDE AT PARAMOUNT — source: Prelude model Market Rent Summary K7:T11 (HD pull 11/2025)
B20: Floor plan | C20: Units | D20: Q3 23 | E20: Q4 23 | F20: Q1 24 | G20: Q2 24 | H20: Q3 24 | I20: Q4 24 | J20: Q1 25 | K20: Q2 25 | L20: Q3 25 | M20: Q4 25 QTD
B21: 1x1-pp (787sf) | C21: 106 | D21: 1493 | E21: 1448 | F21: 1434 | G21: 1383 | H21: 1373 | I21: 1369 | J21: 1342 | K21: 1439 | L21: 1465 | M21: 1462
B22: 2x2a-pp (1092sf) | C22: 100 | D22: 1725 | E22: 1706 | F22: 1685 | G22: 1698 | H22: 1802 | I22: 1629 | J22: 1682 | K22: 1718 | L22: 1811 | M22: 1795
B23: 2x2b-pp (1172sf) | C23: 30 | D23: 1895 | E23: 1835 | F23: 1798 | G23: 1791 | H23: 1818 | I23: 1643 | J23: 1698 | K23: 1792 | L23: 1838 | M23: 1790
B24: 3x2-pp (1291sf) | C24: 44 | D24: 2015 | E24: 1867 | F24: 1870 | G24: 1872 | H24: 2125 | I24: 2030 | J24: 2072 | K24: 2079 | L24: 2088 | M24: 1970
B25: WEIGHTED AVG | C25: =SUM(C21:C24) -> 280 | D25: =SUMPRODUCT(D21:D24,$C$21:$C$24)/SUM($C$21:$C$24) -> 1700.9571 | E25: =SUMPRODUCT(E21:E24,$C$21:$C$24)/SUM($C$21:$C$24) -> 1647.45 | F25: =SUMPRODUCT(F21:F24,$C$21:$C$24)/SUM($C$21:$C$24) -> 1631.1571 | G25: =SUMPRODUCT(G21:G24,$C$21:$C$24)/SUM($C$21:$C$24) -> 1616.0571 | H25: =SUMPRODUCT(H21:H24,$C$21:$C$24)/SUM($C$21:$C$24) -> 1692.0643 | I25: =SUMPRODUCT(I21:I24,$C$21:$C$24)/SUM($C$21:$C$24) -> 1595.0857 | J25: =SUMPRODUCT(J21:J24,$C$21:$C$24)/SUM($C$21:$C$24) -> 1616.2857 | K25: =SUMPRODUCT(K21:K24,$C$21:$C$24)/SUM($C$21:$C$24) -> 1677.0357 | ... M25: =SUMPRODUCT(M21:M24,$C$21:$C$24)/SUM($C$21:$C$24) -> 1695.9

Sheet L5_New_Leases
B2: Last-5 New Leases — Seasons model methodology
B3: Per floor plan: average of the 5 most recent new leases (by move-in) from the rent roll; property total = SUMPRODUCT(plan L5 avg x plan unit count) / total units — mirrors Seasons Assumptions L50:L58 / P49:T49.
B5: PRELUDE AT PARAMOUNT — RR w/ lease charges 8/13/2026 (current residents)
B6: pprA1 — unit | C6: Move-in | D6: Rent
B7: P302 | C7: 46244 | D7: 1605
B8: F303 | C8: 46234 | D8: 1515
B9: T103 | C9: 46232 | D9: 1641
B10: R202 | C10: 46225 | D10: 1505
B11: T303 | C11: 46204 | D11: 1588
B12: L5 avg | D12: =AVERAGE(D7:D11) -> 1570.8
B14: pprB1 — unit | C14: Move-in | D14: Rent
B15: T204 | C15: 46240 | D15: 1852
B16: T301 | C16: 46231 | D16: 1983
B17: M301 | C17: 46231 | D17: 1983
B18: N301 | C18: 46224 | D18: 1862
B19: H204 | C19: 46214 | D19: 1852
B20: L5 avg | D20: =AVERAGE(D15:D19) -> 1906.4
B22: pprB2 — unit | C22: Move-in | D22: Rent
B23: T306 | C23: 46235 | D23: 1820
B24: N205 | C24: 46233 | D24: 2018
B25: L306 | C25: 46226 | D25: 1907
B26: D205 | C26: 46206 | D26: 1807
B27: N305 | C27: 46202 | D27: 1817
B28: L5 avg | D28: =AVERAGE(D23:D27) -> 1873.8
B30: pprC1 — unit | C30: Move-in | D30: Rent
B31: K305 | C31: 46195 | D31: 2233
B32: G206 | C32: 46191 | D32: 2135
B33: C305 | C33: 46176 | D33: 2233
B34: H205 | C34: 46146 | D34: 2117
B35: K206 | C35: 46129 | D35: 1920
B36: L5 avg | D36: =AVERAGE(D31:D35) -> 2127.6
B38: WEIGHTED SUMMARY
B39: Floor plan | C39: Units (mix) | D39: L5 avg
B40: pprA1 | C40: 106 | D40: =D12 -> 1570.8
B41: pprB1 | C41: 100 | D41: =D20 -> 1906.4
B42: pprB2 | C42: 30 | D42: =D28 -> 1873.8
B43: pprC1 | C43: 44 | D43: =D36 -> 2127.6
B44: PRELUDE L5 MIX-WEIGHTED | D44: =SUMPRODUCT(D40:D43,C40:C43)/SUM(C40:C43) -> 1810.6186 | F44: Result: $1,810.62 — vs Prelude UW Y1 market rent $1,730: +4.7%.
B46: SEASONS AT MERIDIAN — model Assumptions L50:L58 (8/4/26 RR), for comparison
B47: Floor plan | C47: Units | D47: L5 avg
...
