Workbook

Sheet Lease-Up Bridge
B2: Lease-Up Bridge — what happened at the property, and how it becomes Year 1 & Year 2
B3: Drop this sheet into the model, then Calculate (Ctrl+Alt+F9). Blue cells are live formulas against HD Dump, T12 Dump, RRA, RR Dump and Cash Flow (Annual). Grey cells are static reconstructed history — the model has no equivalent source for them.
B4: Market & effective rent use the SAME T90 window and mix-weighting as Cash Flow (Annual) rows 252-304, so this tab and the model agree by construction. Contract rent = (AGPR − |vacancy|) ÷ occupied units — vacant units sit in AGPR at market, which overstates contract rent by ~4% at lease-up occupancy, so they are removed.
B6: UNIT MIX (live from tblRentRoll — drives the mix weighting)
C7: S1_Seas | D7: A1_Seas | E7: A2_Seas | F7: B1_Seas | G7: B2_Seas | H7: B3a_Seas | I7: B3b_Seas | J7: C1a_Seas | K7: C1b_Seas | L7: total
B8: units | C8: =COUNTIFS('RR Dump'!$B$2:$B$361,C7) | D8: =COUNTIFS('RR Dump'!$B$2:$B$361,D7) | E8: =COUNTIFS('RR Dump'!$B$2:$B$361,E7) | F8: =COUNTIFS('RR Dump'!$B$2:$B$361,F7) | G8: =COUNTIFS('RR Dump'!$B$2:$B$361,G7) | H8: =COUNTIFS('RR Dump'!$B$2:$B$361,H7) | I8: =COUNTIFS('RR Dump'!$B$2:$B$361,I7) | J8: =COUNTIFS('RR Dump'!$B$2:$B$361,J7) | K8: =COUNTIFS('RR Dump'!$B$2:$B$361,K7) | L8: =SUM(C8:K8)
T9: T90 helper block — market by plan, then effective by plan (hidden)
B10: Month | C10: Basis | D10: Market rent (T90 HelloData) | E10: Effective rent (T90 HelloData) | F10: Contract rent (per occupied) | G10: Physical occupancy | H10: (LTL)/GTL % | I10: New leases | J10: Renew- als | K10: Move- outs | L10: Leases expiring | M10: Expiring rent | N10: Renews at | O10: Renewal increase % | P10: New lease at
B11: 45504 | C11: Actual | D11: =SUMPRODUCT(T11:AB11,$C$8:$K$8)/SUM($C$8:$K$8) | E11: =SUMPRODUCT(AD11:AL11,$C$8:$K$8)/SUM($C$8:$K$8) | F11: =IFERROR((INDEX('T12 Dump'!$D$9:$O$9,MATCH(EOMONTH($B11,-1)+1,'T12 Dump'!$D$3:$O$3,0))-ABS(INDEX('T12 Dump'!$D$11:$O$11,MATCH(EOMONTH($B11,-1)+1,'T12 Dump'!$D$3:$O$3,0))))/($F11*360),"") | G11: =IFERROR(1-ABS(INDEX('T12 Dump'!$D$11:$O$11,MATCH(EOMONTH($B11,-1)+1,'T12 Dump'!$D$3:$O$3,0)))/INDEX('T12 Dump'!$D$7:$O$7,MATCH(EOMONTH($B11,-1)+1,'T12 Dump'!$D$3:$O$3,0)),"") | H11: =IFERROR($F11/$D11-1,"") | I11: 2 | T11: =IF(COUNTIFS('HD Dump'!$U$2:$U$538,C$7,'HD Dump'!$R$2:$R$538,">="&$B11-90,'HD Dump'!$R$2:$R$538,"<="&$B11)>0,AVERAGEIFS('HD Dump'!$M$2:$M$538,'HD Dump'!$U$2:$U$538,C$7,'HD Dump'!$R$2:$R$538,">="&$B11-90,'HD Dump'!$R$2:$R$538,"<="&$B11),"") | U11: =IF(COUNTIFS('HD Dump'!$U$2:$U$538,D$7,'HD Dump'!$R$2:$R$538,">="&$B11-90,'HD Dump'!$R$2:$R$538,"<="&$B11)>0,AVERAGEIFS('HD Dump'!$M$2:$M$538,'HD Dump'!$U$2:$U$538,D$7,'HD Dump'!$R$2:$R$538,">="&$B11-90,'HD Dump'!$R$2:$R$538,"<="&$B11),"") | V11: =IF(COUNTIFS('HD Dump'!$U$2:$U$538,E$7,'HD Dump'!$R$2:$R$538,">="&$B11-90,'HD Dump'!$R$2:$R$538,"<="&$B11)>0,AVERAGEIFS('HD Dump'!$M$2:$M$538,'HD Dump'!$U$2:$U$538,E$7,'HD Dump'!$R$2:$R$538,">="&$B11-90,'HD Dump'!$R$2:$R$538,"<="&$B11),"") | W11: =IF(COUNTIFS('HD Dump'!$U$2:$U$538,F$7,'HD Dump'!$R$2:$R$538,">="&$B11-90,'HD Dump'!$R$2:$R$538,"<="&$B11)>0,AVERAGEIFS('HD Dump'!$M$2:$M$538,'HD Dump'!$U$2:$U$538,F$7,'HD Dump'!$R$2:$R$538,">="&$B11-90,'HD Dump'!$R$2:$R$538,"<="&$B11),"") | X11: =IF(COUNTIFS('HD Dump'!$U$2:$U$538,G$7,'HD Dump'!$R$2:$R$538,">="&$B11-90,'HD Dump'!$R$2:$R$538,"<="&$B11)>0,AVERAGEIFS('HD Dump'!$M$2:$M$538,'HD Dump'!$U$2:$U$538,G$7,'HD Dump'!$R$2:$R$538,">="&$B11-90,'HD Dump'!$R$2:$R$538,"<="&$B11),"") | Y11: =IF(COUNTIFS('HD Dump'!$U$2:$U$538,H$7,'HD Dump'!$R$2:$R$538,">="&$B11-90,'HD Dump'!$R$2:$R$538,"<="&$B11)>0,AVERAGEIFS('HD Dump'!$M$2:$M$538,'HD Dump'!$U$2:$U$538,H$7,'HD Dump'!$R$2:$R$538,">="&$B11-90,'HD Dump'!$R$2:$R$538,"<="&$B11),"") | Z11: =IF(COUNTIFS('HD Dump'!$U$2:$U$538,I$7,'HD Dump'!$R$2:$R$538,">="&$B11-90,'HD Dump'!$R$2:$R$538,"<="&$B11)>0,AVERAGEIFS('HD Dump'!$M$2:$M$538,'HD Dump'!$U$2:$U$538,I$7,'HD Dump'!$R$2:$R$538,">="&$B11-90,'HD Dump'!$R$2:$R$538,"<="&$B11),"") | AA11: =IF(COUNTIFS('HD Dump'!$U$2:$U$538,J$7,'HD Dump'!$R$2:$R$538,">="&$B11-90,'HD Dump'!$R$2:$R$538,"<="&$B11)>0,AVERAGEIFS('HD Dump'!$M$2:$M$538,'HD Dump'!$U$2:$U$538,J$7,'HD Dump'!$R$2:$R$538,">="&$B11-90,'HD Dump'!$R$2:$R$538,"<="&$B11),"") | AB11: =IF(COUNTIFS('HD Dump'!$U$2:$U$538,K$7,'HD Dump'!$R$2:$R$538,">="&$B11-90,'HD Dump'!$R$2:$R$538,"<="&$B11)>0,AVERAGEIFS('HD Dump'!$M$2:$M$538,'HD Dump'!$U$2:$U$538,K$7,'HD Dump'!$R$2:$R$538,">="&$B11-90,'HD Dump'!$R$2:$R$538,"<="&$B11),"") | AD11: =IF(COUNTIFS('HD Dump'!$U$2:$U$538,C$7,'HD Dump'!$R$2:$R$538,">="&$B11-90,'HD Dump'!$R$2:$R$538,"<="&$B11)>0,AVERAGEIFS('HD Dump'!$O$2:$O$538,'HD Dump'!$U$2:$U$538,C$7,'HD Dump'!$R$2:$R$538,">="&$B11-90,'HD Dump'!$R$2:$R$538,"<="&$B11),"") | AE11: =IF(COUNTIFS('HD Dump'!$U$2:$U$538,D$7,'HD Dump'!$R$2:$R$538,">="&$B11-90,'HD Dump'!$R$2:$R$538,"<="&$B11)>0,AVERAGEIFS('HD Dump'!$O$2:$O$538,'HD Dump'!$U$2:$U$538,D$7,'HD Dump'!$R$2:$R$538,">="&$B11-90,'HD Dump'!$R$2:$R$538,"<="&$B11),"") | AF11: =IF(COUNTIFS('HD Dump'!$U$2:$U$538,E$7,'HD Dump'!$R$2:$R$538,">="&$B11-90,'HD Dump'!$R$2:$R$538,"<="&$B11)>0,AVERAGEIFS('HD Dump'!$O$2:$O$538,'HD Dump'!$U$2:$U$538,E$7,'HD Dump'!$R$2:$R$538,">="&$B11-90,'HD Dump'!$R$2:$R$538,"<="&$B11),"") | AG11: =IF(COUNTIFS('HD Dump'!$U$2:$U$538,F$7,'HD Dump'!$R$2:$R$538,">="&$B11-90,'HD Dump'!$R$2:$R$538,"<="&$B11)>0,AVERAGEIFS('HD Dump'!$O$2:$O$538,'HD Dump'!$U$2:$U$538,F$7,'HD Dump'!$R$2:$R$538,">="&$B11-90,'HD Dump'!$R$2:$R$538,"<="&$B11),"") | AH11: =IF(COUNTIFS('HD Dump'!$U$2:$U$538,G$7,'HD Dump'!$R$2:$R$538,">="&$B11-90,'HD Dump'!$R$2:$R$538,"<="&$B11)>0,AVERAGEIFS('HD Dump'!$O$2:$O$538,'HD Dump'!$U$2:$U$538,G$7,'HD Dump'!$R$2:$R$538,">="&$B11-90,'HD Dump'!$R$2:$R$538,"<="&$B11),"") | AI11: =IF(COUNTIFS('HD Dump'!$U$2:$U$538,H$7,'HD Dump'!$R$2:$R$538,">="&$B11-90,'HD Dump'!$R$2:$R$538,"<="&$B11)>0,AVERAGEIFS('HD Dump'!$O$2:$O$538,'HD Dump'!$U$2:$U$538,H$7,'HD Dump'!$R$2:$R$538,">="&$B11-90,'HD Dump'!$R$2:$R$538,"<="&$B11),"") | AJ11: =IF(COUNTIFS('HD Dump'!$U$2:$U$538,I$7,'HD Dump'!$R$2:$R$538,">="&$B11-90,'HD Dump'!$R$2:$R$538,"<="&$B11)>0,AVERAGEIFS('HD Dump'!$O$2:$O$538,'HD Dump'!$U$2:$U$538,I$7,'HD Dump'!$R$2:$R$538,">="&$B11-90,'HD Dump'!$R$2:$R$538,"<="&$B11),"") | AK11: =IF(COUNTIFS('HD Dump'!$U$2:$U$538,J$7,'HD Dump'!$R$2:$R$538,">="&$B11-90,'HD Dump'!$R$2:$R$538,"<="&$B11)>0,AVERAGEIFS('HD Dump'!$O$2:$O$538,'HD Dump'!$U$2:$U$538,J$7,'HD Dump'!$R$2:$R$538,">="&$B11-90,'HD Dump'!$R$2:$R$538,"<="&$B11),"") | AL11: =IF(COUNTIFS('HD Dump'!$U$2:$U$538,K$7,'HD Dump'!$R$2:$R$538,">="&$B11-90,'HD Dump'!$R$2:$R$538,"<="&$B11)>0,AVERAGEIFS('HD Dump'!$O$2:$O$538,'HD Dump'!$U$2:$U$538,K$7,'HD Dump'!$R$2:$R$538,">="&$B11-90,'HD Dump'!$R$2:$R$538,"<="&$B11),"")
B12: 45535 | C12: Actual | D12: =SUMPRODUCT(T12:AB12,$C$8:$K$8)/SUM($C$8:$K$8) | E12: =SUMPRODUCT(AD12:AL12,$C$8:$K$8)/SUM($C$8:$K$8) | F12: =IFERROR((INDEX('T12 Dump'!$D$9:$O$9,MATCH(EOMONTH($B12,-1)+1,'T12 Dump'!$D$3:$O$3,0))-ABS(INDEX('T12 Dump'!$D$11:$O$11,MATCH(EOMONTH($B12,-1)+1,'T12 Dump'!$D$3:$O$3,0))))/($F12*360),"") | G12: =IFERROR(1-ABS(INDEX('T12 Dump'!$D$11:$O$11,MATCH(EOMONTH($B12,-1)+1,'T12 Dump'!$D$3:$O$3,0)))/INDEX('T12 Dump'!$D$7:$O$7,MATCH(EOMONTH($B12,-1)+1,'T12 Dump'!$D$3:$O$3,0)),"") | H12: =IFERROR($F12/$D12-1,"") | I12: 7 | T12: =IF(COUNTIFS('HD Dump'!$U$2:$U$538,C$7,'HD Dump'!$R$2:$R$538,">="&$B12-90,'HD Dump'!$R$2:$R$538,"<="&$B12)>0,AVERAGEIFS('HD Dump'!$M$2:$M$538,'HD Dump'!$U$2:$U$538,C$7,'HD Dump'!$R$2:$R$538,">="&$B12-90,'HD Dump'!$R$2:$R$538,"<="&$B12),T11) | U12: =IF(COUNTIFS('HD Dump'!$U$2:$U$538,D$7,'HD Dump'!$R$2:$R$538,">="&$B12-90,'HD Dump'!$R$2:$R$538,"<="&$B12)>0,AVERAGEIFS('HD Dump'!$M$2:$M$538,'HD Dump'!$U$2:$U$538,D$7,'HD Dump'!$R$2:$R$538,">="&$B12-90,'HD Dump'!$R$2:$R$538,"<="&$B12),U11) | V12: =IF(COUNTIFS('HD Dump'!$U$2:$U$538,E$7,'HD Dump'!$R$2:$R$538,">="&$B12-90,'HD Dump'!$R$2:$R$538,"<="&$B12)>0,AVERAGEIFS('HD Dump'!$M$2:$M$538,'HD Dump'!$U$2:$U$538,E$7,'HD Dump'!$R$2:$R$538,">="&$B12-90,'HD Dump'!$R$2:$R$538,"<="&$B12),V11) | W12: =IF(COUNTIFS('HD Dump'!$U$2:$U$538,F$7,'HD Dump'!$R$2:$R$538,">="&$B12-90,'HD Dump'!$R$2:$R$538,"<="&$B12)>0,AVERAGEIFS('HD Dump'!$M$2:$M$538,'HD Dump'!$U$2:$U$538,F$7,'HD Dump'!$R$2:$R$538,">="&$B12-90,'HD Dump'!$R$2:$R$538,"<="&$B12),W11) | X12: =IF(COUNTIFS('HD Dump'!$U$2:$U$538,G$7,'HD Dump'!$R$2:$R$538,">="&$B12-90,'HD Dump'!$R$2:$R$538,"<="&$B12)>0,AVERAGEIFS('HD Dump'!$M$2:$M$538,'HD Dump'!$U$2:$U$538,G$7,'HD Dump'!$R$2:$R$538,">="&$B12-90,'HD Dump'!$R$2:$R$538,"<="&$B12),X11) | Y12: =IF(COUNTIFS('HD Dump'!$U$2:$U$538,H$7,'HD Dump'!$R$2:$R$538,">="&$B12-90,'HD Dump'!$R$2:$R$538,"<="&$B12)>0,AVERAGEIFS('HD Dump'!$M$2:$M$538,'HD Dump'!$U$2:$U$538,H$7,'HD Dump'!$R$2:$R$538,">="&$B12-90,'HD Dump'!$R$2:$R$538,"<="&$B12),Y11) | Z12: =IF(COUNTIFS('HD Dump'!$U$2:$U$538,I$7,'HD Dump'!$R$2:$R$538,">="&$B12-90,'HD Dump'!$R$2:$R$538,"<="&$B12)>0,AVERAGEIFS('HD Dump'!$M$2:$M$538,'HD Dump'!$U$2:$U$538,I$7,'HD Dump'!$R$2:$R$538,">="&$B12-90,'HD Dump'!$R$2:$R$538,"<="&$B12),Z11) | AA12: =IF(COUNTIFS('HD Dump'!$U$2:$U$538,J$7,'HD Dump'!$R$2:$R$538,">="&$B12-90,'HD Dump'!$R$2:$R$538,"<="&$B12)>0,AVERAGEIFS('HD Dump'!$M$2:$M$538,'HD Dump'!$U$2:$U$538,J$7,'HD Dump'!$R$2:$R$538,">="&$B12-90,'HD Dump'!$R$2:$R$538,"<="&$B12),AA11) | AB12: =IF(COUNTIFS('HD Dump'!$U$2:$U$538,K$7,'HD Dump'!$R$2:$R$538,">="&$B12-90,'HD Dump'!$R$2:$R$538,"<="&$B12)>0,AVERAGEIFS('HD Dump'!$M$2:$M$538,'HD Dump'!$U$2:$U$538,K$7,'HD Dump'!$R$2:$R$538,">="&$B12-90,'HD Dump'!$R$2:$R$538,"<="&$B12),AB11) | AD12: =IF(COUNTIFS('HD Dump'!$U$2:$U$538,C$7,'HD Dump'!$R$2:$R$538,">="&$B12-90,'HD Dump'!$R$2:$R$538,"<="&$B12)>0,AVERAGEIFS('HD Dump'!$O$2:$O$538,'HD Dump'!$U$2:$U$538,C$7,'HD Dump'!$R$2:$R$538,">="&$B12-90,'HD Dump'!$R$2:$R$538,"<="&$B12),AD11) | AE12: =IF(COUNTIFS('HD Dump'!$U$2:$U$538,D$7,'HD Dump'!$R$2:$R$538,">="&$B12-90,'HD Dump'!$R$2:$R$538,"<="&$B12)>0,AVERAGEIFS('HD Dump'!$O$2:$O$538,'HD Dump'!$U$2:$U$538,D$7,'HD Dump'!$R$2:$R$538,">="&$B12-90,'HD Dump'!$R$2:$R$538,"<="&$B12),AE11) | AF12: =IF(COUNTIFS('HD Dump'!$U$2:$U$538,E$7,'HD Dump'!$R$2:$R$538,">="&$B12-90,'HD Dump'!$R$2:$R$538,"<="&$B12)>0,AVERAGEIFS('HD Dump'!$O$2:$O$538,'HD Dump'!$U$2:$U$538,E$7,'HD Dump'!$R$2:$R$538,">="&$B12-90,'HD Dump'!$R$2:$R$538,"<="&$B12),AF11) | AG12: =IF(COUNTIFS('HD Dump'!$U$2:$U$538,F$7,'HD Dump'!$R$2:$R$538,">="&$B12-90,'HD Dump'!$R$2:$R$538,"<="&$B12)>0,AVERAGEIFS('HD Dump'!$O$2:$O$538,'HD Dump'!$U$2:$U$538,F$7,'HD Dump'!$R$2:$R$538,">="&$B12-90,'HD Dump'!$R$2:$R$538,"<="&$B12),AG11) | AH12: =IF(COUNTIFS('HD Dump'!$U$2:$U$538,G$7,'HD Dump'!$R$2:$R$538,">="&$B12-90,'HD Dump'!$R$2:$R$538,"<="&$B12)>0,AVERAGEIFS('HD Dump'!$O$2:$O$538,'HD Dump'!$U$2:$U$538,G$7,'HD Dump'!$R$2:$R$538,">="&$B12-90,'HD Dump'!$R$2:$R$538,"<="&$B12),AH11) | AI12: =IF(COUNTIFS('HD Dump'!$U$2:$U$538,H$7,'HD Dump'!$R$2:$R$538,">="&$B12-90,'HD Dump'!$R$2:$R$538,"<="&$B12)>0,AVERAGEIFS('HD Dump'!$O$2:$O$538,'HD Dump'!$U$2:$U$538,H$7,'HD Dump'!$R$2:$R$538,">="&$B12-90,'HD Dump'!$R$2:$R$538,"<="&$B12),AI11) | AJ12: =IF(COUNTIFS('HD Dump'!$U$2:$U$538,I$7,'HD Dump'!$R$2:$R$538,">="&$B12-90,'HD Dump'!$R$2:$R$538,"<="&$B12)>0,AVERAGEIFS('HD Dump'!$O$2:$O$538,'HD Dump'!$U$2:$U$538,I$7,'HD Dump'!$R$2:$R$538,">="&$B12-90,'HD Dump'!$R$2:$R$538,"<="&$B12),AJ11) | AK12: =IF(COUNTIFS('HD Dump'!$U$2:$U$538,J$7,'HD Dump'!$R$2:$R$538,">="&$B12-90,'HD Dump'!$R$2:$R$538,"<="&$B12)>0,AVERAGEIFS('HD Dump'!$O$2:$O$538,'HD Dump'!$U$2:$U$538,J$7,'HD Dump'!$R$2:$R$538,">="&$B12-90,'HD Dump'!$R$2:$R$538,"<="&$B12),AK11) | AL12: =IF(COUNTIFS('HD Dump'!$U$2:$U$538,K$7,'HD Dump'!$R$2:$R$538,">="&$B12-90,'HD Dump'!$R$2:$R$538,"<="&$B12)>0,AVERAGEIFS('HD Dump'!$O$2:$O$538,'HD Dump'!$U$2:$U$538,K$7,'HD Dump'!$R$2:$R$538,">="&$B12-90,'HD Dump'!$R$2:$R$538,"<="&$B12),AL11)
B13: 45565 | C13: Actual | D13: =SUMPRODUCT(T13:AB13,$C$8:$K$8)/SUM($C$8:$K$8) | E13: =SUMPRODUCT(AD13:AL13,$C$8:$K$8)/SUM($C$8:$K$8) | F13: =IFERROR((INDEX('T12 Dump'!$D$9:$O$9,MATCH(EOMONTH($B13,-1)+1,'T12 Dump'!$D$3:$O$3,0))-ABS(INDEX('T12 Dump'!$D$11:$O$11,MATCH(EOMONTH($B13,-1)+1,'T12 Dump'!$D$3:$O$3,0))))/($F13*360),"") | G13: =IFERROR(1-ABS(INDEX('T12 Dump'!$D$11:$O$11,MATCH(EOMONTH($B13,-1)+1,'T12 Dump'!$D$3:$O$3,0)))/INDEX('T12 Dump'!$D$7:$O$7,MATCH(EOMONTH($B13,-1)+1,'T12 Dump'!$D$3:$O$3,0)),"") | H13: =IFERROR($F13/$D13-1,"") | I13: 47 | T13: =IF(COUNTIFS('HD Dump'!$U$2:$U$538,C$7,'HD Dump'!$R$2:$R$538,">="&$B13-90,'HD Dump'!$R$2:$R$538,"<="&$B13)>0,AVERAGEIFS('HD Dump'!$M$2:$M$538,'HD Dump'!$U$2:$U$538,C$7,'HD Dump'!$R$2:$R$538,">="&$B13-90,'HD Dump'!$R$2:$R$538,"<="&$B13),T12) | U13: =IF(COUNTIFS('HD Dump'!$U$2:$U$538,D$7,'HD Dump'!$R$2:$R$538,">="&$B13-90,'HD Dump'!$R$2:$R$538,"<="&$B13)>0,AVERAGEIFS('HD Dump'!$M$2:$M$538,'HD Dump'!$U$2:$U$538,D$7,'HD Dump'!$R$2:$R$538,">="&$B13-90,'HD Dump'!$R$2:$R$538,"<="&$B13),U12) | V13: =IF(COUNTIFS('HD Dump'!$U$2:$U$538,E$7,'HD Dump'!$R$2:$R$538,">="&$B13-90,'HD Dump'!$R$2:$R$538,"<="&$B13)>0,AVERAGEIFS('HD Dump'!$M$2:$M$538,'HD Dump'!$U$2:$U$538,E$7,'HD Dump'!$R$2:$R$538,">="&$B13-90,'HD Dump'!$R$2:$R$538,"<="&$B13),V12) | W13: =IF(COUNTIFS('HD Dump'!$U$2:$U$538,F$7,'HD Dump'!$R$2:$R$538,">="&$B13-90,'HD Dump'!$R$2:$R$538,"<="&$B13)>0,AVERAGEIFS('HD Dump'!$M$2:$M$538,'HD Dump'!$U$2:$U$538,F$7,'HD Dump'!$R$2:$R$538,">="&$B13-90,'HD Dump'!$R$2:$R$538,"<="&$B13),W12) | X13: =IF(COUNTIFS('HD Dump'!$U$2:$U$538,G$7,'HD Dump'!$R$2:$R$538,">="&$B13-90,'HD Dump'!$R$2:$R$538,"<="&$B13)>0,AVERAGEIFS('HD Dump'!$M$2:$M$538,'HD Dump'!$U$2:$U$538,G$7,'HD Dump'!$R$2:$R$538,">="&$B13-90,'HD Dump'!$R$2:$R$538,"<="&$B13),X12) | Y13: =IF(COUNTIFS('HD Dump'!$U$2:$U$538,H$7,'HD Dump'!$R$2:$R$538,">="&$B13-90,'HD Dump'!$R$2:$R$538,"<="&$B13)>0,AVERAGEIFS('HD Dump'!$M$2:$M$538,'HD Dump'!$U$2:$U$538,H$7,'HD Dump'!$R$2:$R$538,">="&$B13-90,'HD Dump'!$R$2:$R$538,"<="&$B13),Y12) | Z13: =IF(COUNTIFS('HD Dump'!$U$2:$U$538,I$7,'HD Dump'!$R$2:$R$538,">="&$B13-90,'HD Dump'!$R$2:$R$538,"<="&$B13)>0,AVERAGEIFS('HD Dump'!$M$2:$M$538,'HD Dump'!$U$2:$U$538,I$7,'HD Dump'!$R$2:$R$538,">="&$B13-90,'HD Dump'!$R$2:$R$538,"<="&$B13),Z12) | AA13: =IF(COUNTIFS('HD Dump'!$U$2:$U$538,J$7,'HD Dump'!$R$2:$R$538,">="&$B13-90,'HD Dump'!$R$2:$R$538,"<="&$B13)>0,AVERAGEIFS('HD Dump'!$M$2:$M$538,'HD Dump'!$U$2:$U$538,J$7,'HD Dump'!$R$2:$R$538,">="&$B13-90,'HD Dump'!$R$2:$R$538,"<="&$B13),AA12) | AB13: =IF(COUNTIFS('HD Dump'!$U$2:$U$538,K$7,'HD Dump'!$R$2:$R$538,">="&$B13-90,'HD Dump'!$R$2:$R$538,"<="&$B13)>0,AVERAGEIFS('HD Dump'!$M$2:$M$538,'HD Dump'!$U$2:$U$538,K$7,'HD Dump'!$R$2:$R$538,">="&$B13-90,'HD Dump'!$R$2:$R$538,"<="&$B13),AB12) | AD13: =IF(COUNTIFS('HD Dump'!$U$2:$U$538,C$7,'HD Dump'!$R$2:$R$538,">="&$B13-90,'HD Dump'!$R$2:$R$538,"<="&$B13)>0,AVERAGEIFS('HD Dump'!$O$2:$O$538,'HD Dump'!$U$2:$U$538,C$7,'HD Dump'!$R$2:$R$538,">="&$B13-90,'HD Dump'!$R$2:$R$538,"<="&$B13),AD12) | AE13: =IF(COUNTIFS('HD Dump'!$U$2:$U$538,D$7,'HD Dump'!$R$2:$R$538,">="&$B13-90,'HD Dump'!$R$2:$R$538,"<="&$B13)>0,AVERAGEIFS('HD Dump'!$O$2:$O$538,'HD Dump'!$U$2:$U$538,D$7,'HD Dump'!$R$2:$R$538,">="&$B13-90,'HD Dump'!$R$2:$R$538,"<="&$B13),AE12) | AF13: =IF(COUNTIFS('HD Dump'!$U$2:$U$538,E$7,'HD Dump'!$R$2:$R$538,">="&$B13-90,'HD Dump'!$R$2:$R$538,"<="&$B13)>0,AVERAGEIFS('HD Dump'!$O$2:$O$538,'HD Dump'!$U$2:$U$538,E$7,'HD Dump'!$R$2:$R$538,">="&$B13-90,'HD Dump'!$R$2:$R$538,"<="&$B13),AF12) | AG13: =IF(COUNTIFS('HD Dump'!$U$2:$U$538,F$7,'HD Dump'!$R$2:$R$538,">="&$B13-90,'HD Dump'!$R$2:$R$538,"<="&$B13)>0,AVERAGEIFS('HD Dump'!$O$2:$O$538,'HD Dump'!$U$2:$U$538,F$7,'HD Dump'!$R$2:$R$538,">="&$B13-90,'HD Dump'!$R$2:$R$538,"<="&$B13),AG12) | AH13: =IF(COUNTIFS('HD Dump'!$U$2:$U$538,G$7,'HD Dump'!$R$2:$R$538,">="&$B13-90,'HD Dump'!$R$2:$R$538,"<="&$B13)>0,AVERAGEIFS('HD Dump'!$O$2:$O$538,'HD Dump'!$U$2:$U$538,G$7,'HD Dump'!$R$2:$R$538,">="&$B13-90,'HD Dump'!$R$2:$R$538,"<="&$B13),AH12) | AI13: =IF(COUNTIFS('HD Dump'!$U$2:$U$538,H$7,'HD Dump'!$R$2:$R$538,">="&$B13-90,'HD Dump'!$R$2:$R$538,"<="&$B13)>0,AVERAGEIFS('HD Dump'!$O$2:$O$538,'HD Dump'!$U$2:$U$538,H$7,'HD Dump'!$R$2:$R$538,">="&$B13-90,'HD Dump'!$R$2:$R$538,"<="&$B13),AI12) | AJ13: =IF(COUNTIFS('HD Dump'!$U$2:$U$538,I$7,'HD Dump'!$R$2:$R$538,">="&$B13-90,'HD Dump'!$R$2:$R$538,"<="&$B13)>0,AVERAGEIFS('HD Dump'!$O$2:$O$538,'HD Dump'!$U$2:$U$538,I$7,'HD Dump'!$R$2:$R$538,">="&$B13-90,'HD Dump'!$R$2:$R$538,"<="&$B13),AJ12) | AK13: =IF(COUNTIFS('HD Dump'!$U$2:$U$538,J$7,'HD Dump'!$R$2:$R$538,">="&$B13-90,'HD Dump'!$R$2:$R$538,"<="&$B13)>0,AVERAGEIFS('HD Dump'!$O$2:$O$538,'HD Dump'!$U$2:$U$538,J$7,'HD Dump'!$R$2:$R$538,">="&$B13-90,'HD Dump'!$R$2:$R$538,"<="&$B13),AK12) | AL13: =IF(COUNTIFS('HD Dump'!$U$2:$U$538,K$7,'HD Dump'!$R$2:$R$538,">="&$B13-90,'HD Dump'!$R$2:$R$538,"<="&$B13)>0,AVERAGEIFS('HD Dump'!$O$2:$O$538,'HD Dump'!$U$2:$U$538,K$7,'HD Dump'!$R$2:$R$538,">="&$B13-90,'HD Dump'!$R$2:$R$538,"<="&$B13),AL12)
B14: 45596 | C14: Actual | D14: =SUMPRODUCT(T14:AB14,$C$8:$K$8)/SUM($C$8:$K$8) | E14: =SUMPRODUCT(AD14:AL14,$C$8:$K$8)/SUM($C$8:$K$8) | F14: =IFERROR((INDEX('T12 Dump'!$D$9:$O$9,MATCH(EOMONTH($B14,-1)+1,'T12 Dump'!$D$3:$O$3,0))-ABS(INDEX('T12 Dump'!$D$11:$O$11,MATCH(EOMONTH($B14,-1)+1,'T12 Dump'!$D$3:$O$3,0))))/($F14*360),"") | G14: =IFERROR(1-ABS(INDEX('T12 Dump'!$D$11:$O$11,MATCH(EOMONTH($B14,-1)+1,'T12 Dump'!$D$3:$O$3,0)))/INDEX('T12 Dump'!$D$7:$O$7,MATCH(EOMONTH($B14,-1)+1,'T12 Dump'!$D$3:$O$3,0)),"") | H14: =IFERROR($F14/$D14-1,"") | I14: 19 | T14: =IF(COUNTIFS('HD Dump'!$U$2:$U$538,C$7,'HD Dump'!$R$2:$R$538,">="&$B14-90,'HD Dump'!$R$2:$R$538,"<="&$B14)>0,AVERAGEIFS('HD Dump'!$M$2:$M$538,'HD Dump'!$U$2:$U$538,C$7,'HD Dump'!$R$2:$R$538,">="&$B14-90,'HD Dump'!$R$2:$R$538,"<="&$B14),T13) | U14: =IF(COUNTIFS('HD Dump'!$U$2:$U$538,D$7,'HD Dump'!$R$2:$R$538,">="&$B14-90,'HD Dump'!$R$2:$R$538,"<="&$B14)>0,AVERAGEIFS('HD Dump'!$M$2:$M$538,'HD Dump'!$U$2:$U$538,D$7,'HD Dump'!$R$2:$R$538,">="&$B14-90,'HD Dump'!$R$2:$R$538,"<="&$B14),U13) | V14: =IF(COUNTIFS('HD Dump'!$U$2:$U$538,E$7,'HD Dump'!$R$2:$R$538,">="&$B14-90,'HD Dump'!$R$2:$R$538,"<="&$B14)>0,AVERAGEIFS('HD Dump'!$M$2:$M$538,'HD Dump'!$U$2:$U$538,E$7,'HD Dump'!$R$2:$R$538,">="&$B14-90,'HD Dump'!$R$2:$R$538,"<="&$B14),V13) | W14: =IF(COUNTIFS('HD Dump'!$U$2:$U$538,F$7,'HD Dump'!$R$2:$R$538,">="&$B14-90,'HD Dump'!$R$2:$R$538,"<="&$B14)>0,AVERAGEIFS('HD Dump'!$M$2:$M$538,'HD Dump'!$U$2:$U$538,F$7,'HD Dump'!$R$2:$R$538,">="&$B14-90,'HD Dump'!$R$2:$R$538,"<="&$B14),W13) | X14: =IF(COUNTIFS('HD Dump'!$U$2:$U$538,G$7,'HD Dump'!$R$2:$R$538,">="&$B14-90,'HD Dump'!$R$2:$R$538,"<="&$B14)>0,AVERAGEIFS('HD Dump'!$M$2:$M$538,'HD Dump'!$U$2:$U$538,G$7,'HD Dump'!$R$2:$R$538,">="&$B14-90,'HD Dump'!$R$2:$R$538,"<="&$B14),X13) | Y14: =IF(COUNTIFS('HD Dump'!$U$2:$U$538,H$7,'HD Dump'!$R$2:$R$538,">="&$B14-90,'HD Dump'!$R$2:$R$538,"<="&$B14)>0,AVERAGEIFS('HD Dump'!$M$2:$M$538,'HD Dump'!$U$2:$U$538,H$7,'HD Dump'!$R$2:$R$538,">="&$B14-90,'HD Dump'!$R$2:$R$538,"<="&$B14),Y13) | Z14: =IF(COUNTIFS('HD Dump'!$U$2:$U$538,I$7,'HD Dump'!$R$2:$R$538,">="&$B14-90,'HD Dump'!$R$2:$R$538,"<="&$B14)>0,AVERAGEIFS('HD Dump'!$M$2:$M$538,'HD Dump'!$U$2:$U$538,I$7,'HD Dump'!$R$2:$R$538,">="&$B14-90,'HD Dump'!$R$2:$R$538,"<="&$B14),Z13) | AA14: =IF(COUNTIFS('HD Dump'!$U$2:$U$538,J$7,'HD Dump'!$R$2:$R$538,">="&$B14-90,'HD Dump'!$R$2:$R$538,"<="&$B14)>0,AVERAGEIFS('HD Dump'!$M$2:$M$538,'HD Dump'!$U$2:$U$538,J$7,'HD Dump'!$R$2:$R$538,">="&$B14-90,'HD Dump'!$R$2:$R$538,"<="&$B14),AA13) | AB14: =IF(COUNTIFS('HD Dump'!$U$2:$U$538,K$7,'HD Dump'!$R$2:$R$538,">="&$B14-90,'HD Dump'!$R$2:$R$538,"<="&$B14)>0,AVERAGEIFS('HD Dump'!$M$2:$M$538,'HD Dump'!$U$2:$U$538,K$7,'HD Dump'!$R$2:$R$538,">="&$B14-90,'HD Dump'!$R$2:$R$538,"<="&$B14),AB13) | AD14: =IF(COUNTIFS('HD Dump'!$U$2:$U$538,C$7,'HD Dump'!$R$2:$R$538,">="&$B14-90,'HD Dump'!$R$2:$R$538,"<="&$B14)>0,AVERAGEIFS('HD Dump'!$O$2:$O$538,'HD Dump'!$U$2:$U$538,C$7,'HD Dump'!$R$2:$R$538,">="&$B14-90,'HD Dump'!$R$2:$R$538,"<="&$B14),AD13) | AE14: =IF(COUNTIFS('HD Dump'!$U$2:$U$538,D$7,'HD Dump'!$R$2:$R$538,">="&$B14-90,'HD Dump'!$R$2:$R$538,"<="&$B14)>0,AVERAGEIFS('HD Dump'!$O$2:$O$538,'HD Dump'!$U$2:$U$538,D$7,'HD Dump'!$R$2:$R$538,">="&$B14-90,'HD Dump'!$R$2:$R$538,"<="&$B14),AE13) | AF14: =IF(COUNTIFS('HD Dump'!$U$2:$U$538,E$7,'HD Dump'!$R$2:$R$538,">="&$B14-90,'HD Dump'!$R$2:$R$538,"<="&$B14)>0,AVERAGEIFS('HD Dump'!$O$2:$O$538,'HD Dump'!$U$2:$U$538,E$7,'HD Dump'!$R$2:$R$538,">="&$B14-90,'HD Dump'!$R$2:$R$538,"<="&$B14),AF13) | AG14: =IF(COUNTIFS('HD Dump'!$U$2:$U$538,F$7,'HD Dump'!$R$2:$R$538,">="&$B14-90,'HD Dump'!$R$2:$R$538,"<="&$B14)>0,AVERAGEIFS('HD Dump'!$O$2:$O$538,'HD Dump'!$U$2:$U$538,F$7,'HD Dump'!$R$2:$R$538,">="&$B14-90,'HD Dump'!$R$2:$R$538,"<="&$B14),AG13) | AH14: =IF(COUNTIFS('HD Dump'!$U$2:$U$538,G$7,'HD Dump'!$R$2:$R$538,">="&$B14-90,'HD Dump'!$R$2:$R$538,"<="&$B14)>0,AVERAGEIFS('HD Dump'!$O$2:$O$538,'HD Dump'!$U$2:$U$538,G$7,'HD Dump'!$R$2:$R$538,">="&$B14-90,'HD Dump'!$R$2:$R$538,"<="&$B14),AH13) | AI14: =IF(COUNTIFS('HD Dump'!$U$2:$U$538,H$7,'HD Dump'!$R$2:$R$538,">="&$B14-90,'HD Dump'!$R$2:$R$538,"<="&$B14)>0,AVERAGEIFS('HD Dump'!$O$2:$O$538,'HD Dump'!$U$2:$U$538,H$7,'HD Dump'!$R$2:$R$538,">="&$B14-90,'HD Dump'!$R$2:$R$538,"<="&$B14),AI13) | AJ14: =IF(COUNTIFS('HD Dump'!$U$2:$U$538,I$7,'HD Dump'!$R$2:$R$538,">="&$B14-90,'HD Dump'!$R$2:$R$538,"<="&$B14)>0,AVERAGEIFS('HD Dump'!$O$2:$O$538,'HD Dump'!$U$2:$U$538,I$7,'HD Dump'!$R$2:$R$538,">="&$B14-90,'HD Dump'!$R$2:$R$538,"<="&$B14),AJ13) | AK14: =IF(COUNTIFS('HD Dump'!$U$2:$U$538,J$7,'HD Dump'!$R$2:$R$538,">="&$B14-90,'HD Dump'!$R$2:$R$538,"<="&$B14)>0,AVERAGEIFS('HD Dump'!$O$2:$O$538,'HD Dump'!$U$2:$U$538,J$7,'HD Dump'!$R$2:$R$538,">="&$B14-90,'HD Dump'!$R$2:$R$538,"<="&$B14),AK13) | AL14: =IF(COUNTIFS('HD Dump'!$U$2:$U$538,K$7,'HD Dump'!$R$2:$R$538,">="&$B14-90,'HD Dump'!$R$2:$R$538,"<="&$B14)>0,AVERAGEIFS('HD Dump'!$O$2:$O$538,'HD Dump'!$U$2:$U$538,K$7,'HD Dump'!$R$2:$R$538,">="&$B14-90,'HD Dump'!$R$2:$R$538,"<="&$B14),AL13)
B15: 45626 | C15: Actual | D15: =SUMPRODUCT(T15:AB15,$C$8:$K$8)/SUM($C$8:$K$8) | E15: =SUMPRODUCT(AD15:AL15,$C$8:$K$8)/SUM($C$8:$K$8) | F15: =IFERROR((INDEX('T12 Dump'!$D$9:$O$9,MATCH(EOMONTH($B15,-1)+1,'T12 Dump'!$D$3:$O$3,0))-ABS(INDEX('T12 Dump'!$D$11:$O$11,MATCH(EOMONTH($B15,-1)+1,'T12 Dump'!$D$3:$O$3,0))))/($F15*360),"") | G15: =IFERROR(1-ABS(INDEX('T12 Dump'!$D$11:$O$11,MATCH(EOMONTH($B15,-1)+1,'T12 Dump'!$D$3:$O$3,0)))/INDEX('T12 Dump'!$D$7:$O$7,MATCH(EOMONTH($B15,-1)+1,'T12 Dump'!$D$3:$O$3,0)),"") | H15: =IFERROR($F15/$D15-1,"") | I15: 13 | T15: =IF(COUNTIFS('HD Dump'!$U$2:$U$538,C$7,'HD Dump'!$R$2:$R$538,">="&$B15-90,'HD Dump'!$R$2:$R$538,"<="&$B15)>0,AVERAGEIFS('HD Dump'!$M$2:$M$538,'HD Dump'!$U$2:$U$538,C$7,'HD Dump'!$R$2:$R$538,">="&$B15-90,'HD Dump'!$R$2:$R$538,"<="&$B15),T14) | U15: =IF(COUNTIFS('HD Dump'!$U$2:$U$538,D$7,'HD Dump'!$R$2:$R$538,">="&$B15-90,'HD Dump'!$R$2:$R$538,"<="&$B15)>0,AVERAGEIFS('HD Dump'!$M$2:$M$538,'HD Dump'!$U$2:$U$538,D$7,'HD Dump'!$R$2:$R$538,">="&$B15-90,'HD Dump'!$R$2:$R$538,"<="&$B15),U14) | V15: =IF(COUNTIFS('HD Dump'!$U$2:$U$538,E$7,'HD Dump'!$R$2:$R$538,">="&$B15-90,'HD Dump'!$R$2:$R$538,"<="&$B15)>0,AVERAGEIFS('HD Dump'!$M$2:$M$538,'HD Dump'!$U$2:$U$538,E$7,'HD Dump'!$R$2:$R$538,">="&$B15-90,'HD Dump'!$R$2:$R$538,"<="&$B15),V14) | W15: =IF(COUNTIFS('HD Dump'!$U$2:$U$538,F$7,'HD Dump'!$R$2:$R$538,">="&$B15-90,'HD Dump'!$R$2:$R$538,"<="&$B15)>0,AVERAGEIFS('HD Dump'!$M$2:$M$538,'HD Dump'!$U$2:$U$538,F$7,'HD Dump'!$R$2:$R$538,">="&$B15-90,'HD Dump'!$R$2:$R$538,"<="&$B15),W14) | X15: =IF(COUNTIFS('HD Dump'!$U$2:$U$538,G$7,'HD Dump'!$R$2:$R$538,">="&$B15-90,'HD Dump'!$R$2:$R$538,"<="&$B15)>0,AVERAGEIFS('HD Dump'!$M$2:$M$538,'HD Dump'!$U$2:$U$538,G$7,'HD Dump'!$R$2:$R$538,">="&$B15-90,'HD Dump'!$R$2:$R$538,"<="&$B15),X14) | Y15: =IF(COUNTIFS('HD Dump'!$U$2:$U$538,H$7,'HD Dump'!$R$2:$R$538,">="&$B15-90,'HD Dump'!$R$2:$R$538,"<="&$B15)>0,AVERAGEIFS('HD Dump'!$M$2:$M$538,'HD Dump'!$U$2:$U$538,H$7,'HD Dump'!$R$2:$R$538,">="&$B15-90,'HD Dump'!$R$2:$R$538,"<="&$B15),Y14) | Z15: =IF(COUNTIFS('HD Dump'!$U$2:$U$538,I$7,'HD Dump'!$R$2:$R$538,">="&$B15-90,'HD Dump'!$R$2:$R$538,"<="&$B15)>0,AVERAGEIFS('HD Dump'!$M$2:$M$538,'HD Dump'!$U$2:$U$538,I$7,'HD Dump'!$R$2:$R$538,">="&$B15-90,'HD Dump'!$R$2:$R$538,"<="&$B15),Z14) | AA15: =IF(COUNTIFS('HD Dump'!$U$2:$U$538,J$7,'HD Dump'!$R$2:$R$538,">="&$B15-90,'HD Dump'!$R$2:$R$538,"<="&$B15)>0,AVERAGEIFS('HD Dump'!$M$2:$M$538,'HD Dump'!$U$2:$U$538,J$7,'HD Dump'!$R$2:$R$538,">="&$B15-90,'HD Dump'!$R$2:$R$538,"<="&$B15),AA14) | AB15: =IF(COUNTIFS('HD Dump'!$U$2:$U$538,K$7,'HD Dump'!$R$2:$R$538,">="&$B15-90,'HD Dump'!$R$2:$R$538,"<="&$B15)>0,AVERAGEIFS('HD Dump'!$M$2:$M$538,'HD Dump'!$U$2:$U$538,K$7,'HD Dump'!$R$2:$R$538,">="&$B15-90,'HD Dump'!$R$2:$R$538,"<="&$B15),AB14) | AD15: =IF(COUNTIFS('HD Dump'!$U$2:$U$538,C$7,'HD Dump'!$R$2:$R$538,">="&$B15-90,'HD Dump'!$R$2:$R$538,"<="&$B15)>0,AVERAGEIFS('HD Dump'!$O$2:$O$538,'HD Dump'!$U$2:$U$538,C$7,'HD Dump'!$R$2:$R$538,">="&$B15-90,'HD Dump'!$R$2:$R$538,"<="&$B15),AD14) | AE15: =IF(COUNTIFS('HD Dump'!$U$2:$U$538,D$7,'HD Dump'!$R$2:$R$538,">="&$B15-90,'HD Dump'!$R$2:$R$538,"<="&$B15)>0,AVERAGEIFS('HD Dump'!$O$2:$O$538,'HD Dump'!$U$2:$U$538,D$7,'HD Dump'!$R$2:$R$538,">="&$B15-90,'HD Dump'!$R$2:$R$538,"<="&$B15),AE14) | AF15: =IF(COUNTIFS('HD Dump'!$U$2:$U$538,E$7,'HD Dump'!$R$2:$R$538,">="&$B15-90,'HD Dump'!$R$2:$R$538,"<="&$B15)>0,AVERAGEIFS('HD Dump'!$O$2:$O$538,'HD Dump'!$U$2:$U$538,E$7,'HD Dump'!$R$2:$R$538,">="&$B15-90,'HD Dump'!$R$2:$R$538,"<="&$B15),AF14) | AG15: =IF(COUNTIFS('HD Dump'!$U$2:$U$538,F$7,'HD Dump'!$R$2:$R$538,">="&$B15-90,'HD Dump'!$R$2:$R$538,"<="&$B15)>0,AVERAGEIFS('HD Dump'!$O$2:$O$538,'HD Dump'!$U$2:$U$538,F$7,'HD Dump'!$R$2:$R$538,">="&$B15-90,'HD Dump'!$R$2:$R$538,"<="&$B15),AG14) | AH15: =IF(COUNTIFS('HD Dump'!$U$2:$U$538,G$7,'HD Dump'!$R$2:$R$538,">="&$B15-90,'HD Dump'!$R$2:$R$538,"<="&$B15)>0,AVERAGEIFS('HD Dump'!$O$2:$O$538,'HD Dump'!$U$2:$U$538,G$7,'HD Dump'!$R$2:$R$538,">="&$B15-90,'HD Dump'!$R$2:$R$538,"<="&$B15),AH14) | AI15: =IF(COUNTIFS('HD Dump'!$U$2:$U$538,H$7,'HD Dump'!$R$2:$R$538,">="&$B15-90,'HD Dump'!$R$2:$R$538,"<="&$B15)>0,AVERAGEIFS('HD Dump'!$O$2:$O$538,'HD Dump'!$U$2:$U$538,H$7,'HD Dump'!$R$2:$R$538,">="&$B15-90,'HD Dump'!$R$2:$R$538,"<="&$B15),AI14) | AJ15: =IF(COUNTIFS('HD Dump'!$U$2:$U$538,I$7,'HD Dump'!$R$2:$R$538,">="&$B15-90,'HD Dump'!$R$2:$R$538,"<="&$B15)>0,AVERAGEIFS('HD Dump'!$O$2:$O$538,'HD Dump'!$U$2:$U$538,I$7,'HD Dump'!$R$2:$R$538,">="&$B15-90,'HD Dump'!$R$2:$R$538,"<="&$B15),AJ14) | AK15: =IF(COUNTIFS('HD Dump'!$U$2:$U$538,J$7,'HD Dump'!$R$2:$R$538,">="&$B15-90,'HD Dump'!$R$2:$R$538,"<="&$B15)>0,AVERAGEIFS('HD Dump'!$O$2:$O$538,'HD Dump'!$U$2:$U$538,J$7,'HD Dump'!$R$2:$R$538,">="&$B15-90,'HD Dump'!$R$2:$R$538,"<="&$B15),AK14) | AL15: =IF(COUNTIFS('HD Dump'!$U$2:$U$538,K$7,'HD Dump'!$R$2:$R$538,">="&$B15-90,'HD Dump'!$R$2:$R$538,"<="&$B15)>0,AVERAGEIFS('HD Dump'!$O$2:$O$538,'HD Dump'!$U$2:$U$538,K$7,'HD Dump'!$R$2:$R$538,">="&$B15-90,'HD Dump'!$R$2:$R$538,"<="&$B15),AL14)
B16: 45657 | C16: Actual | D16: =SUMPRODUCT(T16:AB16,$C$8:$K$8)/SUM($C$8:$K$8) | E16: =SUMPRODUCT(AD16:AL16,$C$8:$K$8)/SUM($C$8:$K$8) | F16: =IFERROR((INDEX('T12 Dump'!$D$9:$O$9,MATCH(EOMONTH($B16,-1)+1,'T12 Dump'!$D$3:$O$3,0))-ABS(INDEX('T12 Dump'!$D$11:$O$11,MATCH(EOMONTH($B16,-1)+1,'T12 Dump'!$D$3:$O$3,0))))/($F16*360),"") | G16: =IFERROR(1-ABS(INDEX('T12 Dump'!$D$11:$O$11,MATCH(EOMONTH($B16,-1)+1,'T12 Dump'!$D$3:$O$3,0)))/INDEX('T12 Dump'!$D$7:$O$7,MATCH(EOMONTH($B16,-1)+1,'T12 Dump'!$D$3:$O$3,0)),"") | H16: =IFERROR($F16/$D16-1,"") | I16: 9 | T16: =IF(COUNTIFS('HD Dump'!$U$2:$U$538,C$7,'HD Dump'!$R$2:$R$538,">="&$B16-90,'HD Dump'!$R$2:$R$538,"<="&$B16)>0,AVERAGEIFS('HD Dump'!$M$2:$M$538,'HD Dump'!$U$2:$U$538,C$7,'HD Dump'!$R$2:$R$538,">="&$B16-90,'HD Dump'!$R$2:$R$538,"<="&$B16),T15) | U16: =IF(COUNTIFS('HD Dump'!$U$2:$U$538,D$7,'HD Dump'!$R$2:$R$538,">="&$B16-90,'HD Dump'!$R$2:$R$538,"<="&$B16)>0,AVERAGEIFS('HD Dump'!$M$2:$M$538,'HD Dump'!$U$2:$U$538,D$7,'HD Dump'!$R$2:$R$538,">="&$B16-90,'HD Dump'!$R$2:$R$538,"<="&$B16),U15) | V16: =IF(COUNTIFS('HD Dump'!$U$2:$U$538,E$7,'HD Dump'!$R$2:$R$538,">="&$B16-90,'HD Dump'!$R$2:$R$538,"<="&$B16)>0,AVERAGEIFS('HD Dump'!$M$2:$M$538,'HD Dump'!$U$2:$U$538,E$7,'HD Dump'!$R$2:$R$538,">="&$B16-90,'HD Dump'!$R$2:$R$538,"<="&$B16),V15) | W16: =IF(COUNTIFS('HD Dump'!$U$2:$U$538,F$7,'HD Dump'!$R$2:$R$538,">="&$B16-90,'HD Dump'!$R$2:$R$538,"<="&$B16)>0,AVERAGEIFS('HD Dump'!$M$2:$M$538,'HD Dump'!$U$2:$U$538,F$7,'HD Dump'!$R$2:$R$538,">="&$B16-90,'HD Dump'!$R$2:$R$538,"<="&$B16),W15) | X16: =IF(COUNTIFS('HD Dump'!$U$2:$U$538,G$7,'HD Dump'!$R$2:$R$538,">="&$B16-90,'HD Dump'!$R$2:$R$538,"<="&$B16)>0,AVERAGEIFS('HD Dump'!$M$2:$M$538,'HD Dump'!$U$2:$U$538,G$7,'HD Dump'!$R$2:$R$538,">="&$B16-90,'HD Dump'!$R$2:$R$538,"<="&$B16),X15) | Y16: =IF(COUNTIFS('HD Dump'!$U$2:$U$538,H$7,'HD Dump'!$R$2:$R$538,">="&$B16-90,'HD Dump'!$R$2:$R$538,"<="&$B16)>0,AVERAGEIFS('HD Dump'!$M$2:$M$538,'HD Dump'!$U$2:$U$538,H$7,'HD Dump'!$R$2:$R$538,">="&$B16-90,'HD Dump'!$R$2:$R$538,"<="&$B16),Y15) | Z16: =IF(COUNTIFS('HD Dump'!$U$2:$U$538,I$7,'HD Dump'!$R$2:$R$538,">="&$B16-90,'HD Dump'!$R$2:$R$538,"<="&$B16)>0,AVERAGEIFS('HD Dump'!$M$2:$M$538,'HD Dump'!$U$2:$U$538,I$7,'HD Dump'!$R$2:$R$538,">="&$B16-90,'HD Dump'!$R$2:$R$538,"<="&$B16),Z15) | AA16: =IF(COUNTIFS('HD Dump'!$U$2:$U$538,J$7,'HD Dump'!$R$2:$R$538,">="&$B16-90,'HD Dump'!$R$2:$R$538,"<="&$B16)>0,AVERAGEIFS('HD Dump'!$M$2:$M$538,'HD Dump'!$U$2:$U$538,J$7,'HD Dump'!$R$2:$R$538,">="&$B16-90,'HD Dump'!$R$2:$R$538,"<="&$B16),AA15) | AB16: =IF(COUNTIFS('HD Dump'!$U$2:$U$538,K$7,'HD Dump'!$R$2:$R$538,">="&$B16-90,'HD Dump'!$R$2:$R$538,"<="&$B16)>0,AVERAGEIFS('HD Dump'!$M$2:$M$538,'HD Dump'!$U$2:$U$538,K$7,'HD Dump'!$R$2:$R$538,">="&$B16-90,'HD Dump'!$R$2:$R$538,"<="&$B16),AB15) | AD16: =IF(COUNTIFS('HD Dump'!$U$2:$U$538,C$7,'HD Dump'!$R$2:$R$538,">="&$B16-90,'HD Dump'!$R$2:$R$538,"<="&$B16)>0,AVERAGEIFS('HD Dump'!$O$2:$O$538,'HD Dump'!$U$2:$U$538,C$7,'HD Dump'!$R$2:$R$538,">="&$B16-90,'HD Dump'!$R$2:$R$538,"<="&$B16),AD15) | AE16: =IF(COUNTIFS('HD Dump'!$U$2:$U$538,D$7,'HD Dump'!$R$2:$R$538,">="&$B16-90,'HD Dump'!$R$2:$R$538,"<="&$B16)>0,AVERAGEIFS('HD Dump'!$O$2:$O$538,'HD Dump'!$U$2:$U$538,D$7,'HD Dump'!$R$2:$R$538,">="&$B16-90,'HD Dump'!$R$2:$R$538,"<="&$B16),AE15) | AF16: =IF(COUNTIFS('HD Dump'!$U$2:$U$538,E$7,'HD Dump'!$R$2:$R$538,">="&$B16-90,'HD Dump'!$R$2:$R$538,"<="&$B16)>0,AVERAGEIFS('HD Dump'!$O$2:$O$538,'HD Dump'!$U$2:$U$538,E$7,'HD Dump'!$R$2:$R$538,">="&$B16-90,'HD Dump'!$R$2:$R$538,"<="&$B16),AF15) | AG16: =IF(COUNTIFS('HD Dump'!$U$2:$U$538,F$7,'HD Dump'!$R$2:$R$538,">="&$B16-90,'HD Dump'!$R$2:$R$538,"<="&$B16)>0,AVERAGEIFS('HD Dump'!$O$2:$O$538,'HD Dump'!$U$2:$U$538,F$7,'HD Dump'!$R$2:$R$538,">="&$B16-90,'HD Dump'!$R$2:$R$538,"<="&$B16),AG15) | AH16: =IF(COUNTIFS('HD Dump'!$U$2:$U$538,G$7,'HD Dump'!$R$2:$R$538,">="&$B16-90,'HD Dump'!$R$2:$R$538,"<="&$B16)>0,AVERAGEIFS('HD Dump'!$O$2:$O$538,'HD Dump'!$U$2:$U$538,G$7,'HD Dump'!$R$2:$R$538,">="&$B16-90,'HD Dump'!$R$2:$R$538,"<="&$B16),AH15) | AI16: =IF(COUNTIFS('HD Dump'!$U$2:$U$538,H$7,'HD Dump'!$R$2:$R$538,">="&$B16-90,'HD Dump'!$R$2:$R$538,"<="&$B16)>0,AVERAGEIFS('HD Dump'!$O$2:$O$538,'HD Dump'!$U$2:$U$538,H$7,'HD Dump'!$R$2:$R$538,">="&$B16-90,'HD Dump'!$R$2:$R$538,"<="&$B16),AI15) | AJ16: =IF(COUNTIFS('HD Dump'!$U$2:$U$538,I$7,'HD Dump'!$R$2:$R$538,">="&$B16-90,'HD Dump'!$R$2:$R$538,"<="&$B16)>0,AVERAGEIFS('HD Dump'!$O$2:$O$538,'HD Dump'!$U$2:$U$538,I$7,'HD Dump'!$R$2:$R$538,">="&$B16-90,'HD Dump'!$R$2:$R$538,"<="&$B16),AJ15) | AK16: =IF(COUNTIFS('HD Dump'!$U$2:$U$538,J$7,'HD Dump'!$R$2:$R$538,">="&$B16-90,'HD Dump'!$R$2:$R$538,"<="&$B16)>0,AVERAGEIFS('HD Dump'!$O$2:$O$538,'HD Dump'!$U$2:$U$538,J$7,'HD Dump'!$R$2:$R$538,">="&$B16-90,'HD Dump'!$R$2:$R$538,"<="&$B16),AK15) | AL16: =IF(COUNTIFS('HD Dump'!$U$2:$U$538,K$7,'HD Dump'!$R$2:$R$538,">="&$B16-90,'HD Dump'!$R$2:$R$538,"<="&$B16)>0,AVERAGEIFS('HD Dump'!$O$2:$O$538,'HD Dump'!$U$2:$U$538,K$7,'HD Dump'!$R$2:$R$538,">="&$B16-90,'HD Dump'!$R$2:$R$538,"<="&$B16),AL15)
B17: 45688 | C17: Actual | D17: =SUMPRODUCT(T17:AB17,$C$8:$K$8)/SUM($C$8:$K$8) | E17: =SUMPRODUCT(AD17:AL17,$C$8:$K$8)/SUM($C$8:$K$8) | F17: =IFERROR((INDEX('T12 Dump'!$D$9:$O$9,MATCH(EOMONTH($B17,-1)+1,'T12 Dump'!$D$3:$O$3,0))-ABS(INDEX('T12 Dump'!$D$11:$O$11,MATCH(EOMONTH($B17,-1)+1,'T12 Dump'!$D$3:$O$3,0))))/($F17*360),"") | G17: =IFERROR(1-ABS(INDEX('T12 Dump'!$D$11:$O$11,MATCH(EOMONTH($B17,-1)+1,'T12 Dump'!$D$3:$O$3,0)))/INDEX('T12 Dump'!$D$7:$O$7,MATCH(EOMONTH($B17,-1)+1,'T12 Dump'!$D$3:$O$3,0)),"") | H17: =IFERROR($F17/$D17-1,"") | I17: 28 | T17: =IF(COUNTIFS('HD Dump'!$U$2:$U$538,C$7,'HD Dump'!$R$2:$R$538,">="&$B17-90,'HD Dump'!$R$2:$R$538,"<="&$B17)>0,AVERAGEIFS('HD Dump'!$M$2:$M$538,'HD Dump'!$U$2:$U$538,C$7,'HD Dump'!$R$2:$R$538,">="&$B17-90,'HD Dump'!$R$2:$R$538,"<="&$B17),T16) | U17: =IF(COUNTIFS('HD Dump'!$U$2:$U$538,D$7,'HD Dump'!$R$2:$R$538,">="&$B17-90,'HD Dump'!$R$2:$R$538,"<="&$B17)>0,AVERAGEIFS('HD Dump'!$M$2:$M$538,'HD Dump'!$U$2:$U$538,D$7,'HD Dump'!$R$2:$R$538,">="&$B17-90,'HD Dump'!$R$2:$R$538,"<="&$B17),U16) | V17: =IF(COUNTIFS('HD Dump'!$U$2:$U$538,E$7,'HD Dump'!$R$2:$R$538,">="&$B17-90,'HD Dump'!$R$2:$R$538,"<="&$B17)>0,AVERAGEIFS('HD Dump'!$M$2:$M$538,'HD Dump'!$U$2:$U$538,E$7,'HD Dump'!$R$2:$R$538,">="&$B17-90,'HD Dump'!$R$2:$R$538,"<="&$B17),V16) | W17: =IF(COUNTIFS('HD Dump'!$U$2:$U$538,F$7,'HD Dump'!$R$2:$R$538,">="&$B17-90,'HD Dump'!$R$2:$R$538,"<="&$B17)>0,AVERAGEIFS('HD Dump'!$M$2:$M$538,'HD Dump'!$U$2:$U$538,F$7,'HD Dump'!$R$2:$R$538,">="&$B17-90,'HD Dump'!$R$2:$R$538,"<="&$B17),W16) | X17: =IF(COUNTIFS('HD Dump'!$U$2:$U$538,G$7,'HD Dump'!$R$2:$R$538,">="&$B17-90,'HD Dump'!$R$2:$R$538,"<="&$B17)>0,AVERAGEIFS('HD Dump'!$M$2:$M$538,'HD Dump'!$U$2:$U$538,G$7,'HD Dump'!$R$2:$R$538,">="&$B17-90,'HD Dump'!$R$2:$R$538,"<="&$B17),X16) | Y17: =IF(COUNTIFS('HD Dump'!$U$2:$U$538,H$7,'HD Dump'!$R$2:$R$538,">="&$B17-90,'HD Dump'!$R$2:$R$538,"<="&$B17)>0,AVERAGEIFS('HD Dump'!$M$2:$M$538,'HD Dump'!$U$2:$U$538,H$7,'HD Dump'!$R$2:$R$538,">="&$B17-90,'HD Dump'!$R$2:$R$538,"<="&$B17),Y16) | Z17: =IF(COUNTIFS('HD Dump'!$U$2:$U$538,I$7,'HD Dump'!$R$2:$R$538,">="&$B17-90,'HD Dump'!$R$2:$R$538,"<="&$B17)>0,AVERAGEIFS('HD Dump'!$M$2:$M$538,'HD Dump'!$U$2:$U$538,I$7,'HD Dump'!$R$2:$R$538,">="&$B17-90,'HD Dump'!$R$2:$R$538,"<="&$B17),Z16) | AA17: =IF(COUNTIFS('HD Dump'!$U$2:$U$538,J$7,'HD Dump'!$R$2:$R$538,">="&$B17-90,'HD Dump'!$R$2:$R$538,"<="&$B17)>0,AVERAGEIFS('HD Dump'!$M$2:$M$538,'HD Dump'!$U$2:$U$538,J$7,'HD Dump'!$R$2:$R$538,">="&$B17-90,'HD Dump'!$R$2:$R$538,"<="&$B17),AA16) | AB17: =IF(COUNTIFS('HD Dump'!$U$2:$U$538,K$7,'HD Dump'!$R$2:$R$538,">="&$B17-90,'HD Dump'!$R$2:$R$538,"<="&$B17)>0,AVERAGEIFS('HD Dump'!$M$2:$M$538,'HD Dump'!$U$2:$U$538,K$7,'HD Dump'!$R$2:$R$538,">="&$B17-90,'HD Dump'!$R$2:$R$538,"<="&$B17),AB16) | AD17: =IF(COUNTIFS('HD Dump'!$U$2:$U$538,C$7,'HD Dump'!$R$2:$R$538,">="&$B17-90,'HD Dump'!$R$2:$R$538,"<="&$B17)>0,AVERAGEIFS('HD Dump'!$O$2:$O$538,'HD Dump'!$U$2:$U$538,C$7,'HD Dump'!$R$2:$R$538,">="&$B17-90,'HD Dump'!$R$2:$R$538,"<="&$B17),AD16) | AE17: =IF(COUNTIFS('HD Dump'!$U$2:$U$538,D$7,'HD Dump'!$R$2:$R$538,">="&$B17-90,'HD Dump'!$R$2:$R$538,"<="&$B17)>0,AVERAGEIFS('HD Dump'!$O$2:$O$538,'HD Dump'!$U$2:$U$538,D$7,'HD Dump'!$R$2:$R$538,">="&$B17-90,'HD Dump'!$R$2:$R$538,"<="&$B17),AE16) | AF17: =IF(COUNTIFS('HD Dump'!$U$2:$U$538,E$7,'HD Dump'!$R$2:$R$538,">="&$B17-90,'HD Dump'!$R$2:$R$538,"<="&$B17)>0,AVERAGEIFS('HD Dump'!$O$2:$O$538,'HD Dump'!$U$2:$U$538,E$7,'HD Dump'!$R$2:$R$538,">="&$B17-90,'HD Dump'!$R$2:$R$538,"<="&$B17),AF16) | AG17: =IF(COUNTIFS('HD Dump'!$U$2:$U$538,F$7,'HD Dump'!$R$2:$R$538,">="&$B17-90,'HD Dump'!$R$2:$R$538,"<="&$B17)>0,AVERAGEIFS('HD Dump'!$O$2:$O$538,'HD Dump'!$U$2:$U$538,F$7,'HD Dump'!$R$2:$R$538,">="&$B17-90,'HD Dump'!$R$2:$R$538,"<="&$B17),AG16) | AH17: =IF(COUNTIFS('HD Dump'!$U$2:$U$538,G$7,'HD Dump'!$R$2:$R$538,">="&$B17-90,'HD Dump'!$R$2:$R$538,"<="&$B17)>0,AVERAGEIFS('HD Dump'!$O$2:$O$538,'HD Dump'!$U$2:$U$538,G$7,'HD Dump'!$R$2:$R$538,">="&$B17-90,'HD Dump'!$R$2:$R$538,"<="&$B17),AH16) | AI17: =IF(COUNTIFS('HD Dump'!$U$2:$U$538,H$7,'HD Dump'!$R$2:$R$538,">="&$B17-90,'HD Dump'!$R$2:$R$538,"<="&$B17)>0,AVERAGEIFS('HD Dump'!$O$2:$O$538,'HD Dump'!$U$2:$U$538,H$7,'HD Dump'!$R$2:$R$538,">="&$B17-90,'HD Dump'!$R$2:$R$538,"<="&$B17),AI16) | AJ17: =IF(COUNTIFS('HD Dump'!$U$2:$U$538,I$7,'HD Dump'!$R$2:$R$538,">="&$B17-90,'HD Dump'!$R$2:$R$538,"<="&$B17)>0,AVERAGEIFS('HD Dump'!$O$2:$O$538,'HD Dump'!$U$2:$U$538,I$7,'HD Dump'!$R$2:$R$538,">="&$B17-90,'HD Dump'!$R$2:$R$538,"<="&$B17),AJ16) | AK17: =IF(COUNTIFS('HD Dump'!$U$2:$U$538,J$7,'HD Dump'!$R$2:$R$538,">="&$B17-90,'HD Dump'!$R$2:$R$538,"<="&$B17)>0,AVERAGEIFS('HD Dump'!$O$2:$O$538,'HD Dump'!$U$2:$U$538,J$7,'HD Dump'!$R$2:$R$538,">="&$B17-90,'HD Dump'!$R$2:$R$538,"<="&$B17),AK16) | AL17: =IF(COUNTIFS('HD Dump'!$U$2:$U$538,K$7,'HD Dump'!$R$2:$R$538,">="&$B17-90,'HD Dump'!$R$2:$R$538,"<="&$B17)>0,AVERAGEIFS('HD Dump'!$O$2:$O$538,'HD Dump'!$U$2:$U$538,K$7,'HD Dump'!$R$2:$R$538,">="&$B17-90,'HD Dump'!$R$2:$R$538,"<="&$B17),AL16)
B18: 45716 | C18: Actual | D18: =SUMPRODUCT(T18:AB18,$C$8:$K$8)/SUM($C$8:$K$8) | E18: =SUMPRODUCT(AD18:AL18,$C$8:$K$8)/SUM($C$8:$K$8) | F18: =IFERROR((INDEX('T12 Dump'!$D$9:$O$9,MATCH(EOMONTH($B18,-1)+1,'T12 Dump'!$D$3:$O$3,0))-ABS(INDEX('T12 Dump'!$D$11:$O$11,MATCH(EOMONTH($B18,-1)+1,'T12 Dump'!$D$3:$O$3,0))))/($F18*360),"") | G18: =IFERROR(1-ABS(INDEX('T12 Dump'!$D$11:$O$11,MATCH(EOMONTH($B18,-1)+1,'T12 Dump'!$D$3:$O$3,0)))/INDEX('T12 Dump'!$D$7:$O$7,MATCH(EOMONTH($B18,-1)+1,'T12 Dump'!$D$3:$O$3,0)),"") | H18: =IFERROR($F18/$D18-1,"") | I18: 14 | T18: =IF(COUNTIFS('HD Dump'!$U$2:$U$538,C$7,'HD Dump'!$R$2:$R$538,">="&$B18-90,'HD Dump'!$R$2:$R$538,"<="&$B18)>0,AVERAGEIFS('HD Dump'!$M$2:$M$538,'HD Dump'!$U$2:$U$538,C$7,'HD Dump'!$R$2:$R$538,">="&$B18-90,'HD Dump'!$R$2:$R$538,"<="&$B18),T17) | U18: =IF(COUNTIFS('HD Dump'!$U$2:$U$538,D$7,'HD Dump'!$R$2:$R$538,">="&$B18-90,'HD Dump'!$R$2:$R$538,"<="&$B18)>0,AVERAGEIFS('HD Dump'!$M$2:$M$538,'HD Dump'!$U$2:$U$538,D$7,'HD Dump'!$R$2:$R$538,">="&$B18-90,'HD Dump'!$R$2:$R$538,"<="&$B18),U17) | V18: =IF(COUNTIFS('HD Dump'!$U$2:$U$538,E$7,'HD Dump'!$R$2:$R$538,">="&$B18-90,'HD Dump'!$R$2:$R$538,"<="&$B18)>0,AVERAGEIFS('HD Dump'!$M$2:$M$538,'HD Dump'!$U$2:$U$538,E$7,'HD Dump'!$R$2:$R$538,">="&$B18-90,'HD Dump'!$R$2:$R$538,"<="&$B18),V17) | W18: =IF(COUNTIFS('HD Dump'!$U$2:$U$538,F$7,'HD Dump'!$R$2:$R$538,">="&$B18-90,'HD Dump'!$R$2:$R$538,"<="&$B18)>0,AVERAGEIFS('HD Dump'!$M$2:$M$538,'HD Dump'!$U$2:$U$538,F$7,'HD Dump'!$R$2:$R$538,">="&$B18-90,'HD Dump'!$R$2:$R$538,"<="&$B18),W17) | X18: =IF(COUNTIFS('HD Dump'!$U$2:$U$538,G$7,'HD Dump'!$R$2:$R$538,">="&$B18-90,'HD Dump'!$R$2:$R$538,"<="&$B18)>0,AVERAGEIFS('HD Dump'!$M$2:$M$538,'HD Dump'!$U$2:$U$538,G$7,'HD Dump'!$R$2:$R$538,">="&$B18-90,'HD Dump'!$R$2:$R$538,"<="&$B18),X17) | Y18: =IF(COUNTIFS('HD Dump'!$U$2:$U$538,H$7,'HD Dump'!$R$2:$R$538,">="&$B18-90,'HD Dump'!$R$2:$R$538,"<="&$B18)>0,AVERAGEIFS('HD Dump'!$M$2:$M$538,'HD Dump'!$U$2:$U$538,H$7,'HD Dump'!$R$2:$R$538,">="&$B18-90,'HD Dump'!$R$2:$R$538,"<="&$B18),Y17) | Z18: =IF(COUNTIFS('HD Dump'!$U$2:$U$538,I$7,'HD Dump'!$R$2:$R$538,">="&$B18-90,'HD Dump'!$R$2:$R$538,"<="&$B18)>0,AVERAGEIFS('HD Dump'!$M$2:$M$538,'HD Dump'!$U$2:$U$538,I$7,'HD Dump'!$R$2:$R$538,">="&$B18-90,'HD Dump'!$R$2:$R$538,"<="&$B18),Z17) | AA18: =IF(COUNTIFS('HD Dump'!$U$2:$U$538,J$7,'HD Dump'!$R$2:$R$538,">="&$B18-90,'HD Dump'!$R$2:$R$538,"<="&$B18)>0,AVERAGEIFS('HD Dump'!$M$2:$M$538,'HD Dump'!$U$2:$U$538,J$7,'HD Dump'!$R$2:$R$538,">="&$B18-90,'HD Dump'!$R$2:$R$538,"<="&$B18),AA17) | AB18: =IF(COUNTIFS('HD Dump'!$U$2:$U$538,K$7,'HD Dump'!$R$2:$R$538,">="&$B18-90,'HD Dump'!$R$2:$R$538,"<="&$B18)>0,AVERAGEIFS('HD Dump'!$M$2:$M$538,'HD Dump'!$U$2:$U$538,K$7,'HD Dump'!$R$2:$R$538,">="&$B18-90,'HD Dump'!$R$2:$R$538,"<="&$B18),AB17) | AD18: =IF(COUNTIFS('HD Dump'!$U$2:$U$538,C$7,'HD Dump'!$R$2:$R$538,">="&$B18-90,'HD Dump'!$R$2:$R$538,"<="&$B18)>0,AVERAGEIFS('HD Dump'!$O$2:$O$538,'HD Dump'!$U$2:$U$538,C$7,'HD Dump'!$R$2:$R$538,">="&$B18-90,'HD Dump'!$R$2:$R$538,"<="&$B18),AD17) | AE18: =IF(COUNTIFS('HD Dump'!$U$2:$U$538,D$7,'HD Dump'!$R$2:$R$538,">="&$B18-90,'HD Dump'!$R$2:$R$538,"<="&$B18)>0,AVERAGEIFS('HD Dump'!$O$2:$O$538,'HD Dump'!$U$2:$U$538,D$7,'HD Dump'!$R$2:$R$538,">="&$B18-90,'HD Dump'!$R$2:$R$538,"<="&$B18),AE17) | AF18: =IF(COUNTIFS('HD Dump'!$U$2:$U$538,E$7,'HD Dump'!$R$2:$R$538,">="&$B18-90,'HD Dump'!$R$2:$R$538,"<="&$B18)>0,AVERAGEIFS('HD Dump'!$O$2:$O$538,'HD Dump'!$U$2:$U$538,E$7,'HD Dump'!$R$2:$R$538,">="&$B18-90,'HD Dump'!$R$2:$R$538,"<="&$B18),AF17) | AG18: =IF(COUNTIFS('HD Dump'!$U$2:$U$538,F$7,'HD Dump'!$R$2:$R$538,">="&$B18-90,'HD Dump'!$R$2:$R$538,"<="&$B18)>0,AVERAGEIFS('HD Dump'!$O$2:$O$538,'HD Dump'!$U$2:$U$538,F$7,'HD Dump'!$R$2:$R$538,">="&$B18-90,'HD Dump'!$R$2:$R$538,"<="&$B18),AG17) | AH18: =IF(COUNTIFS('HD Dump'!$U$2:$U$538,G$7,'HD Dump'!$R$2:$R$538,">="&$B18-90,'HD Dump'!$R$2:$R$538,"<="&$B18)>0,AVERAGEIFS('HD Dump'!$O$2:$O$538,'HD Dump'!$U$2:$U$538,G$7,'HD Dump'!$R$2:$R$538,">="&$B18-90,'HD Dump'!$R$2:$R$538,"<="&$B18),AH17) | AI18: =IF(COUNTIFS('HD Dump'!$U$2:$U$538,H$7,'HD Dump'!$R$2:$R$538,">="&$B18-90,'HD Dump'!$R$2:$R$538,"<="&$B18)>0,AVERAGEIFS('HD Dump'!$O$2:$O$538,'HD Dump'!$U$2:$U$538,H$7,'HD Dump'!$R$2:$R$538,">="&$B18-90,'HD Dump'!$R$2:$R$538,"<="&$B18),AI17) | AJ18: =IF(COUNTIFS('HD Dump'!$U$2:$U$538,I$7,'HD Dump'!$R$2:$R$538,">="&$B18-90,'HD Dump'!$R$2:$R$538,"<="&$B18)>0,AVERAGEIFS('HD Dump'!$O$2:$O$538,'HD Dump'!$U$2:$U$538,I$7,'HD Dump'!$R$2:$R$538,">="&$B18-90,'HD Dump'!$R$2:$R$538,"<="&$B18),AJ17) | AK18: =IF(COUNTIFS('HD Dump'!$U$2:$U$538,J$7,'HD Dump'!$R$2:$R$538,">="&$B18-90,'HD Dump'!$R$2:$R$538,"<="&$B18)>0,AVERAGEIFS('HD Dump'!$O$2:$O$538,'HD Dump'!$U$2:$U$538,J$7,'HD Dump'!$R$2:$R$538,">="&$B18-90,'HD Dump'!$R$2:$R$538,"<="&$B18),AK17) | AL18: =IF(COUNTIFS('HD Dump'!$U$2:$U$538,K$7,'HD Dump'!$R$2:$R$538,">="&$B18-90,'HD Dump'!$R$2:$R$538,"<="&$B18)>0,AVERAGEIFS('HD Dump'!$O$2:$O$538,'HD Dump'!$U$2:$U$538,K$7,'HD Dump'!$R$2:$R$538,">="&$B18-90,'HD Dump'!$R$2:$R$538,"<="&$B18),AL17)
B19: 45747 | C19: Actual | D19: =SUMPRODUCT(T19:AB19,$C$8:$K$8)/SUM($C$8:$K$8) | E19: =SUMPRODUCT(AD19:AL19,$C$8:$K$8)/SUM($C$8:$K$8) | F19: =IFERROR((INDEX('T12 Dump'!$D$9:$O$9,MATCH(EOMONTH($B19,-1)+1,'T12 Dump'!$D$3:$O$3,0))-ABS(INDEX('T12 Dump'!$D$11:$O$11,MATCH(EOMONTH($B19,-1)+1,'T12 Dump'!$D$3:$O$3,0))))/($F19*360),"") | G19: =IFERROR(1-ABS(INDEX('T12 Dump'!$D$11:$O$11,MATCH(EOMONTH($B19,-1)+1,'T12 Dump'!$D$3:$O$3,0)))/INDEX('T12 Dump'!$D$7:$O$7,MATCH(EOMONTH($B19,-1)+1,'T12 Dump'!$D$3:$O$3,0)),"") | H19: =IFERROR($F19/$D19-1,"") | I19: 29 | T19: =IF(COUNTIFS('HD Dump'!$U$2:$U$538,C$7,'HD Dump'!$R$2:$R$538,">="&$B19-90,'HD Dump'!$R$2:$R$538,"<="&$B19)>0,AVERAGEIFS('HD Dump'!$M$2:$M$538,'HD Dump'!$U$2:$U$538,C$7,'HD Dump'!$R$2:$R$538,">="&$B19-90,'HD Dump'!$R$2:$R$538,"<="&$B19),T18) | U19: =IF(COUNTIFS('HD Dump'!$U$2:$U$538,D$7,'HD Dump'!$R$2:$R$538,">="&$B19-90,'HD Dump'!$R$2:$R$538,"<="&$B19)>0,AVERAGEIFS('HD Dump'!$M$2:$M$538,'HD Dump'!$U$2:$U$538,D$7,'HD Dump'!$R$2:$R$538,">="&$B19-90,'HD Dump'!$R$2:$R$538,"<="&$B19),U18) | V19: =IF(COUNTIFS('HD Dump'!$U$2:$U$538,E$7,'HD Dump'!$R$2:$R$538,">="&$B19-90,'HD Dump'!$R$2:$R$538,"<="&$B19)>0,AVERAGEIFS('HD Dump'!$M$2:$M$538,'HD Dump'!$U$2:$U$538,E$7,'HD Dump'!$R$2:$R$538,">="&$B19-90,'HD Dump'!$R$2:$R$538,"<="&$B19),V18) | W19: =IF(COUNTIFS('HD Dump'!$U$2:$U$538,F$7,'HD Dump'!$R$2:$R$538,">="&$B19-90,'HD Dump'!$R$2:$R$538,"<="&$B19)>0,AVERAGEIFS('HD Dump'!$M$2:$M$538,'HD Dump'!$U$2:$U$538,F$7,'HD Dump'!$R$2:$R$538,">="&$B19-90,'HD Dump'!$R$2:$R$538,"<="&$B19),W18) | X19: =IF(COUNTIFS('HD Dump'!$U$2:$U$538,G$7,'HD Dump'!$R$2:$R$538,">="&$B19-90,'HD Dump'!$R$2:$R$538,"<="&$B19)>0,AVERAGEIFS('HD Dump'!$M$2:$M$538,'HD Dump'!$U$2:$U$538,G$7,'HD Dump'!$R$2:$R$538,">="&$B19-90,'HD Dump'!$R$2:$R$538,"<="&$B19),X18) | Y19: =IF(COUNTIFS('HD Dump'!$U$2:$U$538,H$7,'HD Dump'!$R$2:$R$538,">="&$B19-90,'HD Dump'!$R$2:$R$538,"<="&$B19)>0,AVERAGEIFS('HD Dump'!$M$2:$M$538,'HD Dump'!$U$2:$U$538,H$7,'HD Dump'!$R$2:$R$538,">="&$B19-90,'HD Dump'!$R$2:$R$538,"<="&$B19),Y18) | Z19: =IF(COUNTIFS('HD Dump'!$U$2:$U$538,I$7,'HD Dump'!$R$2:$R$538,">="&$B19-90,'HD Dump'!$R$2:$R$538,"<="&$B19)>0,AVERAGEIFS('HD Dump'!$M$2:$M$538,'HD Dump'!$U$2:$U$538,I$7,'HD Dump'!$R$2:$R$538,">="&$B19-90,'HD Dump'!$R$2:$R$538,"<="&$B19),Z18) | AA19: =IF(COUNTIFS('HD Dump'!$U$2:$U$538,J$7,'HD Dump'!$R$2:$R$538,">="&$B19-90,'HD Dump'!$R$2:$R$538,"<="&$B19)>0,AVERAGEIFS('HD Dump'!$M$2:$M$538,'HD Dump'!$U$2:$U$538,J$7,'HD Dump'!$R$2:$R$538,">="&$B19-90,'HD Dump'!$R$2:$R$538,"<="&$B19),AA18) | AB19: =IF(COUNTIFS('HD Dump'!$U$2:$U$538,K$7,'HD Dump'!$R$2:$R$538,">="&$B19-90,'HD Dump'!$R$2:$R$538,"<="&$B19)>0,AVERAGEIFS('HD Dump'!$M$2:$M$538,'HD Dump'!$U$2:$U$538,K$7,'HD Dump'!$R$2:$R$538,">="&$B19-90,'HD Dump'!$R$2:$R$538,"<="&$B19),AB18) | AD19: =IF(COUNTIFS('HD Dump'!$U$2:$U$538,C$7,'HD Dump'!$R$2:$R$538,">="&$B19-90,'HD Dump'!$R$2:$R$538,"<="&$B19)>0,AVERAGEIFS('HD Dump'!$O$2:$O$538,'HD Dump'!$U$2:$U$538,C$7,'HD Dump'!$R$2:$R$538,">="&$B19-90,'HD Dump'!$R$2:$R$538,"<="&$B19),AD18) | AE19: =IF(COUNTIFS('HD Dump'!$U$2:$U$538,D$7,'HD Dump'!$R$2:$R$538,">="&$B19-90,'HD Dump'!$R$2:$R$538,"<="&$B19)>0,AVERAGEIFS('HD Dump'!$O$2:$O$538,'HD Dump'!$U$2:$U$538,D$7,'HD Dump'!$R$2:$R$538,">="&$B19-90,'HD Dump'!$R$2:$R$538,"<="&$B19),AE18) | AF19: =IF(COUNTIFS('HD Dump'!$U$2:$U$538,E$7,'HD Dump'!$R$2:$R$538,">="&$B19-90,'HD Dump'!$R$2:$R$538,"<="&$B19)>0,AVERAGEIFS('HD Dump'!$O$2:$O$538,'HD Dump'!$U$2:$U$538,E$7,'HD Dump'!$R$2:$R$538,">="&$B19-90,'HD Dump'!$R$2:$R$538,"<="&$B19),AF18) | AG19: =IF(COUNTIFS('HD Dump'!$U$2:$U$538,F$7,'HD Dump'!$R$2:$R$538,">="&$B19-90,'HD Dump'!$R$2:$R$538,"<="&$B19)>0,AVERAGEIFS('HD Dump'!$O$2:$O$538,'HD Dump'!$U$2:$U$538,F$7,'HD Dump'!$R$2:$R$538,">="&$B19-90,'HD Dump'!$R$2:$R$538,"<="&$B19),AG18) | AH19: =IF(COUNTIFS('HD Dump'!$U$2:$U$538,G$7,'HD Dump'!$R$2:$R$538,">="&$B19-90,'HD Dump'!$R$2:$R$538,"<="&$B19)>0,AVERAGEIFS('HD Dump'!$O$2:$O$538,'HD Dump'!$U$2:$U$538,G$7,'HD Dump'!$R$2:$R$538,">="&$B19-90,'HD Dump'!$R$2:$R$538,"<="&$B19),AH18) | AI19: =IF(COUNTIFS('HD Dump'!$U$2:$U$538,H$7,'HD Dump'!$R$2:$R$538,">="&$B19-90,'HD Dump'!$R$2:$R$538,"<="&$B19)>0,AVERAGEIFS('HD Dump'!$O$2:$O$538,'HD Dump'!$U$2:$U$538,H$7,'HD Dump'!$R$2:$R$538,">="&$B19-90,'HD Dump'!$R$2:$R$538,"<="&$B19),AI18) | AJ19: =IF(COUNTIFS('HD Dump'!$U$2:$U$538,I$7,'HD Dump'!$R$2:$R$538,">="&$B19-90,'HD Dump'!$R$2:$R$538,"<="&$B19)>0,AVERAGEIFS('HD Dump'!$O$2:$O$538,'HD Dump'!$U$2:$U$538,I$7,'HD Dump'!$R$2:$R$538,">="&$B19-90,'HD Dump'!$R$2:$R$538,"<="&$B19),AJ18) | AK19: =IF(COUNTIFS('HD Dump'!$U$2:$U$538,J$7,'HD Dump'!$R$2:$R$538,">="&$B19-90,'HD Dump'!$R$2:$R$538,"<="&$B19)>0,AVERAGEIFS('HD Dump'!$O$2:$O$538,'HD Dump'!$U$2:$U$538,J$7,'HD Dump'!$R$2:$R$538,">="&$B19-90,'HD Dump'!$R$2:$R$538,"<="&$B19),AK18) | AL19: =IF(COUNTIFS('HD Dump'!$U$2:$U$538,K$7,'HD Dump'!$R$2:$R$538,">="&$B19-90,'HD Dump'!$R$2:$R$538,"<="&$B19)>0,AVERAGEIFS('HD Dump'!$O$2:$O$538,'HD Dump'!$U$2:$U$538,K$7,'HD Dump'!$R$2:$R$538,">="&$B19-90,'HD Dump'!$R$2:$R$538,"<="&$B19),AL18)
B20: 45777 | C20: Actual | D20: =SUMPRODUCT(T20:AB20,$C$8:$K$8)/SUM($C$8:$K$8) | E20: =SUMPRODUCT(AD20:AL20,$C$8:$K$8)/SUM($C$8:$K$8) | F20: =IFERROR((INDEX('T12 Dump'!$D$9:$O$9,MATCH(EOMONTH($B20,-1)+1,'T12 Dump'!$D$3:$O$3,0))-ABS(INDEX('T12 Dump'!$D$11:$O$11,MATCH(EOMONTH($B20,-1)+1,'T12 Dump'!$D$3:$O$3,0))))/($F20*360),"") | G20: =IFERROR(1-ABS(INDEX('T12 Dump'!$D$11:$O$11,MATCH(EOMONTH($B20,-1)+1,'T12 Dump'!$D$3:$O$3,0)))/INDEX('T12 Dump'!$D$7:$O$7,MATCH(EOMONTH($B20,-1)+1,'T12 Dump'!$D$3:$O$3,0)),"") | H20: =IFERROR($F20/$D20-1,"") | I20: 27 | T20: =IF(COUNTIFS('HD Dump'!$U$2:$U$538,C$7,'HD Dump'!$R$2:$R$538,">="&$B20-90,'HD Dump'!$R$2:$R$538,"<="&$B20)>0,AVERAGEIFS('HD Dump'!$M$2:$M$538,'HD Dump'!$U$2:$U$538,C$7,'HD Dump'!$R$2:$R$538,">="&$B20-90,'HD Dump'!$R$2:$R$538,"<="&$B20),T19) | U20: =IF(COUNTIFS('HD Dump'!$U$2:$U$538,D$7,'HD Dump'!$R$2:$R$538,">="&$B20-90,'HD Dump'!$R$2:$R$538,"<="&$B20)>0,AVERAGEIFS('HD Dump'!$M$2:$M$538,'HD Dump'!$U$2:$U$538,D$7,'HD Dump'!$R$2:$R$538,">="&$B20-90,'HD Dump'!$R$2:$R$538,"<="&$B20),U19) | V20: =IF(COUNTIFS('HD Dump'!$U$2:$U$538,E$7,'HD Dump'!$R$2:$R$538,">="&$B20-90,'HD Dump'!$R$2:$R$538,"<="&$B20)>0,AVERAGEIFS('HD Dump'!$M$2:$M$538,'HD Dump'!$U$2:$U$538,E$7,'HD Dump'!$R$2:$R$538,">="&$B20-90,'HD Dump'!$R$2:$R$538,"<="&$B20),V19) | W20: =IF(COUNTIFS('HD Dump'!$U$2:$U$538,F$7,'HD Dump'!$R$2:$R$538,">="&$B20-90,'HD Dump'!$R$2:$R$538,"<="&$B20)>0,AVERAGEIFS('HD Dump'!$M$2:$M$538,'HD Dump'!$U$2:$U$538,F$7,'HD Dump'!$R$2:$R$538,">="&$B20-90,'HD Dump'!$R$2:$R$538,"<="&$B20),W19) | X20: =IF(COUNTIFS('HD Dump'!$U$2:$U$538,G$7,'HD Dump'!$R$2:$R$538,">="&$B20-90,'HD Dump'!$R$2:$R$538,"<="&$B20)>0,AVERAGEIFS('HD Dump'!$M$2:$M$538,'HD Dump'!$U$2:$U$538,G$7,'HD Dump'!$R$2:$R$538,">="&$B20-90,'HD Dump'!$R$2:$R$538,"<="&$B20),X19) | Y20: =IF(COUNTIFS('HD Dump'!$U$2:$U$538,H$7,'HD Dump'!$R$2:$R$538,">="&$B20-90,'HD Dump'!$R$2:$R$538,"<="&$B20)>0,AVERAGEIFS('HD Dump'!$M$2:$M$538,'HD Dump'!$U$2:$U$538,H$7,'HD Dump'!$R$2:$R$538,">="&$B20-90,'HD Dump'!$R$2:$R$538,"<="&$B20),Y19) | Z20: =IF(COUNTIFS('HD Dump'!$U$2:$U$538,I$7,'HD Dump'!$R$2:$R$538,">="&$B20-90,'HD Dump'!$R$2:$R$538,"<="&$B20)>0,AVERAGEIFS('HD Dump'!$M$2:$M$538,'HD Dump'!$U$2:$U$538,I$7,'HD Dump'!$R$2:$R$538,">="&$B20-90,'HD Dump'!$R$2:$R$538,"<="&$B20),Z19) | AA20: =IF(COUNTIFS('HD Dump'!$U$2:$U$538,J$7,'HD Dump'!$R$2:$R$538,">="&$B20-90,'HD Dump'!$R$2:$R$538,"<="&$B20)>0,AVERAGEIFS('HD Dump'!$M$2:$M$538,'HD Dump'!$U$2:$U$538,J$7,'HD Dump'!$R$2:$R$538,">="&$B20-90,'HD Dump'!$R$2:$R$538,"<="&$B20),AA19) | AB20: =IF(COUNTIFS('HD Dump'!$U$2:$U$538,K$7,'HD Dump'!$R$2:$R$538,">="&$B20-90,'HD Dump'!$R$2:$R$538,"<="&$B20)>0,AVERAGEIFS('HD Dump'!$M$2:$M$538,'HD Dump'!$U$2:$U$538,K$7,'HD Dump'!$R$2:$R$538,">="&$B20-90,'HD Dump'!$R$2:$R$538,"<="&$B20),AB19) | AD20: =IF(COUNTIFS('HD Dump'!$U$2:$U$538,C$7,'HD Dump'!$R$2:$R$538,">="&$B20-90,'HD Dump'!$R$2:$R$538,"<="&$B20)>0,AVERAGEIFS('HD Dump'!$O$2:$O$538,'HD Dump'!$U$2:$U$538,C$7,'HD Dump'!$R$2:$R$538,">="&$B20-90,'HD Dump'!$R$2:$R$538,"<="&$B20),AD19) | AE20: =IF(COUNTIFS('HD Dump'!$U$2:$U$538,D$7,'HD Dump'!$R$2:$R$538,">="&$B20-90,'HD Dump'!$R$2:$R$538,"<="&$B20)>0,AVERAGEIFS('HD Dump'!$O$2:$O$538,'HD Dump'!$U$2:$U$538,D$7,'HD Dump'!$R$2:$R$538,">="&$B20-90,'HD Dump'!$R$2:$R$538,"<="&$B20),AE19) | AF20: =IF(COUNTIFS('HD Dump'!$U$2:$U$538,E$7,'HD Dump'!$R$2:$R$538,">="&$B20-90,'HD Dump'!$R$2:$R$538,"<="&$B20)>0,AVERAGEIFS('HD Dump'!$O$2:$O$538,'HD Dump'!$U$2:$U$538,E$7,'HD Dump'!$R$2:$R$538,">="&$B20-90,'HD Dump'!$R$2:$R$538,"<="&$B20),AF19) | AG20: =IF(COUNTIFS('HD Dump'!$U$2:$U$538,F$7,'HD Dump'!$R$2:$R$538,">="&$B20-90,'HD Dump'!$R$2:$R$538,"<="&$B20)>0,AVERAGEIFS('HD Dump'!$O$2:$O$538,'HD Dump'!$U$2:$U$538,F$7,'HD Dump'!$R$2:$R$538,">="&$B20-90,'HD Dump'!$R$2:$R$538,"<="&$B20),AG19) | AH20: =IF(COUNTIFS('HD Dump'!$U$2:$U$538,G$7,'HD Dump'!$R$2:$R$538,">="&$B20-90,'HD Dump'!$R$2:$R$538,"<="&$B20)>0,AVERAGEIFS('HD Dump'!$O$2:$O$538,'HD Dump'!$U$2:$U$538,G$7,'HD Dump'!$R$2:$R$538,">="&$B20-90,'HD Dump'!$R$2:$R$538,"<="&$B20),AH19) | AI20: =IF(COUNTIFS('HD Dump'!$U$2:$U$538,H$7,'HD Dump'!$R$2:$R$538,">="&$B20-90,'HD Dump'!$R$2:$R$538,"<="&$B20)>0,AVERAGEIFS('HD Dump'!$O$2:$O$538,'HD Dump'!$U$2:$U$538,H$7,'HD Dump'!$R$2:$R$538,">="&$B20-90,'HD Dump'!$R$2:$R$538,"<="&$B20),AI19) | AJ20: =IF(COUNTIFS('HD Dump'!$U$2:$U$538,I$7,'HD Dump'!$R$2:$R$538,">="&$B20-90,'HD Dump'!$R$2:$R$538,"<="&$B20)>0,AVERAGEIFS('HD Dump'!$O$2:$O$538,'HD Dump'!$U$2:$U$538,I$7,'HD Dump'!$R$2:$R$538,">="&$B20-90,'HD Dump'!$R$2:$R$538,"<="&$B20),AJ19) | AK20: =IF(COUNTIFS('HD Dump'!$U$2:$U$538,J$7,'HD Dump'!$R$2:$R$538,">="&$B20-90,'HD Dump'!$R$2:$R$538,"<="&$B20)>0,AVERAGEIFS('HD Dump'!$O$2:$O$538,'HD Dump'!$U$2:$U$538,J$7,'HD Dump'!$R$2:$R$538,">="&$B20-90,'HD Dump'!$R$2:$R$538,"<="&$B20),AK19) | AL20: =IF(COUNTIFS('HD Dump'!$U$2:$U$538,K$7,'HD Dump'!$R$2:$R$538,">="&$B20-90,'HD Dump'!$R$2:$R$538,"<="&$B20)>0,AVERAGEIFS('HD Dump'!$O$2:$O$538,'HD Dump'!$U$2:$U$538,K$7,'HD Dump'!$R$2:$R$538,">="&$B20-90,'HD Dump'!$R$2:$R$538,"<="&$B20),AL19)
B21: 45808 | C21: Actual | D21: =SUMPRODUCT(T21:AB21,$C$8:$K$8)/SUM($C$8:$K$8) | E21: =SUMPRODUCT(AD21:AL21,$C$8:$K$8)/SUM($C$8:$K$8) | F21: =IFERROR((INDEX('T12 Dump'!$D$9:$O$9,MATCH(EOMONTH($B21,-1)+1,'T12 Dump'!$D$3:$O$3,0))-ABS(INDEX('T12 Dump'!$D$11:$O$11,MATCH(EOMONTH($B21,-1)+1,'T12 Dump'!$D$3:$O$3,0))))/($F21*360),"") | G21: =IFERROR(1-ABS(INDEX('T12 Dump'!$D$11:$O$11,MATCH(EOMONTH($B21,-1)+1,'T12 Dump'!$D$3:$O$3,0)))/INDEX('T12 Dump'!$D$7:$O$7,MATCH(EOMONTH($B21,-1)+1,'T12 Dump'!$D$3:$O$3,0)),"") | H21: =IFERROR($F21/$D21-1,"") | I21: 26 | T21: =IF(COUNTIFS('HD Dump'!$U$2:$U$538,C$7,'HD Dump'!$R$2:$R$538,">="&$B21-90,'HD Dump'!$R$2:$R$538,"<="&$B21)>0,AVERAGEIFS('HD Dump'!$M$2:$M$538,'HD Dump'!$U$2:$U$538,C$7,'HD Dump'!$R$2:$R$538,">="&$B21-90,'HD Dump'!$R$2:$R$538,"<="&$B21),T20) | U21: =IF(COUNTIFS('HD Dump'!$U$2:$U$538,D$7,'HD Dump'!$R$2:$R$538,">="&$B21-90,'HD Dump'!$R$2:$R$538,"<="&$B21)>0,AVERAGEIFS('HD Dump'!$M$2:$M$538,'HD Dump'!$U$2:$U$538,D$7,'HD Dump'!$R$2:$R$538,">="&$B21-90,'HD Dump'!$R$2:$R$538,"<="&$B21),U20) | V21: =IF(COUNTIFS('HD Dump'!$U$2:$U$538,E$7,'HD Dump'!$R$2:$R$538,">="&$B21-90,'HD Dump'!$R$2:$R$538,"<="&$B21)>0,AVERAGEIFS('HD Dump'!$M$2:$M$538,'HD Dump'!$U$2:$U$538,E$7,'HD Dump'!$R$2:$R$538,">="&$B21-90,'HD Dump'!$R$2:$R$538,"<="&$B21),V20) | W21: =IF(COUNTIFS('HD Dump'!$U$2:$U$538,F$7,'HD Dump'!$R$2:$R$538,">="&$B21-90,'HD Dump'!$R$2:$R$538,"<="&$B21)>0,AVERAGEIFS('HD Dump'!$M$2:$M$538,'HD Dump'!$U$2:$U$538,F$7,'HD Dump'!$R$2:$R$538,">="&$B21-90,'HD Dump'!$R$2:$R$538,"<="&$B21),W20) | X21: =IF(COUNTIFS('HD Dump'!$U$2:$U$538,G$7,'HD Dump'!$R$2:$R$538,">="&$B21-90,'HD Dump'!$R$2:$R$538,"<="&$B21)>0,AVERAGEIFS('HD Dump'!$M$2:$M$538,'HD Dump'!$U$2:$U$538,G$7,'HD Dump'!$R$2:$R$538,">="&$B21-90,'HD Dump'!$R$2:$R$538,"<="&$B21),X20) | Y21: =IF(COUNTIFS('HD Dump'!$U$2:$U$538,H$7,'HD Dump'!$R$2:$R$538,">="&$B21-90,'HD Dump'!$R$2:$R$538,"<="&$B21)>0,AVERAGEIFS('HD Dump'!$M$2:$M$538,'HD Dump'!$U$2:$U$538,H$7,'HD Dump'!$R$2:$R$538,">="&$B21-90,'HD Dump'!$R$2:$R$538,"<="&$B21),Y20) | Z21: =IF(COUNTIFS('HD Dump'!$U$2:$U$538,I$7,'HD Dump'!$R$2:$R$538,">="&$B21-90,'HD Dump'!$R$2:$R$538,"<="&$B21)>0,AVERAGEIFS('HD Dump'!$M$2:$M$538,'HD Dump'!$U$2:$U$538,I$7,'HD Dump'!$R$2:$R$538,">="&$B21-90,'HD Dump'!$R$2:$R$538,"<="&$B21),Z20) | AA21: =IF(COUNTIFS('HD Dump'!$U$2:$U$538,J$7,'HD Dump'!$R$2:$R$538,">="&$B21-90,'HD Dump'!$R$2:$R$538,"<="&$B21)>0,AVERAGEIFS('HD Dump'!$M$2:$M$538,'HD Dump'!$U$2:$U$538,J$7,'HD Dump'!$R$2:$R$538,">="&$B21-90,'HD Dump'!$R$2:$R$538,"<="&$B21),AA20) | AB21: =IF(COUNTIFS('HD Dump'!$U$2:$U$538,K$7,'HD Dump'!$R$2:$R$538,">="&$B21-90,'HD Dump'!$R$2:$R$538,"<="&$B21)>0,AVERAGEIFS('HD Dump'!$M$2:$M$538,'HD Dump'!$U$2:$U$538,K$7,'HD Dump'!$R$2:$R$538,">="&$B21-90,'HD Dump'!$R$2:$R$538,"<="&$B21),AB20) | AD21: =IF(COUNTIFS('HD Dump'!$U$2:$U$538,C$7,'HD Dump'!$R$2:$R$538,">="&$B21-90,'HD Dump'!$R$2:$R$538,"<="&$B21)>0,AVERAGEIFS('HD Dump'!$O$2:$O$538,'HD Dump'!$U$2:$U$538,C$7,'HD Dump'!$R$2:$R$538,">="&$B21-90,'HD Dump'!$R$2:$R$538,"<="&$B21),AD20) | AE21: =IF(COUNTIFS('HD Dump'!$U$2:$U$538,D$7,'HD Dump'!$R$2:$R$538,">="&$B21-90,'HD Dump'!$R$2:$R$538,"<="&$B21)>0,AVERAGEIFS('HD Dump'!$O$2:$O$538,'HD Dump'!$U$2:$U$538,D$7,'HD Dump'!$R$2:$R$538,">="&$B21-90,'HD Dump'!$R$2:$R$538,"<="&$B21),AE20) | AF21: =IF(COUNTIFS('HD Dump'!$U$2:$U$538,E$7,'HD Dump'!$R$2:$R$538,">="&$B21-90,'HD Dump'!$R$2:$R$538,"<="&$B21)>0,AVERAGEIFS('HD Dump'!$O$2:$O$538,'HD Dump'!$U$2:$U$538,E$7,'HD Dump'!$R$2:$R$538,">="&$B21-90,'HD Dump'!$R$2:$R$538,"<="&$B21),AF20) | AG21: =IF(COUNTIFS('HD Dump'!$U$2:$U$538,F$7,'HD Dump'!$R$2:$R$538,">="&$B21-90,'HD Dump'!$R$2:$R$538,"<="&$B21)>0,AVERAGEIFS('HD Dump'!$O$2:$O$538,'HD Dump'!$U$2:$U$538,F$7,'HD Dump'!$R$2:$R$538,">="&$B21-90,'HD Dump'!$R$2:$R$538,"<="&$B21),AG20) | AH21: =IF(COUNTIFS('HD Dump'!$U$2:$U$538,G$7,'HD Dump'!$R$2:$R$538,">="&$B21-90,'HD Dump'!$R$2:$R$538,"<="&$B21)>0,AVERAGEIFS('HD Dump'!$O$2:$O$538,'HD Dump'!$U$2:$U$538,G$7,'HD Dump'!$R$2:$R$538,">="&$B21-90,'HD Dump'!$R$2:$R$538,"<="&$B21),AH20) | AI21: =IF(COUNTIFS('HD Dump'!$U$2:$U$538,H$7,'HD Dump'!$R$2:$R$538,">="&$B21-90,'HD Dump'!$R$2:$R$538,"<="&$B21)>0,AVERAGEIFS('HD Dump'!$O$2:$O$538,'HD Dump'!$U$2:$U$538,H$7,'HD Dump'!$R$2:$R$538,">="&$B21-90,'HD Dump'!$R$2:$R$538,"<="&$B21),AI20) | AJ21: =IF(COUNTIFS('HD Dump'!$U$2:$U$538,I$7,'HD Dump'!$R$2:$R$538,">="&$B21-90,'HD Dump'!$R$2:$R$538,"<="&$B21)>0,AVERAGEIFS('HD Dump'!$O$2:$O$538,'HD Dump'!$U$2:$U$538,I$7,'HD Dump'!$R$2:$R$538,">="&$B21-90,'HD Dump'!$R$2:$R$538,"<="&$B21),AJ20) | AK21: =IF(COUNTIFS('HD Dump'!$U$2:$U$538,J$7,'HD Dump'!$R$2:$R$538,">="&$B21-90,'HD Dump'!$R$2:$R$538,"<="&$B21)>0,AVERAGEIFS('HD Dump'!$O$2:$O$538,'HD Dump'!$U$2:$U$538,J$7,'HD Dump'!$R$2:$R$538,">="&$B21-90,'HD Dump'!$R$2:$R$538,"<="&$B21),AK20) | AL21: =IF(COUNTIFS('HD Dump'!$U$2:$U$538,K$7,'HD Dump'!$R$2:$R$538,">="&$B21-90,'HD Dump'!$R$2:$R$538,"<="&$B21)>0,AVERAGEIFS('HD Dump'!$O$2:$O$538,'HD Dump'!$U$2:$U$538,K$7,'HD Dump'!$R$2:$R$538,">="&$B21-90,'HD Dump'!$R$2:$R$538,"<="&$B21),AL20)
