Workbook

Sheet Competitive Analysis
C2: CANYON RIDGE — 5-Mile Competitive Supply
B3: 2023–2026 New Construction | 5-mile radius | As of 2026 Q3 QTD
B4: # | C4: Property | D4: Units | E4: Est. Delivery | F4: Occupancy | G4: Avg Mkt Rent | H4: Owner | I4: Proximity | J4: Type | K4: Notes
C5: STABILIZED / STABILIZING (4 properties, 367 units)
B6: 1 | C6: The Timbers at Harris Ranch | D6: 274 | E6: Q2 2023 | F6: 0.974453 | G6: 2213 | H6: Highland Canyon Partners | I6: 2.3 | J6: Garden | K6: Year built: 2023/2024; Occ: CoStar 97% vs RealPage 100% | M6: =IFERROR(VALUE(RIGHT(E6,4))*4+MATCH(LEFT(E6,2),{"Q1","Q2","Q3","Q4"},0)-1,"")
B7: 2 | C7: The Betty | D7: 46 | E7: Q4 2023 | F7: 0.934783 | G7: 1577 | H7: Commercial Northwest Property Management | I7: 4.2 | J7: Mid-Rise | K7: Occ: CoStar 93% vs RealPage 96%; Rent: CoStar ask $1,577 vs RealPage eff $1,273 | M7: =IFERROR(VALUE(RIGHT(E7,4))*4+MATCH(LEFT(E7,2),{"Q1","Q2","Q3","Q4"},0)-1,"")
B8: 3 | C8: Mesa Pointe Apartments | D8: 12 | E8: Q3 2024 | F8: 1 | G8: 1647 | H8: Rre Mesa Pointe Llc | I8: 4.2 | J8: Low-Rise | M8: =IFERROR(VALUE(RIGHT(E8,4))*4+MATCH(LEFT(E8,2),{"Q1","Q2","Q3","Q4"},0)-1,"")
B9: 4 | C9: Veazey Apartments | D9: 35 | E9: Q4 2024 | F9: 0.971429 | G9: 1547 | H9: Conrad J Frank | I9: 3.4 | J9: Low-Rise | M9: =IFERROR(VALUE(RIGHT(E9,4))*4+MATCH(LEFT(E9,2),{"Q1","Q2","Q3","Q4"},0)-1,"")
C11: UNDER CONSTRUCTION (1 properties, 27 units)
B12: 5 | C12: 737 ParkCenter | D12: 27 | E12: Q3 2027 | G12: — | H12: Scott G Kimball | I12: 3.2 | J12: Low-Rise | M12: =IFERROR(VALUE(RIGHT(E12,4))*4+MATCH(LEFT(E12,2),{"Q1","Q2","Q3","Q4"},0)-1,"")
C14: PROPOSED (7 properties, 1,901 units)
B15: 6 | C15: The Ranahan | D15: 138 | E15: Q4 2028 | G15: — | H15: Dave Evans Construction | I15: 2.2 | J15: Mid-Rise | M15: =IFERROR(VALUE(RIGHT(E15,4))*4+MATCH(LEFT(E15,2),{"Q1","Q2","Q3","Q4"},0)-1,"")
B16: 7 | C16: Vista Point | D16: 893 | E16: TBD | G16: — | H16: — | I16: 3.4 | J16: Mid-Rise | K16: RealPage pipeline (not yet in CoStar) | M16: =IFERROR(VALUE(RIGHT(E16,4))*4+MATCH(LEFT(E16,2),{"Q1","Q2","Q3","Q4"},0)-1,"")
B17: 8 | C17: Seasons on the Bench | D17: 358 | E17: TBD | G17: — | H17: — | I17: 3.6 | J17: Garden | K17: RealPage pipeline (not yet in CoStar) | M17: =IFERROR(VALUE(RIGHT(E17,4))*4+MATCH(LEFT(E17,2),{"Q1","Q2","Q3","Q4"},0)-1,"")
B18: 9 | C18: 1519 South Londoner Avenue | D18: 189 | E18: TBD | G18: — | H18: — | I18: 4 | J18: Garden | K18: RealPage pipeline (not yet in CoStar) | M18: =IFERROR(VALUE(RIGHT(E18,4))*4+MATCH(LEFT(E18,2),{"Q1","Q2","Q3","Q4"},0)-1,"")
B19: 10 | C19: 3300 South Vista Avenue | D19: 180 | E19: TBD | G19: — | H19: — | I19: 3.7 | J19: Mid-Rise | K19: RealPage pipeline (not yet in CoStar) | M19: =IFERROR(VALUE(RIGHT(E19,4))*4+MATCH(LEFT(E19,2),{"Q1","Q2","Q3","Q4"},0)-1,"")
B20: 11 | C20: Station Village | D20: 84 | E20: TBD | G20: — | H20: Privately Owned | I20: 4.7 | J20: Garden | K20: RealPage pipeline (not yet in CoStar) | M20: =IFERROR(VALUE(RIGHT(E20,4))*4+MATCH(LEFT(E20,2),{"Q1","Q2","Q3","Q4"},0)-1,"")
B21: 12 | C21: Harris Ranch East | D21: 59 | E21: TBD | G21: — | H21: — | I21: 2.9 | J21: Single Family | K21: RealPage pipeline (not yet in CoStar) | M21: =IFERROR(VALUE(RIGHT(E21,4))*4+MATCH(LEFT(E21,2),{"Q1","Q2","Q3","Q4"},0)-1,"")
B24: * 5-Mile radius. Rent ($) = market asking. Proximity (mi) = straight-line distance from the subject. Est. Delivery drives the Supply & Absorption tab's per-window supply (edit it there or here — they are linked). See the 'Supply & Absorption' tab for the forward supply / absorption / overall-occupancy forecast.

Sheet Supply & Absorption
Z1: 8105
B2: SUPPLY & ABSORPTION — 5-MILE MARKET (relative-year / TTM) | Z2: =IFERROR(VALUE(RIGHT($C$5,4))*4+MATCH(LEFT($C$5,2),{"Q1","Q2","Q3","Q4"},0)-1,0)
R3: UNDER CONSTRUCTION (linked from Competitive Analysis) | Z3: =IF($C$7="Bear",3,IF($C$7="Base",2,1))
B4: As-of Quarter (Y0 end) | C4: Q2 2026 | D4: ◂ Y0 = the trailing-12-months ending here (latest complete CoStar quarter); -Y1…-Y6 step back a year each. | R4: Property | S4: Units | T4: Est. Delivery
B5: Close Quarter (Y1 start) | C5: Q4 2026 | D5: ◂ Expected deal close. Y1 = the 12 months starting here; pipeline deliveries bucket into hold years off this anchor — edit it and the Y1–Y6 windows & supply shift. | R5: ='Competitive Analysis'!C12 | S5: ='Competitive Analysis'!D12 | T5: ='Competitive Analysis'!E12 | V5: =IFERROR(VALUE(RIGHT(T5,4))*4+MATCH(LEFT(T5,2),{"Q1","Q2","Q3","Q4"},0)-1,"") | W5: =IF(V5="","",IF(V5<=$Z$1,0,MAX(1,INT((V5-$Z$2)/4)+1)))
B6: Stabilization Target | C6: 0.95
B7: Demand Scenario | C7: Base | R7: PROPOSED PIPELINE (scenario toggle)
B8: Bear Annual Absorption | C8: 150 | R8: Property | S8: Units | T8: Est. Delivery | U8: Built In
B9: Base Annual Absorption | C9: 300 | R9: Vista Point | S9: 893 | U9: Bear only | V9: =IFERROR(VALUE(RIGHT(T9,4))*4+MATCH(LEFT(T9,2),{"Q1","Q2","Q3","Q4"},0)-1,"") | W9: =IF(V9="","",IF(V9<=$Z$1,0,MAX(1,INT((V9-$Z$2)/4)+1))) | X9: =IF(U9="All",1,IF(U9="Bear+Base",IF($Z$3>=2,1,0),IF(U9="Bear only",IF($Z$3>=3,1,0),0)))
B10: Bull Annual Absorption | C10: 450 | D10: ◂ Base = trailing-3-yr CoStar average (annualized, complete quarters). | R10: Seasons on the Bench | S10: 358 | U10: Bear only | V10: =IFERROR(VALUE(RIGHT(T10,4))*4+MATCH(LEFT(T10,2),{"Q1","Q2","Q3","Q4"},0)-1,"") | W10: =IF(V10="","",IF(V10<=$Z$1,0,MAX(1,INT((V10-$Z$2)/4)+1))) | X10: =IF(U10="All",1,IF(U10="Bear+Base",IF($Z$3>=2,1,0),IF(U10="Bear only",IF($Z$3>=3,1,0),0)))
B11: Selected Annual Demand | C11: =IF($C$7="Bear",$C$8,IF($C$7="Bull",$C$10,$C$9)) | R11: 1519 South Londoner Avenue | S11: 189 | U11: Bear only | V11: =IFERROR(VALUE(RIGHT(T11,4))*4+MATCH(LEFT(T11,2),{"Q1","Q2","Q3","Q4"},0)-1,"") | W11: =IF(V11="","",IF(V11<=$Z$1,0,MAX(1,INT((V11-$Z$2)/4)+1))) | X11: =IF(U11="All",1,IF(U11="Bear+Base",IF($Z$3>=2,1,0),IF(U11="Bear only",IF($Z$3>=3,1,0),0)))
R12: 3300 South Vista Avenue | S12: 180 | U12: Bear only | V12: =IFERROR(VALUE(RIGHT(T12,4))*4+MATCH(LEFT(T12,2),{"Q1","Q2","Q3","Q4"},0)-1,"") | W12: =IF(V12="","",IF(V12<=$Z$1,0,MAX(1,INT((V12-$Z$2)/4)+1))) | X12: =IF(U12="All",1,IF(U12="Bear+Base",IF($Z$3>=2,1,0),IF(U12="Bear only",IF($Z$3>=3,1,0),0)))
R13: The Ranahan | S13: 138 | T13: Q4 2028 | U13: Bear only | V13: =IFERROR(VALUE(RIGHT(T13,4))*4+MATCH(LEFT(T13,2),{"Q1","Q2","Q3","Q4"},0)-1,"") | W13: =IF(V13="","",IF(V13<=$Z$1,0,MAX(1,INT((V13-$Z$2)/4)+1))) | X13: =IF(U13="All",1,IF(U13="Bear+Base",IF($Z$3>=2,1,0),IF(U13="Bear only",IF($Z$3>=3,1,0),0)))
R14: Station Village | S14: 84 | U14: Bear only | V14: =IFERROR(VALUE(RIGHT(T14,4))*4+MATCH(LEFT(T14,2),{"Q1","Q2","Q3","Q4"},0)-1,"") | W14: =IF(V14="","",IF(V14<=$Z$1,0,MAX(1,INT((V14-$Z$2)/4)+1))) | X14: =IF(U14="All",1,IF(U14="Bear+Base",IF($Z$3>=2,1,0),IF(U14="Bear only",IF($Z$3>=3,1,0),0)))
R15: Harris Ranch East | S15: 59 | U15: Bear only | V15: =IFERROR(VALUE(RIGHT(T15,4))*4+MATCH(LEFT(T15,2),{"Q1","Q2","Q3","Q4"},0)-1,"") | W15: =IF(V15="","",IF(V15<=$Z$1,0,MAX(1,INT((V15-$Z$2)/4)+1))) | X15: =IF(U15="All",1,IF(U15="Bear+Base",IF($Z$3>=2,1,0),IF(U15="Bear only",IF($Z$3>=3,1,0),0)))
B17: 5-MILE MARKET | C17: -Y6 | D17: -Y5 | E17: -Y4 | F17: -Y3 | G17: -Y2 | H17: -Y1 | I17: Y0 | J17: Y1 | K17: Y2 | L17: Y3 | M17: Y4 | N17: Y5 | O17: Y6
C18: Q3'19-Q2'20 | D18: Q3'20-Q2'21 | E18: Q3'21-Q2'22 | F18: Q3'22-Q2'23 | G18: Q3'23-Q2'24 | H18: Q3'24-Q2'25 | I18: Q3'25-Q2'26 | J18: ="Q"&(MOD(($Z$2+0),4)+1)&"'"&RIGHT(INT(($Z$2+0)/4),2)&"-Q"&(MOD(($Z$2+3),4)+1)&"'"&RIGHT(INT(($Z$2+3)/4),2) | K18: ="Q"&(MOD(($Z$2+4),4)+1)&"'"&RIGHT(INT(($Z$2+4)/4),2)&"-Q"&(MOD(($Z$2+7),4)+1)&"'"&RIGHT(INT(($Z$2+7)/4),2) | L18: ="Q"&(MOD(($Z$2+8),4)+1)&"'"&RIGHT(INT(($Z$2+8)/4),2)&"-Q"&(MOD(($Z$2+11),4)+1)&"'"&RIGHT(INT(($Z$2+11)/4),2) | M18: ="Q"&(MOD(($Z$2+12),4)+1)&"'"&RIGHT(INT(($Z$2+12)/4),2)&"-Q"&(MOD(($Z$2+15),4)+1)&"'"&RIGHT(INT(($Z$2+15)/4),2) | N18: ="Q"&(MOD(($Z$2+16),4)+1)&"'"&RIGHT(INT(($Z$2+16)/4),2)&"-Q"&(MOD(($Z$2+19),4)+1)&"'"&RIGHT(INT(($Z$2+19)/4),2) | O18: ="Q"&(MOD(($Z$2+20),4)+1)&"'"&RIGHT(INT(($Z$2+20)/4),2)&"-Q"&(MOD(($Z$2+23),4)+1)&"'"&RIGHT(INT(($Z$2+23)/4),2)
B19: NEW SUPPLY (5-mi) | C19: 213 | D19: 237 | E19: 33 | F19: 289 | G19: 178 | H19: 334 | I19: =SUMIFS('Competitive Analysis'!$D$5:$D$21,'Competitive Analysis'!$M$5:$M$21,">="&8102,'Competitive Analysis'!$M$5:$M$21,"<="&8105) | J19: =SUMIFS($S$5:$S$5,$W$5:$W$5,1)+SUMIFS($S$9:$S$15,$W$9:$W$15,1,$X$9:$X$15,1) | K19: =SUMIFS($S$5:$S$5,$W$5:$W$5,2)+SUMIFS($S$9:$S$15,$W$9:$W$15,2,$X$9:$X$15,1) | L19: =SUMIFS($S$5:$S$5,$W$5:$W$5,3)+SUMIFS($S$9:$S$15,$W$9:$W$15,3,$X$9:$X$15,1) | M19: =SUMIFS($S$5:$S$5,$W$5:$W$5,4)+SUMIFS($S$9:$S$15,$W$9:$W$15,4,$X$9:$X$15,1) | N19: =SUMIFS($S$5:$S$5,$W$5:$W$5,5)+SUMIFS($S$9:$S$15,$W$9:$W$15,5,$X$9:$X$15,1) | O19: =SUMIFS($S$5:$S$5,$W$5:$W$5,6)+SUMIFS($S$9:$S$15,$W$9:$W$15,6,$X$9:$X$15,1)
B20: ABSORPTION (5-mi) | C20: 213 | D20: 150 | E20: 86 | F20: -91 | G20: 277 | H20: 400 | I20: 209 | J20: =J31-I31 | K20: =K31-J31 | L20: =L31-K31 | M20: =M31-L31 | N20: =N31-M31 | O20: =O31-N31
B21: OCCUPANCY (5-mi) | C21: 0.968 | D21: 0.952 | E21: 0.963 | F21: 0.895 | G21: 0.916 | H21: 0.932 | I21: =IFERROR(I31/I30,"") | J21: =IFERROR(J31/J30,0) | K21: =IFERROR(K31/K30,0) | L21: =IFERROR(L31/L30,0) | M21: =IFERROR(M31/M30,0) | N21: =IFERROR(N31/N30,0) | O21: =IFERROR(O31/O30,0)
B22: SUBJECT (Canyon Ridge)
B23: Market Rent (CoStar→HD) | C23: 1811 | D23: 1845 | E23: 1885 | F23: 1925 | G23: 1953 | H23: 1977 | I23: =IFERROR('Cash Flow (Annual)'!$F$4,2136) | J23: =IFERROR('Cash Flow (Annual)'!$K$4,"") | K23: =IFERROR('Cash Flow (Annual)'!$L$4,"") | L23: =IFERROR('Cash Flow (Annual)'!$M$4,"") | M23: =IFERROR('Cash Flow (Annual)'!$N$4,"") | N23: =IFERROR('Cash Flow (Annual)'!$O$4,"") | O23: =IFERROR('Cash Flow (Annual)'!$P$4,"")
B24: Market Rent YoY % | D24: =IFERROR(D23/C23-1,"") | E24: =IFERROR(E23/D23-1,"") | F24: =IFERROR(F23/E23-1,"") | G24: =IFERROR(G23/F23-1,"") | H24: =IFERROR(H23/G23-1,"") | I24: =IFERROR(I23/H23-1,"") | J24: =IFERROR(J23/I23-1,"") | K24: =IFERROR(K23/J23-1,"") | ... O24: =IFERROR(O23/N23-1,"")
B25: Effective Rent | C25: 1793 | D25: 1832 | E25: 1867 | F25: 1897 | G25: 1953 | H25: 1823 | I25: =IFERROR('Cash Flow (Annual)'!$F$5,2018) | J25: =IFERROR('Cash Flow (Annual)'!$K$5,"") | K25: =IFERROR('Cash Flow (Annual)'!$L$5,"") | L25: =IFERROR('Cash Flow (Annual)'!$M$5,"") | M25: =IFERROR('Cash Flow (Annual)'!$N$5,"") | N25: =IFERROR('Cash Flow (Annual)'!$O$5,"") | O25: =IFERROR('Cash Flow (Annual)'!$P$5,"")
B26: Effective Rent YoY % | D26: =IFERROR(D25/C25-1,"") | E26: =IFERROR(E25/D25-1,"") | F26: =IFERROR(F25/E25-1,"") | G26: =IFERROR(G25/F25-1,"") | H26: =IFERROR(H25/G25-1,"") | I26: =IFERROR(I25/H25-1,"") | J26: =IFERROR(J25/I25-1,"") | K26: =IFERROR(K25/J25-1,"") | ... O26: =IFERROR(O25/N25-1,"")
B27: Occupancy (financials / CoStar) | H27: 0.42747843 | I27: =IFERROR('Cash Flow (Annual)'!$F$14,0.8020596099111482) | J27: =IFERROR('Cash Flow (Annual)'!$K$14,"") | K27: =IFERROR('Cash Flow (Annual)'!$L$14,"") | L27: =IFERROR('Cash Flow (Annual)'!$M$14,"") | M27: =IFERROR('Cash Flow (Annual)'!$N$14,"") | N27: =IFERROR('Cash Flow (Annual)'!$O$14,"") | O27: =IFERROR('Cash Flow (Annual)'!$P$14,"")
B28: Concession % | C28: =IFERROR((C23-C25)/C23,"") | D28: =IFERROR((D23-D25)/D23,"") | E28: =IFERROR((E23-E25)/E23,"") | F28: =IFERROR((F23-F25)/F23,"") | G28: =IFERROR((G23-G25)/G23,"") | H28: =IFERROR((H23-H25)/H23,"") | I28: =IFERROR((I23-I25)/I23,"") | J28: =IFERROR((J23-J25)/J23,"") | ... O28: =IFERROR((O23-O25)/O23,"")
B30: inventory | C30: 4834 | D30: 5071 | E30: 5104 | F30: 5393 | G30: 5571 | H30: 5905 | I30: =H30+I19 | J30: =I30+J19 | K30: =J30+K19 | L30: =K30+L19 | M30: =L30+M19 | N30: =M30+N19 | O30: =N30+O19
B31: occupied | C31: 4680 | D31: 4830 | E31: 4916 | F31: 4825 | G31: 5102 | H31: 5501 | I31: =H31+I20 | J31: =MIN($C$6*J30,I31+$C$11) | K31: =MIN($C$6*K30,J31+$C$11) | L31: =MIN($C$6*L30,K31+$C$11) | M31: =MIN($C$6*M30,L31+$C$11) | N31: =MIN($C$6*N30,M31+$C$11) | O31: =MIN($C$6*O30,N31+$C$11)
B33: MARKET-RENT GROWTH — TMG vs 3RD-PARTY FORECAST | J33: Y1 | K33: Y2 | L33: Y3 | M33: Y4 | N33: Y5 | O33: Y6 | P33: AVG
B34: CoStar | J34: =IFERROR('Rent & Occ Data'!$C$31,"") | K34: =IFERROR('Rent & Occ Data'!$D$31,"") | L34: =IFERROR('Rent & Occ Data'!$E$31,"") | M34: =IFERROR('Rent & Occ Data'!$F$31,"") | N34: =IFERROR('Rent & Occ Data'!$G$31,"") | O34: =IFERROR('Rent & Occ Data'!$H$31,"") | P34: =IFERROR(AVERAGE(J34:O34),"")
B35: RealPage | J35: =IFERROR('Rent & Occ Data'!$C$32,"") | K35: =IFERROR('Rent & Occ Data'!$D$32,"") | L35: =IFERROR('Rent & Occ Data'!$E$32,"") | M35: =IFERROR('Rent & Occ Data'!$F$32,"") | N35: =IFERROR('Rent & Occ Data'!$G$32,"") | O35: =IFERROR('Rent & Occ Data'!$H$32,"") | P35: =IFERROR(AVERAGE(J35:O35),"")
B36: Yardi | J36: =IFERROR('Rent & Occ Data'!$C$33,"") | K36: =IFERROR('Rent & Occ Data'!$D$33,"") | L36: =IFERROR('Rent & Occ Data'!$E$33,"") | M36: =IFERROR('Rent & Occ Data'!$F$33,"") | N36: =IFERROR('Rent & Occ Data'!$G$33,"") | O36: =IFERROR('Rent & Occ Data'!$H$33,"") | P36: =IFERROR(AVERAGE(J36:O36),"")
B37: GreenStreet | J37: =IFERROR('Rent & Occ Data'!$C$34,"") | K37: =IFERROR('Rent & Occ Data'!$D$34,"") | L37: =IFERROR('Rent & Occ Data'!$E$34,"") | M37: =IFERROR('Rent & Occ Data'!$F$34,"") | N37: =IFERROR('Rent & Occ Data'!$G$34,"") | O37: =IFERROR('Rent & Occ Data'!$H$34,"") | P37: =IFERROR(AVERAGE(J37:O37),"")
B38: Consensus (4-source avg) | J38: =IFERROR(AVERAGE(J34:J37),"") | K38: =IFERROR(AVERAGE(K34:K37),"") | L38: =IFERROR(AVERAGE(L34:L37),"") | M38: =IFERROR(AVERAGE(M34:M37),"") | N38: =IFERROR(AVERAGE(N34:N37),"") | O38: =IFERROR(AVERAGE(O34:O37),"") | P38: =IFERROR(AVERAGE(P34:P37),"")
B39: TMG — our market-rent growth ◄ | J39: =IFERROR(J24,"") | K39: =IFERROR(K24,"") | L39: =IFERROR(L24,"") | M39: =IFERROR(M24,"") | N39: =IFERROR(N24,"") | O39: =IFERROR(O24,"") | P39: =IFERROR(AVERAGE(J39:O39),"")
B41: ▸ SCENARIO INPUTS — Bear / Base / Bull (implied occupancy, rent-growth & concession assumptions — click + to expand)
B42: IMPLIED 5-MI OCCUPANCY BY DEMAND SCENARIO | J42: Y1 | K42: Y2 | L42: Y3 | M42: Y4 | N42: Y5 | O42: Y6
B43: Bear | J43: =MIN($C$6,($I$31+$C$8*1)/J30) | K43: =MIN($C$6,($I$31+$C$8*2)/K30) | L43: =MIN($C$6,($I$31+$C$8*3)/L30) | M43: =MIN($C$6,($I$31+$C$8*4)/M30) | N43: =MIN($C$6,($I$31+$C$8*5)/N30) | O43: =MIN($C$6,($I$31+$C$8*6)/O30)
B44: Base | J44: =MIN($C$6,($I$31+$C$9*1)/J30) | K44: =MIN($C$6,($I$31+$C$9*2)/K30) | L44: =MIN($C$6,($I$31+$C$9*3)/L30) | M44: =MIN($C$6,($I$31+$C$9*4)/M30) | N44: =MIN($C$6,($I$31+$C$9*5)/N30) | O44: =MIN($C$6,($I$31+$C$9*6)/O30)
...

Sheet Reconciliation Log
A1: Property | B1: Address | C1: Units | D1: Year Built | E1: Est. Delivery | F1: Deliv. Source | G1: Bucket | H1: CoStar Occ | I1: RealPage Occ | J1: HD Occ | K1: CoStar Ask Rent | L1: RealPage Eff Rent | M1: HD Ask (mix-wtd) | N1: HD Eff (mix-wtd) | O1: Sources | P1: Notes
A2: Veazey Apartments | B2: 2408 S Broadway Ave | C2: 35 | D2: 2024 | E2: Q4 2024 | F2: CoStar property analytics | G2: STABILIZED / STABILIZING | H2: 0.971429 | K2: 1547 | O2: CoStar
A3: Mesa Pointe Apartments | B3: 1805 W Overland Rd | C3: 12 | D3: 2024 | E3: Q3 2024 | F3: CoStar property analytics | G3: STABILIZED / STABILIZING | K3: 1647 | O3: CoStar
A4: The Betty | B4: 2550 W Targee St | C4: 46 | D4: 2023 | E4: Q4 2023 | F4: CoStar property analytics | G4: STABILIZED / STABILIZING | H4: 0.934783 | I4: 0.961 | K4: 1577 | L4: 1273 | O4: CoStar+RealPage | P4: Occ: CoStar 93% vs RealPage 96%; Rent: CoStar ask $1,577 vs RealPage eff $1,273
A5: The Timbers at Harris Ranch | B5: 3469 S Old Hickory Way | C5: 274 | D5: 2023 | E5: Q2 2023 | F5: CoStar property analytics | G5: STABILIZED / STABILIZING | H5: 0.974453 | I5: 0.996 | K5: 2213 | L5: 2303 | O5: CoStar+RealPage | P5: Year built: 2023/2024; Occ: CoStar 97% vs RealPage 100%
A6: 737 ParkCenter | B6: 787 E Parkcenter Blvd | C6: 27 | D6: 2027 | E6: Q3 2027 | G6: UNDER CONSTRUCTION | O6: CoStar
A7: The Ranahan | B7: 4227 E Brightside St | C7: 138 | D7: 2027 | E7: Q4 2028 | G7: PROPOSED | O7: CoStar
A8: 3300 South Vista Avenue | B8: 3300 S Vista Ave | C8: 180 | G8: PROPOSED | O8: RealPage | P8: RealPage pipeline (not yet in CoStar)
A9: 1519 South Londoner Avenue | B9: 1519 S Londoner Ave | C9: 189 | G9: PROPOSED | O9: RealPage | P9: RealPage pipeline (not yet in CoStar)
A10: Station Village | B10: 2350 W Kootenai St | C10: 84 | G10: PROPOSED | O10: RealPage | P10: RealPage pipeline (not yet in CoStar)
A11: Seasons on the Bench | B11: 2521 W Victory Rd | C11: 358 | G11: PROPOSED | O11: RealPage | P11: RealPage pipeline (not yet in CoStar)
A12: Harris Ranch East | B12: 3201 S Council Spring Rd | C12: 59 | G12: PROPOSED | O12: RealPage | P12: RealPage pipeline (not yet in CoStar)
A13: Vista Point | B13: 2017 W Victory Rd | C13: 893 | G13: PROPOSED | O13: RealPage | P13: RealPage pipeline (not yet in CoStar)

Sheet Diligence
B2: SHADOW SUPPLY (latent / untracked — watch list)
B3: Property / Site | C3: Units | D3: Est. Delivery | E3: Status | F3: Leasing Pace | G3: Notes | H3: Source
B4: Barber Valley SP-02 HDR block (Parkcenter) | G4: Land-use analysis site CR-51: 11.5 ac zoned SP-02 with High-Density Residential FLU inside the adopted Barber Valley Specific Plan; OUTSIDE the Airport Influence Area. Entitled/planned multifamily block, master-developed by Barber Valley Development (Harris Family LP); HDR blocks typically sold to merchant apartment developers. No active application found — the most apartment-competitive latent site in the 5-mi ring. | H4: https://boisedev.com/news/2021/11/12/harris-ranch-town-center/
B5: McDonald Tract (S Oakland Ave) | G5: Land-use analysis site CR-57: 10.3 ac zoned R-3 (multifamily by-right) with Mixed Use FLU, outside the Airport Influence Area. Dormant — no application, listing, or news found; owner not published. By-right MF capacity makes it a genuine watch item despite no activity. | H5: https://www.redfin.com/ID/Boise/1507-S-Oakland-Ave-83706/home/109555986
B6: East Columbia bench (Rush Valley / planned community) | G6: Land-use analysis sites CR-2/CR-3/CR-5: ~1,700+ ac far-SE 'East Columbia' bench with Boise 'Planned Community' FLU — one of three strategic planning areas the city began studying Jan 2026. Rush Valley subdivision portion (Conger Group/DevCo) approved but capped and largely unbuilt; residential blocked by missing secondary fire access and landowner coordination (Simplot, Micron, Ball Ventures, Murgoitio). Long-horizon supply, not near-term. | H6: https://boisedev.com/news/2026/01/28/southeast-boise-planning/
