Workbook

Sheet Competitive Analysis
C2: SEASONS AT MERIDIAN — 5-Mile Competitive Supply
B3: 2022–2026 New Construction | 5-mile radius | As of 2026 Q3 QTD | rev. Aug 14 2026 — blind-spot audit
B4: # | C4: Property | D4: Units | E4: Est. Delivery | F4: Occupancy | G4: Avg Mkt Rent | H4: Owner | I4: Proximity | J4: Type | K4: Notes
C5: STABILIZED / STABILIZING (22 properties, 2,879 units)
B6: 1 | C6: The Lost Rapid Townhomes | D6: 72 | E6: Q1 2022 | F6: 0.944444 | G6: — | H6: Baker, Matthew J | I6: 5 | J6: Townhome | M6: =IFERROR(VALUE(RIGHT(E6,4))*4+MATCH(LEFT(E6,2),{"Q1","Q2","Q3","Q4"},0)-1,"")
B7: 2 | C7: South Ridge I | D7: 476 | E7: Q2 2022 | F7: 0.994 | G7: — | H7: Privately Owned | I7: 3.1 | J7: Garden | K7: Delivery quarter estimated; RealPage-only — not in CoStar's 5-mi series | M7: =IFERROR(VALUE(RIGHT(E7,4))*4+MATCH(LEFT(E7,2),{"Q1","Q2","Q3","Q4"},0)-1,"")
B8: 3 | C8: Meritage West | D8: 83 | E8: Q2 2022 | F8: 0.987952 | G8: 1651.435 | H8: Pacific West Communities, Inc. | I8: 3.2 | J8: Mid-Rise | M8: =IFERROR(VALUE(RIGHT(E8,4))*4+MATCH(LEFT(E8,2),{"Q1","Q2","Q3","Q4"},0)-1,"")
B9: 4 | C9: Ambleside Townhomes | D9: 67 | E9: Q2 2022 | F9: 0.970149 | G9: 2130 | H9: Open Door Rentals Llc | I9: 2.8 | J9: Townhome | M9: =IFERROR(VALUE(RIGHT(E9,4))*4+MATCH(LEFT(E9,2),{"Q1","Q2","Q3","Q4"},0)-1,"")
B10: 5 | C10: Celebration Acres | D10: 28 | E10: Q2 2022 | F10: 0.964286 | G10: — | H10: El Ada Comm Action Agency Inc | I10: 2.7 | J10: Low-Rise | M10: =IFERROR(VALUE(RIGHT(E10,4))*4+MATCH(LEFT(E10,2),{"Q1","Q2","Q3","Q4"},0)-1,"")
B11: 6 | C11: Pine 43 | D11: 25 | E11: Q2 2022 | F11: 1 | G11: 2236 | H11: Bruce M Reichard | I11: 1.7 | J11: Garden | M11: =IFERROR(VALUE(RIGHT(E11,4))*4+MATCH(LEFT(E11,2),{"Q1","Q2","Q3","Q4"},0)-1,"")
B12: 7 | C12: Old Town Lofts | D12: 102 | E12: Q3 2022 | F12: 0.990196 | G12: 1665.5116 | H12: Pacific West Communities, Inc. | I12: 2.1 | J12: Townhome | K12: Year built: 2022/2023 | M12: =IFERROR(VALUE(RIGHT(E12,4))*4+MATCH(LEFT(E12,2),{"Q1","Q2","Q3","Q4"},0)-1,"")
B13: 8 | C13: Lavender Village | D13: 6 | E13: Q3 2022 | F13: 1 | G13: 1747.5137 | H13: — | I13: 3.9 | J13: Garden | K13: Rent: HD mix-wtd $1,748 vs CoStar ask $2,110 | M13: =IFERROR(VALUE(RIGHT(E13,4))*4+MATCH(LEFT(E13,2),{"Q1","Q2","Q3","Q4"},0)-1,"")
B14: 9 | C14: The Prospect | D14: 91 | E14: Q4 2022 | F14: 0.989011 | G14: 1165.5556 | H14: Ke Holdings Llc | I14: 3.9 | J14: Garden | M14: =IFERROR(VALUE(RIGHT(E14,4))*4+MATCH(LEFT(E14,2),{"Q1","Q2","Q3","Q4"},0)-1,"")
B15: 10 | C15: Etheridge Lane | D15: 12 | E15: Q4 2022 | F15: 1 | G15: — | H15: Visser Building Co | I15: 4.4 | J15: Garden | M15: =IFERROR(VALUE(RIGHT(E15,4))*4+MATCH(LEFT(E15,2),{"Q1","Q2","Q3","Q4"},0)-1,"")
B16: 11 | C16: Modern Craftsman Ten Mile | D16: 135 | E16: Q1 2023 | F16: 0.948148 | G16: 2164.3198 | H16: Baron Properties | I16: 3.9 | J16: Single Family | K16: Year built: 2022/2023; Occ: CoStar 95% vs RealPage 99% | M16: =IFERROR(VALUE(RIGHT(E16,4))*4+MATCH(LEFT(E16,2),{"Q1","Q2","Q3","Q4"},0)-1,"")
B17: 12 | C17: WaterWalk Boise – Meridian | D17: 38 | E17: Q1 2023 | F17: 0.947368 | G17: 1655 | H17: WaterWalk Live Stay | I17: 1 | J17: Mid-Rise | M17: =IFERROR(VALUE(RIGHT(E17,4))*4+MATCH(LEFT(E17,2),{"Q1","Q2","Q3","Q4"},0)-1,"")
B18: 13 | C18: Alante Homes at Hazelwood | D18: 32 | E18: Q1 2023 | F18: 0.96875 | G18: 2276 | H18: PEG Companies | I18: 3.8 | J18: Garden | M18: =IFERROR(VALUE(RIGHT(E18,4))*4+MATCH(LEFT(E18,2),{"Q1","Q2","Q3","Q4"},0)-1,"")
B19: 14 | C19: Altair | D19: 240 | E19: Q2 2023 | F19: 0.945833 | G19: 1624.4078 | H19: Brighton | I19: 3.4 | J19: Mid-Rise | K19: Occ: CoStar 95% vs RealPage 100% | M19: =IFERROR(VALUE(RIGHT(E19,4))*4+MATCH(LEFT(E19,2),{"Q1","Q2","Q3","Q4"},0)-1,"")
B20: 15 | C20: Dovetail | D20: 240 | E20: Q2 2023 | F20: 0.958333 | G20: 1832 | H20: Kennedy Wilson, Inc. | I20: 1.8 | J20: Garden | K20: Units: CoStar 240 vs RealPage 480; Year built: 2020/2023; Occ: CoStar 96% vs RealPage 99% | M20: =IFERROR(VALUE(RIGHT(E20,4))*4+MATCH(LEFT(E20,2),{"Q1","Q2","Q3","Q4"},0)-1,"")
B21: 16 | C21: Yellowstone Apartments | D21: 216 | E21: Q2 2023 | F21: 0.763889 | G21: 1735.4694 | H21: CBH Homes | I21: 4.1 | J21: Garden | K21: Year built: 2023/2025; Occ: CoStar 76% vs RealPage 94% | M21: =IFERROR(VALUE(RIGHT(E21,4))*4+MATCH(LEFT(E21,2),{"Q1","Q2","Q3","Q4"},0)-1,"")
B22: 17 | C22: Telluride | D22: 102 | E22: Q2 2023 | F22: 0.990196 | G22: 1884.4468 | H22: Albert Meier | I22: 3.5 | J22: Low-Rise | M22: =IFERROR(VALUE(RIGHT(E22,4))*4+MATCH(LEFT(E22,2),{"Q1","Q2","Q3","Q4"},0)-1,"")
B23: 18 | C23: Movado Village | D23: 60 | E23: Q1 2024 | F23: 0.933333 | G23: 1995 | H23: Realty Asset Management, Inc. | I23: 1 | J23: Garden | M23: =IFERROR(VALUE(RIGHT(E23,4))*4+MATCH(LEFT(E23,2),{"Q1","Q2","Q3","Q4"},0)-1,"")
B24: 19 | C24: Viera at Pinnacle | D24: 56 | E24: Q1 2024 | F24: 1 | G24: 2489.375 | H24: Brighton | I24: 3.2 | J24: Garden | M24: =IFERROR(VALUE(RIGHT(E24,4))*4+MATCH(LEFT(E24,2),{"Q1","Q2","Q3","Q4"},0)-1,"")
B25: 20 | C25: The Aren | D25: 396 | E25: Q2 2024 | F25: 0.969697 | G25: 1739.209 | H25: Brighton | I25: 0.9 | J25: Garden | K25: Year built: 2024/2025; Occ: CoStar 97% vs RealPage 100% | M25: =IFERROR(VALUE(RIGHT(E25,4))*4+MATCH(LEFT(E25,2),{"Q1","Q2","Q3","Q4"},0)-1,"")
B26: 21 | C26: ★ Seasons at Meridian (SUBJECT) | D26: 360 | E26: Q3 2024 | F26: 0.955556 | G26: 1911.1191 | H26: The Carlyle Group | I26: 0 | J26: Garden | K26: Year built: 2024/2025; SUBJECT — this deal; Occ: CoStar 96% vs RealPage 99% | M26: =IFERROR(VALUE(RIGHT(E26,4))*4+MATCH(LEFT(E26,2),{"Q1","Q2","Q3","Q4"},0)-1,"")
B27: 22 | C27: Springtree Apartments | D27: 42 | E27: Q4 2024 | F27: 0.952381 | G27: 1514 | H27: Commercial Northwest Property Management | I27: 4.8 | J27: Low-Rise | M27: =IFERROR(VALUE(RIGHT(E27,4))*4+MATCH(LEFT(E27,2),{"Q1","Q2","Q3","Q4"},0)-1,"")
C29: LEASING UP (5 properties, 815 units)
B30: 23 | C30: Village Apartments | D30: 336 | E30: Q2 2024 | F30: 0.11904762 | G30: 1747.5137 | H30: Rockworth Companies | I30: 2.6 | J30: Mid-Rise | K30: Occ: CoStar 80% vs RealPage 11%; Occ: HD ~12% (CoStar/RP showed 80%); HD (90d): occ ~12% (units leased), ~13 leases/mo | M30: =IFERROR(VALUE(RIGHT(E30,4))*4+MATCH(LEFT(E30,2),{"Q1","Q2","Q3","Q4"},0)-1,"")
B31: 24 | C31: Wesley Apartments and Townhomes | D31: 191 | E31: Q2 2024 | F31: 0.47643979 | G31: 1994.4847 | H31: Executive Management Services, LLC | I31: 3.5 | J31: Townhome | K31: Occ: CoStar 28% vs RealPage 84%; Rent: CoStar ask $1,716 vs RealPage eff $2,004; Rent: HD mix-wtd $1,994 vs CoStar ask $1,716; Occ: HD ~48% (CoStar/RP showed 28%); HD (90d): occ ~48% (units leased), ~22 leases/mo | M31: =IFERROR(VALUE(RIGHT(E31,4))*4+MATCH(LEFT(E31,2),{"Q1","Q2","Q3","Q4"},0)-1,"")
B32: 25 | C32: Shamrock Apartments | D32: 48 | E32: Q2 2025 | F32: 0.833333 | G32: — | H32: Dc Fairview Llc | I32: 2.6 | J32: Low-Rise | K32: Verify rent/occ w/ HelloData | M32: =IFERROR(VALUE(RIGHT(E32,4))*4+MATCH(LEFT(E32,2),{"Q1","Q2","Q3","Q4"},0)-1,"")
B33: 26 | C33: Tauri Apartments | D33: 156 | E33: Q2 2026 | F33: 1 | G33: 1833.7261 | H33: Brighton | I33: 4.6 | J33: Townhome | K33: Units: CoStar 156 vs RealPage 128; Year built: 2026/2027; Occ: CoStar 25% vs RealPage 18%; Rent: CoStar ask $1,862 vs RealPage eff $1,684; Occ: HD ~100% (CoStar/RP showed 25%); HD (90d): occ ~100% (units leased), ~20 leases/mo | M33: =IFERROR(VALUE(RIGHT(E33,4))*4+MATCH(LEFT(E33,2),{"Q1","Q2","Q3","Q4"},0)-1,"")
B34: 27 | C34: Delano | D34: 84 | E34: Q2 2026 | F34: 0.452 | G34: — | H34: CBH Homes | I34: 3.3 | J34: Garden | K34: Delivery quarter estimated; Verify rent/occ w/ HelloData; RealPage-only — not in CoStar's 5-mi series | M34: =IFERROR(VALUE(RIGHT(E34,4))*4+MATCH(LEFT(E34,2),{"Q1","Q2","Q3","Q4"},0)-1,"")
C36: UNDER CONSTRUCTION (5 properties, 1,213 units)
B37: 28 | C37: South Ridge II | D37: 164 | E37: Q2 2027 | G37: — | H37: — | I37: 3.1 | J37: Garden | M37: =IFERROR(VALUE(RIGHT(E37,4))*4+MATCH(LEFT(E37,2),{"Q1","Q2","Q3","Q4"},0)-1,"")
B38: 29 | C38: Dorado Station | D38: 212 | E38: Q3 2027 | G38: — | H38: — | I38: 4.9 | K38: Analyst-sourced deal (not in CoStar/RealPage); Diligence: under construction | M38: =IFERROR(VALUE(RIGHT(E38,4))*4+MATCH(LEFT(E38,2),{"Q1","Q2","Q3","Q4"},0)-1,"")
B39: 30 | C39: Summertown (remaining phases) | D39: 72 | E39: Q3 2027 | G39: — | H39: — | I39: 3.5 | K39: Analyst-sourced deal (not in CoStar/RealPage); Diligence: under construction | M39: =IFERROR(VALUE(RIGHT(E39,4))*4+MATCH(LEFT(E39,2),{"Q1","Q2","Q3","Q4"},0)-1,"")
B40: 31 | C40: Vanguard Village | D40: 552 | E40: Q1 2028 | G40: — | H40: — | I40: 4.3 | J40: Mid-Rise | M40: =IFERROR(VALUE(RIGHT(E40,4))*4+MATCH(LEFT(E40,2),{"Q1","Q2","Q3","Q4"},0)-1,"")
B41: 32 | C41: Centrepoint | D41: 213 | E41: Q1 2028 | G41: — | H41: Privately Owned | I41: 2.9 | J41: Mid-Rise | K41: RealPage pipeline (not yet in CoStar); Diligence: under construction - revived; permits issuing 2026 | M41: =IFERROR(VALUE(RIGHT(E41,4))*4+MATCH(LEFT(E41,2),{"Q1","Q2","Q3","Q4"},0)-1,"")
C43: PROPOSED (15 properties, 3,942 units)
B44: 33 | C44: Outer Banks Apartments | D44: 516 | E44: Q4 2027 | G44: — | H44: Elk Ventures | I44: 3.3 | J44: Garden | K44: Audit find Aug 2026: 2024 CUP (364 apts/126 flats/26 TH, 19.34 ac R-40/C-C, SW Franklin & Ten Mile); groundbreaking expected 2026, first units summer 2027 (Statesman); Diligence: proposed - near-UC | M44: =IFERROR(VALUE(RIGHT(E44,4))*4+MATCH(LEFT(E44,2),{"Q1","Q2","Q3","Q4"},0)-1,"")
...

Sheet Supply & Absorption
Z1: 8105
B2: SUPPLY & ABSORPTION — 5-MILE MARKET (relative-year / TTM) | Z2: =IFERROR(VALUE(RIGHT($C$5,4))*4+MATCH(LEFT($C$5,2),{"Q1","Q2","Q3","Q4"},0)-1,0)
R3: UNDER CONSTRUCTION (linked from Competitive Analysis) | Z3: =IF($C$7="Bear",3,IF($C$7="Base",2,1))
B4: As-of Quarter (Y0 end) | C4: Q2 2026 | D4: ◂ Y0 = the trailing-12-months ending here (latest complete CoStar quarter); -Y1…-Y6 step back a year each. | R4: Property | S4: Units | T4: Est. Delivery
B5: Close Quarter (Y1 start) | C5: Q4 2026 | D5: ◂ Expected deal close. Y1 = the 12 months starting here; pipeline deliveries bucket into hold years off this anchor — edit it and the Y1–Y6 windows & supply shift. | R5: ='Competitive Analysis'!C40 | S5: ='Competitive Analysis'!D40 | T5: ='Competitive Analysis'!E40 | V5: =IFERROR(VALUE(RIGHT(T5,4))*4+MATCH(LEFT(T5,2),{"Q1","Q2","Q3","Q4"},0)-1,"") | W5: =IF(V5="","",IF(V5<=$Z$1,0,MAX(1,INT((V5-$Z$2)/4)+1)))
B6: Stabilization Target | C6: 0.95 | R6: ='Competitive Analysis'!C41 | S6: ='Competitive Analysis'!D41 | T6: ='Competitive Analysis'!E41 | V6: =IFERROR(VALUE(RIGHT(T6,4))*4+MATCH(LEFT(T6,2),{"Q1","Q2","Q3","Q4"},0)-1,"") | W6: =IF(V6="","",IF(V6<=$Z$1,0,MAX(1,INT((V6-$Z$2)/4)+1)))
B7: Demand Scenario | C7: Base | R7: ='Competitive Analysis'!C38 | S7: ='Competitive Analysis'!D38 | T7: ='Competitive Analysis'!E38 | V7: =IFERROR(VALUE(RIGHT(T7,4))*4+MATCH(LEFT(T7,2),{"Q1","Q2","Q3","Q4"},0)-1,"") | W7: =IF(V7="","",IF(V7<=$Z$1,0,MAX(1,INT((V7-$Z$2)/4)+1)))
B8: Bear Annual Absorption | C8: 425 | R8: ='Competitive Analysis'!C37 | S8: ='Competitive Analysis'!D37 | T8: ='Competitive Analysis'!E37 | V8: =IFERROR(VALUE(RIGHT(T8,4))*4+MATCH(LEFT(T8,2),{"Q1","Q2","Q3","Q4"},0)-1,"") | W8: =IF(V8="","",IF(V8<=$Z$1,0,MAX(1,INT((V8-$Z$2)/4)+1)))
B9: Base Annual Absorption | C9: 850 | R9: ='Competitive Analysis'!C39 | S9: ='Competitive Analysis'!D39 | T9: ='Competitive Analysis'!E39 | V9: =IFERROR(VALUE(RIGHT(T9,4))*4+MATCH(LEFT(T9,2),{"Q1","Q2","Q3","Q4"},0)-1,"") | W9: =IF(V9="","",IF(V9<=$Z$1,0,MAX(1,INT((V9-$Z$2)/4)+1)))
B10: Bull Annual Absorption | C10: 1275 | D10: ◂ Base = trailing-3-yr CoStar average (annualized, complete quarters).
B11: Selected Annual Demand | C11: =IF($C$7="Bear",$C$8,IF($C$7="Bull",$C$10,$C$9)) | R11: PROPOSED PIPELINE (scenario toggle)
R12: Property | S12: Units | T12: Est. Delivery | U12: Built In
R13: Record | S13: 472 | U13: Bear only | V13: =IFERROR(VALUE(RIGHT(T13,4))*4+MATCH(LEFT(T13,2),{"Q1","Q2","Q3","Q4"},0)-1,"") | W13: =IF(V13="","",IF(V13<=$Z$1,0,MAX(1,INT((V13-$Z$2)/4)+1))) | X13: =IF(U13="All",1,IF(U13="Bear+Base",IF($Z$3>=2,1,0),IF(U13="Bear only",IF($Z$3>=3,1,0),0)))
R14: The Gateway at Ten Mile | S14: 390 | U14: Bear only | V14: =IFERROR(VALUE(RIGHT(T14,4))*4+MATCH(LEFT(T14,2),{"Q1","Q2","Q3","Q4"},0)-1,"") | W14: =IF(V14="","",IF(V14<=$Z$1,0,MAX(1,INT((V14-$Z$2)/4)+1))) | X14: =IF(U14="All",1,IF(U14="Bear+Base",IF($Z$3>=2,1,0),IF(U14="Bear only",IF($Z$3>=3,1,0),0)))
R15: Syringa Crossing | S15: 302 | U15: Bear only | V15: =IFERROR(VALUE(RIGHT(T15,4))*4+MATCH(LEFT(T15,2),{"Q1","Q2","Q3","Q4"},0)-1,"") | W15: =IF(V15="","",IF(V15<=$Z$1,0,MAX(1,INT((V15-$Z$2)/4)+1))) | X15: =IF(U15="All",1,IF(U15="Bear+Base",IF($Z$3>=2,1,0),IF(U15="Bear only",IF($Z$3>=3,1,0),0)))
R16: Victory Flats | S16: 301 | U16: Bear only | V16: =IFERROR(VALUE(RIGHT(T16,4))*4+MATCH(LEFT(T16,2),{"Q1","Q2","Q3","Q4"},0)-1,"") | W16: =IF(V16="","",IF(V16<=$Z$1,0,MAX(1,INT((V16-$Z$2)/4)+1))) | X16: =IF(U16="All",1,IF(U16="Bear+Base",IF($Z$3>=2,1,0),IF(U16="Bear only",IF($Z$3>=3,1,0),0)))
B17: 5-MILE MARKET | C17: -Y6 | D17: -Y5 | E17: -Y4 | F17: -Y3 | G17: -Y2 | H17: -Y1 | I17: Y0 | J17: Y1 | K17: Y2 | L17: Y3 | M17: Y4 | N17: Y5 | O17: Y6 | R17: 12565 West Fairview Avenue | S17: 275 | U17: Bear only | V17: =IFERROR(VALUE(RIGHT(T17,4))*4+MATCH(LEFT(T17,2),{"Q1","Q2","Q3","Q4"},0)-1,"") | W17: =IF(V17="","",IF(V17<=$Z$1,0,MAX(1,INT((V17-$Z$2)/4)+1))) | X17: =IF(U17="All",1,IF(U17="Bear+Base",IF($Z$3>=2,1,0),IF(U17="Bear only",IF($Z$3>=3,1,0),0)))
C18: Q3'19-Q2'20 | D18: Q3'20-Q2'21 | E18: Q3'21-Q2'22 | F18: Q3'22-Q2'23 | G18: Q3'23-Q2'24 | H18: Q3'24-Q2'25 | I18: Q3'25-Q2'26 | J18: ="Q"&(MOD(($Z$2+0),4)+1)&"'"&RIGHT(INT(($Z$2+0)/4),2)&"-Q"&(MOD(($Z$2+3),4)+1)&"'"&RIGHT(INT(($Z$2+3)/4),2) | K18: ="Q"&(MOD(($Z$2+4),4)+1)&"'"&RIGHT(INT(($Z$2+4)/4),2)&"-Q"&(MOD(($Z$2+7),4)+1)&"'"&RIGHT(INT(($Z$2+7)/4),2) | L18: ="Q"&(MOD(($Z$2+8),4)+1)&"'"&RIGHT(INT(($Z$2+8)/4),2)&"-Q"&(MOD(($Z$2+11),4)+1)&"'"&RIGHT(INT(($Z$2+11)/4),2) | M18: ="Q"&(MOD(($Z$2+12),4)+1)&"'"&RIGHT(INT(($Z$2+12)/4),2)&"-Q"&(MOD(($Z$2+15),4)+1)&"'"&RIGHT(INT(($Z$2+15)/4),2) | N18: ="Q"&(MOD(($Z$2+16),4)+1)&"'"&RIGHT(INT(($Z$2+16)/4),2)&"-Q"&(MOD(($Z$2+19),4)+1)&"'"&RIGHT(INT(($Z$2+19)/4),2) | O18: ="Q"&(MOD(($Z$2+20),4)+1)&"'"&RIGHT(INT(($Z$2+20)/4),2)&"-Q"&(MOD(($Z$2+23),4)+1)&"'"&RIGHT(INT(($Z$2+23)/4),2) | R18: Pine 43 Multifamily (Pine & Webb) | S18: 270 | U18: Bear only | V18: =IFERROR(VALUE(RIGHT(T18,4))*4+MATCH(LEFT(T18,2),{"Q1","Q2","Q3","Q4"},0)-1,"") | W18: =IF(V18="","",IF(V18<=$Z$1,0,MAX(1,INT((V18-$Z$2)/4)+1))) | X18: =IF(U18="All",1,IF(U18="Bear+Base",IF($Z$3>=2,1,0),IF(U18="Bear only",IF($Z$3>=3,1,0),0)))
B19: NEW SUPPLY (5-mi) | C19: 1227 | D19: 1575 | E19: 629 | F19: 1232 | G19: 1049 | H19: 450 | I19: =SUMIFS('Competitive Analysis'!$D$5:$D$58,'Competitive Analysis'!$M$5:$M$58,">="&8102,'Competitive Analysis'!$M$5:$M$58,"<="&8105) | J19: =SUMIFS($S$5:$S$9,$W$5:$W$9,1)+SUMIFS($S$13:$S$27,$W$13:$W$27,1,$X$13:$X$27,1) | K19: =SUMIFS($S$5:$S$9,$W$5:$W$9,2)+SUMIFS($S$13:$S$27,$W$13:$W$27,2,$X$13:$X$27,1) | L19: =SUMIFS($S$5:$S$9,$W$5:$W$9,3)+SUMIFS($S$13:$S$27,$W$13:$W$27,3,$X$13:$X$27,1) | M19: =SUMIFS($S$5:$S$9,$W$5:$W$9,4)+SUMIFS($S$13:$S$27,$W$13:$W$27,4,$X$13:$X$27,1) | N19: =SUMIFS($S$5:$S$9,$W$5:$W$9,5)+SUMIFS($S$13:$S$27,$W$13:$W$27,5,$X$13:$X$27,1) | O19: =SUMIFS($S$5:$S$9,$W$5:$W$9,6)+SUMIFS($S$13:$S$27,$W$13:$W$27,6,$X$13:$X$27,1) | R19: Heritage Square (ex-Union 93) | S19: 250 | T19: Q1 2029 | U19: Bear only | V19: =IFERROR(VALUE(RIGHT(T19,4))*4+MATCH(LEFT(T19,2),{"Q1","Q2","Q3","Q4"},0)-1,"") | W19: =IF(V19="","",IF(V19<=$Z$1,0,MAX(1,INT((V19-$Z$2)/4)+1))) | X19: =IF(U19="All",1,IF(U19="Bear+Base",IF($Z$3>=2,1,0),IF(U19="Bear only",IF($Z$3>=3,1,0),0)))
B20: ABSORPTION (5-mi) | C20: 1334 | D20: 1532 | E20: 736 | F20: 44 | G20: 852 | H20: 1144 | I20: 585 | J20: =J31-I31 | K20: =K31-J31 | L20: =L31-K31 | M20: =M31-L31 | N20: =N31-M31 | O20: =O31-N31 | R20: The Cole Denton | S20: 224 | T20: Q1 2029 | U20: Bear only | V20: =IFERROR(VALUE(RIGHT(T20,4))*4+MATCH(LEFT(T20,2),{"Q1","Q2","Q3","Q4"},0)-1,"") | W20: =IF(V20="","",IF(V20<=$Z$1,0,MAX(1,INT((V20-$Z$2)/4)+1))) | X20: =IF(U20="All",1,IF(U20="Bear+Base",IF($Z$3>=2,1,0),IF(U20="Bear only",IF($Z$3>=3,1,0),0)))
B21: OCCUPANCY (5-mi) | C21: 0.935 | D21: 0.94 | E21: 0.953 | F21: 0.865 | G21: 0.861 | H21: 0.914 | I21: =IFERROR(I31/I30,"") | J21: =IFERROR(J31/J30,0) | K21: =IFERROR(K31/K30,0) | L21: =IFERROR(L31/L30,0) | M21: =IFERROR(M31/M30,0) | N21: =IFERROR(N31/N30,0) | O21: =IFERROR(O31/O30,0) | R21: Rolling Hill (Assemble Management) | S21: 200 | T21: Q1 2029 | U21: Bear only | V21: =IFERROR(VALUE(RIGHT(T21,4))*4+MATCH(LEFT(T21,2),{"Q1","Q2","Q3","Q4"},0)-1,"") | W21: =IF(V21="","",IF(V21<=$Z$1,0,MAX(1,INT((V21-$Z$2)/4)+1))) | X21: =IF(U21="All",1,IF(U21="Bear+Base",IF($Z$3>=2,1,0),IF(U21="Bear only",IF($Z$3>=3,1,0),0)))
B22: SUBJECT (Seasons at Meridian) | R22: The Judy (Maple Grove & Overland) | S22: 162 | T22: Q1 2028 | U22: Bear only | V22: =IFERROR(VALUE(RIGHT(T22,4))*4+MATCH(LEFT(T22,2),{"Q1","Q2","Q3","Q4"},0)-1,"") | W22: =IF(V22="","",IF(V22<=$Z$1,0,MAX(1,INT((V22-$Z$2)/4)+1))) | X22: =IF(U22="All",1,IF(U22="Bear+Base",IF($Z$3>=2,1,0),IF(U22="Bear only",IF($Z$3>=3,1,0),0)))
B23: Market Rent (HelloData mix-wtd) | H23: 1777 | I23: =IFERROR('[1]Cash Flow (Annual)'!$F$4,1735) | J23: =IFERROR('[1]Cash Flow (Annual)'!$K$4,"") | K23: =IFERROR('[1]Cash Flow (Annual)'!$L$4,"") | L23: =IFERROR('[1]Cash Flow (Annual)'!$M$4,"") | M23: =IFERROR('[1]Cash Flow (Annual)'!$N$4,"") | N23: =IFERROR('[1]Cash Flow (Annual)'!$O$4,"") | O23: =IFERROR('[1]Cash Flow (Annual)'!$P$4,"") | R23: 12548 West Overland Road | S23: 156 | U23: Bear only | V23: =IFERROR(VALUE(RIGHT(T23,4))*4+MATCH(LEFT(T23,2),{"Q1","Q2","Q3","Q4"},0)-1,"") | W23: =IF(V23="","",IF(V23<=$Z$1,0,MAX(1,INT((V23-$Z$2)/4)+1))) | X23: =IF(U23="All",1,IF(U23="Bear+Base",IF($Z$3>=2,1,0),IF(U23="Bear only",IF($Z$3>=3,1,0),0)))
B24: Market Rent YoY % | D24: =IFERROR(D23/C23-1,"") | E24: =IFERROR(E23/D23-1,"") | F24: =IFERROR(F23/E23-1,"") | G24: =IFERROR(G23/F23-1,"") | H24: =IFERROR(H23/G23-1,"") | I24: =IFERROR(I23/H23-1,"") | J24: =IFERROR(J23/I23-1,"") | K24: =IFERROR(K23/J23-1,"") | ... O24: =IFERROR(O23/N23-1,"") | R24: Ascent Overland | S24: 138 | U24: Bear only | V24: =IFERROR(VALUE(RIGHT(T24,4))*4+MATCH(LEFT(T24,2),{"Q1","Q2","Q3","Q4"},0)-1,"") | W24: =IF(V24="","",IF(V24<=$Z$1,0,MAX(1,INT((V24-$Z$2)/4)+1))) | X24: =IF(U24="All",1,IF(U24="Bear+Base",IF($Z$3>=2,1,0),IF(U24="Bear only",IF($Z$3>=3,1,0),0)))
B25: Effective Rent | H25: 1619 | I25: =IFERROR('[1]Cash Flow (Annual)'!$F$5,1578) | J25: =IFERROR('[1]Cash Flow (Annual)'!$K$5,"") | K25: =IFERROR('[1]Cash Flow (Annual)'!$L$5,"") | L25: =IFERROR('[1]Cash Flow (Annual)'!$M$5,"") | M25: =IFERROR('[1]Cash Flow (Annual)'!$N$5,"") | N25: =IFERROR('[1]Cash Flow (Annual)'!$O$5,"") | O25: =IFERROR('[1]Cash Flow (Annual)'!$P$5,"") | R25: Meridian OZ Apartments | S25: 36 | U25: Bear only | V25: =IFERROR(VALUE(RIGHT(T25,4))*4+MATCH(LEFT(T25,2),{"Q1","Q2","Q3","Q4"},0)-1,"") | W25: =IF(V25="","",IF(V25<=$Z$1,0,MAX(1,INT((V25-$Z$2)/4)+1))) | X25: =IF(U25="All",1,IF(U25="Bear+Base",IF($Z$3>=2,1,0),IF(U25="Bear only",IF($Z$3>=3,1,0),0)))
B26: Effective Rent YoY % | D26: =IFERROR(D25/C25-1,"") | E26: =IFERROR(E25/D25-1,"") | F26: =IFERROR(F25/E25-1,"") | G26: =IFERROR(G25/F25-1,"") | H26: =IFERROR(H25/G25-1,"") | I26: =IFERROR(I25/H25-1,"") | J26: =IFERROR(J25/I25-1,"") | K26: =IFERROR(K25/J25-1,"") | ... O26: =IFERROR(O25/N25-1,"") | R26: Outer Banks Apartments | S26: 516 | T26: Q4 2027 | U26: Bear+Base | V26: =IFERROR(VALUE(RIGHT(T26,4))*4+MATCH(LEFT(T26,2),{"Q1","Q2","Q3","Q4"},0)-1,"") | W26: =IF(V26="","",IF(V26<=$Z$1,0,MAX(1,INT((V26-$Z$2)/4)+1))) | X26: =IF(U26="All",1,IF(U26="Bear+Base",IF($Z$3>=2,1,0),IF(U26="Bear only",IF($Z$3>=3,1,0),0)))
B27: Occupancy (financials / CoStar) | H27: 0.52394281 | I27: =IFERROR('[1]Cash Flow (Annual)'!$F$14,0.829026506335206) | J27: =IFERROR('[1]Cash Flow (Annual)'!$K$14,"") | K27: =IFERROR('[1]Cash Flow (Annual)'!$L$14,"") | L27: =IFERROR('[1]Cash Flow (Annual)'!$M$14,"") | M27: =IFERROR('[1]Cash Flow (Annual)'!$N$14,"") | N27: =IFERROR('[1]Cash Flow (Annual)'!$O$14,"") | O27: =IFERROR('[1]Cash Flow (Annual)'!$P$14,"") | R27: Emblem Meridian (Quarterra) | S27: 250 | T27: TBD | U27: Bear only | V27: =IFERROR(VALUE(RIGHT(T27,4))*4+MATCH(LEFT(T27,2),{"Q1","Q2","Q3","Q4"},0)-1,"") | W27: =IF(V27="","",IF(V27<=$Z$1,0,MAX(1,INT((V27-$Z$2)/4)+1))) | X27: =IF(U27="All",1,IF(U27="Bear+Base",IF($Z$3>=2,1,0),IF(U27="Bear only",IF($Z$3>=3,1,0),0)))
B28: Concession % | C28: =IFERROR((C23-C25)/C23,"") | D28: =IFERROR((D23-D25)/D23,"") | E28: =IFERROR((E23-E25)/E23,"") | F28: =IFERROR((F23-F25)/F23,"") | G28: =IFERROR((G23-G25)/G23,"") | H28: =IFERROR((H23-H25)/H23,"") | I28: =IFERROR((I23-I25)/I23,"") | J28: =IFERROR((J23-J25)/J23,"") | ... O28: =IFERROR((O23-O25)/O23,"")
B30: inventory | C30: 9402 | D30: 10977 | E30: 11606 | F30: 12838 | G30: 13887 | H30: 14337 | I30: =H30+I19 | J30: =I30+J19 | K30: =J30+K19 | L30: =K30+L19 | M30: =L30+M19 | N30: =M30+N19 | O30: =N30+O19
B31: occupied | C31: 8789 | D31: 10320 | E31: 11057 | F31: 11105 | G31: 11956 | H31: 13099 | I31: =H31+I20 | J31: =MIN($C$6*J30,I31+$C$11) | K31: =MIN($C$6*K30,J31+$C$11) | L31: =MIN($C$6*L30,K31+$C$11) | M31: =MIN($C$6*M30,L31+$C$11) | N31: =MIN($C$6*N30,M31+$C$11) | O31: =MIN($C$6*O30,N31+$C$11)
B33: MARKET-RENT GROWTH — TMG vs 3RD-PARTY FORECAST | J33: Y1 | K33: Y2 | L33: Y3 | M33: Y4 | N33: Y5 | O33: Y6 | P33: AVG
B34: CoStar | J34: =IFERROR('[2]Rent & Occ Data'!$C$31,"") | K34: =IFERROR('[2]Rent & Occ Data'!$D$31,"") | L34: =IFERROR('[2]Rent & Occ Data'!$E$31,"") | M34: =IFERROR('[2]Rent & Occ Data'!$F$31,"") | N34: =IFERROR('[2]Rent & Occ Data'!$G$31,"") | O34: =IFERROR('[2]Rent & Occ Data'!$H$31,"") | P34: =IFERROR(AVERAGE(J34:O34),"")
B35: RealPage | J35: =IFERROR('[2]Rent & Occ Data'!$C$32,"") | K35: =IFERROR('[2]Rent & Occ Data'!$D$32,"") | L35: =IFERROR('[2]Rent & Occ Data'!$E$32,"") | M35: =IFERROR('[2]Rent & Occ Data'!$F$32,"") | N35: =IFERROR('[2]Rent & Occ Data'!$G$32,"") | O35: =IFERROR('[2]Rent & Occ Data'!$H$32,"") | P35: =IFERROR(AVERAGE(J35:O35),"")
B36: Yardi | J36: =IFERROR('[2]Rent & Occ Data'!$C$33,"") | K36: =IFERROR('[2]Rent & Occ Data'!$D$33,"") | L36: =IFERROR('[2]Rent & Occ Data'!$E$33,"") | M36: =IFERROR('[2]Rent & Occ Data'!$F$33,"") | N36: =IFERROR('[2]Rent & Occ Data'!$G$33,"") | O36: =IFERROR('[2]Rent & Occ Data'!$H$33,"") | P36: =IFERROR(AVERAGE(J36:O36),"")
B37: GreenStreet | J37: =IFERROR('[2]Rent & Occ Data'!$C$34,"") | K37: =IFERROR('[2]Rent & Occ Data'!$D$34,"") | L37: =IFERROR('[2]Rent & Occ Data'!$E$34,"") | M37: =IFERROR('[2]Rent & Occ Data'!$F$34,"") | N37: =IFERROR('[2]Rent & Occ Data'!$G$34,"") | O37: =IFERROR('[2]Rent & Occ Data'!$H$34,"") | P37: =IFERROR(AVERAGE(J37:O37),"")
B38: Consensus (4-source avg) | J38: =IFERROR(AVERAGE(J34:J37),"") | K38: =IFERROR(AVERAGE(K34:K37),"") | L38: =IFERROR(AVERAGE(L34:L37),"") | M38: =IFERROR(AVERAGE(M34:M37),"") | N38: =IFERROR(AVERAGE(N34:N37),"") | O38: =IFERROR(AVERAGE(O34:O37),"") | P38: =IFERROR(AVERAGE(P34:P37),"")
B39: TMG — our market-rent growth ◄ | J39: =IFERROR(J24,"") | K39: =IFERROR(K24,"") | L39: =IFERROR(L24,"") | M39: =IFERROR(M24,"") | N39: =IFERROR(N24,"") | O39: =IFERROR(O24,"") | P39: =IFERROR(AVERAGE(J39:O39),"")
B41: ▸ SCENARIO INPUTS — Bear / Base / Bull (implied occupancy, rent-growth & concession assumptions — click + to expand)
B42: IMPLIED 5-MI OCCUPANCY BY DEMAND SCENARIO | J42: Y1 | K42: Y2 | L42: Y3 | M42: Y4 | N42: Y5 | O42: Y6
B43: Bear | J43: =MIN($C$6,($I$31+$C$8*1)/J30) | K43: =MIN($C$6,($I$31+$C$8*2)/K30) | L43: =MIN($C$6,($I$31+$C$8*3)/L30) | M43: =MIN($C$6,($I$31+$C$8*4)/M30) | N43: =MIN($C$6,($I$31+$C$8*5)/N30) | O43: =MIN($C$6,($I$31+$C$8*6)/O30)
...

Sheet Reconciliation Log
A1: Property | B1: Address | C1: Units | D1: Year Built | E1: Est. Delivery | F1: Deliv. Source | G1: Bucket | H1: CoStar Occ | I1: RealPage Occ | J1: HD Occ | K1: CoStar Ask Rent | L1: RealPage Eff Rent | M1: HD Ask (mix-wtd) | N1: HD Eff (mix-wtd) | O1: Sources | P1: Notes
A2: Springtree Apartments | B2: 121 S Springtree Ln | C2: 42 | D2: 2024 | E2: Q4 2024 | F2: CoStar property analytics | G2: STABILIZED / STABILIZING | H2: 0.952381 | K2: 1514 | O2: CoStar
A3: Seasons at Meridian | B3: 2700 E Overland Rd | C3: 360 | D3: 2024 | E3: Q3 2024 | F3: CoStar property analytics | G3: STABILIZED / STABILIZING | H3: 0.955556 | I3: 0.989 | K3: 1951 | L3: 1884 | M3: 1911.1191 | N3: 1879.2616 | O3: CoStar+RealPage | P3: Year built: 2024/2025; SUBJECT — this deal; Occ: CoStar 96% vs RealPage 99%
A4: The Aren | B4: 1066 S Silverstone Way | C4: 396 | D4: 2024 | E4: Q2 2024 | F4: CoStar property analytics | G4: STABILIZED / STABILIZING | H4: 0.969697 | I4: 0.998 | K4: 1762 | L4: 1841 | M4: 1739.209 | N4: 1663.8122 | O4: CoStar+RealPage | P4: Year built: 2024/2025; Occ: CoStar 97% vs RealPage 100%
A5: Viera at Pinnacle | B5: 6269 S Aspiration Ave | C5: 56 | D5: 2024 | E5: Q1 2024 | F5: CoStar property analytics | G5: STABILIZED / STABILIZING | H5: 1 | K5: 2595 | M5: 2489.375 | N5: 2395.8958 | O5: CoStar
A6: Movado Village | B6: 1711 S Movado Way | C6: 60 | D6: 2024 | E6: Q1 2024 | F6: CoStar property analytics | G6: STABILIZED / STABILIZING | H6: 0.933333 | K6: 2070 | M6: 1995 | N6: 1995 | O6: CoStar
A7: Telluride | B7: 597 N Maple Grove Rd | C7: 102 | D7: 2023 | E7: Q2 2023 | F7: CoStar property analytics | G7: STABILIZED / STABILIZING | H7: 0.990196 | K7: 1898 | M7: 1884.4468 | N7: 1884.4468 | O7: CoStar
A8: Altair | B8: 2743 W Peak Cloud Ln | C8: 240 | D8: 2023 | E8: Q2 2023 | F8: CoStar property analytics | G8: STABILIZED / STABILIZING | H8: 0.945833 | I8: 0.996 | K8: 1689 | L8: 1754 | M8: 1624.4078 | N8: 1573.1923 | O8: CoStar+RealPage | P8: Occ: CoStar 95% vs RealPage 100%
A9: Dovetail | B9: 1350 N Webb Way | C9: 240 | D9: 2023 | E9: Q2 2023 | F9: CoStar property analytics | G9: STABILIZED / STABILIZING | H9: 0.958333 | I9: 0.992 | K9: 1832 | L9: 1856 | O9: CoStar+RealPage | P9: Units: CoStar 240 vs RealPage 480; Year built: 2020/2023; Occ: CoStar 96% vs RealPage 99%
A10: Yellowstone Apartments | B10: 3500 West Pine Avenue | C10: 216 | D10: 2023 | E10: Q2 2023 | F10: CoStar property analytics | G10: STABILIZED / STABILIZING | H10: 0.763889 | I10: 0.944 | K10: 1707 | L10: 1691 | M10: 1735.4694 | N10: 1735.4694 | O10: CoStar+RealPage | P10: Year built: 2023/2025; Occ: CoStar 76% vs RealPage 94%
A11: Alante Homes at Hazelwood | B11: 6222 S Gloriosa Ln | C11: 32 | D11: 2023 | E11: Q1 2023 | F11: CoStar property analytics | G11: STABILIZED / STABILIZING | H11: 0.96875 | K11: 2276 | O11: CoStar
A12: Modern Craftsman Ten Mile | B12: 3233 W Littleton Ln | C12: 135 | D12: 2023 | E12: Q1 2023 | F12: CoStar property analytics | G12: STABILIZED / STABILIZING | H12: 0.948148 | I12: 0.993 | K12: 2229 | L12: 2243 | M12: 2164.3198 | N12: 2140.342 | O12: CoStar+RealPage | P12: Year built: 2022/2023; Occ: CoStar 95% vs RealPage 99%
A13: WaterWalk Boise – Meridian | B13: 88 n Olson Ave | C13: 38 | D13: 2023 | E13: Q1 2023 | F13: CoStar property analytics | G13: STABILIZED / STABILIZING | H13: 0.947368 | K13: 1655 | O13: CoStar
A14: The Prospect | B14: 8002 W Overland Rd | C14: 91 | D14: 2022 | E14: Q4 2022 | F14: CoStar property analytics | G14: STABILIZED / STABILIZING | H14: 0.989011 | K14: 1189 | M14: 1165.5556 | N14: 1156.3266 | O14: CoStar
A15: Etheridge Lane | B15: 1428 N Etheridge Ln | C15: 12 | D15: 2022 | E15: Q4 2022 | F15: CoStar property analytics | G15: STABILIZED / STABILIZING | O15: CoStar
A16: Old Town Lofts | B16: 33 E Idaho Ave | C16: 102 | D16: 2022 | E16: Q3 2022 | F16: CoStar property analytics | G16: STABILIZED / STABILIZING | H16: 0.990196 | I16: 0.99 | K16: 1683 | L16: 1661 | M16: 1665.5116 | N16: 1665.5116 | O16: CoStar+RealPage | P16: Year built: 2022/2023
A17: Lavender Village | B17: 2607-2615 N Linda Vista Ln | C17: 6 | D17: 2022 | E17: Q3 2022 | F17: CoStar property analytics | G17: STABILIZED / STABILIZING | K17: 2110 | M17: 1747.5137 | N17: 1747.5137 | O17: CoStar | P17: Rent: HD mix-wtd $1,748 vs CoStar ask $2,110
A18: Meritage West | B18: 13450 W Baldcypress St | C18: 83 | D18: 2022 | E18: Q2 2022 | F18: CoStar property analytics | G18: STABILIZED / STABILIZING | H18: 0.987952 | I18: 0.976 | K18: 1664 | L18: 1641 | M18: 1651.435 | N18: 1651.435 | O18: CoStar+RealPage
A19: Celebration Acres | B19: 10881 W Florence Dr | C19: 28 | D19: 2022 | E19: Q2 2022 | F19: CoStar property analytics | G19: STABILIZED / STABILIZING | H19: 0.964286 | O19: CoStar
A20: Ambleside Townhomes | B20: 1890 N Shamrock Ave | C20: 67 | D20: 2022 | E20: Q2 2022 | F20: CoStar property analytics | G20: STABILIZED / STABILIZING | H20: 0.970149 | K20: 2130 | O20: CoStar
A21: Pine 43 | B21: 1301 N Meadowglen Ave | C21: 25 | D21: 2022 | E21: Q2 2022 | F21: CoStar property analytics | G21: STABILIZED / STABILIZING | K21: 2236 | O21: CoStar
A22: South Ridge I | B22: 1703 S Grand Frk Wy | C22: 476 | D22: 2022 | E22: Q2 2022 | G22: STABILIZED / STABILIZING | I22: 0.994 | L22: 1672 | O22: RealPage | P22: Delivery quarter estimated; RealPage-only — not in CoStar's 5-mi series
A23: The Lost Rapid Townhomes | B23: 3400 W Chinden Blvd | C23: 72 | D23: 2022 | E23: Q1 2022 | F23: CoStar property analytics | G23: STABILIZED / STABILIZING | H23: 0.944444 | O23: CoStar
A24: Tauri Apartments | B24: 12673 W Ashcreek St | C24: 156 | D24: 2026 | E24: Q2 2026 | F24: CoStar property analytics | G24: LEASING UP | H24: 0.25 | I24: 0.18 | J24: 1 | K24: 1862 | L24: 1684 | M24: 1833.7261 | N24: 1813.1546 | O24: CoStar+RealPage | P24: Units: CoStar 156 vs RealPage 128; Year built: 2026/2027; Occ: CoStar 25% vs RealPage 18%; Rent: CoStar ask $1,862 vs RealPage eff $1,684; Occ: HD ~100% (CoStar/RP showed 25%); HD (90d): occ ~100% (units leased), ~20 leases/mo
A25: Delano | B25: 3858 N Centrepoint Way | C25: 84 | D25: 2026 | E25: Q2 2026 | G25: LEASING UP | I25: 0.452 | L25: 1491 | O25: RealPage | P25: Delivery quarter estimated; Verify rent/occ w/ HelloData; RealPage-only — not in CoStar's 5-mi series
A26: Shamrock Apartments | B26: 1590 N Shamrock St | C26: 48 | D26: 2025 | E26: Q2 2025 | F26: CoStar property analytics | G26: LEASING UP | H26: 0.833333 | O26: CoStar | P26: Verify rent/occ w/ HelloData
A27: Village Apartments | B27: 2651 N Records Ave | C27: 336 | D27: 2024 | E27: Q2 2024 | F27: CoStar property analytics | G27: LEASING UP | H27: 0.803571 | I27: 0.113 | J27: 0.11904762 | K27: 1742 | L27: 1677 | M27: 1747.5137 | N27: 1747.5137 | O27: CoStar+RealPage | P27: Occ: CoStar 80% vs RealPage 11%; Occ: HD ~12% (CoStar/RP showed 80%); HD (90d): occ ~12% (units leased), ~13 leases/mo
A28: Wesley Apartments and Townhomes | B28: 3104 N Venable Ln | C28: 191 | D28: 2024 | E28: Q2 2024 | F28: CoStar property analytics | G28: LEASING UP | H28: 0.277487 | I28: 0.838 | J28: 0.47643979 | K28: 1716 | L28: 2004 | M28: 1994.4847 | N28: 1994.4847 | O28: CoStar+RealPage | P28: Occ: CoStar 28% vs RealPage 84%; Rent: CoStar ask $1,716 vs RealPage eff $2,004; Rent: HD mix-wtd $1,994 vs CoStar ask $1,716; Occ: HD ~48% (CoStar/RP showed 28%); HD (90d): occ ~48% (units leased), ~22 leases/mo
A29: Vanguard Village | B29: 1085 S 10 Mile Rd | C29: 552 | D29: 2027 | E29: Q1 2028 | G29: UNDER CONSTRUCTION | M29: 1747.5137 | N29: 1747.5137 | O29: CoStar
A30: Centrepoint | B30: 3100 N Centrepoint Way | C30: 213 | E30: Q1 2028 | G30: UNDER CONSTRUCTION | O30: RealPage | P30: RealPage pipeline (not yet in CoStar); Diligence: under construction - revived; permits issuing 2026
A31: Dorado Station | B31: 1500 N Eldorado St, Boise 83704 | C31: 212 | E31: Q3 2027 | G31: UNDER CONSTRUCTION | O31: Diligence | P31: Analyst-sourced deal (not in CoStar/RealPage); Diligence: under construction
A32: Summertown (remaining phases) | B32: 3005 N Ridgebury Ln, Meridian 83646 | C32: 72 | E32: Q3 2027 | G32: UNDER CONSTRUCTION | O32: Diligence | P32: Analyst-sourced deal (not in CoStar/RealPage); Diligence: under construction
A33: South Ridge II | B33: 1703 S Grand Frk Wy | C33: 164 | D33: 2027 | E33: Q2 2027 | G33: UNDER CONSTRUCTION | O33: RealPage
A34: The Cole Denton | B34: 580 N Cole Rd | C34: 224 | E34: Q1 2029 | G34: PROPOSED | O34: RealPage | P34: RealPage pipeline (not yet in CoStar); Diligence: proposed - refiled May/Jun 2026 as 6-story 200+ units (PLN26-00493)
A35: Rolling Hill (Assemble Management) | B35: 4270 E Overland Rd, Meridian 83642 | C35: 200 | E35: Q1 2029 | G35: PROPOSED | O35: Diligence | P35: Analyst-sourced deal (not in CoStar/RealPage); Diligence: proposed
A36: Heritage Square (ex-Union 93) | B36: SE corner Main St & Broadway Ave, Meridian 83642 | C36: 250 | E36: Q1 2029 | G36: PROPOSED | O36: Diligence | P36: Analyst-sourced deal (not in CoStar/RealPage); Diligence: proposed - announced Jul 13 2026; Union 93 skeleton repurposed
A37: The Judy (Maple Grove & Overland) | B37: 1770 S Maple Grove Rd, Boise 83704 | C37: 162 | E37: Q1 2028 | G37: PROPOSED | O37: Diligence | P37: Analyst-sourced deal (not in CoStar/RealPage); Diligence: proposed - equity raise underway; construction targeted Q3 2026
A38: Meridian OZ Apartments | B38: 1475 E Franklin Rd | C38: 36 | G38: PROPOSED | O38: CoStar+RealPage | P38: Diligence: proposed - stalled; downsized to 36u Oct 2024 - entitled site listed then off-market
A39: The Gateway at Ten Mile | B39: 2954 W Franklin Rd | C39: 390 | D39: 2027 | G39: PROPOSED | O39: CoStar | P39: Diligence: proposed - long-dated; residential 5-7 yrs out per developer
A40: Ascent Overland | B40: 11101 W Overland Rd | C40: 138 | D40: 2028 | G40: PROPOSED | O40: CoStar | P40: Diligence: proposed - stalled; entitled site for sale via CBRE at $5.0M
...

Sheet Diligence
B2: PIPELINE DILIGENCE
B3: Property / Site | C3: Units | D3: Est. Delivery | E3: Status | F3: Leasing Pace | G3: Notes | H3: Source
B4: The 10 | E4: withdrawn - superseded by The Gateway at Ten Mile | G4: Original 559-unit 'The 10' (Elk Ventures, 2021) never proceeded; the site was re-entitled as The Gateway at Ten Mile (H-2024-0010) for 390 units, approved Nov 2024. Removed to avoid double-counting the same site as two deals — the Gateway row carries the live entitlement. | H4: https://boisedev.com/news/2024/11/20/the-gateway-at-10-mile-meridian/
B5: Record | C5: 472 | D5: TBD | E5: proposed - stalled; CUP likely lapsed - Brighton silent 4+ years | G5: DEEP-DIVE VERIFIED 7/16/2026 (all verdicts survived 3-lens adversarial check). CUP H-2022-0008 heard Apr 7 2022 (staff conditioned approval on cutting to ~40 du/ac ≈ 398u vs 472 proposed); NO CZC, permit, extension, or hearing step since, and Meridian permit reports through Apr 2026 show nothing at Records Way. Under Meridian's 2-yr CUP commencement rule the entitlement has very likely expired — would need re-entitlement. Brighton's page has said 'coming soon' for 4+ years while its news feed promotes everything else. Not verifiably dead (no site sale found) — Bear-only, undated. | H5: https://www.brighton.co/brighton-place/records-way-the-village-at-meridian/
B6: Centrepoint | C6: 213 | D6: Q1 2028 | E6: under construction - revived; permits issuing 2026 | G6: AUDIT CORRECTION (July 2026): previously marked withdrawn per 2024 reporting, but the project was revived — Meridian's June 2026 permit report shows C-MULTI-2026-0007 (Bldg C, 56u) ISSUED 6/25/2026; 213 units in 5 buildings at N Centrepoint Way south of Ustick (Rockefeller; workforce/affordable positioning). Phased delivery est. from permit timing. | H6: https://meridiancity.org/media/f5alu5zs/bldgmonthlypermits.pdf
B7: Cobalt Point | C7: 264 | E7: withdrawn - applicant withdrew CUP H-2022-0042 on Dec 1 2022; never re-filed | G7: DEEP-DIVE VERIFIED 7/16/2026 (all verdicts survived 3-lens adversarial check). DEAD: The Land Group's 264u CUP (H-2022-0042, 11.95 ac C-G parcel R7909850396 east of S Cobalt Point Way) was continued from 10/20/2022 and formally WITHDRAWN by the applicant at the 12/1/2022 P&Z meeting — never approved. No re-application in 3.5 years, no permits, cobaltpointmeridian.com no longer resolves (DNS dead, verified 7/16/2026), and the land was marketed for office/mixed-use. RealPage's Ten Mile framing confuses it with Flats/Lofts at Ten Mile on W Cobalt Dr. Dropped; at most Bear-case shadow LAND, not a project.' | H7: https://boisedev.com/news/2022/06/13/cobalt-point-meridian/
B8: Madison Town Square | E8: dead - plan pulled June 2024; site for sale | G8: Madison Capital Group (MCG Boise Owner LLC) bought the old Sears at 460 N Milwaukee in 2021 and proposed 251 units, but pulled its design-review request and the plan was reported dead June 2024; site listed for sale at $8M (later $7.5M), still unsold. | H8: https://boisedev.com/news/2024/06/04/boise-sears-sale/
B9: Syringa Crossing | C9: 302 | E9: proposed - remanded; revised 302u CUP re-heard P&Z 8/6/2026 (outcome unpublished) | G9: DEEP-DIVE VERIFIED 7/16/2026 (all verdicts survived 3-lens adversarial check). Status unchanged and current: P&Z recommended denial Apr 2 2026; council unanimously REMANDED the revised plan (up to 400 homes, more office/retail, ITD right-in/right-out granted on SH-69) back to P&Z on 6/17/2026; no re-hearing outcome as of 7/16/2026 and staff still say revisions don't cure comp-plan inconsistencies. Hawkins still markets the corners as a 'proposed' shopping center. No annexation, plat, or permits — Bear-case only with elevated kill risk; earliest delivery ~2029 if it survives. Land-use dossier SM-12 covers the adjacent block. | AUG 2026 AUDIT: CUP now 302 units on 15.23 ac R-40 inside ~400-home plan; P&Z rec. denial 4/2/26, council remanded 6/17/26, re-heard 8/6/26. | H9: https://boisedev.com/news/2026/06/17/a-developer-made-changes-to-a-proposed-400-home-mixed-use-project-meridian-gives-commission-another-vote-on-it/
B10: The Cole Denton | C10: 224 | D10: Q1 2029 | E10: proposed - refiled May/Jun 2026 as 6-story, 224 units | G10: DEEP-DIVE VERIFIED 7/16/2026 (all verdicts survived 3-lens adversarial check). Stale in BOTH directions: the 136u plan got further than believed — $11.2M foundation/podium permit BLD22-03293 was ISSUED 4/5/2024 — but was never built and EXPIRED 3/31/2026 (parcel S1007325725 still vacant land, $2.78M, on the 2026 roll). Then in May/Jun 2026 a NEW filing appeared on the same 2.13-ac MX-3/DA parcel: PLN26-00493 '580 N COLE RD - DRH', a six-story mixed-use building with 200+ apartments (sponsor almost certainly Kal Pacific), at neighborhood-meeting/design-review stage (tracker 6/15/2026). LoopNet listing off-market. Live early-stage ~200u proposal; delivery 2029+; do NOT promote to UC. City separately buying neighboring 709 N Cole for affordable housing. | AUG 2026 AUDIT: unit count raised to 224 per BoiseDev 7/27/26 (Kal Pacific abandons 2021 DA, uses Boise 2023 code). | H10: https://boisedev.com/news/2021/05/04/five-story-apartment-building-coming-to-lot-across-from-boise-town-square/
B11: 12565 West Fairview Avenue | C11: 275 | D11: TBD | E11: proposed - stalled; pre-application only - silent since Apr 2025 | G11: DEEP-DIVE VERIFIED 7/16/2026 (all verdicts survived 3-lens adversarial check). Never verifiably advanced past pre-application/neighborhood-meeting stage (Apr 2025); no application, hearing, approval, or permit since — ~15 months of silence. Mar 2026 city permit report shows nothing at the address; absent from BoiseDev's Feb 2026 zoning-year recap of 2025 approvals. AutoNation still owner, site not re-listed. Bear-only shadow. Sits on land-use developable parcel S1109110516. | H11: https://boisedev.com/news/2025/04/23/boise-fairview-apartments/
B12: 12548 West Overland Road | C12: 156 | D12: TBD | E12: proposed - stalled; PUD likely lapsed ~Mar 2026 - RV storage still operating | G12: DEEP-DIVE VERIFIED 7/16/2026 (all verdicts survived 3-lens adversarial check). Built-to-sell entitlement drifting toward dead: PUD approved 3/12/2024 and the site was listed on LoopNet THE SAME WEEK (3/4/2024); listing since pulled with no evidence of sale (Ada Cty roll still bare 5.4-ac commercial parcel, $2.66M). Boise PUD approvals lapse 24 months absent construction => likely expired ~Mar 2026; no permit through June 2026. Overland RV Storage still operating with active waiting lists (site live; Yelp updated Jun 2026). Bear-only. | H12: https://boisedev.com/news/2023/11/29/hook-trust-boise/
B13: 10975 West Lake Hazel Road | E13: exclude - unverifiable / likely misidentified | G13: No development application found at this address (an 11.85-ac parcel with a 1994 single-family home per county records); the nearest real deal — PEG Companies' 118-unit proposal at Five Mile & Lake Hazel — was denied twice by Ada County commissioners (2022 and May 2024). RealPage entry cannot be tied to any live project. | H13: https://boisedev.com/news/2024/05/22/southwest-boise-commercial/
B14: Cole Road | E14: exclude - existing 1978-82 asset (76u Ridgeline Apartments); not new supply | G14: 709 N Cole Rd is the EXISTING 76-unit Ridgeline Apartments (built 1978-1982), marketed for sale by Berkadia — a misidentified pipeline entry; no evidence of any new 61-unit multifamily proposal or rezone at this address. | H14: https://properties.berkadia.com/cole-road-469858/
B15: Villas at Twelve Oaks East | E15: exclude - likely duplicate of existing built Twelve Oaks community | G15: Could not confirm a distinct 64-unit 'East' phase at 115 S Linder Rd; Meridian records show only ZV-2021-0055 'Twelve Oaks Apartments' and the existing CBH Twelve Oaks (~106u) is built and leasing — the RealPage entry likely duplicates or misidentifies it. | H15: https://weblink.meridiancity.org/WebLink/Browse.aspx?id=244917&dbid=0&repo=MeridianCity&cr=1
B16: Promenade Cottages I | E16: not multifamily - for-sale townhomes/cottages | G16: Per BuildIdaho and a City of Meridian site plan, Promenade Cottages at the SE corner of Fairview Ave & 3rd St (A-Team Consultants) is a 30-unit mix of FOR-SALE townhomes and single-family alley-load cottage homes — not a rental apartment community. | H16: https://www.buildidaho.com/meridian-homes-for-sale/promenade-cottages/
B17: Meridian OZ Apartments | C17: 36 | D17: TBD | E17: proposed - stalled; downsized to 36u Oct 2024 - entitled site listed then off-market | G17: DEEP-DIVE VERIFIED 7/16/2026 (all verdicts survived 3-lens adversarial check). 60u plan never built; entitlement MODIFIED DOWN to 36 units Oct 2024 (MCU-2024-0002, Pivot North; findings adopted 10/17/2024). Owner then listed the 2.39-ac site at $1.7M as a 'fully entitled' OZ development opportunity (IMLS 98949803); listing went PENDING, now off-market as of 7/16/2026 — sale closed or withdrawn, no new owner/permit surfaced; no building permit in Meridian reports. Sponsor Realm's other Meridian project was denied Nov 2024 (winding down). Bear-only at 36u, undated. | H17: https://boisedev.com/news/2023/01/23/meridian-oz-apartments/
B18: Union 93 | E18: dead - foreclosed & sold at auction Oct 2025; superseded by Heritage Square | G18: DEEP-DIVE VERIFIED 7/16/2026 (all verdicts survived 3-lens adversarial check). Union 93 is definitively dead: Galena's project stalled late 2022 under $20M+ contractor liens, went through foreclosure, and the property was SOLD at an Ada County Sheriff's auction Oct 2025 to Ahlquist (Gray Owl) + Pacific Companies. Dropped from the competitive set; the successor project is tracked as 'Heritage Square (ex-Union 93)' — ~250u, announced 7/13/2026. | H18: https://boisedev.com/news/2025/10/09/ahlquist-pacific-companies-union-93-meridian/
B19: Victory Flats | C19: 301 | D19: TBD | E19: proposed - stalled; Jan 2024 start extension lapsed unbuilt | G19: DEEP-DIVE VERIFIED 7/16/2026 (all verdicts survived 3-lens adversarial check). Approved Mar 2022; real permitting-stage effort followed (submittals, Idaho Power payments, ACHD/Veolia coordination) but Jan 2024 Welltower took a cost-driven TWO-YEAR extension to start construction — that window has now run out with no permit ever issued at 8373 W Victory Rd (city open-data through June 2026). BoiseDev tracker stale since Feb 2022; Welltower still owns. Bear-only; CoStar's Q3 2028 has no support. | H19: https://boisedev.com/news/2022/03/11/mix-of-hundreds-of-housing-units-approved-on-former-school-district-site-in-southwest-boise/
B20: The Hummingbird | E20: dead - approval expired spring 2025 | G20: Approved 2023 at 170 units (reworked from ~200) on the Aquarium of Boise site at Franklin & Cole (60 N Cole Rd); the two-year approval expired spring 2025 and the owner instead proposed an aquarium expansion on the site (Aug 2025) — CoStar's Q3 2028 delivery is not supported. | H20: https://boisedev.com/news/2025/08/18/aquarium-boise-expansion/
B21: The Gateway at Ten Mile | C21: 390 | D21: TBD | E21: proposed - long-dated; residential 5-7 yrs out per developer | G21: DEEP-DIVE VERIFIED 7/16/2026 (all verdicts survived 3-lens adversarial check). Entitlement live (H-2024-0010, Nov 2024) and the COMMERCIAL phase is being marketed (MJPCRE retail pad ground-lease campaign, Nov 2025) — but developer told council residential is 'at least five to seven years out' (~2030-2032) and no residential permits/plats exist through June 2026. IDENTITY WARNING: the June 2026 C-MULTI-2025-0023/24/25 permits at Franklin & Ten Mile are OUTER BANKS (516u, SW corner) — do NOT attribute to Gateway. Bear-only; discard CoStar's Q4 2028. | H21: https://boisedev.com/news/2024/11/20/the-gateway-at-10-mile-meridian/
B22: Ascent Overland | C22: 138 | D22: TBD | E22: proposed - stalled; entitled site for sale via CBRE at $5.0M | G22: DEEP-DIVE VERIFIED 7/16/2026 (all verdicts survived 3-lens adversarial check). Approved 5-1 Nov 2023 (11880 W Overland Rd, ~3.5 ac); 2.5+ yrs later no permit, no groundbreaking, and MVRK's own projects page still says 'TBD' (checked 7/16/2026). The site is marketed FOR SALE as a 'fully entitled development opportunity' at $4,999,999 with CBRE (MLS 98945418) — sponsor exiting, not building. Feb 2025 ConstructConnect record still 'Design' stage. Bear-only; delivery depends on a hypothetical buyer. | H22: https://boisedev.com/news/2023/11/15/boise-city-council-approves-overland-road-apartment-project-over-some-neighborhood-opposition/
B23: Fairview | C23: 150 | E23: withdrawn - CUP H-2023-0001 withdrawn Jun 15 2023; site re-tenanted as RV dealership Apr 2024 | G23: DEEP-DIVE VERIFIED 7/16/2026 (all verdicts survived 3-lens adversarial check). DEAD: Biltmore/Pivot North's 150u CUP (H-2023-0001, 8.25 ac C-G at 1005 E Fairview) was WITHDRAWN by the applicant at the 6/15/2023 P&Z hearing before any vote. The 20k sf ex-dealership building was marketed for retail lease Jan 2024 and the city issued occupancy permit C-CO-2024-0029 on 4/10/2024 to Uncharted Recreation (RV/golf-cart dealership), still operating mid-2026. Biltmore's 'coming soon' page is a stale placeholder. Dropped; C-G zoning would allow a future resubmittal — shadow footnote only. | H23: https://boisedev.com/news/2023/01/11/fairview-apartments-meridian/
B24: Promenade Cottages II | E24: not multifamily - for-sale townhomes/cottages (same community as Phase I) | G24: Phase II of the Promenade Cottages for-sale townhome/cottage community at Fairview & 3rd (A-Team Consultants) — same for-sale product as Phase I; not rental apartment supply. | H24: https://www.buildidaho.com/meridian-homes-for-sale/promenade-cottages/
B25: The Judy (Maple Grove & Overland) | C25: 162 | D25: Q1 2028 | E25: proposed - equity raise underway; construction targeted Q3 2026 | G25: DEEP-DIVE VERIFIED 7/16/2026 (all verdicts survived 3-lens adversarial check). Fully entitled (council Sep 2024; DRH24-00090 refined 174→162u per city Aug 2025 Development Trends). Hawkins closed land Oct 2024, CDs complete Apr 2026, live $12.4M LP equity raise targeting Q3 2026 start. OM schedule: building permit ESTIMATED TO ISSUE ~7/21/2026; first CofO Aug 2027, last Apr 2028; 20u/mo lease-up => ~Q1 2028 first meaningful units. No permit in city lists through 6/30/2026 — stays PROPOSED. RE-CHECK Aug-Sep 2026: likely UC promotion if the raise closes. Capitalization is the timing risk. Land-use site 177 / parcel S1124223215 — conditional R-2 path being exercised. | H25: Hawkins Capital Markets OM — research/oms/Maple_Grove_Overland_Equity_Hawkins_OM.pdf
B26: Rolling Hill (Assemble Management) | C26: 200 | D26: Q1 2029 | E26: proposed | G26: DEEP-DIVE VERIFIED 7/16/2026 (all verdicts survived 3-lens adversarial check). Annexation + rezone + DA approved 5-1 on 5/19/2026 (200u over ~19.5-20k sf commercial, four 3-story bldgs; up from the 184u resubmittal after the 2024 denial). DA recording + CZC/design review still ahead of permits => vertical realistically late 2026 at earliest, first units unlikely before late 2028 (~Q1 2029). Old LoopNet land listing inactive (assemblage complete); 7 of 10 adjacent owners gave letters of intent to sell. Keep PROPOSED — live pipeline. | H26: https://boisedev.com/news/2026/05/20/ready-for-its-next-phase-meridian-approves-project-bringing-something-new-to-overland-rd/
B27: Pine 43 Multifamily (Pine & Webb) | C27: 270 | E27: proposed | G27: DEEP-DIVE VERIFIED 7/16/2026 (all verdicts survived 3-lens adversarial check). CUP H-2024-0071 live (approved 10/21/2025; commencement clock to ~Oct 2027); no appeal, foreclosure, or listing. DRB Investments says no groundbreak before 2027, townhomes first, ~$1B/900+u build-out phased 10-12 yrs. Only 2026 Pine 43 permits are SF/townhome + a monument sign — no MF permit through June 2026. Keep PROPOSED, undated; earliest plausible MF delivery ~2029. Distinct from the existing 25u 'Pine 43' comp. | AUG 2026 AUDIT: the SAME approved MDA (H-2024-0071, council 10/21/2025 4-1) also allows up to 604 vertically-integrated units + 30 TH beyond this 270u CUP — see shadow row "Pine 43 VI residential". | H27: https://boisedev.com/news/2025/10/22/large-urban-project-gets-green-light-from-meridian-city-council/
B28: Dorado Station | C28: 212 | D28: Q3 2027 | E28: under construction | G28: AUDIT FIND: J. Fisher Companies 6-story, 100% income-restricted (50-80% AMI, incl. 21 Our Path Home units), $70M, broke ground Oct 2025 at 1500 N Eldorado St (west Boise bench) — 4.9 mi from subject, just inside the ring. Delivery targeted summer 2027. Affordable positioning limits direct rent competition but adds ring supply. Classic CoStar/RealPage-invisible affordable deal. | H28: https://www.cityofboise.org/news/planning-and-development-services/2025/october/dorado-station-apartments-celebrate-groundbreaking/
B29: Summertown (remaining phases) | C29: 72 | D29: Q3 2027 | E29: under construction | G29: AUDIT FIND: Shannon Robnett Industries' 191-unit phased garden/rowhouse community at Ustick & Venable (~3.5 mi); early buildings already leasing but THREE new 24-plex permits issued June 2026 (C-MULTI-2025-0016/-0022/-0023, incl. 3005 N Ridgebury Ln) = 72 units of fresh supply. Not in CoStar/RealPage; verify delivered-vs-remaining split against next vendor pull. | H29: https://meridiancity.org/media/f5alu5zs/bldgmonthlypermits.pdf
B30: Heritage Square (ex-Union 93) | C30: 250 | D30: Q1 2029 | E30: proposed - announced Jul 13 2026; Union 93 skeleton repurposed | G30: DEEP-DIVE VERIFIED 7/16/2026 (all verdicts survived 3-lens adversarial check). Tommy Ahlquist (Gray Owl Holdings) + The Pacific Companies bought the failed Union 93 block at the Ada County Sheriff's foreclosure auction Oct 2025 and on 7/13/2026 announced Heritage Square: the existing concrete skeleton repurposed into TWO residential towers totaling ~250 units + 120k sf Class A office + 32k sf retail (Babcock Design; McAlvain GC). Owners hope to start late 2026/early 2027, 20-24 mo buildout => ~Q1 2029. No permits issued yet — PROPOSED. Replaces the dead Union 93 row (dropped; see its diligence entry). | H30: https://boisedev.com/news/2026/07/13/union-93-heritage-square-meridian-ahlquist-pacific-companies/
B32: Outer Banks Apartments
B33: Overland & Wells II / "Seasons at Meridian II" (2600 E Overland) | C33: 345 | E33: DEAD - DENIED by City Council 10/25/2022; findings adopted 11/9/2022; no re-application through Aug 2026 | G33: AUG 2026 AUDIT (the blind-spot find): Morgan Stonehill's marketed 351u Phase II next door to the subject (345u at hearing; H-2022-0030 MDA+CUP, owner WinCo Foods). P&Z rec. denial 3-1 (traffic; original approval was retail); council denied both requests — employment-land loss, failing Overland/Eagle intersections, MF over-concentration next to Phase 1. No CUP ever issued → no TEC possible. WinCo lot-split the 18 ac Feb 2025 along future Cinema Dr; marketed since Jan 2024 (Colliers) as big-box/pad retail ground leases. ~5% de-novo revival; earliest delivery ~2030 if ever. Denial precedent SHIELDS the subject's node. | H33: https://meetings.municode.com/adaHtmlDocument/index?cc=MERIDIANID&me=3aa003edf07646dc9cbd1598e8b33e22&ip=true
B34: Emblem Meridian (Quarterra) | C34: 250 | D34: TBD | E34: proposed - formal early plans filed June 2026 | G34: PROMOTED from shadow watch Aug 2026 (user call: it is a live proposal). Quarterra "Emblem Meridian" 250 units (apartments + TH) on ~13 ac R-15, N of Eagle & Victory — ex-Artisan Victory Market site (H-2022-0066 131u BTR approved 2023, never built). Formal early plans filed June 2026 per BoiseDev 6/10/26; no hearing date yet. Nearest live MF application to the subject (1.0 mi, same Eagle Rd corridor). | H34: https://boisedev.com/news/2026/06/10/meridian-emblem-victory-eagle-homes-apartment/
B35: SHADOW SUPPLY (latent / untracked — watch list)
B36: Property / Site | C36: Units | D36: Est. Delivery | E36: Status | F36: Leasing Pace | G36: Notes | H36: Source
B37: Emblem Meridian (Quarterra) / Artisan Victory Market site | C37: 250 | G37: PROMOTED Aug 2026 to pipeline row #44 (250u) — kept here for history. Land-use analysis site SM-76: ~12-ac BPS Eagle Road LLC assemblage on S Eagle Rd. 'Artisan Victory Market' (H-2022-0066) approved 2023 for 131 build-to-rent units + commercial but never built; superseded by Quarterra's 'Emblem Meridian' ~250-unit concept (pre-application June 2026). Closest large latent MF site to the subject (~1 mi). | AUG 2026 AUDIT: formal early plans FILED June 2026 — 250 units (apts+TH) on ~13 ac (BoiseDev 6/10/26). Nearest live MF application to the subject (1.0 mi). | H37: https://boisedev.com/news/2026/06/10/meridian-emblem-victory-eagle-homes-apartment/
B38: Tanner Creek apartments (Waltman/Johnson Ln) | C38: 280 | G38: Land-use analysis site SM-15: Tanner Creek (heard Nov 2023; moved forward) — 83 SF homes + 45 townhomes + 280 phased apartments on ~38 ac, paired with ~30-ac Hawkins commercial between I-84 and Waltman Ln. Residential now being built by CBH Homes; the 280-unit apartment component is latent supply not yet in the CoStar/RealPage pipeline. | H38: https://boisedev.com/news/2023/11/28/plans-for-two-large-developments-off-i-84-and-meridian-rd-move-forward/
B39: Graycliff Estates R-40 block | C39: 224 | G39: Land-use analysis site SM-3: Graycliff Estates (Star Development) approved preliminary plat of ~200 SF homes PLUS 224 apartments (R-40 high-density block) on ~52 ac; SF portion building since 2021. The 224-unit apartment block remains unbuilt latent supply. | AUG 2026 AUDIT: confirmed still unbuilt; no 2026 hearing/permit activity found. | H39: https://www.weknowboise.com/graycliff-estates.php
B40: Touchmark Meadow Lake Village expansion | G40: Land-use analysis site SM-9: ~64 undeveloped ac of Touchmark's ~121-ac senior community. July 2025 development-modification agreement + rezone + PUD in progress to a broader 'Touchmark Mixed Use' (mixed housing types). Senior-oriented, but adds rental housing capacity 1.5 mi from subject. | H40: https://boisedev.com/news/2025/07/14/touchmark-meridian-meadowlake-mixed-use/
B41: Ten Mile Crossing residual HDR parcels | G41: Land-use analysis site SM-4: residential portion (R-15/R-8) of Brighton's Ten Mile Crossing at SW Overland & Ten Mile — partially built (Cortland South Meridian + CBH SF); remaining High-Density Residential parcels planned/dormant, including an 8.6-ac and a 14.4-ac R-15 vacant parcel (highest-interest sites in the land-use ranking). Note: South Ridge II (164u UC, tracked in the chart) is rising in this same corridor. | H41: https://www.brighton.co/brighton-place/ten-mile-crossing/
B42: Brighton Apex R-15 parcel (Lake Hazel) | G42: Land-use analysis site SM-61: 15.1-ac R-15 (med-high-density) parcel on E Lake Hazel Rd inside Brighton's approved Apex/Pinnacle master-plan footprint; adjacent phases actively building. Latent MF-capable ground in the fast-growing S Meridian corridor. | H42: https://boisedev.com/news/2024/12/20/brighton-pinnacle-costco-meridian/
...
