Workbook

Sheet READ ME
A1: Canyon Ridge vs Seasons at Meridian — Demographics, Employer & Micron-Exposure Comparison
A3: Prepared | B3: July 20, 2026
A4: Purpose | B4: Apples-to-apples comparison of the two live deals across tenant quality, employer diversification, and Micron exposure, using the same T1–T6 framework as the Canyon Ridge Employer / Micron Analysis (2026.06.24).
A6: SOURCES
A7: Canyon Ridge | B7: Entrata "Resident Data 3.0" as of 06/24/2026 (Primary + Co-Applicant; statuses Future/Current/Notice) · standardized employers/tiers from Canyon Ridge Employer & Micron Analysis (2026.06.24) · move-in timeline from Canyon Ridge Rent Roll Cross-Analysis (2026.06.24). 287 units; 2552 E Gowen Rd, Boise — adjacent to Micron HQ/Triton fab campus.
A8: Seasons at Meridian | B8: Seller "Demographics Report w/Roommates" 07/10/2026 (Yardi; Status=Current) + "Rent Roll with Lease Charges" as of 07/09/2026. 360 units; Meridian, ID (~20 mi from Micron campus).
A9: New work in this book | B9: All 375 raw Seasons employer spellings standardized to 304 canonical employers and classified T1–T6; ~45 ambiguous / Micron-plausible names individually web-researched (July 2026) — see Employers - Seasons & Name Map tabs. Industry coding added to both properties.
A11: TIER FRAMEWORK | B11: T1 = Micron direct · T2 = Micron construction subcontractor (fab build) · T3 = Micron engineering/design/consulting/IT-staffing · T4 = semiconductor equipment/tool/materials vendor serving Micron · T5 = other semiconductor/tech, NOT Micron-related · T6 = unrelated/local. "Micron-related broad" = T1+T2+T3+T4. Confidence scale follows the CR workbook (Confirmed / Strong-inferred / Inferred / Weak-inferred / Weak-unverified / Confirmed-NotMicron).
A12: Alignment notes | B12: Prime Controls and POWER Engineers appear at both properties; Seasons classifications were aligned to the CR workbook (both T3). ESI = Engineered Structures Inc. (Meridian HQ; ENR documents ESI building structures at Micron's Boise HQ campus) — classified T2 Confirmed.
A14: COUNTING RULES
A15: Occupant counting | B15: Occupant level, matching the CR workbook: CR = Primary + Co-Applicant (457 records). Seasons = Primary/Spouse/Roommate/Other, EXCLUDING the 29 Guarantors (604 unique people → 575 resident occupants). Seasons raw export duplicates a person once per pet — collapsed to one row per person.
A16: "Employed" | B16: Occupants with a classified employer. Retired / student / homemaker / alimony (Seasons: 10) and blanks (CR: 119 · Seasons: 122) are excluded from the employed denominator. Self-employed and gig workers count as employed.
A17: Income screens | B17: Seasons per-person incomes exclude: guarantors; $0/blank; 51 rows that are byte-for-byte copies of another occupant in the same unit (same DOB + same salary — children/roommates keyed in from the primary's record); 3 entries ≥$1M (corporate lease entered as a person at $2.49M; two probable monthly-as-annual entry errors). CR incomes used as stated (>0).
A18: Household income | B18: Sum of qualifying occupant incomes per unit. Rent coverage = household income ÷ (12 × contract rent). CR rent = Entrata scheduled rent; Seasons rent = "rentres" contract rent from the rent roll (excludes utility/parking/pet charges).
A19: Coverage gap | B19: Seasons demographics cover 305 of 342 occupied units — the 38 units on notice are absent from the seller export (Status=Current filter). CR data includes notice + future leases. Keep in mind when comparing churn.
A20: Coworker units | B20: Units with 2+ occupants sharing an employer, no spouse relationship, different surnames AND different DOBs (the DOB screen removes copied-record artifacts). CR figure (33) is from the CR cross-analysis workbook.
A22: CONVENTIONS | B22: Blue = value computed from source data in this analysis (medians, sourced counts). Green = linked from another tab. Black = formula on the same tab. Yellow highlight = Micron-related (T1–T4) rows.
A23: Caveats | B23: Employer text is self-reported at application; ~21-26% of occupants at both properties have no employer stated. Web-researched tier calls below "Confirmed" are trade-fit inferences, not documented contracts — see per-employer evidence and confidence columns before leaning on any single name. Income figures are unverified applicant statements.

Sheet Overview
A1: Canyon Ridge vs Seasons at Meridian — Tenant Demographics, Employer & Micron-Exposure Comparison
A2: Data as of: Canyon Ridge 06/24/2026 (Entrata) · Seasons 07/09–07/10/2026 (Yardi rent roll + seller demographics). Green = linked to detail tabs · Blue = computed from source data (see READ ME).
B4: Canyon Ridge | C4: Seasons at Meridian | D4: Comment
A5: PROPERTY SNAPSHOT
A6: Location | B6: 2552 E Gowen Rd, Boise (adjacent to Micron HQ / Triton fab campus) | C6: Meridian, ID (~20 mi W of Micron campus) | D6: Physical proximity to the fab is the root of the exposure difference
A7: Total units | B7: 287 | C7: 360
A8: Opened / first move-ins | B8: Sep-2024 | C8: Aug-2024 | D8: Both are 2024-opened lease-ups — same vintage cohort
A9: Occupied units | B9: ='Lease-Up & Churn'!B18 -> 286 | C9: ='Lease-Up & Churn'!C18 -> 342
A10: Physical occupancy | B10: ='Lease-Up & Churn'!B19 -> 0.99651568 | C10: ='Lease-Up & Churn'!C19 -> 0.95
A11: Units on notice | B11: ='Lease-Up & Churn'!B20 -> 24 | C11: ='Lease-Up & Churn'!C20 -> 38 | D11: CR 6/24/26; Seasons 7/9/26
A12: Notice % of occupied | B12: ='Lease-Up & Churn'!B21 -> 0.083916084 | C12: ='Lease-Up & Churn'!C21 -> 0.11111111
A13: Median contract rent | B13: 1975 | C13: 1714 | D13: Seasons contract ~11% below own asking/market (lease-up LTL)
A15: MICRON EXPOSURE — occupant level (% of employed residents)
A16: Employed occupants (classified T1–T6) | B16: ='Tier Summary'!C11 -> 337 | C16: ='Tier Summary'!E11 -> 443 | D16: Excl. guarantors, retirees, blanks
A17: Micron DIRECT (T1) | B17: ='Tier Summary'!D17 -> 0.26409496 | C17: ='Tier Summary'!F17 -> 0.020316027 | D17: CR: 89 residents · Seasons: 9
A18: Micron-related narrow (T1+T2) | B18: ='Tier Summary'!D18 -> 0.62611276 | C18: ='Tier Summary'!F18 -> 0.047404063
A19: Micron-related mid (T1+T2+T3) | B19: ='Tier Summary'!D19 -> 0.67655786 | C19: ='Tier Summary'!F19 -> 0.054176072
A20: Micron-related BROAD (T1–T4) | B20: ='Tier Summary'!D20 -> 0.71513353 | C20: ='Tier Summary'!F20 -> 0.063205418 | D20: The headline exposure gap: ~72% vs ~6%
A22: MICRON EXPOSURE — unit level (revenue at risk)
A23: Units with ≥1 Micron-related earner (T1–T4) | B23: ='Tier Summary'!D24 -> 0.6958042 | C23: ='Tier Summary'!F24 -> 0.078688525 | D23: CR ~70% of units vs Seasons ~8%
A24: Units with ≥1 Micron DIRECT earner (T1) | B24: ='Tier Summary'!D25 -> 0.25524476 | C24: ='Tier Summary'!F25 -> 0.029508197
A26: INCOME & RENT COVERAGE
A27: Median personal income (stated earners) | B27: ='Income & Coverage'!B14 -> 107000 | C27: ='Income & Coverage'!D14 -> 58020 | D27: CR ≈ 1.8× Seasons
A28: Median household income | B28: ='Income & Coverage'!B26 -> 144600 | C28: ='Income & Coverage'!D26 -> 80160
A29: Median rent-coverage multiple | B29: ='Income & Coverage'!B38 -> 6.14 | C29: ='Income & Coverage'!D38 -> 3.84 | D29: HH income ÷ (12 × rent)
A30: Units ≥ 3x rent | B30: ='Income & Coverage'!B39/'Income & Coverage'!B37 -> 0.93359375 | C30: ='Income & Coverage'!D39/'Income & Coverage'!D37 -> 0.79180887
A31: Units < 2x rent (thin coverage) | B31: ='Income & Coverage'!B31/'Income & Coverage'!B37 -> 0.0078125 | C31: ='Income & Coverage'!D31/'Income & Coverage'!D37 -> 0.081911263 | D31: Seasons carries a real thin-coverage tail; CR nearly none
A33: EMPLOYER DIVERSIFICATION
A34: Distinct employers | B34: 151 | C34: 304 | D34: Seasons has 2× the employer count on a similar base
A35: Top employer share of employed | B35: 0.26409496 | C35: 0.036117381 | D35: CR: Micron 26.4% · Seasons: Amazon 3.6%
A36: Top-5 employer share | B36: 0.38575668 | C36: 0.1241535
A37: Top-10 employer share | B37: 0.47774481 | C37: 0.18510158
A38: Largest industry cluster | B38: ='Industry Mix'!C5+'Industry Mix'!C6+'Industry Mix'!C7+'Industry Mix'!C8 -> 0.71513353 | C38: ='Industry Mix'!E12 -> 0.21670429 | D38: CR: Micron+fab supply chain · Seasons: healthcare (largest at ~22%)
A40: HOUSEHOLD COMPOSITION & STABILITY
A41: Avg occupants per unit (excl. guarantors) | B41: 1.59 | C41: 1.89 | D41: Seasons skews larger households (roommates, spouses, kids)
A42: Single-occupant units | B42: 0.50699301 | C42: 0.39016393
A43: Roommate households | C43: 0.34098361 | D43: CR export doesn't distinguish roommate vs partner co-applicants
A44: Couple / family households | C44: 0.21967213 | D44: Seasons: spouse on lease
A45: Guarantor-backed units | B45: 0 | C45: 0.095081967 | D45: Seasons 29 units (9.5%); CR export shows none
A46: Coworker-roommate units (same employer) | B46: 33 | C46: 14 | D46: CR: 33 units, 15 Micron (per CR cross-analysis). Seasons: 14 genuine, largely non-Micron
...

Sheet Tier Summary
A1: Micron-Exposure Tier Summary — Canyon Ridge vs Seasons at Meridian
A2: Occupant counts exclude guarantors (Seasons) and use Primary + Co-Applicant (Canyon Ridge). "% of employed" = share of occupants with a classified employer (retired/student/homemaker excluded). All counts are live formulas on the data tabs.
A4: Tier | B4: Description | C4: Canyon Ridge | D4: CR % of employed | E4: Seasons | F4: Seasons % of employed
A5: T1 | B5: Micron (direct employer) | C5: =COUNTIF('CR Data'!K$5:K$460,"T1") -> 89 | D5: =C5/C$11 -> 0.26409496 | E5: =COUNTIFS('Seasons Data'!H$5:H$608,"T1",'Seasons Data'!E$5:E$608,"Y") -> 9 | F5: =E5/E$11 -> 0.020316027
A6: T2 | B6: Micron construction subcontractor (building the fabs) | C6: =COUNTIF('CR Data'!K$5:K$460,"T2") -> 122 | D6: =C6/C$11 -> 0.3620178 | E6: =COUNTIFS('Seasons Data'!H$5:H$608,"T2",'Seasons Data'!E$5:E$608,"Y") -> 12 | F6: =E6/E$11 -> 0.027088036
A7: T3 | B7: Micron engineering / design / consulting / IT-staffing contractor | C7: =COUNTIF('CR Data'!K$5:K$460,"T3") -> 17 | D7: =C7/C$11 -> 0.050445104 | E7: =COUNTIFS('Seasons Data'!H$5:H$608,"T3",'Seasons Data'!E$5:E$608,"Y") -> 3 | F7: =E7/E$11 -> 0.006772009
A8: T4 | B8: Semiconductor equipment / tool / materials vendor serving Micron | C8: =COUNTIF('CR Data'!K$5:K$460,"T4") -> 13 | D8: =C8/C$11 -> 0.038575668 | E8: =COUNTIFS('Seasons Data'!H$5:H$608,"T4",'Seasons Data'!E$5:E$608,"Y") -> 4 | F8: =E8/E$11 -> 0.0090293454
A9: T5 | B9: Other semiconductor / tech company — NOT Micron-related | C9: =COUNTIF('CR Data'!K$5:K$460,"T5") -> 5 | D9: =C9/C$11 -> 0.014836795 | E9: =COUNTIFS('Seasons Data'!H$5:H$608,"T5",'Seasons Data'!E$5:E$608,"Y") -> 2 | F9: =E9/E$11 -> 0.0045146727
A10: T6 | B10: Unrelated / local | C10: =COUNTIF('CR Data'!K$5:K$460,"T6") -> 91 | D10: =C10/C$11 -> 0.27002967 | E10: =COUNTIFS('Seasons Data'!H$5:H$608,"T6",'Seasons Data'!E$5:E$608,"Y") -> 413 | F10: =E10/E$11 -> 0.93227991
B11: Employed occupants (T1–T6) | C11: =SUM(C5:C10) -> 337 | D11: 1 | E11: =SUM(E5:E10) -> 443 | F11: 1
B12: Not employed (retired / student / homemaker / other income) | C12: 0 | E12: =COUNTIFS('Seasons Data'!H$5:H$608,"",'Seasons Data'!E$5:E$608,"Y",'Seasons Data'!G$5:G$608,"<>") -> 10
B13: No employer stated (blank) | C13: =COUNTIFS('CR Data'!K$5:K$460,"",'CR Data'!A$5:A$460,"<>") -> 119 | E13: =COUNTIFS('Seasons Data'!G$5:G$608,"",'Seasons Data'!E$5:E$608,"Y") -> 122
B14: Total occupant records (excl. guarantors) | C14: =SUM(C11:C13) -> 456 | E14: =SUM(E11:E13) -> 575
A16: MICRON-EXPOSURE ROLL-UPS — occupant level
B17: MICRON DIRECT (T1) | C17: =C5 -> 89 | D17: =C17/C$11 -> 0.26409496 | E17: =E5 -> 9 | F17: =E17/E$11 -> 0.020316027
B18: MICRON-RELATED narrow (T1+T2) | C18: =C5+C6 -> 211 | D18: =C18/C$11 -> 0.62611276 | E18: =E5+E6 -> 21 | F18: =E18/E$11 -> 0.047404063
B19: MICRON-RELATED mid (T1+T2+T3) | C19: =C5+C6+C7 -> 228 | D19: =C19/C$11 -> 0.67655786 | E19: =E5+E6+E7 -> 24 | F19: =E19/E$11 -> 0.054176072
B20: MICRON-RELATED broad (T1+T2+T3+T4) | C20: =SUM(C5:C8) -> 241 | D20: =C20/C$11 -> 0.71513353 | E20: =SUM(E5:E8) -> 28 | F20: =E20/E$11 -> 0.063205418
A22: MICRON-EXPOSURE — unit level (revenue-at-risk lens)
B23: Units with demographic data | C23: =COUNTIF('Unit Coverage Detail'!A$5:A$595,"Canyon Ridge") -> 286 | E23: =COUNTIF('Unit Coverage Detail'!A$5:A$595,"Seasons") -> 305
B24: Units with ≥1 Micron-related earner (T1–T4) | C24: =COUNTIFS('Unit Coverage Detail'!A$5:A$595,"Canyon Ridge",'Unit Coverage Detail'!G$5:G$595,"Y") -> 199 | D24: =C24/C23 -> 0.6958042 | E24: =COUNTIFS('Unit Coverage Detail'!A$5:A$595,"Seasons",'Unit Coverage Detail'!G$5:G$595,"Y") -> 24 | F24: =E24/E23 -> 0.078688525
B25: Units with ≥1 Micron DIRECT earner (T1) | C25: =COUNTIFS('Unit Coverage Detail'!A$5:A$595,"Canyon Ridge",'Unit Coverage Detail'!H$5:H$595,"Y") -> 73 | D25: =C25/C23 -> 0.25524476 | E25: =COUNTIFS('Unit Coverage Detail'!A$5:A$595,"Seasons",'Unit Coverage Detail'!H$5:H$595,"Y") -> 9 | F25: =E25/E23 -> 0.029508197
A27: Note: Seasons demographics cover 305 of 342 occupied units (the 38 units on notice are excluded from the seller export). Canyon Ridge covers 286 units incl. notice & future leases. Guarantor employers (e.g., a Micron guarantor at Seasons unit B208) are excluded.

Sheet Income & Coverage
A1: Income Distributions & Rent Coverage
A2: Personal income: occupants with a qualifying stated income (excl. guarantors, $0, copied records, ≥$1M outliers). Household income: sum of qualifying occupant incomes per unit. Coverage = HH income ÷ (12 × contract rent). Band counts are live COUNTIFS; medians/means are computed from the same data (values shown in blue).
A4: PERSONAL (occupant-level) ANNUAL INCOME
A5: Band | B5: Canyon Ridge | C5: CR % | D5: Seasons | E5: Seasons %
A6: < $40K | B6: =COUNTIFS('CR Data'!M$5:M$460,">0",'CR Data'!M$5:M$460,"<40000") -> 26 | C6: =B6/B$13 -> 0.070080863 | D6: =COUNTIFS('Seasons Data'!K$5:K$608,">0",'Seasons Data'!L$5:L$608,"Y",'Seasons Data'!K$5:K$608,"<40000") -> 109 | E6: =D6/D$13 -> 0.2626506
A7: $40K – $60K | B7: =COUNTIFS('CR Data'!M$5:M$460,">0",'CR Data'!M$5:M$460,">=40000",'CR Data'!M$5:M$460,"<60000") -> 27 | C7: =B7/B$13 -> 0.07277628 | D7: =COUNTIFS('Seasons Data'!K$5:K$608,">0",'Seasons Data'!L$5:L$608,"Y",'Seasons Data'!K$5:K$608,">=40000",'Seasons Data'!K$5:K$608,"<60000") -> 107 | E7: =D7/D$13 -> 0.25783133
A8: $60K – $80K | B8: =COUNTIFS('CR Data'!M$5:M$460,">0",'CR Data'!M$5:M$460,">=60000",'CR Data'!M$5:M$460,"<80000") -> 37 | C8: =B8/B$13 -> 0.099730458 | D8: =COUNTIFS('Seasons Data'!K$5:K$608,">0",'Seasons Data'!L$5:L$608,"Y",'Seasons Data'!K$5:K$608,">=60000",'Seasons Data'!K$5:K$608,"<80000") -> 91 | E8: =D8/D$13 -> 0.21927711
A9: $80K – $100K | B9: =COUNTIFS('CR Data'!M$5:M$460,">0",'CR Data'!M$5:M$460,">=80000",'CR Data'!M$5:M$460,"<100000") -> 67 | C9: =B9/B$13 -> 0.18059299 | D9: =COUNTIFS('Seasons Data'!K$5:K$608,">0",'Seasons Data'!L$5:L$608,"Y",'Seasons Data'!K$5:K$608,">=80000",'Seasons Data'!K$5:K$608,"<100000") -> 40 | E9: =D9/D$13 -> 0.096385542
A10: $100K – $150K | B10: =COUNTIFS('CR Data'!M$5:M$460,">0",'CR Data'!M$5:M$460,">=100000",'CR Data'!M$5:M$460,"<150000") -> 121 | C10: =B10/B$13 -> 0.32614555 | D10: =COUNTIFS('Seasons Data'!K$5:K$608,">0",'Seasons Data'!L$5:L$608,"Y",'Seasons Data'!K$5:K$608,">=100000",'Seasons Data'!K$5:K$608,"<150000") -> 53 | E10: =D10/D$13 -> 0.12771084
A11: $150K – $200K | B11: =COUNTIFS('CR Data'!M$5:M$460,">0",'CR Data'!M$5:M$460,">=150000",'CR Data'!M$5:M$460,"<200000") -> 46 | C11: =B11/B$13 -> 0.12398922 | D11: =COUNTIFS('Seasons Data'!K$5:K$608,">0",'Seasons Data'!L$5:L$608,"Y",'Seasons Data'!K$5:K$608,">=150000",'Seasons Data'!K$5:K$608,"<200000") -> 3 | E11: =D11/D$13 -> 0.0072289157
A12: $200K+ | B12: =COUNTIFS('CR Data'!M$5:M$460,">0",'CR Data'!M$5:M$460,">=200000") -> 47 | C12: =B12/B$13 -> 0.12668464 | D12: =COUNTIFS('Seasons Data'!K$5:K$608,">0",'Seasons Data'!L$5:L$608,"Y",'Seasons Data'!K$5:K$608,">=200000") -> 12 | E12: =D12/D$13 -> 0.028915663
A13: Occupants with qualifying income | B13: =SUM(B6:B12) -> 371 | D13: =SUM(D6:D12) -> 415
A14: MEDIAN personal income | B14: 107000 | D14: 58020
A15: Average personal income | B15: 162598 | D15: 71814 | E15: CR average inflated by high construction/per-diem earners
A17: HOUSEHOLD (unit-level) ANNUAL INCOME
A18: Band | B18: Canyon Ridge | C18: CR % | D18: Seasons | E18: Seasons %
A19: < $50K | B19: =COUNTIFS('Unit Coverage Detail'!A$5:A$595,"Canyon Ridge",'Unit Coverage Detail'!C$5:C$595,">0",'Unit Coverage Detail'!C$5:C$595,"<50000") -> 1 | C19: =B19/B$25 -> 0.0038910506 | D19: =COUNTIFS('Unit Coverage Detail'!A$5:A$595,"Seasons",'Unit Coverage Detail'!C$5:C$595,">0",'Unit Coverage Detail'!C$5:C$595,"<50000") -> 41 | E19: =D19/D$25 -> 0.13993174
A20: $50K – $75K | B20: =COUNTIFS('Unit Coverage Detail'!A$5:A$595,"Canyon Ridge",'Unit Coverage Detail'!C$5:C$595,">0",'Unit Coverage Detail'!C$5:C$595,">=50000",'Unit Coverage Detail'!C$5:C$595,"<75000") -> 24 | C20: =B20/B$25 -> 0.093385214 | D20: =COUNTIFS('Unit Coverage Detail'!A$5:A$595,"Seasons",'Unit Coverage Detail'!C$5:C$595,">0",'Unit Coverage Detail'!C$5:C$595,">=50000",'Unit Coverage Detail'!C$5:C$595,"<75000") -> 87 | E20: =D20/D$25 -> 0.29692833
A21: $75K – $100K | B21: =COUNTIFS('Unit Coverage Detail'!A$5:A$595,"Canyon Ridge",'Unit Coverage Detail'!C$5:C$595,">0",'Unit Coverage Detail'!C$5:C$595,">=75000",'Unit Coverage Detail'!C$5:C$595,"<100000") -> 39 | C21: =B21/B$25 -> 0.15175097 | D21: =COUNTIFS('Unit Coverage Detail'!A$5:A$595,"Seasons",'Unit Coverage Detail'!C$5:C$595,">0",'Unit Coverage Detail'!C$5:C$595,">=75000",'Unit Coverage Detail'!C$5:C$595,"<100000") -> 65 | E21: =D21/D$25 -> 0.221843
A22: $100K – $150K | B22: =COUNTIFS('Unit Coverage Detail'!A$5:A$595,"Canyon Ridge",'Unit Coverage Detail'!C$5:C$595,">0",'Unit Coverage Detail'!C$5:C$595,">=100000",'Unit Coverage Detail'!C$5:C$595,"<150000") -> 69 | C22: =B22/B$25 -> 0.26848249 | D22: =COUNTIFS('Unit Coverage Detail'!A$5:A$595,"Seasons",'Unit Coverage Detail'!C$5:C$595,">0",'Unit Coverage Detail'!C$5:C$595,">=100000",'Unit Coverage Detail'!C$5:C$595,"<150000") -> 67 | E22: =D22/D$25 -> 0.22866894
A23: $150K – $250K | B23: =COUNTIFS('Unit Coverage Detail'!A$5:A$595,"Canyon Ridge",'Unit Coverage Detail'!C$5:C$595,">0",'Unit Coverage Detail'!C$5:C$595,">=150000",'Unit Coverage Detail'!C$5:C$595,"<250000") -> 75 | C23: =B23/B$25 -> 0.29182879 | D23: =COUNTIFS('Unit Coverage Detail'!A$5:A$595,"Seasons",'Unit Coverage Detail'!C$5:C$595,">0",'Unit Coverage Detail'!C$5:C$595,">=150000",'Unit Coverage Detail'!C$5:C$595,"<250000") -> 23 | E23: =D23/D$25 -> 0.078498294
A24: $250K+ | B24: =COUNTIFS('Unit Coverage Detail'!A$5:A$595,"Canyon Ridge",'Unit Coverage Detail'!C$5:C$595,">0",'Unit Coverage Detail'!C$5:C$595,">=250000") -> 49 | C24: =B24/B$25 -> 0.19066148 | D24: =COUNTIFS('Unit Coverage Detail'!A$5:A$595,"Seasons",'Unit Coverage Detail'!C$5:C$595,">0",'Unit Coverage Detail'!C$5:C$595,">=250000") -> 10 | E24: =D24/D$25 -> 0.034129693
A25: Households with income data | B25: =SUM(B19:B24) -> 257 | D25: =SUM(D19:D24) -> 293
A26: MEDIAN household income | B26: 144600 | D26: 80160
A27: Average household income | B27: 234723 | D27: 101716
A29: RENT COVERAGE (HH income ÷ 12 × contract rent)
A30: Bucket | B30: Canyon Ridge | C30: CR % | D30: Seasons | E30: Seasons %
A31: < 2.0x (thin) | B31: =COUNTIFS('Unit Coverage Detail'!A$5:A$595,"Canyon Ridge",'Unit Coverage Detail'!E$5:E$595,">0",'Unit Coverage Detail'!E$5:E$595,"<2") -> 2 | C31: =B31/B$37 -> 0.0078125 | D31: =COUNTIFS('Unit Coverage Detail'!A$5:A$595,"Seasons",'Unit Coverage Detail'!E$5:E$595,">0",'Unit Coverage Detail'!E$5:E$595,"<2") -> 24 | E31: =D31/D$37 -> 0.081911263
A32: 2.0x – 2.5x | B32: =COUNTIFS('Unit Coverage Detail'!A$5:A$595,"Canyon Ridge",'Unit Coverage Detail'!E$5:E$595,">0",'Unit Coverage Detail'!E$5:E$595,">=2",'Unit Coverage Detail'!E$5:E$595,"<2.5") -> 2 | C32: =B32/B$37 -> 0.0078125 | D32: =COUNTIFS('Unit Coverage Detail'!A$5:A$595,"Seasons",'Unit Coverage Detail'!E$5:E$595,">0",'Unit Coverage Detail'!E$5:E$595,">=2",'Unit Coverage Detail'!E$5:E$595,"<2.5") -> 19 | E32: =D32/D$37 -> 0.064846416
A33: 2.5x – 3.0x | B33: =COUNTIFS('Unit Coverage Detail'!A$5:A$595,"Canyon Ridge",'Unit Coverage Detail'!E$5:E$595,">0",'Unit Coverage Detail'!E$5:E$595,">=2.5",'Unit Coverage Detail'!E$5:E$595,"<3") -> 13 | C33: =B33/B$37 -> 0.05078125 | D33: =COUNTIFS('Unit Coverage Detail'!A$5:A$595,"Seasons",'Unit Coverage Detail'!E$5:E$595,">0",'Unit Coverage Detail'!E$5:E$595,">=2.5",'Unit Coverage Detail'!E$5:E$595,"<3") -> 18 | E33: =D33/D$37 -> 0.061433447
A34: 3.0x – 4.0x | B34: =COUNTIFS('Unit Coverage Detail'!A$5:A$595,"Canyon Ridge",'Unit Coverage Detail'!E$5:E$595,">0",'Unit Coverage Detail'!E$5:E$595,">=3",'Unit Coverage Detail'!E$5:E$595,"<4") -> 34 | C34: =B34/B$37 -> 0.1328125 | D34: =COUNTIFS('Unit Coverage Detail'!A$5:A$595,"Seasons",'Unit Coverage Detail'!E$5:E$595,">0",'Unit Coverage Detail'!E$5:E$595,">=3",'Unit Coverage Detail'!E$5:E$595,"<4") -> 98 | E34: =D34/D$37 -> 0.33447099
A35: 4.0x – 6.0x | B35: =COUNTIFS('Unit Coverage Detail'!A$5:A$595,"Canyon Ridge",'Unit Coverage Detail'!E$5:E$595,">0",'Unit Coverage Detail'!E$5:E$595,">=4",'Unit Coverage Detail'!E$5:E$595,"<6") -> 72 | C35: =B35/B$37 -> 0.28125 | D35: =COUNTIFS('Unit Coverage Detail'!A$5:A$595,"Seasons",'Unit Coverage Detail'!E$5:E$595,">0",'Unit Coverage Detail'!E$5:E$595,">=4",'Unit Coverage Detail'!E$5:E$595,"<6") -> 75 | E35: =D35/D$37 -> 0.2559727
A36: 6.0x+ | B36: =COUNTIFS('Unit Coverage Detail'!A$5:A$595,"Canyon Ridge",'Unit Coverage Detail'!E$5:E$595,">0",'Unit Coverage Detail'!E$5:E$595,">=6") -> 133 | C36: =B36/B$37 -> 0.51953125 | D36: =COUNTIFS('Unit Coverage Detail'!A$5:A$595,"Seasons",'Unit Coverage Detail'!E$5:E$595,">0",'Unit Coverage Detail'!E$5:E$595,">=6") -> 59 | E36: =D36/D$37 -> 0.20136519
A37: Units with rent + income | B37: =SUM(B31:B36) -> 256 | D37: =SUM(D31:D36) -> 293
A38: MEDIAN coverage multiple | B38: 6.14 | D38: 3.84
A39: Units ≥ 3.0x rent | B39: =COUNTIFS('Unit Coverage Detail'!A$5:A$595,"Canyon Ridge",'Unit Coverage Detail'!F$5:F$595,"Y") -> 239 | C39: =B39/B37 -> 0.93359375 | D39: =COUNTIFS('Unit Coverage Detail'!A$5:A$595,"Seasons",'Unit Coverage Detail'!F$5:F$595,"Y") -> 232 | E39: =D39/D37 -> 0.79180887
A41: RENT LEVELS (contract)
A42: Median contract rent / occupied unit | B42: 1975 | D42: 1714
A43: Average contract rent / occupied unit | B43: 1991 | D43: 1738
A44: Median MARKET rent (Seasons rent roll) | B44: — | D44: 1896.5
...

Sheet Industry Mix
A1: Employer Industry Mix — employed occupants
A2: Live COUNTIFS on the data tabs. Denominator = employed occupants (Tier Summary row 11). Micron-related industries highlighted.
A4: Industry | B4: Canyon Ridge | C4: CR % | D4: Seasons | E4: Seasons %
A5: Micron (direct) | B5: =COUNTIF('CR Data'!L$5:L$460,A5) -> 89 | C5: =B5/'Tier Summary'!C$11 -> 0.26409496 | D5: =COUNTIFS('Seasons Data'!I$5:I$608,A5,'Seasons Data'!E$5:E$608,"Y",'Seasons Data'!H$5:H$608,"<>") -> 9 | E5: =D5/'Tier Summary'!E$11 -> 0.020316027
A6: Micron fab construction | B6: =COUNTIF('CR Data'!L$5:L$460,A6) -> 122 | C6: =B6/'Tier Summary'!C$11 -> 0.3620178 | D6: =COUNTIFS('Seasons Data'!I$5:I$608,A6,'Seasons Data'!E$5:E$608,"Y",'Seasons Data'!H$5:H$608,"<>") -> 12 | E6: =D6/'Tier Summary'!E$11 -> 0.027088036
A7: Micron eng/consulting/IT | B7: =COUNTIF('CR Data'!L$5:L$460,A7) -> 17 | C7: =B7/'Tier Summary'!C$11 -> 0.050445104 | D7: =COUNTIFS('Seasons Data'!I$5:I$608,A7,'Seasons Data'!E$5:E$608,"Y",'Seasons Data'!H$5:H$608,"<>") -> 3 | E7: =D7/'Tier Summary'!E$11 -> 0.006772009
A8: Semi equipment & materials | B8: =COUNTIF('CR Data'!L$5:L$460,A8) -> 13 | C8: =B8/'Tier Summary'!C$11 -> 0.038575668 | D8: =COUNTIFS('Seasons Data'!I$5:I$608,A8,'Seasons Data'!E$5:E$608,"Y",'Seasons Data'!H$5:H$608,"<>") -> 4 | E8: =D8/'Tier Summary'!E$11 -> 0.0090293454
A9: Semiconductor (non-Micron) | B9: =COUNTIF('CR Data'!L$5:L$460,A9) -> 5 | C9: =B9/'Tier Summary'!C$11 -> 0.014836795 | D9: =COUNTIFS('Seasons Data'!I$5:I$608,A9,'Seasons Data'!E$5:E$608,"Y",'Seasons Data'!H$5:H$608,"<>") -> 2 | E9: =D9/'Tier Summary'!E$11 -> 0.0045146727
A10: Government, Military & Public Safety | B10: =COUNTIF('CR Data'!L$5:L$460,A10) -> 16 | C10: =B10/'Tier Summary'!C$11 -> 0.047477745 | D10: =COUNTIFS('Seasons Data'!I$5:I$608,A10,'Seasons Data'!E$5:E$608,"Y",'Seasons Data'!H$5:H$608,"<>") -> 32 | E10: =D10/'Tier Summary'!E$11 -> 0.072234763
A11: Retail & Food Service | B11: =COUNTIF('CR Data'!L$5:L$460,A11) -> 13 | C11: =B11/'Tier Summary'!C$11 -> 0.038575668 | D11: =COUNTIFS('Seasons Data'!I$5:I$608,A11,'Seasons Data'!E$5:E$608,"Y",'Seasons Data'!H$5:H$608,"<>") -> 61 | E11: =D11/'Tier Summary'!E$11 -> 0.13769752
A12: Healthcare & Social Services | B12: =COUNTIF('CR Data'!L$5:L$460,A12) -> 11 | C12: =B12/'Tier Summary'!C$11 -> 0.03264095 | D12: =COUNTIFS('Seasons Data'!I$5:I$608,A12,'Seasons Data'!E$5:E$608,"Y",'Seasons Data'!H$5:H$608,"<>") -> 96 | E12: =D12/'Tier Summary'!E$11 -> 0.21670429
A13: Education & Childcare | B13: =COUNTIF('CR Data'!L$5:L$460,A13) -> 10 | C13: =B13/'Tier Summary'!C$11 -> 0.029673591 | D13: =COUNTIFS('Seasons Data'!I$5:I$608,A13,'Seasons Data'!E$5:E$608,"Y",'Seasons Data'!H$5:H$608,"<>") -> 20 | E13: =D13/'Tier Summary'!E$11 -> 0.045146727
A14: Tech & Software (non-semi) | B14: =COUNTIF('CR Data'!L$5:L$460,A14) -> 10 | C14: =B14/'Tier Summary'!C$11 -> 0.029673591 | D14: =COUNTIFS('Seasons Data'!I$5:I$608,A14,'Seasons Data'!E$5:E$608,"Y",'Seasons Data'!H$5:H$608,"<>") -> 9 | E14: =D14/'Tier Summary'!E$11 -> 0.020316027
A15: Financial, Legal & Professional | B15: =COUNTIF('CR Data'!L$5:L$460,A15) -> 8 | C15: =B15/'Tier Summary'!C$11 -> 0.023738872 | D15: =COUNTIFS('Seasons Data'!I$5:I$608,A15,'Seasons Data'!E$5:E$608,"Y",'Seasons Data'!H$5:H$608,"<>") -> 33 | E15: =D15/'Tier Summary'!E$11 -> 0.074492099
A16: Wholesale, Transport & Logistics | B16: =COUNTIF('CR Data'!L$5:L$460,A16) -> 5 | C16: =B16/'Tier Summary'!C$11 -> 0.014836795 | D16: =COUNTIFS('Seasons Data'!I$5:I$608,A16,'Seasons Data'!E$5:E$608,"Y",'Seasons Data'!H$5:H$608,"<>") -> 22 | E16: =D16/'Tier Summary'!E$11 -> 0.0496614
... A28: Corporate housing entity | B28: =COUNTIF('CR Data'!L$5:L$460,A28) -> 0 | C28: =B28/'Tier Summary'!C$11 -> 0 | D28: =COUNTIFS('Seasons Data'!I$5:I$608,A28,'Seasons Data'!E$5:E$608,"Y",'Seasons Data'!H$5:H$608,"<>") -> 4 | E28: =D28/'Tier Summary'!E$11 -> 0.0090293454
A29: Total employed | B29: =SUM(B5:B28) -> 337 | D29: =SUM(D5:D28) -> 443

Sheet Lease-Up & Churn
A1: Lease-Up Timeline & Current Churn — both are 2024-opened lease-ups
A2: Canyon Ridge opened Sep-2024 (first move-ins); Seasons at Meridian opened Aug-2024. Move-in counts: CR = occupant move-ins by quarter (from CR Rent Roll Cross-Analysis 2026.06.24); Seasons = occupied-unit move-ins by quarter (07/09/2026 rent roll). Values in blue are sourced counts.
A4: Quarter | B4: CR move-ins (occupants) | C4: CR % Micron-related | D4: Seasons move-ins (units) | E4: Milestone / context
A5: 2024-Q3 | B5: 13 | C5: 0.38 | D5: 4 | E5: Canyon Ridge opens (Sep); Seasons opens (Aug)
A6: 2024-Q4 | B6: 5 | C6: 0.6 | D6: 12
A7: 2025-Q1 | B7: 17 | C7: 0.71 | D7: 39
A8: 2025-Q2 | B8: 58 | C8: 0.48 | D8: 50 | E8: Micron construction ramp; steel topping out mid-2025
A9: 2025-Q3 | B9: 69 | C9: 0.67 | D9: 66 | E9: CR peak (69 move-ins); Exyte discontinued Sep 2, 2025
A10: 2025-Q4 | B10: 48 | C10: 0.71 | D10: 66 | E10: CR sub population peaks; broker-noted Exyte-linked terminations
A11: 2026-Q1 | B11: 43 | C11: 0.77 | D11: 59 | E11: CR sub fit-out wave continues
A12: 2026-Q2 | B12: 32 | C12: 0.81 | D12: 43 | E12: 12-mo leases from mid-2025 maturing at both properties
A13: 2026-Q3 | B13: 1 | C13: 0 | D13: 3
A14: Total | B14: =SUM(B5:B13) -> 286 | D14: =SUM(D5:D13) -> 342
A16: CURRENT OCCUPANCY & CHURN SNAPSHOT
A17: Total units | B17: 287 | C17: 360
A18: Occupied units | B18: 286 | C18: 342 | E18: Seasons: 07/09/2026 rent roll; CR: 06/24/2026 roster
A19: Physical occupancy | B19: =B18/B17 -> 0.99651568 | C19: =C18/C17 -> 0.95
A20: Units on notice | B20: 24 | C20: 38 | E20: CR notice incl. both Intel units & last Exyte resident; Seasons notice units are excluded from the seller demographics export
A21: Notice % of occupied | B21: =B20/B18 -> 0.083916084 | C21: =C20/C18 -> 0.11111111
A22: Vacant units | B22: 1 | C22: 18

Sheet Micron Detail - Seasons
A1: Seasons at Meridian — Micron & Micron-related occupants (T1–T4), person level
A2: Every occupant whose standardized employer is Micron or Micron-related. Guarantors shown for reference but excluded from headline counts. Note only ~6% of employed residents are Micron-related vs 72% at Canyon Ridge.
A4: Tier | B4: Standardized Employer | C4: Unit | D4: Relationship | E4: Counts in headline | F4: Annual Salary | G4: Confidence | H4: Micron relationship & evidence
A5: T1 | B5: Micron Technology | C5: A106 | D5: Primary | E5: Yes | F5: 51180 | G5: Confirmed
A6: T1 | B6: Micron Technology | C6: B208 | D6: Guarantor | E6: No (guarantor) | F6: 276816 | G6: Confirmed
A7: T1 | B7: Micron Technology | C7: E211 | D7: Primary | E7: Yes | F7: 56700 | G7: Confirmed
A8: T1 | B8: Micron Technology | C8: G306 | D8: Primary | E8: Yes | F8: 58812 | G8: Confirmed
A9: T1 | B9: Micron Technology | C9: I108 | D9: Primary | E9: Yes | F9: 124272 | G9: Confirmed
A10: T1 | B10: Micron Technology | C10: I208 | D10: Primary | E10: Yes | F10: 96996 | G10: Confirmed
A11: T1 | B11: Micron Technology | C11: I304 | D11: Primary | E11: Yes | F11: 121608 | G11: Confirmed
A12: T1 | B12: Micron Technology | C12: I312 | D12: Roommate | E12: Yes | F12: 50400 | G12: Confirmed
A13: T1 | B13: Micron Technology | C13: J102 | D13: Primary | E13: Yes | F13: 54000 | G13: Confirmed
A14: T1 | B14: Micron Technology | C14: J313 | D14: Primary | E14: Yes | F14: 87600 | G14: Confirmed
A15: T2 | B15: Engineered Structures, Inc. (ESI) | C15: C305 | D15: Spouse | E15: Yes | F15: 133620 | G15: Confirmed | H15: ENR documents ESI building office and parking structures at Micron's Boise global HQ as part of the campus expansion; $133.6K salary fits a PM/superintendent.
A16: T2 | B16: Engineered Structures, Inc. (ESI) | C16: C305 | D16: Roommate | E16: Yes | F16: 133620 | G16: Confirmed | H16: ENR documents ESI building office and parking structures at Micron's Boise global HQ as part of the campus expansion; $133.6K salary fits a PM/superintendent.
A17: T2 | B17: Hensel Phelps | C17: G106 | D17: Primary | E17: Yes | F17: 83160 | G17: Confirmed | H17: Listed among GCs/EPC contractors performing work on Micron's Boise fab project.
A18: T2 | B18: Hoffman Construction Company | C18: A207 | D18: Primary | E18: Yes | F18: 120000 | G18: Confirmed
A19: T2 | B19: IBEW (electricians union) | C19: D101 | D19: Primary | E19: Yes | F19: 118392 | G19: Strong-inferred
A20: T2 | B20: IBEW (electricians union) | C20: D101 | D20: Spouse | E20: Yes | F20: 183312 | G20: Strong-inferred
A21: T2 | B21: JH Kelly | C21: D109 | D21: Roommate | E21: Yes | F21: 107172 | G21: Confirmed
A22: T2 | B22: Oregon Electric Group (OEG) | C22: B108 | D22: Primary | E22: Yes | F22: 120000 | G22: Strong-inferred
A23: T2 | B23: Phoenix Industrial | C23: D109 | D23: Primary | E23: Yes | F23: 72372 | G23: Strong-inferred
A24: T2 | B24: Southland Industries | C24: C306 | D24: Primary | E24: Yes | F24: 80040 | G24: Strong-inferred | H24: A national MEP giant staffing up in Boise for a mission-critical industrial project during the fab build is a strong fit for Micron ID1 mechanical scope.
A25: T2 | B25: W&W Steel Erectors (W&W|AFCO Steel) | C25: D313 | D25: Roommate | E25: Yes | F25: 118356 | G25: Strong-inferred | H25: ID1 involves ~70,000 tons of steel and W&W is the dominant US fab steel erector; an erector resident 20 miles from site during peak erection is a strong trade fit.
A26: T2 | B26: Western Partitions, Inc. (WPI) | C26: D312 | D26: Primary | E26: Yes | F26: 103200 | G26: Weak-inferred | H26: No public Micron contract, but a top-tier NW mission-critical interiors sub with a Boise-area office and a $103K resident wage is consistent with fab support-building/interiors scope.
A27: T3 | B27: Atlas Technical Consultants (OneAtlas) | C27: E205 | D27: Primary | E27: Yes | F27: 64488 | G27: Strong-inferred | H27: Boise-area Atlas job postings explicitly reference staffing for the 'Micron Triton project', indicating active testing/inspection work on the Triton site.
A28: T3 | B28: POWER Engineers (a WSP company) | C28: J208 | D28: Primary | E28: Yes | F28: 70716 | G28: Inferred | H28: Aligned to Canyon Ridge workbook: POWER Engineers classified T3 there; Idaho power-delivery engineering consultant plausibly supporting fab power infrastructure.
A29: T3 | B29: Prime Controls, LP | C29: E309 | D29: Primary | E29: Yes | F29: 124860 | G29: Inferred | H29: Aligned to Canyon Ridge workbook: Prime Controls classified T3 there (3 residents); fab FMCS/I&C specialty.
A30: T4 | B30: Critical Systems, Inc. (CSI) | C30: F313 | D30: Primary | E30: Yes | F30: 60000 | G30: Strong-inferred | H30: Not publicly named by Micron, but a Boise-HQ'd UHP gas-systems house next to Micron's campus is squarely in the fab tool-hookup/gas supply chain; two modest-wage residents fit techs/fabricators.
A31: T4 | B31: Critical Systems, Inc. (CSI) | C31: F313 | D31: Roommate | E31: Yes | F31: 45600 | G31: Strong-inferred | H31: Not publicly named by Micron, but a Boise-HQ'd UHP gas-systems house next to Micron's campus is squarely in the fab tool-hookup/gas supply chain; two modest-wage residents fit techs/fabricators.
A32: T4 | B32: Kurita America (Kurita Water Industries) | C32: D103 | D32: Primary | E32: Yes | F32: 72000 | G32: Confirmed | H32: Kurita's CEO publicly stated the company would bid to supply ultrapure water for Micron's Boise fab and hire several hundred Boise-area workers; Boise postings indicate staffing that scope.
A33: T4 | B33: Photronics, Inc. | C33: C201 | D33: Primary | E33: Yes | F33: 80004 | G33: Confirmed | H33: Facility originated as a JV with Micron with a technology license and long-term supply arrangement; Boise site supplies Micron.

Sheet Employers - Seasons
A1: Seasons at Meridian — Standardized Employer Summary (all employers)
A2: 375 raw spellings standardized to canonical employers; each classified by relationship to Micron (T1–T6). Resident counts are live COUNTIFS on the Seasons Data tab (occupants excl. guarantors). Ambiguous / Micron-plausible names were individually web-researched (July 2026).
A4: Seasons - Top Employers | B4: Residents | C4: Tier | D4: Industry | E4: What they do | F4: HQ / Boise presence | G4: Micron relationship & evidence | H4: Confidence | I4: Source
A5: St. Luke's Health System | B5: =COUNTIFS('Seasons Data'!G:G,A5,'Seasons Data'!E:E,"Y") -> 16 | C5: T6 | D5: Healthcare & Social Services | H5: Confirmed-NotMicron
A6: Saint Alphonsus (Trinity Health) | B6: =COUNTIFS('Seasons Data'!G:G,A6,'Seasons Data'!E:E,"Y") -> 14 | C6: T6 | D6: Healthcare & Social Services | H6: Confirmed-NotMicron
A7: Micron Technology | B7: =COUNTIFS('Seasons Data'!G:G,A7,'Seasons Data'!E:E,"Y") -> 9 | C7: T1 | D7: Micron (direct) | H7: Confirmed
A8: Self-employed | B8: =COUNTIFS('Seasons Data'!G:G,A8,'Seasons Data'!E:E,"Y") -> 9 | C8: T6 | D8: Self-employed / private | H8: Confirmed-NotMicron
A9: Amazon | B9: =COUNTIFS('Seasons Data'!G:G,A9,'Seasons Data'!E:E,"Y") -> 7 | C9: T6 | D9: Wholesale, Transport & Logistics | H9: Confirmed-NotMicron
A10: Retired | B10: =COUNTIFS('Seasons Data'!G:G,A10,'Seasons Data'!E:E,"Y") -> 7 | C10: — | D10: Not employed / other income | H10: Confirmed-NotMicron
A11: Albertsons | B11: =COUNTIFS('Seasons Data'!G:G,A11,'Seasons Data'!E:E,"Y") -> 6 | C11: T6 | D11: Retail & Food Service | H11: Confirmed-NotMicron
A12: Chick-fil-A | B12: =COUNTIFS('Seasons Data'!G:G,A12,'Seasons Data'!E:E,"Y") -> 6 | C12: T6 | D12: Retail & Food Service | H12: Confirmed-NotMicron
A13: Idaho College of Osteopathic Medicine (ICOM) | B13: =COUNTIFS('Seasons Data'!G:G,A13,'Seasons Data'!E:E,"Y") -> 6 | C13: T6 | D13: Healthcare & Social Services | H13: Inferred
A14: Aimbridge Hospitality | B14: =COUNTIFS('Seasons Data'!G:G,A14,'Seasons Data'!E:E,"Y") -> 5 | C14: T6 | D14: Hospitality | H14: Confirmed-NotMicron
A15: Coleman Environmental Engineering, Inc. | B15: =COUNTIFS('Seasons Data'!G:G,A15,'Seasons Data'!E:E,"Y") -> 4 | C15: T6 | D15: Engineering & Technical Services | E15: Anaheim, CA remediation and disaster-recovery GC: utility vegetation management, wildfire debris removal, soil remediation, demolition; clients include PG&E, SCE, USFS. | F15: No Idaho office found; 4-person corporate-leased Meridian unit indicates a traveling field-crew deployment. | G15: No mention of Idaho, Boise, Micron, or semiconductor work; deployment client unidentified. | H15: Weak-unverified | I15: colemanenvironmental.com
A16: Goodwill | B16: =COUNTIFS('Seasons Data'!G:G,A16,'Seasons Data'!E:E,"Y") -> 4 | C16: T6 | D16: Retail & Food Service | H16: Confirmed-NotMicron
A17: Idaho Central Credit Union | B17: =COUNTIFS('Seasons Data'!G:G,A17,'Seasons Data'!E:E,"Y") -> 4 | C17: T6 | D17: Financial, Legal & Professional | H17: Confirmed-NotMicron
A18: The AZEK Company | B18: =COUNTIFS('Seasons Data'!G:G,A18,'Seasons Data'!E:E,"Y") -> 4 | C18: T6 | D18: Manufacturing & Consumer Products | H18: Confirmed-NotMicron
A19: 'Si' (data-entry artifact) | B19: =COUNTIFS('Seasons Data'!G:G,A19,'Seasons Data'!E:E,"Y") -> 3 | C19: T6 | D19: Unknown / unresolved | E19: No Boise-area company named 'Si'; likely 'Sí'/yes on a Spanish-language application. | F19: — | G19: None; not plausibly a silicon/semiconductor reference. | H19: Weak-unverified | I19: —
A20: 84 Lumber | B20: =COUNTIFS('Seasons Data'!G:G,A20,'Seasons Data'!E:E,"Y") -> 3 | C20: T6 | D20: Construction & Trades (non-Micron) | H20: Confirmed-NotMicron
A21: Arbor Valley of Cascadia | B21: =COUNTIFS('Seasons Data'!G:G,A21,'Seasons Data'!E:E,"Y") -> 3 | C21: T6 | D21: Healthcare & Social Services | H21: Confirmed-NotMicron
A22: Dr. Yvonne Rochon Pediatric Dentistry | B22: =COUNTIFS('Seasons Data'!G:G,A22,'Seasons Data'!E:E,"Y") -> 3 | C22: T6 | D22: Healthcare & Social Services | H22: Confirmed-NotMicron
A23: Eye Care Center of Northern Colorado | B23: =COUNTIFS('Seasons Data'!G:G,A23,'Seasons Data'!E:E,"Y") -> 3 | C23: T6 | D23: Healthcare & Social Services | H23: Confirmed-NotMicron
A24: Idaho Department of Corrections | B24: =COUNTIFS('Seasons Data'!G:G,A24,'Seasons Data'!E:E,"Y") -> 3 | C24: T6 | D24: Government, Military & Public Safety | H24: Confirmed-NotMicron
A25: Idaho Survey Group LLC | B25: =COUNTIFS('Seasons Data'!G:G,A25,'Seasons Data'!E:E,"Y") -> 3 | C25: T6 | D25: Engineering & Technical Services | E25: Boise-based land surveying and construction staking firm serving ID/NV/OR. | F25: HQ Boise, ID. | G25: No Micron connection found; Micron's documented site surveyor since 2017 is a different firm (Eagle Land Surveying). | H25: Inferred | I25: idahosurvey.com
A26: Modern Wealth Management | B26: =COUNTIFS('Seasons Data'!G:G,A26,'Seasons Data'!E:E,"Y") -> 3 | C26: T6 | D26: Financial, Legal & Professional | H26: Confirmed-NotMicron
A27: Royal Coffee Co. | B27: =COUNTIFS('Seasons Data'!G:G,A27,'Seasons Data'!E:E,"Y") -> 3 | C27: T6 | D27: Retail & Food Service | H27: Confirmed-NotMicron
A28: Shea Homes | B28: =COUNTIFS('Seasons Data'!G:G,A28,'Seasons Data'!E:E,"Y") -> 3 | C28: T6 | D28: Construction & Trades (non-Micron) | H28: Confirmed-NotMicron
A29: Uber | B29: =COUNTIFS('Seasons Data'!G:G,A29,'Seasons Data'!E:E,"Y") -> 3 | C29: T6 | D29: Gig economy | H29: Confirmed-NotMicron
A30: WESCO Microscopes (Western Scientific) | B30: =COUNTIFS('Seasons Data'!G:G,A30,'Seasons Data'!E:E,"Y") -> 3 | C30: T6 | D30: Personal Services & Other Local | E30: Family-scale sales, repair, and maintenance of optical microscopes for educational, clinical, industrial users (since 1962). | F30: Relocated from California to Idaho; small Treasure Valley operation. | G30: No semiconductor or Micron connection — optical/lab microscope service shop, not fab metrology. | H30: Confirmed-NotMicron | I30: wescomicroscopes.com
A31: West Ada School District | B31: =COUNTIFS('Seasons Data'!G:G,A31,'Seasons Data'!E:E,"Y") -> 3 | C31: T6 | D31: Education & Childcare | H31: Confirmed-NotMicron
A32: Engineered Structures, Inc. (ESI) | B32: =COUNTIFS('Seasons Data'!G:G,A32,'Seasons Data'!E:E,"Y") -> 2 | C32: T2 | D32: Micron fab construction | E32: Idaho's largest privately owned GC/CM/design-build firm (founded 1973, licensed in 42 states). | F32: Headquartered in Meridian, ID — same city as the property. | G32: ENR documents ESI building office and parking structures at Micron's Boise global HQ as part of the campus expansion; $133.6K salary fits a PM/superintendent. | H32: Confirmed | I32: enr.com
A33: IBEW (electricians union) | B33: =COUNTIFS('Seasons Data'!G:G,A33,'Seasons Data'!E:E,"Y") -> 2 | C33: T2 | D33: Micron fab construction | H33: Strong-inferred
A34: Critical Systems, Inc. (CSI) | B34: =COUNTIFS('Seasons Data'!G:G,A34,'Seasons Data'!E:E,"Y") -> 2 | C34: T4 | D34: Semi equipment & materials | E34: Designs, builds, refurbishes and services ultra-high-purity gas cabinets, valve manifold boxes, gas abatement and orbital welding for semiconductor fabs (since 1998). | F34: HQ at 7000 W Victory Rd, Boise ID — ~2 miles from Micron's Federal Way campus; also MN, PA, TX, UT. | G34: Not publicly named by Micron, but a Boise-HQ'd UHP gas-systems house next to Micron's campus is squarely in the fab tool-hookup/gas supply chain; two modest-wage residents fit techs/fabricators. | H34: Strong-inferred | I34: criticalsystemsinc.com
A35: Access Behavioral Health | B35: =COUNTIFS('Seasons Data'!G:G,A35,'Seasons Data'!E:E,"Y") -> 2 | C35: T6 | D35: Healthcare & Social Services | H35: Confirmed-NotMicron
A36: Ada County | B36: =COUNTIFS('Seasons Data'!G:G,A36,'Seasons Data'!E:E,"Y") -> 2 | C36: T6 | D36: Government, Military & Public Safety | H36: Confirmed-NotMicron
A37: Aqua-Tots Swim School | B37: =COUNTIFS('Seasons Data'!G:G,A37,'Seasons Data'!E:E,"Y") -> 2 | C37: T6 | D37: Education & Childcare | H37: Confirmed-NotMicron
A38: Boise State University | B38: =COUNTIFS('Seasons Data'!G:G,A38,'Seasons Data'!E:E,"Y") -> 2 | C38: T6 | D38: Education & Childcare | H38: Confirmed-NotMicron
A39: Columbia Electric Supply (Sonepar) | B39: =COUNTIFS('Seasons Data'!G:G,A39,'Seasons Data'!E:E,"Y") -> 2 | C39: T6 | D39: Wholesale, Transport & Logistics | E39: Industrial electrical products, automation, and smart-manufacturing distribution. | F39: Branch at 8645 Westpark St, Boise; NW distributor in the Sonepar family. | G39: No supplier-of-record evidence; incidental sales to fab subs plausible but classed as ordinary local distribution. | H39: Inferred | I39: cesboise.com
A40: Crumbl | B40: =COUNTIFS('Seasons Data'!G:G,A40,'Seasons Data'!E:E,"Y") -> 2 | C40: T6 | D40: Retail & Food Service | H40: Confirmed-NotMicron
A41: DHS / TSA | B41: =COUNTIFS('Seasons Data'!G:G,A41,'Seasons Data'!E:E,"Y") -> 2 | C41: T6 | D41: Government, Military & Public Safety | H41: Confirmed-NotMicron
...

Sheet Employers - Canyon Ridge
A1: Canyon Ridge — Standardized Employer Summary (all 151 employers)
A2: Carried over verbatim from Canyon Ridge Employer / Micron Analysis (2026.06.24). Counts are occupant-level (Primary + Co-Applicant).
A4: Canyon Ridge - Top Employers | B4: Residents | C4: Tier | D4: Category | E4: What they do | F4: HQ / Boise presence | G4: Micron relationship & evidence | H4: Confidence | I4: Source
A5: Micron Technology | B5: 89 | C5: T1 | D5: Micron (direct employer) | E5: DRAM & NAND memory/storage chip designer & manufacturer | F5: Boise, ID (HQ, 8000 S Federal Way) | G5: THE employer/anchor. ~$50B "Triton" Boise expansion: two new DRAM fabs, first wafers ~2H2027, ~17,000 projected ID jobs. Property is adjacent worker housing. | H5: Confirmed | I5: micron.com/us-expansion/id
A6: Oregon Electric Group (OEG) | B6: 12 | C6: T2 | D6: Micron construction subcontractor (building the fabs) | E6: Electrical contractor (mission-critical/high-tech/industrial) | F6: Portland, OR (MDU Construction Services); IBEW 291 signatory | G6: Variants incl. "Oregon Electric"/"Oregon electric group"; IBEW 291 dispatch on Micron PLA; fab electrical fit. | H6: Strong-inferred | I6: oeg.us.com; ibew291.org
A7: Hoffman Structures, Inc. | B7: 10 | C7: T2 | D7: Micron construction subcontractor (building the fabs) | E7: Structural/concrete self-perform affiliate of Hoffman Construction | F7: Portland, OR | G7: In-house concrete arm of Hoffman; concrete scope on Triton via parent GC role (inferred). | H7: Strong-inferred | I7: wikipedia/Hoffman Construction
A8: Performance Contracting, Inc. (PCI) | B8: 10 | C8: T2 | D8: Micron construction subcontractor (building the fabs) | E8: Specialty contractor: cleanroom build-out & insulation for microelectronics | F8: Lenexa, KS; Boise location | G8: Cleanroom/microelectronics specialty + Boise presence; classic fab cleanroom sub. | H8: Strong-inferred | I8: performancecontracting.com
A9: Phoenix Industrial | B9: 9 | C9: T2 | D9: Micron construction subcontractor (building the fabs) | E9: Heavy-industrial GC (civil, steel, process piping, electrical); a MasTec company | F9: Vancouver, WA (MasTec subsidiary); Boise job postings | G9: MasTec-owned ("Mas tec - phoenix industrial" per a resident); Boise hiring + industrial scope fit the fab build. | H9: Strong-inferred | I9: phxind.com/about
A10: Hoffman Construction Company | B10: 8 | C10: T2 | D10: Micron construction subcontractor (building the fabs) | E10: General contractor (largest in Pacific NW) | F10: Portland, OR (Boise offices) | G10: CONFIRMED: became GC of the Micron Triton build ~Sept 2025 after Exyte was discontinued. | H10: Confirmed | I10: boisedev.com 2025/11/24
A11: Trew Contracting Solutions | B11: 8 | C11: T2 | D11: Micron construction subcontractor (building the fabs) | E11: Site/civil & general contracting (TCS) labor | F11: Idaho | G11: Idaho site contractor (variants "Tcs construction"/"TCS, LLC"); resident laborers/yard foreman/project engineer on the build. | H11: Inferred | I11: —
A12: United States Air Force | B12: 7 | C12: T6 | D12: Unrelated / local | E12: U.S. military service branch | F12: Mountain Home AFB (~40mi SE) & Idaho ANG, Gowen Field | G12: Military. No Micron tie. | H12: Confirmed-NotMicron | I12: af.mil
A13: JH Kelly | B13: 4 | C13: T2 | D13: Micron construction subcontractor (building the fabs) | E13: Industrial mechanical contractor / self-perform GC | F13: Longview, WA; Boise jobsites | G13: CONFIRMED: dedicated project page "Micron Project Triton F08B"; ~97,000 lf process piping installed. | H13: Confirmed | I13: jhkelly.com/projects/micron-project-triton-f08b
A14: SME Steel Contractors | B14: 4 | C14: T2 | D14: Micron construction subcontractor (building the fabs) | E14: Structural steel fabricator/erector (SME Industries) | F14: West Jordan, UT (Western US) | G14: Steel erection trade; major Western steel contractor on large fab/industrial builds. Resident ironworkers/journeymen. | H14: Strong-inferred | I14: smesteel.com
A15: Suntec Concrete | B15: 4 | C15: T2 | D15: Micron construction subcontractor (building the fabs) | E15: Large structural/cast-in-place concrete contractor | F15: Phoenix, AZ | G15: Major Southwest concrete contractor active on semiconductor megaprojects; resident cement masons/finishers/laborers. | H15: Strong-inferred | I15: suntecconcrete.com
A16: St. Luke's Health System | B16: 4 | C16: T6 | D16: Unrelated / local | E16: Idaho's largest health system (hospitals) | F16: Boise, ID | G16: Local healthcare. No Micron tie. | H16: Confirmed-NotMicron | I16: stlukesonline.org
... A155: Yardi Systems | B155: 1 | C155: T6 | D155: Unrelated / local | E155: Property-management software | F155: Santa Barbara, CA | G155: Software. No Micron tie. | H155: Confirmed-NotMicron | I155: yardi.com

Sheet Unit Coverage Detail
A1: Unit-level household income, rent & coverage — both properties
A2: One row per unit with demographic data. HH Income = sum of qualifying occupant incomes (excl. guarantors, copied records, ≥$1M outliers). Rent: Canyon Ridge = scheduled rent (Entrata); Seasons = contract rent (rentres) from 07/09/2026 rent roll. Multiple = HH income ÷ (12 × rent).
A4: Property | B4: Unit | C4: HH Income | D4: Contract Rent | E4: Income Multiple | F4: ≥3x Rent | G4: Micron-related unit (T1–T4) | H4: Micron direct unit (T1)
A5: Canyon Ridge | B5: A-101 | C5: 105000 | D5: 1725 | E5: =IF(AND(ISNUMBER(C5),ISNUMBER(D5)),C5/(12*D5),"") -> 5.0724638 | F5: =IF(E5="","",IF(E5>=3,"Y","N")) -> Y | G5: Y | H5: Y
A6: Canyon Ridge | B6: A-102 | C6: 8310000 | D6: 2560 | E6: =IF(AND(ISNUMBER(C6),ISNUMBER(D6)),C6/(12*D6),"") -> 270.50781 | F6: =IF(E6="","",IF(E6>=3,"Y","N")) -> Y | G6: Y | H6: N
A7: Canyon Ridge | B7: A-103 | C7: 391820 | D7: 2375 | E7: =IF(AND(ISNUMBER(C7),ISNUMBER(D7)),C7/(12*D7),"") -> 13.74807 | F7: =IF(E7="","",IF(E7>=3,"Y","N")) -> Y | G7: Y | H7: N
A8: Canyon Ridge | B8: A-104 | C8: 182500 | D8: 1840 | E8: =IF(AND(ISNUMBER(C8),ISNUMBER(D8)),C8/(12*D8),"") -> 8.2653986 | F8: =IF(E8="","",IF(E8>=3,"Y","N")) -> Y | G8: Y | H8: Y
A9: Canyon Ridge | B9: A-105 | C9: 216000 | D9: 2115 | E9: =IF(AND(ISNUMBER(C9),ISNUMBER(D9)),C9/(12*D9),"") -> 8.5106383 | F9: =IF(E9="","",IF(E9>=3,"Y","N")) -> Y | G9: Y | H9: N
A10: Canyon Ridge | B10: A-106 | D10: 1842 | E10: =IF(AND(ISNUMBER(C10),ISNUMBER(D10)),C10/(12*D10),"") | F10: =IF(E10="","",IF(E10>=3,"Y","N")) | G10: N | H10: N
A11: Canyon Ridge | B11: A-107 | C11: 146000 | D11: 1525 | E11: =IF(AND(ISNUMBER(C11),ISNUMBER(D11)),C11/(12*D11),"") -> 7.9781421 | F11: =IF(E11="","",IF(E11>=3,"Y","N")) -> Y | G11: Y | H11: N
A12: Canyon Ridge | B12: A-108 | D12: 1868 | E12: =IF(AND(ISNUMBER(C12),ISNUMBER(D12)),C12/(12*D12),"") | F12: =IF(E12="","",IF(E12>=3,"Y","N")) | G12: N | H12: N
A13: Canyon Ridge | B13: A-109 | C13: 144600 | D13: 1740 | E13: =IF(AND(ISNUMBER(C13),ISNUMBER(D13)),C13/(12*D13),"") -> 6.9252874 | F13: =IF(E13="","",IF(E13>=3,"Y","N")) -> Y | G13: Y | H13: N
A14: Canyon Ridge | B14: A-110 | C14: 65000 | D14: 2250 | E14: =IF(AND(ISNUMBER(C14),ISNUMBER(D14)),C14/(12*D14),"") -> 2.4074074 | F14: =IF(E14="","",IF(E14>=3,"Y","N")) -> N | G14: N | H14: N
A15: Canyon Ridge | B15: A-112 | C15: 62000 | D15: 1895 | E15: =IF(AND(ISNUMBER(C15),ISNUMBER(D15)),C15/(12*D15),"") -> 2.7264732 | F15: =IF(E15="","",IF(E15>=3,"Y","N")) -> N | G15: N | H15: N
A16: Canyon Ridge | B16: A-113 | C16: 401000 | D16: 2610 | E16: =IF(AND(ISNUMBER(C16),ISNUMBER(D16)),C16/(12*D16),"") -> 12.803321 | F16: =IF(E16="","",IF(E16>=3,"Y","N")) -> Y | G16: Y | H16: N
A17: Canyon Ridge | B17: A-114 | C17: 87312 | D17: 1865 | E17: =IF(AND(ISNUMBER(C17),ISNUMBER(D17)),C17/(12*D17),"") -> 3.9013405 | F17: =IF(E17="","",IF(E17>=3,"Y","N")) -> Y | G17: N | H17: N
A18: Canyon Ridge | B18: A-115 | C18: 129380.2 | D18: 2285 | E18: =IF(AND(ISNUMBER(C18),ISNUMBER(D18)),C18/(12*D18),"") -> 4.718461 | F18: =IF(E18="","",IF(E18>=3,"Y","N")) -> Y | G18: N | H18: N
A19: Canyon Ridge | B19: A-116 | D19: 2185 | E19: =IF(AND(ISNUMBER(C19),ISNUMBER(D19)),C19/(12*D19),"") | F19: =IF(E19="","",IF(E19>=3,"Y","N")) | G19: N | H19: N
A20: Canyon Ridge | B20: A-201 | D20: 1975 | E20: =IF(AND(ISNUMBER(C20),ISNUMBER(D20)),C20/(12*D20),"") | F20: =IF(E20="","",IF(E20>=3,"Y","N")) | G20: N | H20: N
A21: Canyon Ridge | B21: A-202 | C21: 180000 | D21: 2345 | E21: =IF(AND(ISNUMBER(C21),ISNUMBER(D21)),C21/(12*D21),"") -> 6.3965885 | F21: =IF(E21="","",IF(E21>=3,"Y","N")) -> Y | G21: N | H21: N
A22: Canyon Ridge | B22: A-203 | C22: 81608.04 | D22: 1795 | E22: =IF(AND(ISNUMBER(C22),ISNUMBER(D22)),C22/(12*D22),"") -> 3.7886741 | F22: =IF(E22="","",IF(E22>=3,"Y","N")) -> Y | G22: N | H22: N
A23: Canyon Ridge | B23: A-204 | C23: 130000 | D23: 1895 | E23: =IF(AND(ISNUMBER(C23),ISNUMBER(D23)),C23/(12*D23),"") -> 5.7167986 | F23: =IF(E23="","",IF(E23>=3,"Y","N")) -> Y | G23: Y | H23: N
A24: Canyon Ridge | B24: A-205 | C24: 168400 | D24: 1850 | E24: =IF(AND(ISNUMBER(C24),ISNUMBER(D24)),C24/(12*D24),"") -> 7.5855856 | F24: =IF(E24="","",IF(E24>=3,"Y","N")) -> Y | G24: N | H24: N
A25: Canyon Ridge | B25: A-206 | D25: 1863 | E25: =IF(AND(ISNUMBER(C25),ISNUMBER(D25)),C25/(12*D25),"") | F25: =IF(E25="","",IF(E25>=3,"Y","N")) | G25: N | H25: N
A26: Canyon Ridge | B26: A-207 | C26: 78250 | D26: 1495 | E26: =IF(AND(ISNUMBER(C26),ISNUMBER(D26)),C26/(12*D26),"") -> 4.3617614 | F26: =IF(E26="","",IF(E26>=3,"Y","N")) -> Y | G26: Y | H26: N
A27: Canyon Ridge | B27: A-208 | D27: 1850 | E27: =IF(AND(ISNUMBER(C27),ISNUMBER(D27)),C27/(12*D27),"") | F27: =IF(E27="","",IF(E27>=3,"Y","N")) | G27: N | H27: N
A28: Canyon Ridge | B28: A-209 | D28: 2000 | E28: =IF(AND(ISNUMBER(C28),ISNUMBER(D28)),C28/(12*D28),"") | F28: =IF(E28="","",IF(E28>=3,"Y","N")) | G28: N | H28: N
A29: Canyon Ridge | B29: A-210 | C29: 328000 | D29: 1895 | E29: =IF(AND(ISNUMBER(C29),ISNUMBER(D29)),C29/(12*D29),"") -> 14.423923 | F29: =IF(E29="","",IF(E29>=3,"Y","N")) -> Y | G29: Y | H29: Y
A30: Canyon Ridge | B30: A-211 | C30: 50000 | D30: 2155 | E30: =IF(AND(ISNUMBER(C30),ISNUMBER(D30)),C30/(12*D30),"") -> 1.933488 | F30: =IF(E30="","",IF(E30>=3,"Y","N")) -> N | G30: N | H30: N
A31: Canyon Ridge | B31: A-212 | C31: 206000 | D31: 1995 | E31: =IF(AND(ISNUMBER(C31),ISNUMBER(D31)),C31/(12*D31),"") -> 8.6048454 | F31: =IF(E31="","",IF(E31>=3,"Y","N")) -> Y | G31: Y | H31: Y
A32: Canyon Ridge | B32: A-213 | C32: 176800 | D32: 2495 | E32: =IF(AND(ISNUMBER(C32),ISNUMBER(D32)),C32/(12*D32),"") -> 5.9051436 | F32: =IF(E32="","",IF(E32>=3,"Y","N")) -> Y | G32: Y | H32: N
A33: Canyon Ridge | B33: A-214 | C33: 432000 | D33: 2410 | E33: =IF(AND(ISNUMBER(C33),ISNUMBER(D33)),C33/(12*D33),"") -> 14.937759 | F33: =IF(E33="","",IF(E33>=3,"Y","N")) -> Y | G33: Y | H33: N
A34: Canyon Ridge | B34: A-215 | C34: 183000 | D34: 2325 | E34: =IF(AND(ISNUMBER(C34),ISNUMBER(D34)),C34/(12*D34),"") -> 6.5591398 | F34: =IF(E34="","",IF(E34>=3,"Y","N")) -> Y | G34: Y | H34: Y
A35: Canyon Ridge | B35: A-216 | C35: 143000 | D35: 2275 | E35: =IF(AND(ISNUMBER(C35),ISNUMBER(D35)),C35/(12*D35),"") -> 5.2380952 | F35: =IF(E35="","",IF(E35>=3,"Y","N")) -> Y | G35: Y | H35: N
A36: Canyon Ridge | B36: A-301 | C36: 125000 | D36: 1925 | E36: =IF(AND(ISNUMBER(C36),ISNUMBER(D36)),C36/(12*D36),"") -> 5.4112554 | F36: =IF(E36="","",IF(E36>=3,"Y","N")) -> Y | G36: Y | H36: N
A37: Canyon Ridge | B37: A-302 | D37: 2520 | E37: =IF(AND(ISNUMBER(C37),ISNUMBER(D37)),C37/(12*D37),"") | F37: =IF(E37="","",IF(E37>=3,"Y","N")) | G37: N | H37: N
A38: Canyon Ridge | B38: A-303 | C38: 290000 | D38: 2510 | E38: =IF(AND(ISNUMBER(C38),ISNUMBER(D38)),C38/(12*D38),"") -> 9.6281541 | F38: =IF(E38="","",IF(E38>=3,"Y","N")) -> Y | G38: Y | H38: N
A39: Canyon Ridge | B39: A-304 | C39: 321500 | D39: 2170 | E39: =IF(AND(ISNUMBER(C39),ISNUMBER(D39)),C39/(12*D39),"") -> 12.34639 | F39: =IF(E39="","",IF(E39>=3,"Y","N")) -> Y | G39: Y | H39: Y
A40: Canyon Ridge | B40: A-305 | C40: 80400 | D40: 2185 | E40: =IF(AND(ISNUMBER(C40),ISNUMBER(D40)),C40/(12*D40),"") -> 3.0663616 | F40: =IF(E40="","",IF(E40>=3,"Y","N")) -> Y | G40: Y | H40: Y
A41: Canyon Ridge | B41: A-306 | D41: 1885 | E41: =IF(AND(ISNUMBER(C41),ISNUMBER(D41)),C41/(12*D41),"") | F41: =IF(E41="","",IF(E41>=3,"Y","N")) | G41: N | H41: N
...

Sheet Seasons Data
A1: Seasons at Meridian — Demographics (standardized & classified)
A2: Source: seller "Demographics Report w/Roommates" 07/10/2026 (Status=Current — excludes the 38 units on notice), de-duplicated to one row per person (pet rows collapsed). Employer standardization & T1–T6 tiers added by this analysis.
A4: Unit | B4: Tenant Code | C4: Name | D4: Relationship | E4: Resident (excl. guarantor) | F4: Raw Company (as entered) | G4: Standardized Employer | H4: Tier | I4: Industry | J4: Confidence | K4: Annual Salary | L4: Income OK | M4: Income Flag | N4: DOB | O4: Marital
A5: A101 | B5: t0035267 | C5: Ramirez, Emely | D5: Primary | E5: Y | F5: drybar | G5: Drybar | H5: T6 | I5: Personal Services & Other Local | J5: Confirmed-NotMicron | K5: 24000 | L5: Y | N5: 02/06/1994
A6: A101 | B6: r0035291 | C6: dilone, franxesca | D6: Roommate | E6: Y | F6: st Alphonso | G6: Saint Alphonsus (Trinity Health) | H6: T6 | I6: Healthcare & Social Services | J6: Confirmed-NotMicron | K6: 128100 | L6: Y | N6: 12/21/1974
A7: A102 | B7: t0038493 | C7: Fielder, Matthew | D7: Primary | E7: Y | F7: GardaWorld | G7: GardaWorld | H7: T6 | I7: Government, Military & Public Safety | J7: Confirmed-NotMicron | K7: 51780 | L7: Y | N7: 02/19/1983 | O7: Married
A8: A102 | B8: r0038541 | C8: Fielder, Shanae | D8: Spouse | E8: Y | F8: Ulta Beauty | G8: Ulta Beauty | H8: T6 | I8: Retail & Food Service | J8: Confirmed-NotMicron | K8: 76056 | L8: Y | N8: 04/17/1990 | O8: Married
A9: A104 | B9: t0036159 | C9: Bain, Nancy | D9: Primary | E9: Y | F9: Retired | G9: Retired | I9: Not employed / other income | J9: Confirmed-NotMicron | K9: 48120 | L9: Y | N9: 06/22/1951
A10: A106 | B10: t0035645 | C10: Hanna, Dominic | D10: Primary | E10: Y | F10: Micron Technology | G10: Micron Technology | H10: T1 | I10: Micron (direct) | J10: Confirmed | K10: 51180 | L10: Y | N10: 05/22/2003
A11: A106 | B11: r0035820 | C11: Evans, Hannah | D11: Roommate | E11: Y | F11: Great Harvest Bakery Company | G11: Great Harvest Bread Co. | H11: T6 | I11: Retail & Food Service | J11: Confirmed-NotMicron | K11: 29004 | L11: Y | N11: 01/22/2007
A12: A107 | B12: t0030452 | C12: Orchard, Heather | D12: Primary | E12: Y | F12: Epionce | G12: Epionce (Episciences) | H12: T6 | I12: Healthcare & Social Services | J12: Confirmed-NotMicron | K12: 69996 | L12: Y | N12: 08/12/1988
A13: A108 | B13: t0035973 | C13: Knox, Katrina | D13: Primary | E13: Y | F13: St Luke's Medical Center | G13: St. Luke's Health System | H13: T6 | I13: Healthcare & Social Services | J13: Confirmed-NotMicron | K13: 59340 | L13: Y | N13: 11/13/1972
A14: A109 | B14: t0034222 | C14: Edens, Gavin | D14: Primary | E14: Y | F14: US Army | G14: U.S. Army | H14: T6 | I14: Government, Military & Public Safety | J14: Confirmed-NotMicron | K14: 78228 | L14: Y | N14: 09/06/1999 | O14: Married
A15: A109 | B15: r0034315 | C15: Edens, Amanda | D15: Spouse | E15: Y | F15: Barbara Morgan stem Academy | G15: Barbara Morgan STEM Academy (West Ada) | H15: T6 | I15: Education & Childcare | J15: Confirmed-NotMicron | K15: 21360 | L15: Y | N15: 12/03/1999 | O15: Married
A16: A110 | B16: t0036419 | C16: Dent, Zackary | D16: Primary | E16: Y | F16: Liberty Energy | G16: Liberty Energy | H16: T6 | I16: Energy & Utilities | J16: Confirmed-NotMicron | K16: 112596 | L16: Y | N16: 04/01/2002 | O16: Single
A17: A111 | B17: t0035171 | C17: Zuniga, Jonathan | D17: Primary | E17: Y | F17: Barak Group Inc. DBA Jani-King | G17: Jani-King (Barak Group) | H17: T6 | I17: Personal Services & Other Local | J17: Confirmed-NotMicron | K17: 72924 | L17: Y | N17: 03/28/1999 | O17: Single
A18: A112 | B18: t0040841 | C18: Hart, Angela | D18: Primary | E18: Y | F18: Life Care center of Boise | G18: Life Care Center of Boise | H18: T6 | I18: Healthcare & Social Services | J18: Confirmed-NotMicron | K18: 78336 | L18: Y | N18: 06/21/1970 | O18: Single
A19: A112 | B19: r0040962 | C19: Hart, Charity | D19: Roommate | E19: Y | F19: NA | I19: (blank) | K19: 0 | L19: N | M19: No income stated | N19: 09/04/2001
A20: A202 | B20: t0029908 | C20: McKenzie, Alexandra | D20: Primary | E20: Y | F20: Arbor Valley of Cascadia | G20: Arbor Valley of Cascadia | H20: T6 | I20: Healthcare & Social Services | J20: Confirmed-NotMicron | K20: 48000 | L20: Y | N20: 02/22/2001
A21: A202 | B21: r0030032 | C21: McKenzie, Brandon | D21: Roommate | E21: Y | I21: (blank) | K21: 0 | L21: N | M21: No income stated | N21: 10/19/2009
A22: A202 | B22: r0030083 | C22: McKenzie, Eli | D22: Roommate | E22: Y | I22: (blank) | K22: 0 | L22: N | M22: No income stated | N22: 10/19/2009
