Workbook

Sheet Summary
A1: Seasons at Meridian — First Turn of the Rent Roll
A2: Initial tenant cohort = 314 residents in place on the 1/1/2026 rent roll, tracked to the 8/4/2026 rent roll. Measurement date: 8/4/2026.
A3: Convention: Retention = renewals ÷ initial leases whose first expiration came due by 8/4/26. Early terminations (left before expiration) are excluded from the ratio until their expiration passes, and shown separately. Early renewals count as renewed at their original expiration.
A5: RETENTION — FIRST TURN
A6: Initial cohort (residents on 1/1/26 roll) | B6: =COUNTA('Unit Ledger'!$A$2:$A$315) -> 314
A7: First expirations come due by 8/4/26 | B7: =COUNTIF('Unit Ledger'!$S$2:$S$315,"Y") -> 154
A8: Renewed | B8: =COUNTIFS('Unit Ledger'!$S$2:$S$315,"Y",'Unit Ledger'!$Q$2:$Q$315,"Renewed") -> 64
A9: Moved out | B9: =COUNTIFS('Unit Ledger'!$S$2:$S$315,"Y",'Unit Ledger'!$Q$2:$Q$315,"Moved Out") -> 83
A10: Month-to-month holdover (no new lease yet) | B10: =COUNTIFS('Unit Ledger'!$S$2:$S$315,"Y",'Unit Ledger'!$Q$2:$Q$315,"MTM Holdover") -> 7
A11: RETENTION RATIO (renewed ÷ expirations) | B11: =B8/B7 -> 0.41558442
A12: Retention if MTM holdovers ultimately renew | B12: =(B8+B10)/B7 -> 0.46103896 | C12: Upper bound — 7 tenants expired but still in place without a new lease
A14: Early terminations, expiration not yet due | B14: =COUNTIFS('Unit Ledger'!$Q$2:$Q$315,"Moved Out",'Unit Ledger'!$S$2:$S$315,"<>Y") -> 21 | C14: Lease-breaks/skips; real attrition but no renewal decision yet
A15: All-in retention (early terms counted as lost) | B15: =B8/(B7+B14) -> 0.36571429
A16: Not yet expired (first turn still ahead) | B16: =COUNTIFS('Unit Ledger'!$Q$2:$Q$315,"Not Yet Expired") -> 139
A18: RENEWAL TRADE-OUT (n = renewed; corporate excluded)
B19: Average | C19: Median | D19: n
A20: Gross trade-out (contract rent → contract rent) | B20: =AVERAGEIFS('Unit Ledger'!$AC$2:$AC$315,'Unit Ledger'!$Q$2:$Q$315,"Renewed",'Unit Ledger'!$V$2:$V$315,"<>Y") -> 0.015364205 | C20: =MEDIAN('Unit Ledger'!$AC$2:$AC$315) -> 0.015985697 | D20: =COUNTIFS('Unit Ledger'!$Q$2:$Q$315,"Renewed",'Unit Ledger'!$V$2:$V$315,"<>Y",'Unit Ledger'!$Y$2:$Y$315,">0") -> 64
A21: Effective trade-out (net of concessions, amortized) | B21: =AVERAGEIFS('Unit Ledger'!$AD$2:$AD$315,'Unit Ledger'!$Q$2:$Q$315,"Renewed",'Unit Ledger'!$V$2:$V$315,"<>Y") -> 0.095309584 | C21: =MEDIAN('Unit Ledger'!$AD$2:$AD$315) -> 0.086368682 | D21: =D20 -> 64
A22: Avg prior gross rent → avg renewal gross rent | B22: =AVERAGEIFS('Unit Ledger'!$L$2:$L$315,'Unit Ledger'!$Q$2:$Q$315,"Renewed",'Unit Ledger'!$V$2:$V$315,"<>Y") -> 1731.875 | C22: =AVERAGEIFS('Unit Ledger'!$Y$2:$Y$315,'Unit Ledger'!$Q$2:$Q$315,"Renewed",'Unit Ledger'!$V$2:$V$315,"<>Y") -> 1757.8906
A23: Renewals signing at flat/zero gross increase | B23: =COUNTIFS('Unit Ledger'!$Q$2:$Q$315,"Renewed",'Unit Ledger'!$AC$2:$AC$315,"<=0",'Unit Ledger'!$V$2:$V$315,"<>Y") -> 23 | C23: Flat renewals are invisible without lease-start data — see Notes
A25: NEW-LEASE TRADE-OUT (turned units re-leased; corporate excluded)
B26: Average | C26: Median | D26: n
A27: Gross trade-out (prior tenant → new tenant) | B27: =AVERAGEIFS('Unit Ledger'!$AM$2:$AM$315,'Unit Ledger'!$Q$2:$Q$315,"Moved Out",'Unit Ledger'!$V$2:$V$315,"<>Y") -> 0.051747484 | C27: =MEDIAN('Unit Ledger'!$AM$2:$AM$315) -> 0.039921245 | D27: =COUNTIFS('Unit Ledger'!$Q$2:$Q$315,"Moved Out",'Unit Ledger'!$V$2:$V$315,"<>Y",'Unit Ledger'!$AJ$2:$AJ$315,">0") -> 92
A28: Effective trade-out (net of concessions both sides) | B28: =AVERAGEIFS('Unit Ledger'!$AN$2:$AN$315,'Unit Ledger'!$Q$2:$Q$315,"Moved Out",'Unit Ledger'!$V$2:$V$315,"<>Y") -> 0.1066842 | C28: =MEDIAN('Unit Ledger'!$AN$2:$AN$315) -> 0.1019753 | D28: =SUMPRODUCT(('Unit Ledger'!$Q$2:$Q$315="Moved Out")*('Unit Ledger'!$V$2:$V$315<>"Y")*ISNUMBER('Unit Ledger'!$AN$2:$AN$315)) -> 88
A29: Avg prior tenant gross → avg new tenant gross | B29: =AVERAGEIFS('Unit Ledger'!$L$2:$L$315,'Unit Ledger'!$Q$2:$Q$315,"Moved Out",'Unit Ledger'!$AJ$2:$AJ$315,">0",'Unit Ledger'!$V$2:$V$315,"<>Y") -> 1751.2283 | C29: =AVERAGEIFS('Unit Ledger'!$AJ$2:$AJ$315,'Unit Ledger'!$Q$2:$Q$315,"Moved Out",'Unit Ledger'!$AJ$2:$AJ$315,">0",'Unit Ledger'!$V$2:$V$315,"<>Y") -> 1838.1413
A30: Avg days vacant between tenants | B30: =AVERAGEIFS('Unit Ledger'!$AO$2:$AO$315,'Unit Ledger'!$Q$2:$Q$315,"Moved Out") -> 23.033708
A32: CONCESSION BURN-OFF (the real story)
A33: Initial leases with a concession (where known) | B33: =COUNTIF('Unit Ledger'!$M$2:$M$315,">0")/(COUNTIF('Unit Ledger'!$M$2:$M$315,">0")+COUNTIF('Unit Ledger'!$M$2:$M$315,"0")) -> 0.70989761 | C33: Denominator = leases with concession data
A34: Avg initial concession (leases w/ concession) | B34: =AVERAGEIF('Unit Ledger'!$M$2:$M$315,">0") -> 2058.458
A35: Avg initial concession in months free | B35: =AVERAGEIF('Unit Ledger'!$M$2:$M$315,">0")/AVERAGEIFS('Unit Ledger'!$L$2:$L$315,'Unit Ledger'!$M$2:$M$315,">0") -> 1.1769925
A36: Avg concession on renewal leases | B36: =AVERAGEIFS('Unit Ledger'!$Z$2:$Z$315,'Unit Ledger'!$Q$2:$Q$315,"Renewed") -> 23.398438 | C36: Concessions largely disappear at renewal — hence eff >> gross trade-out
A37: Avg concession on replacement (new) leases | B37: =AVERAGEIFS('Unit Ledger'!$AK$2:$AK$315,'Unit Ledger'!$Q$2:$Q$315,"Moved Out",'Unit Ledger'!$AJ$2:$AJ$315,">0") -> 455.78977
A39: Sources: Yardi rent rolls (1/1, 7/07, 7/19, 8/4/2026), Concession Burn Off (6/21, 7/30/2026 — lease start dates), Renewal Tradeouts report (5/10–7/9/2026), HelloData unit details (8/12/2026). See Notes tab for methodology and caveats.

Sheet Unit Ledger
A1: Unit | B1: Unit Type | C1: Beds | D1: SF | E1: Resident ID | F1: Resident | G1: Move In | H1: Initial Term (mo) | I1: Orig. First Expiration | J1: Exp Month | K1: Orig. Exp Source | L1: Initial Gross Rent | M1: Initial Concession ($) | N1: Initial Effective Rent | O1: Initial Rent Source | P1: Concession Source | Q1: Outcome | R1: Expired by 8/4/26 | S1: In Retention Denom | T1: Early Term | U1: Notice | V1: Exclude | W1: Renewal Date | X1: Renewal Term (mo) | Y1: Renewal Gross Rent | Z1: Renewal Concession ($) | AA1: Renewal Effective Rent | AB1: In Renewal Report | AC1: Renewal Trade-Out Gross % | AD1: Renewal Trade-Out Eff % | AE1: Vacated Date | AF1: New Resident ID | AG1: New Resident | AH1: New Move In | AI1: New Lease Term (mo) | AJ1: New Gross Rent | AK1: New Concession ($) | AL1: New Effective Rent | AM1: New-Lease Trade-Out Gross % | AN1: New-Lease Trade-Out Eff % | AO1: Days Vacant
A2: A101 | B2: B2_Seas | C2: 2x2 | D2: 1141 | E2: t0035267 | F2: Emely Ramirez | G2: 45998 | H2: 12 | I2: 46362 | J2: 2026-12 | K2: Rent roll (still on initial lease) | L2: 1775 | M2: 887.5 | N2: =IF(OR($L2="",$H2="",$H2=0),"",$L2-N($M2)/$H2) -> 1701.0417 | O2: RR 1/1/26 | P2: Burn-off | Q2: Not Yet Expired | AA2: =IF(OR($Y2="",$X2="",$X2=0),"",$Y2-N($Z2)/$X2) | AC2: =IF(OR($Y2="",$L2="",$L2=0),"",$Y2/$L2-1) | AD2: =IF(OR($AA2="",$N2="",$N2=0),"",$AA2/$N2-1) | AL2: =IF(OR($AJ2="",$AI2="",$AI2=0),"",$AJ2-N($AK2)/$AI2) | AM2: =IF(OR($AJ2="",$L2="",$L2=0),"",$AJ2/$L2-1) | AN2: =IF(OR($AL2="",$N2="",$N2=0),"",$AL2/$N2-1)
A3: A102 | B3: C1a_Seas | C3: 3x2 | D3: 1328 | E3: t0030269 | F3: Derek Barham | G3: 45695 | H3: 15 | I3: 46059 | J3: 2026-02 | K3: Rent roll (still on initial lease) | L3: 2130 | M3: 495 | N3: =IF(OR($L3="",$H3="",$H3=0),"",$L3-N($M3)/$H3) -> 2097 | O3: RR 1/1/26 | P3: HelloData (ask-eff x term) | Q3: Moved Out | R3: Y | S3: Y | AA3: =IF(OR($Y3="",$X3="",$X3=0),"",$Y3-N($Z3)/$X3) | AC3: =IF(OR($Y3="",$L3="",$L3=0),"",$Y3/$L3-1) | AD3: =IF(OR($AA3="",$N3="",$N3=0),"",$AA3/$N3-1) | AE3: 46059 | AF3: t0038493 | AG3: Matthew Fielder | AH3: 46133 | AI3: 12 | AJ3: 2351 | AK3: 2351 | AL3: =IF(OR($AJ3="",$AI3="",$AI3=0),"",$AJ3-N($AK3)/$AI3) -> 2155.0833 | AM3: =IF(OR($AJ3="",$L3="",$L3=0),"",$AJ3/$L3-1) -> 0.10375587 | AN3: =IF(OR($AL3="",$N3="",$N3=0),"",$AL3/$N3-1) -> 0.027698299 | AO3: 74
A4: A103 | B4: A1_Seas | C4: 1x1 | D4: 693 | E4: t0041303 | F4: Samantha Post | G4: 45960 | H4: 12 | I4: 46324 | J4: 2026-10 | K4: Rent roll (still on initial lease) | L4: 1349 | M4: 674 | N4: =IF(OR($L4="",$H4="",$H4=0),"",$L4-N($M4)/$H4) -> 1292.8333 | O4: RR 1/1/26 | P4: Burn-off | Q4: Moved Out | T4: Y | AA4: =IF(OR($Y4="",$X4="",$X4=0),"",$Y4-N($Z4)/$X4) | AC4: =IF(OR($Y4="",$L4="",$L4=0),"",$Y4/$L4-1) | AD4: =IF(OR($AA4="",$N4="",$N4=0),"",$AA4/$N4-1) | AE4: 46230 | AL4: =IF(OR($AJ4="",$AI4="",$AI4=0),"",$AJ4-N($AK4)/$AI4) | AM4: =IF(OR($AJ4="",$L4="",$L4=0),"",$AJ4/$L4-1) | AN4: =IF(OR($AL4="",$N4="",$N4=0),"",$AL4/$N4-1)
A5: A104 | B5: A2_Seas | C5: 1x1 | D5: 746 | E5: t0036159 | F5: Nancy Bain | G5: 45975 | H5: 18 | I5: 46520 | J5: 2027-05 | K5: Rent roll (still on initial lease) | L5: 1499 | M5: 0 | N5: =IF(OR($L5="",$H5="",$H5=0),"",$L5-N($M5)/$H5) -> 1499 | O5: RR 1/1/26 | P5: Burn-off | Q5: Not Yet Expired | AA5: =IF(OR($Y5="",$X5="",$X5=0),"",$Y5-N($Z5)/$X5) | AC5: =IF(OR($Y5="",$L5="",$L5=0),"",$Y5/$L5-1) | AD5: =IF(OR($AA5="",$N5="",$N5=0),"",$AA5/$N5-1) | AL5: =IF(OR($AJ5="",$AI5="",$AI5=0),"",$AJ5-N($AK5)/$AI5) | AM5: =IF(OR($AJ5="",$L5="",$L5=0),"",$AJ5/$L5-1) | AN5: =IF(OR($AL5="",$N5="",$N5=0),"",$AL5/$N5-1)
A6: A105 | B6: B1_Seas | C6: 2x2 | D6: 1092 | E6: t0031838 | F6: Weslynn Clyne | G6: 45781 | H6: 14 | I6: 46206 | J6: 2026-07 | K6: Rent roll (still on initial lease) | L6: 1885 | M6: 0 | N6: =IF(OR($L6="",$H6="",$H6=0),"",$L6-N($M6)/$H6) -> 1885 | O6: RR 1/1/26 | P6: Burn-off | Q6: Moved Out | R6: Y | S6: Y | AA6: =IF(OR($Y6="",$X6="",$X6=0),"",$Y6-N($Z6)/$X6) | AC6: =IF(OR($Y6="",$L6="",$L6=0),"",$Y6/$L6-1) | AD6: =IF(OR($AA6="",$N6="",$N6=0),"",$AA6/$N6-1) | AE6: 46206 | AF6: t0040872 | AG6: Parker Banner | AH6: 46220 | AI6: 12 | AJ6: 1924 | AK6: 0 | AL6: =IF(OR($AJ6="",$AI6="",$AI6=0),"",$AJ6-N($AK6)/$AI6) -> 1924 | AM6: =IF(OR($AJ6="",$L6="",$L6=0),"",$AJ6/$L6-1) -> 0.020689655 | AN6: =IF(OR($AL6="",$N6="",$N6=0),"",$AL6/$N6-1) -> 0.020689655 | AO6: 14
A7: A106 | B7: A1_Seas | C7: 1x1 | D7: 693 | E7: t0035645 | F7: Dominic Hanna | G7: 45957 | H7: 12 | I7: 46321 | J7: 2026-10 | K7: Rent roll (still on initial lease) | L7: 1349 | M7: 0 | N7: =IF(OR($L7="",$H7="",$H7=0),"",$L7-N($M7)/$H7) -> 1349 | O7: RR 1/1/26 | P7: Burn-off | Q7: Not Yet Expired | AA7: =IF(OR($Y7="",$X7="",$X7=0),"",$Y7-N($Z7)/$X7) | AC7: =IF(OR($Y7="",$L7="",$L7=0),"",$Y7/$L7-1) | AD7: =IF(OR($AA7="",$N7="",$N7=0),"",$AA7/$N7-1) | AL7: =IF(OR($AJ7="",$AI7="",$AI7=0),"",$AJ7-N($AK7)/$AI7) | AM7: =IF(OR($AJ7="",$L7="",$L7=0),"",$AJ7/$L7-1) | AN7: =IF(OR($AL7="",$N7="",$N7=0),"",$AL7/$N7-1)
A8: A107 | B8: B2_Seas | C8: 2x2 | D8: 1141 | E8: t0030452 | F8: Heather Orchard | G8: 45730 | H8: 15 | I8: 46094 | J8: 2026-03 | K8: Renewal lease start - 1d | L8: 1995 | M8: 495 | N8: =IF(OR($L8="",$H8="",$H8=0),"",$L8-N($M8)/$H8) -> 1962 | O8: RR 1/1/26 | P8: HelloData (ask-eff x term) | Q8: Renewed | R8: Y | S8: Y | W8: 46095 | X8: 6 | Y8: 1995 | Z8: 0 | AA8: =IF(OR($Y8="",$X8="",$X8=0),"",$Y8-N($Z8)/$X8) -> 1995 | AC8: =IF(OR($Y8="",$L8="",$L8=0),"",$Y8/$L8-1) -> 0 | AD8: =IF(OR($AA8="",$N8="",$N8=0),"",$AA8/$N8-1) -> 0.016819572 | AL8: =IF(OR($AJ8="",$AI8="",$AI8=0),"",$AJ8-N($AK8)/$AI8) | AM8: =IF(OR($AJ8="",$L8="",$L8=0),"",$AJ8/$L8-1) | AN8: =IF(OR($AL8="",$N8="",$N8=0),"",$AL8/$N8-1)
A9: A108 | B9: A1_Seas | C9: 1x1 | D9: 693 | E9: t0035973 | F9: Katrina Knox | G9: 45961 | H9: 17 | I9: 46476 | J9: 2027-03 | K9: Rent roll (still on initial lease) | L9: 1349 | M9: 674.5 | N9: =IF(OR($L9="",$H9="",$H9=0),"",$L9-N($M9)/$H9) -> 1309.3235 | O9: RR 1/1/26 | P9: Burn-off | Q9: Not Yet Expired | AA9: =IF(OR($Y9="",$X9="",$X9=0),"",$Y9-N($Z9)/$X9) | AC9: =IF(OR($Y9="",$L9="",$L9=0),"",$Y9/$L9-1) | AD9: =IF(OR($AA9="",$N9="",$N9=0),"",$AA9/$N9-1) | AL9: =IF(OR($AJ9="",$AI9="",$AI9=0),"",$AJ9-N($AK9)/$AI9) | AM9: =IF(OR($AJ9="",$L9="",$L9=0),"",$AJ9/$L9-1) | AN9: =IF(OR($AL9="",$N9="",$N9=0),"",$AL9/$N9-1)
A10: A109 | B10: A1_Seas | C10: 1x1 | D10: 693 | E10: t0034222 | F10: Gavin Edens | G10: 45882 | H10: 12 | I10: 46246 | J10: 2026-08 | K10: Rent roll (still on initial lease) | L10: 1600 | M10: 2400 | N10: =IF(OR($L10="",$H10="",$H10=0),"",$L10-N($M10)/$H10) -> 1400 | O10: RR 1/1/26 | P10: Burn-off | Q10: Not Yet Expired | AA10: =IF(OR($Y10="",$X10="",$X10=0),"",$Y10-N($Z10)/$X10) | AC10: =IF(OR($Y10="",$L10="",$L10=0),"",$Y10/$L10-1) | AD10: =IF(OR($AA10="",$N10="",$N10=0),"",$AA10/$N10-1) | AL10: =IF(OR($AJ10="",$AI10="",$AI10=0),"",$AJ10-N($AK10)/$AI10) | AM10: =IF(OR($AJ10="",$L10="",$L10=0),"",$AJ10/$L10-1) | AN10: =IF(OR($AL10="",$N10="",$N10=0),"",$AL10/$N10-1)
A11: A110 | B11: A2_Seas | C11: 1x1 | D11: 746 | E11: t0036419 | F11: Zackary Dent | G11: 46009 | H11: 18 | I11: 46555 | J11: 2027-06 | K11: Rent roll (still on initial lease) | L11: 1499 | M11: 0 | N11: =IF(OR($L11="",$H11="",$H11=0),"",$L11-N($M11)/$H11) -> 1499 | O11: RR 1/1/26 | P11: Burn-off | Q11: Not Yet Expired | AA11: =IF(OR($Y11="",$X11="",$X11=0),"",$Y11-N($Z11)/$X11) | AC11: =IF(OR($Y11="",$L11="",$L11=0),"",$Y11/$L11-1) | AD11: =IF(OR($AA11="",$N11="",$N11=0),"",$AA11/$N11-1) | AL11: =IF(OR($AJ11="",$AI11="",$AI11=0),"",$AJ11-N($AK11)/$AI11) | AM11: =IF(OR($AJ11="",$L11="",$L11=0),"",$AJ11/$L11-1) | AN11: =IF(OR($AL11="",$N11="",$N11=0),"",$AL11/$N11-1)
A12: A111 | B12: A1_Seas | C12: 1x1 | D12: 693 | E12: t0035171 | F12: Jonathan Zuniga | G12: 45936 | H12: 18 | I12: 46482 | J12: 2027-04 | K12: Rent roll (still on initial lease) | L12: 1349 | M12: 674 | N12: =IF(OR($L12="",$H12="",$H12=0),"",$L12-N($M12)/$H12) -> 1311.5556 | O12: RR 1/1/26 | P12: Burn-off | Q12: Not Yet Expired | AA12: =IF(OR($Y12="",$X12="",$X12=0),"",$Y12-N($Z12)/$X12) | AC12: =IF(OR($Y12="",$L12="",$L12=0),"",$Y12/$L12-1) | AD12: =IF(OR($AA12="",$N12="",$N12=0),"",$AA12/$N12-1) | AL12: =IF(OR($AJ12="",$AI12="",$AI12=0),"",$AJ12-N($AK12)/$AI12) | AM12: =IF(OR($AJ12="",$L12="",$L12=0),"",$AJ12/$L12-1) | AN12: =IF(OR($AL12="",$N12="",$N12=0),"",$AL12/$N12-1)
A13: A112 | B13: B3a_Seas | C13: 2x2 | D13: 1165 | E13: t0031915 | F13: Alexandria Cowles | G13: 45776 | H13: 12 | I13: 46170 | J13: 2026-05 | K13: Rent roll (still on initial lease) | L13: 1820 | M13: 1824 | N13: =IF(OR($L13="",$H13="",$H13=0),"",$L13-N($M13)/$H13) -> 1668 | O13: RR 1/1/26 | P13: HelloData (ask-eff x term) | Q13: Moved Out | R13: Y | S13: Y | AA13: =IF(OR($Y13="",$X13="",$X13=0),"",$Y13-N($Z13)/$X13) | AC13: =IF(OR($Y13="",$L13="",$L13=0),"",$Y13/$L13-1) | AD13: =IF(OR($AA13="",$N13="",$N13=0),"",$AA13/$N13-1) | AE13: 46170 | AL13: =IF(OR($AJ13="",$AI13="",$AI13=0),"",$AJ13-N($AK13)/$AI13) | AM13: =IF(OR($AJ13="",$L13="",$L13=0),"",$AJ13/$L13-1) | AN13: =IF(OR($AL13="",$N13="",$N13=0),"",$AL13/$N13-1)
A14: A113 | B14: B3a_Seas | C14: 2x2 | D14: 1165 | E14: t0032535 | F14: Simone Thompson | G14: 45829 | H14: 12 | I14: 46193 | J14: 2026-06 | K14: Rent roll (still on initial lease) | L14: 1885 | M14: 2827 | N14: =IF(OR($L14="",$H14="",$H14=0),"",$L14-N($M14)/$H14) -> 1649.4167 | O14: RR 1/1/26 | P14: Burn-off | Q14: Moved Out | R14: Y | S14: Y | AA14: =IF(OR($Y14="",$X14="",$X14=0),"",$Y14-N($Z14)/$X14) | AC14: =IF(OR($Y14="",$L14="",$L14=0),"",$Y14/$L14-1) | AD14: =IF(OR($AA14="",$N14="",$N14=0),"",$AA14/$N14-1) | AE14: 46223 | AF14: t0042564 | AG14: Jabier Flores Garcia | AH14: 46232 | AI14: 18 | AJ14: 2117 | AK14: 0 | AL14: =IF(OR($AJ14="",$AI14="",$AI14=0),"",$AJ14-N($AK14)/$AI14) -> 2117 | AM14: =IF(OR($AJ14="",$L14="",$L14=0),"",$AJ14/$L14-1) -> 0.12307692 | AN14: =IF(OR($AL14="",$N14="",$N14=0),"",$AL14/$N14-1) -> 0.28348406 | AO14: 9
A15: A201 | B15: B2_Seas | C15: 2x2 | D15: 1141 | E15: t0033545 | F15: Alan Khan | G15: 45852 | H15: 12 | I15: 46216 | J15: 2026-07 | K15: Rent roll (still on initial lease) | L15: 1869 | M15: 1869 | N15: =IF(OR($L15="",$H15="",$H15=0),"",$L15-N($M15)/$H15) -> 1713.25 | O15: RR 1/1/26 | P15: Burn-off | Q15: Moved Out | R15: Y | S15: Y | AA15: =IF(OR($Y15="",$X15="",$X15=0),"",$Y15-N($Z15)/$X15) | AC15: =IF(OR($Y15="",$L15="",$L15=0),"",$Y15/$L15-1) | AD15: =IF(OR($AA15="",$N15="",$N15=0),"",$AA15/$N15-1) | AE15: 46216 | AF15: t0040592 | AG15: Katelyn Greenwald | AH15: 46232 | AI15: 12 | AJ15: 2070 | AK15: 0 | AL15: =IF(OR($AJ15="",$AI15="",$AI15=0),"",$AJ15-N($AK15)/$AI15) -> 2070 | AM15: =IF(OR($AJ15="",$L15="",$L15=0),"",$AJ15/$L15-1) -> 0.10754414 | AN15: =IF(OR($AL15="",$N15="",$N15=0),"",$AL15/$N15-1) -> 0.20822997 | AO15: 16
A16: A202 | B16: C1b_Seas | C16: 3x2 | D16: 1340 | E16: t0029908 | F16: Alexandra McKenzie | G16: 45682 | H16: 15 | I16: 46105 | J16: 2026-03 | K16: Renewal lease start - 1d | L16: 2055 | M16: 495 | N16: =IF(OR($L16="",$H16="",$H16=0),"",$L16-N($M16)/$H16) -> 2022 | O16: RR 1/1/26 | P16: HelloData (ask-eff x term) | Q16: Renewed | R16: Y | S16: Y | W16: 46106 | X16: 12 | Y16: 2055 | Z16: 0 | AA16: =IF(OR($Y16="",$X16="",$X16=0),"",$Y16-N($Z16)/$X16) -> 2055 | AC16: =IF(OR($Y16="",$L16="",$L16=0),"",$Y16/$L16-1) -> 0 | AD16: =IF(OR($AA16="",$N16="",$N16=0),"",$AA16/$N16-1) -> 0.016320475 | AL16: =IF(OR($AJ16="",$AI16="",$AI16=0),"",$AJ16-N($AK16)/$AI16) | AM16: =IF(OR($AJ16="",$L16="",$L16=0),"",$AJ16/$L16-1) | AN16: =IF(OR($AL16="",$N16="",$N16=0),"",$AL16/$N16-1)
A17: A203 | B17: A1_Seas | C17: 1x1 | D17: 693 | E17: t0037105 | F17: Malik Sullivan | G17: 45708 | H17: 15 | I17: 46131 | J17: 2026-04 | K17: Rent roll (still on initial lease) | L17: 1410 | M17: 495 | N17: =IF(OR($L17="",$H17="",$H17=0),"",$L17-N($M17)/$H17) -> 1377 | O17: RR 1/1/26 | P17: HelloData (ask-eff x term) | Q17: Moved Out | R17: Y | S17: Y | T17: Y | AA17: =IF(OR($Y17="",$X17="",$X17=0),"",$Y17-N($Z17)/$X17) | AC17: =IF(OR($Y17="",$L17="",$L17=0),"",$Y17/$L17-1) | AD17: =IF(OR($AA17="",$N17="",$N17=0),"",$AA17/$N17-1) | AE17: 46062 | AF17: t0038410 | AG17: Dakotah Brown | AH17: 46092 | AI17: 12 | AJ17: 1490 | AK17: 0 | AL17: =IF(OR($AJ17="",$AI17="",$AI17=0),"",$AJ17-N($AK17)/$AI17) -> 1490 | AM17: =IF(OR($AJ17="",$L17="",$L17=0),"",$AJ17/$L17-1) -> 0.056737589 | AN17: =IF(OR($AL17="",$N17="",$N17=0),"",$AL17/$N17-1) -> 0.082062455 | AO17: 30
A18: A204 | B18: A2_Seas | C18: 1x1 | D18: 746 | E18: t0028992 | F18: Kristine Campagni | G18: 45673 | H18: 18 | I18: 46219 | J18: 2026-07 | K18: Rent roll (still on initial lease) | L18: 1664 | M18: 1664 | N18: =IF(OR($L18="",$H18="",$H18=0),"",$L18-N($M18)/$H18) -> 1571.5556 | O18: RR 1/1/26 | P18: Burn-off | Q18: MTM Holdover | R18: Y | S18: Y | AA18: =IF(OR($Y18="",$X18="",$X18=0),"",$Y18-N($Z18)/$X18) | AC18: =IF(OR($Y18="",$L18="",$L18=0),"",$Y18/$L18-1) | AD18: =IF(OR($AA18="",$N18="",$N18=0),"",$AA18/$N18-1) | AL18: =IF(OR($AJ18="",$AI18="",$AI18=0),"",$AJ18-N($AK18)/$AI18) | AM18: =IF(OR($AJ18="",$L18="",$L18=0),"",$AJ18/$L18-1) | AN18: =IF(OR($AL18="",$N18="",$N18=0),"",$AL18/$N18-1)
A19: A205 | B19: B1_Seas | C19: 2x2 | D19: 1092 | E19: t0030425 | F19: Katie Crook | G19: 45744 | H19: 15 | I19: 46049 | J19: 2026-01 | K19: Rent roll (still on initial lease) | L19: 1715 | M19: 495 | N19: =IF(OR($L19="",$H19="",$H19=0),"",$L19-N($M19)/$H19) -> 1682 | O19: RR 1/1/26 | P19: HelloData (ask-eff x term) | Q19: Moved Out | R19: Y | S19: Y | AA19: =IF(OR($Y19="",$X19="",$X19=0),"",$Y19-N($Z19)/$X19) | AC19: =IF(OR($Y19="",$L19="",$L19=0),"",$Y19/$L19-1) | AD19: =IF(OR($AA19="",$N19="",$N19=0),"",$AA19/$N19-1) | AE19: 46053 | AF19: t0031017 | AG19: Michael Saffery Hoopii | AH19: 46073 | AI19: 18 | AJ19: 1799 | AK19: 0 | AL19: =IF(OR($AJ19="",$AI19="",$AI19=0),"",$AJ19-N($AK19)/$AI19) -> 1799 | AM19: =IF(OR($AJ19="",$L19="",$L19=0),"",$AJ19/$L19-1) -> 0.048979592 | AN19: =IF(OR($AL19="",$N19="",$N19=0),"",$AL19/$N19-1) -> 0.069560048 | AO19: 20
A20: A206 | B20: A1_Seas | C20: 1x1 | D20: 693 | E20: t0036235 | F20: Lukas Holloman | G20: 46001 | H20: 12 | I20: 46365 | J20: 2026-12 | K20: Rent roll (still on initial lease) | L20: 1399 | M20: 0 | N20: =IF(OR($L20="",$H20="",$H20=0),"",$L20-N($M20)/$H20) -> 1399 | O20: RR 1/1/26 | P20: Burn-off | Q20: Not Yet Expired | AA20: =IF(OR($Y20="",$X20="",$X20=0),"",$Y20-N($Z20)/$X20) | AC20: =IF(OR($Y20="",$L20="",$L20=0),"",$Y20/$L20-1) | AD20: =IF(OR($AA20="",$N20="",$N20=0),"",$AA20/$N20-1) | AL20: =IF(OR($AJ20="",$AI20="",$AI20=0),"",$AJ20-N($AK20)/$AI20) | AM20: =IF(OR($AJ20="",$L20="",$L20=0),"",$AJ20/$L20-1) | AN20: =IF(OR($AL20="",$N20="",$N20=0),"",$AL20/$N20-1)
A21: A207 | B21: B2_Seas | C21: 2x2 | D21: 1141 | E21: t0034692 | F21: Amy Brading | G21: 45904 | H21: 12 | I21: 46268 | J21: 2026-09 | K21: Rent roll (still on initial lease) | L21: 1919 | M21: 1919 | N21: =IF(OR($L21="",$H21="",$H21=0),"",$L21-N($M21)/$H21) -> 1759.0833 | O21: RR 1/1/26 | P21: Burn-off | Q21: Not Yet Expired | U21: Y | AA21: =IF(OR($Y21="",$X21="",$X21=0),"",$Y21-N($Z21)/$X21) | AC21: =IF(OR($Y21="",$L21="",$L21=0),"",$Y21/$L21-1) | AD21: =IF(OR($AA21="",$N21="",$N21=0),"",$AA21/$N21-1) | AL21: =IF(OR($AJ21="",$AI21="",$AI21=0),"",$AJ21-N($AK21)/$AI21) | AM21: =IF(OR($AJ21="",$L21="",$L21=0),"",$AJ21/$L21-1) | AN21: =IF(OR($AL21="",$N21="",$N21=0),"",$AL21/$N21-1)
A22: A208 | B22: A1_Seas | C22: 1x1 | D22: 693 | E22: t0035813 | F22: Dylan Croner | G22: 45957 | H22: 12 | I22: 46321 | J22: 2026-10 | K22: Rent roll (still on initial lease) | L22: 1349 | M22: 674.5 | N22: =IF(OR($L22="",$H22="",$H22=0),"",$L22-N($M22)/$H22) -> 1292.7917 | O22: RR 1/1/26 | P22: Burn-off | Q22: Not Yet Expired | AA22: =IF(OR($Y22="",$X22="",$X22=0),"",$Y22-N($Z22)/$X22) | AC22: =IF(OR($Y22="",$L22="",$L22=0),"",$Y22/$L22-1) | AD22: =IF(OR($AA22="",$N22="",$N22=0),"",$AA22/$N22-1) | AL22: =IF(OR($AJ22="",$AI22="",$AI22=0),"",$AJ22-N($AK22)/$AI22) | AM22: =IF(OR($AJ22="",$L22="",$L22=0),"",$AJ22/$L22-1) | AN22: =IF(OR($AL22="",$N22="",$N22=0),"",$AL22/$N22-1)
A23: A209 | B23: A1_Seas | C23: 1x1 | D23: 693 | E23: t0035239 | F23: Emily Bonner | G23: 45971 | H23: 12 | I23: 46335 | J23: 2026-11 | K23: Rent roll (still on initial lease) | L23: 1399 | M23: 0 | N23: =IF(OR($L23="",$H23="",$H23=0),"",$L23-N($M23)/$H23) -> 1399 | O23: RR 1/1/26 | P23: Burn-off | Q23: Not Yet Expired | AA23: =IF(OR($Y23="",$X23="",$X23=0),"",$Y23-N($Z23)/$X23) | AC23: =IF(OR($Y23="",$L23="",$L23=0),"",$Y23/$L23-1) | AD23: =IF(OR($AA23="",$N23="",$N23=0),"",$AA23/$N23-1) | AL23: =IF(OR($AJ23="",$AI23="",$AI23=0),"",$AJ23-N($AK23)/$AI23) | AM23: =IF(OR($AJ23="",$L23="",$L23=0),"",$AJ23/$L23-1) | AN23: =IF(OR($AL23="",$N23="",$N23=0),"",$AL23/$N23-1)
A24: A210 | B24: A2_Seas | C24: 1x1 | D24: 746 | E24: t0036709 | F24: PAYDEN WARNER | G24: 45913 | H24: 12 | I24: 46277 | J24: 2026-09 | K24: Rent roll (still on initial lease) | L24: 1694 | M24: 3384 | N24: =IF(OR($L24="",$H24="",$H24=0),"",$L24-N($M24)/$H24) -> 1412 | O24: RR 1/1/26 | P24: HelloData (ask-eff x term) | Q24: Moved Out | T24: Y | AA24: =IF(OR($Y24="",$X24="",$X24=0),"",$Y24-N($Z24)/$X24) | AC24: =IF(OR($Y24="",$L24="",$L24=0),"",$Y24/$L24-1) | AD24: =IF(OR($AA24="",$N24="",$N24=0),"",$AA24/$N24-1) | AE24: 46024 | AF24: t0037724 | AG24: Edward Gorman | AH24: 46071 | AI24: 9 | AJ24: 1644 | AK24: 0 | AL24: =IF(OR($AJ24="",$AI24="",$AI24=0),"",$AJ24-N($AK24)/$AI24) -> 1644 | AM24: =IF(OR($AJ24="",$L24="",$L24=0),"",$AJ24/$L24-1) -> -0.029515939 | AN24: =IF(OR($AL24="",$N24="",$N24=0),"",$AL24/$N24-1) -> 0.16430595 | AO24: 47
A25: A211 | B25: A1_Seas | C25: 1x1 | D25: 693 | E25: t0031285 | F25: Jaime Valdez | G25: 45772 | H25: 13 | I25: 46166 | J25: 2026-05 | K25: Renewal report | L25: 1520 | M25: 2280 | N25: =IF(OR($L25="",$H25="",$H25=0),"",$L25-N($M25)/$H25) -> 1344.6154 | O25: RR 1/1/26 | P25: Renewal report | Q25: Renewed | R25: Y | S25: Y | W25: 46167 | X25: 11 | Y25: 1570 | Z25: 0 | AA25: =IF(OR($Y25="",$X25="",$X25=0),"",$Y25-N($Z25)/$X25) -> 1570 | AB25: Y | AC25: =IF(OR($Y25="",$L25="",$L25=0),"",$Y25/$L25-1) -> 0.032894737 | AD25: =IF(OR($AA25="",$N25="",$N25=0),"",$AA25/$N25-1) -> 0.16762014 | AL25: =IF(OR($AJ25="",$AI25="",$AI25=0),"",$AJ25-N($AK25)/$AI25) | AM25: =IF(OR($AJ25="",$L25="",$L25=0),"",$AJ25/$L25-1) | AN25: =IF(OR($AL25="",$N25="",$N25=0),"",$AL25/$N25-1)
A26: A212 | B26: B3b_Seas | C26: 2x2 | D26: 1177 | E26: t0034758 | F26: PAYDEN WARNER | G26: 46022 | H26: 12 | I26: 46386 | J26: 2026-12 | K26: Rent roll (still on initial lease) | L26: 1999 | M26: 0 | N26: =IF(OR($L26="",$H26="",$H26=0),"",$L26-N($M26)/$H26) -> 1999 | O26: RR 1/1/26 | P26: Burn-off | Q26: Not Yet Expired | AA26: =IF(OR($Y26="",$X26="",$X26=0),"",$Y26-N($Z26)/$X26) | AC26: =IF(OR($Y26="",$L26="",$L26=0),"",$Y26/$L26-1) | AD26: =IF(OR($AA26="",$N26="",$N26=0),"",$AA26/$N26-1) | AL26: =IF(OR($AJ26="",$AI26="",$AI26=0),"",$AJ26-N($AK26)/$AI26) | AM26: =IF(OR($AJ26="",$L26="",$L26=0),"",$AJ26/$L26-1) | AN26: =IF(OR($AL26="",$N26="",$N26=0),"",$AL26/$N26-1)
A27: A213 | B27: B3b_Seas | C27: 2x2 | D27: 1177 | E27: t0035698 | F27: Silviu Apostu | G27: 45969 | H27: 12 | I27: 46333 | J27: 2026-11 | K27: Rent roll (still on initial lease) | L27: 1800 | M27: 900 | N27: =IF(OR($L27="",$H27="",$H27=0),"",$L27-N($M27)/$H27) -> 1725 | O27: RR 1/1/26 | P27: Burn-off | Q27: Not Yet Expired | AA27: =IF(OR($Y27="",$X27="",$X27=0),"",$Y27-N($Z27)/$X27) | AC27: =IF(OR($Y27="",$L27="",$L27=0),"",$Y27/$L27-1) | AD27: =IF(OR($AA27="",$N27="",$N27=0),"",$AA27/$N27-1) | AL27: =IF(OR($AJ27="",$AI27="",$AI27=0),"",$AJ27-N($AK27)/$AI27) | AM27: =IF(OR($AJ27="",$L27="",$L27=0),"",$AJ27/$L27-1) | AN27: =IF(OR($AL27="",$N27="",$N27=0),"",$AL27/$N27-1)
A28: A301 | B28: B2_Seas | C28: 2x2 | D28: 1141 | E28: t0034549 | F28: Roberto Magana | G28: 45924 | H28: 12 | I28: 46288 | J28: 2026-09 | K28: Rent roll (still on initial lease) | L28: 1954 | M28: 1954 | N28: =IF(OR($L28="",$H28="",$H28=0),"",$L28-N($M28)/$H28) -> 1791.1667 | O28: RR 1/1/26 | P28: Burn-off | Q28: Not Yet Expired | U28: Y | AA28: =IF(OR($Y28="",$X28="",$X28=0),"",$Y28-N($Z28)/$X28) | AC28: =IF(OR($Y28="",$L28="",$L28=0),"",$Y28/$L28-1) | AD28: =IF(OR($AA28="",$N28="",$N28=0),"",$AA28/$N28-1) | AL28: =IF(OR($AJ28="",$AI28="",$AI28=0),"",$AJ28-N($AK28)/$AI28) | AM28: =IF(OR($AJ28="",$L28="",$L28=0),"",$AJ28/$L28-1) | AN28: =IF(OR($AL28="",$N28="",$N28=0),"",$AL28/$N28-1)
A29: A303 | B29: A1_Seas | C29: 1x1 | D29: 693 | E29: t0035188 | F29: Samantha Rodriguez | G29: 45960 | H29: 18 | I29: 46506 | J29: 2027-04 | K29: Rent roll (still on initial lease) | L29: 1349 | M29: 674 | N29: =IF(OR($L29="",$H29="",$H29=0),"",$L29-N($M29)/$H29) -> 1311.5556 | O29: RR 1/1/26 | P29: Burn-off | Q29: Not Yet Expired | U29: Y | AA29: =IF(OR($Y29="",$X29="",$X29=0),"",$Y29-N($Z29)/$X29) | AC29: =IF(OR($Y29="",$L29="",$L29=0),"",$Y29/$L29-1) | AD29: =IF(OR($AA29="",$N29="",$N29=0),"",$AA29/$N29-1) | AL29: =IF(OR($AJ29="",$AI29="",$AI29=0),"",$AJ29-N($AK29)/$AI29) | AM29: =IF(OR($AJ29="",$L29="",$L29=0),"",$AJ29/$L29-1) | AN29: =IF(OR($AL29="",$N29="",$N29=0),"",$AL29/$N29-1)
A30: A304 | B30: A2_Seas | C30: 1x1 | D30: 746 | E30: t0030795 | F30: Joseph Castillo | G30: 45763 | H30: 15 | I30: 46218 | J30: 2026-07 | K30: Rent roll (still on initial lease) | L30: 1689 | M30: 2533 | N30: =IF(OR($L30="",$H30="",$H30=0),"",$L30-N($M30)/$H30) -> 1520.1333 | O30: RR 1/1/26 | P30: Burn-off | Q30: Moved Out | R30: Y | S30: Y | AA30: =IF(OR($Y30="",$X30="",$X30=0),"",$Y30-N($Z30)/$X30) | AC30: =IF(OR($Y30="",$L30="",$L30=0),"",$Y30/$L30-1) | AD30: =IF(OR($AA30="",$N30="",$N30=0),"",$AA30/$N30-1) | AE30: 46218 | AF30: t0042429 | AG30: Sriharsha Kolla | AH30: 46228 | AI30: 12 | AJ30: 1869 | AK30: 0 | AL30: =IF(OR($AJ30="",$AI30="",$AI30=0),"",$AJ30-N($AK30)/$AI30) -> 1869 | AM30: =IF(OR($AJ30="",$L30="",$L30=0),"",$AJ30/$L30-1) -> 0.10657194 | AN30: =IF(OR($AL30="",$N30="",$N30=0),"",$AL30/$N30-1) -> 0.22949741 | AO30: 10
A31: A305 | B31: B1_Seas | C31: 2x2 | D31: 1092 | E31: t0032547 | F31: Johnny Harris | G31: 45804 | H31: 12 | I31: 46168 | J31: 2026-05 | K31: Renewal report | L31: 1995 | M31: 3989.5 | N31: =IF(OR($L31="",$H31="",$H31=0),"",$L31-N($M31)/$H31) -> 1662.5417 | O31: RR 1/1/26 | P31: Renewal report | Q31: Renewed | R31: Y | S31: Y | W31: 46169 | X31: 13 | Y31: 1995 | Z31: 997.5 | AA31: =IF(OR($Y31="",$X31="",$X31=0),"",$Y31-N($Z31)/$X31) -> 1918.2692 | AB31: Y | AC31: =IF(OR($Y31="",$L31="",$L31=0),"",$Y31/$L31-1) -> 0 | AD31: =IF(OR($AA31="",$N31="",$N31=0),"",$AA31/$N31-1) -> 0.15381724 | AL31: =IF(OR($AJ31="",$AI31="",$AI31=0),"",$AJ31-N($AK31)/$AI31) | AM31: =IF(OR($AJ31="",$L31="",$L31=0),"",$AJ31/$L31-1) | AN31: =IF(OR($AL31="",$N31="",$N31=0),"",$AL31/$N31-1)
A32: A306 | B32: A1_Seas | C32: 1x1 | D32: 693 | E32: t0035738 | F32: Lillyan Dunlap | G32: 45961 | H32: 12 | I32: 46325 | J32: 2026-10 | K32: Rent roll (still on initial lease) | L32: 1349 | M32: 0 | N32: =IF(OR($L32="",$H32="",$H32=0),"",$L32-N($M32)/$H32) -> 1349 | O32: RR 1/1/26 | P32: Burn-off | Q32: Not Yet Expired | AA32: =IF(OR($Y32="",$X32="",$X32=0),"",$Y32-N($Z32)/$X32) | AC32: =IF(OR($Y32="",$L32="",$L32=0),"",$Y32/$L32-1) | AD32: =IF(OR($AA32="",$N32="",$N32=0),"",$AA32/$N32-1) | AL32: =IF(OR($AJ32="",$AI32="",$AI32=0),"",$AJ32-N($AK32)/$AI32) | AM32: =IF(OR($AJ32="",$L32="",$L32=0),"",$AJ32/$L32-1) | AN32: =IF(OR($AL32="",$N32="",$N32=0),"",$AL32/$N32-1)
A33: A307 | B33: B2_Seas | C33: 2x2 | D33: 1141 | E33: t0029257 | F33: Nicholas Sleyko | G33: 45674 | H33: 12 | I33: 46219 | J33: 2026-07 | K33: Renewal lease start - 1d | L33: 2020 | M33: 3732 | N33: =IF(OR($L33="",$H33="",$H33=0),"",$L33-N($M33)/$H33) -> 1709 | O33: RR 1/1/26 | P33: HelloData (ask-eff x term) | Q33: Renewed | R33: Y | S33: Y | W33: 46220 | X33: 12 | Y33: 2058 | Z33: 0 | AA33: =IF(OR($Y33="",$X33="",$X33=0),"",$Y33-N($Z33)/$X33) -> 2058 | AC33: =IF(OR($Y33="",$L33="",$L33=0),"",$Y33/$L33-1) -> 0.018811881 | AD33: =IF(OR($AA33="",$N33="",$N33=0),"",$AA33/$N33-1) -> 0.20421299 | AL33: =IF(OR($AJ33="",$AI33="",$AI33=0),"",$AJ33-N($AK33)/$AI33) | AM33: =IF(OR($AJ33="",$L33="",$L33=0),"",$AJ33/$L33-1) | AN33: =IF(OR($AL33="",$N33="",$N33=0),"",$AL33/$N33-1)
A34: A310 | B34: A2_Seas | C34: 1x1 | D34: 746 | E34: t0029775 | F34: Leah Walborn | G34: 45717 | H34: 18 | I34: 46265 | J34: 2026-08 | K34: Rent roll (still on initial lease) | L34: 1689 | M34: 0 | N34: =IF(OR($L34="",$H34="",$H34=0),"",$L34-N($M34)/$H34) -> 1689 | O34: RR 1/1/26 | P34: Burn-off | Q34: Not Yet Expired | AA34: =IF(OR($Y34="",$X34="",$X34=0),"",$Y34-N($Z34)/$X34) | AC34: =IF(OR($Y34="",$L34="",$L34=0),"",$Y34/$L34-1) | AD34: =IF(OR($AA34="",$N34="",$N34=0),"",$AA34/$N34-1) | AL34: =IF(OR($AJ34="",$AI34="",$AI34=0),"",$AJ34-N($AK34)/$AI34) | AM34: =IF(OR($AJ34="",$L34="",$L34=0),"",$AJ34/$L34-1) | AN34: =IF(OR($AL34="",$N34="",$N34=0),"",$AL34/$N34-1)
A35: A312 | B35: B3b_Seas | C35: 2x2 | D35: 1177 | E35: t0030987 | F35: Natalle Wallace | G35: 45744 | H35: 12 | I35: 46292 | J35: 2026-09 | K35: Rent roll (still on initial lease) | L35: 1770 | M35: 2448 | N35: =IF(OR($L35="",$H35="",$H35=0),"",$L35-N($M35)/$H35) -> 1566 | O35: RR 1/1/26 | P35: HelloData (ask-eff x term) | Q35: Moved Out | T35: Y | AA35: =IF(OR($Y35="",$X35="",$X35=0),"",$Y35-N($Z35)/$X35) | AC35: =IF(OR($Y35="",$L35="",$L35=0),"",$Y35/$L35-1) | AD35: =IF(OR($AA35="",$N35="",$N35=0),"",$AA35/$N35-1) | AE35: 46053 | AF35: t0037719 | AG35: Madeline Schmitt | AH35: 46093 | AI35: 12 | AJ35: 1850 | AK35: 0 | AL35: =IF(OR($AJ35="",$AI35="",$AI35=0),"",$AJ35-N($AK35)/$AI35) -> 1850 | AM35: =IF(OR($AJ35="",$L35="",$L35=0),"",$AJ35/$L35-1) -> 0.04519774 | AN35: =IF(OR($AL35="",$N35="",$N35=0),"",$AL35/$N35-1) -> 0.18135377 | AO35: 40
A36: A313 | B36: B3b_Seas | C36: 2x2 | D36: 1177 | E36: t0031035 | F36: Paul Bockstedt III | G36: 45754 | H36: 13 | I36: 46148 | J36: 2026-05 | K36: Rent roll (still on initial lease) | L36: 1935 | M36: 2902.5 | N36: =IF(OR($L36="",$H36="",$H36=0),"",$L36-N($M36)/$H36) -> 1711.7308 | O36: RR 1/1/26 | P36: Burn-off | Q36: MTM Holdover | R36: Y | S36: Y | AA36: =IF(OR($Y36="",$X36="",$X36=0),"",$Y36-N($Z36)/$X36) | AC36: =IF(OR($Y36="",$L36="",$L36=0),"",$Y36/$L36-1) | AD36: =IF(OR($AA36="",$N36="",$N36=0),"",$AA36/$N36-1) | AL36: =IF(OR($AJ36="",$AI36="",$AI36=0),"",$AJ36-N($AK36)/$AI36) | AM36: =IF(OR($AJ36="",$L36="",$L36=0),"",$AJ36/$L36-1) | AN36: =IF(OR($AL36="",$N36="",$N36=0),"",$AL36/$N36-1)
A37: B101 | B37: B2_Seas | C37: 2x2 | D37: 1141 | E37: t0029806 | F37: Joseph Dobson | G37: 45694 | H37: 18 | I37: 46239 | J37: 2026-08 | K37: Rent roll (still on initial lease) | L37: 1845 | M37: 0 | N37: =IF(OR($L37="",$H37="",$H37=0),"",$L37-N($M37)/$H37) -> 1845 | O37: RR 1/1/26 | P37: Burn-off | Q37: Not Yet Expired | AA37: =IF(OR($Y37="",$X37="",$X37=0),"",$Y37-N($Z37)/$X37) | AC37: =IF(OR($Y37="",$L37="",$L37=0),"",$Y37/$L37-1) | AD37: =IF(OR($AA37="",$N37="",$N37=0),"",$AA37/$N37-1) | AL37: =IF(OR($AJ37="",$AI37="",$AI37=0),"",$AJ37-N($AK37)/$AI37) | AM37: =IF(OR($AJ37="",$L37="",$L37=0),"",$AJ37/$L37-1) | AN37: =IF(OR($AL37="",$N37="",$N37=0),"",$AL37/$N37-1)
A38: B102 | B38: B3a_Seas | C38: 2x2 | D38: 1165 | E38: t0038568 | F38: Christopher Dante | G38: 45813 | H38: 12 | I38: 46360 | J38: 2026-12 | K38: Rent roll (still on initial lease) | L38: 1820 | M38: 2520 | N38: =IF(OR($L38="",$H38="",$H38=0),"",$L38-N($M38)/$H38) -> 1610 | O38: RR 1/1/26 | P38: HelloData (ask-eff x term) | Q38: Moved Out | T38: Y | AA38: =IF(OR($Y38="",$X38="",$X38=0),"",$Y38-N($Z38)/$X38) | AC38: =IF(OR($Y38="",$L38="",$L38=0),"",$Y38/$L38-1) | AD38: =IF(OR($AA38="",$N38="",$N38=0),"",$AA38/$N38-1) | AE38: 46112 | AF38: t0035749 | AG38: Scott Pardew | AH38: 46122 | AI38: 12 | AJ38: 2045 | AK38: 0 | AL38: =IF(OR($AJ38="",$AI38="",$AI38=0),"",$AJ38-N($AK38)/$AI38) -> 2045 | AM38: =IF(OR($AJ38="",$L38="",$L38=0),"",$AJ38/$L38-1) -> 0.12362637 | AN38: =IF(OR($AL38="",$N38="",$N38=0),"",$AL38/$N38-1) -> 0.27018634 | AO38: 10
A39: B103 | B39: A1_Seas | C39: 1x1 | D39: 693 | E39: t0031260 | F39: Kevin Dustin | G39: 45762 | H39: 22 | I39: 46432 | J39: 2027-02 | K39: Rent roll (still on initial lease) | L39: 1510 | M39: 2265 | N39: =IF(OR($L39="",$H39="",$H39=0),"",$L39-N($M39)/$H39) -> 1407.0455 | O39: RR 1/1/26 | P39: Burn-off | Q39: Not Yet Expired | AA39: =IF(OR($Y39="",$X39="",$X39=0),"",$Y39-N($Z39)/$X39) | AC39: =IF(OR($Y39="",$L39="",$L39=0),"",$Y39/$L39-1) | AD39: =IF(OR($AA39="",$N39="",$N39=0),"",$AA39/$N39-1) | AL39: =IF(OR($AJ39="",$AI39="",$AI39=0),"",$AJ39-N($AK39)/$AI39) | AM39: =IF(OR($AJ39="",$L39="",$L39=0),"",$AJ39/$L39-1) | AN39: =IF(OR($AL39="",$N39="",$N39=0),"",$AL39/$N39-1)
A40: B105 | B40: A1_Seas | C40: 1x1 | D40: 693 | E40: t0038003 | F40: Mariana Luna | G40: 45680 | H40: 18 | I40: 46225 | J40: 2026-07 | K40: Rent roll (still on initial lease) | L40: 1425 | M40: 0 | N40: =IF(OR($L40="",$H40="",$H40=0),"",$L40-N($M40)/$H40) -> 1425 | O40: RR 1/1/26 | P40: Burn-off | Q40: Moved Out | R40: Y | S40: Y | AA40: =IF(OR($Y40="",$X40="",$X40=0),"",$Y40-N($Z40)/$X40) | AC40: =IF(OR($Y40="",$L40="",$L40=0),"",$Y40/$L40-1) | AD40: =IF(OR($AA40="",$N40="",$N40=0),"",$AA40/$N40-1) | AE40: 46225 | AF40: t0041407 | AG40: Paragon Corporate Housing | AH40: 46232 | AI40: 9 | AJ40: 1678 | AK40: 0 | AL40: =IF(OR($AJ40="",$AI40="",$AI40=0),"",$AJ40-N($AK40)/$AI40) -> 1678 | AM40: =IF(OR($AJ40="",$L40="",$L40=0),"",$AJ40/$L40-1) -> 0.17754386 | AN40: =IF(OR($AL40="",$N40="",$N40=0),"",$AL40/$N40-1) -> 0.17754386 | AO40: 7
...

Sheet By Floor Plan
A1: Group | B1: Cohort Units | C1: Expirations Due | D1: Renewed | E1: Moved Out | F1: MTM | G1: Retention % | H1: Avg Initial Gross | I1: Renewal TO Gross % | J1: Renewal TO Eff % | K1: New-Lease TO Gross % | L1: New-Lease TO Eff %
A2: A1_Seas | B2: =COUNTIF('Unit Ledger'!$B$2:$B$315,"A1_Seas") -> 108 | C2: =D2+E2+F2 -> 49 | D2: =COUNTIFS('Unit Ledger'!$B$2:$B$315,"A1_Seas",'Unit Ledger'!$S$2:$S$315,"Y",'Unit Ledger'!$Q$2:$Q$315,"Renewed") -> 25 | E2: =COUNTIFS('Unit Ledger'!$B$2:$B$315,"A1_Seas",'Unit Ledger'!$S$2:$S$315,"Y",'Unit Ledger'!$Q$2:$Q$315,"Moved Out") -> 23 | F2: =COUNTIFS('Unit Ledger'!$B$2:$B$315,"A1_Seas",'Unit Ledger'!$S$2:$S$315,"Y",'Unit Ledger'!$Q$2:$Q$315,"MTM Holdover") -> 1 | G2: =IF(C2=0,"",D2/C2) -> 0.51020408 | H2: =IFERROR(AVERAGEIFS('Unit Ledger'!$L$2:$L$315,'Unit Ledger'!$Q$2:$Q$315,"<>zz",'Unit Ledger'!$B$2:$B$315,"A1_Seas"),"") -> 1457.2037 | I2: =IFERROR(AVERAGEIFS('Unit Ledger'!$AC$2:$AC$315,'Unit Ledger'!$Q$2:$Q$315,"Renewed",'Unit Ledger'!$V$2:$V$315,"<>Y",'Unit Ledger'!$B$2:$B$315,"A1_Seas"),"") -> 0.015513322 | J2: =IFERROR(AVERAGEIFS('Unit Ledger'!$AD$2:$AD$315,'Unit Ledger'!$Q$2:$Q$315,"Renewed",'Unit Ledger'!$V$2:$V$315,"<>Y",'Unit Ledger'!$B$2:$B$315,"A1_Seas"),"") -> 0.10125143 | K2: =IFERROR(AVERAGEIFS('Unit Ledger'!$AM$2:$AM$315,'Unit Ledger'!$Q$2:$Q$315,"Moved Out",'Unit Ledger'!$V$2:$V$315,"<>Y",'Unit Ledger'!$B$2:$B$315,"A1_Seas"),"") -> 0.060345481 | L2: =IFERROR(AVERAGEIFS('Unit Ledger'!$AN$2:$AN$315,'Unit Ledger'!$Q$2:$Q$315,"Moved Out",'Unit Ledger'!$V$2:$V$315,"<>Y",'Unit Ledger'!$B$2:$B$315,"A1_Seas"),"") -> 0.1313323
A3: A2_Seas | B3: =COUNTIF('Unit Ledger'!$B$2:$B$315,"A2_Seas") -> 32 | C3: =D3+E3+F3 -> 14 | D3: =COUNTIFS('Unit Ledger'!$B$2:$B$315,"A2_Seas",'Unit Ledger'!$S$2:$S$315,"Y",'Unit Ledger'!$Q$2:$Q$315,"Renewed") -> 3 | E3: =COUNTIFS('Unit Ledger'!$B$2:$B$315,"A2_Seas",'Unit Ledger'!$S$2:$S$315,"Y",'Unit Ledger'!$Q$2:$Q$315,"Moved Out") -> 10 | F3: =COUNTIFS('Unit Ledger'!$B$2:$B$315,"A2_Seas",'Unit Ledger'!$S$2:$S$315,"Y",'Unit Ledger'!$Q$2:$Q$315,"MTM Holdover") -> 1 | G3: =IF(C3=0,"",D3/C3) -> 0.21428571 | H3: =IFERROR(AVERAGEIFS('Unit Ledger'!$L$2:$L$315,'Unit Ledger'!$Q$2:$Q$315,"<>zz",'Unit Ledger'!$B$2:$B$315,"A2_Seas"),"") -> 1648.5938 | I3: =IFERROR(AVERAGEIFS('Unit Ledger'!$AC$2:$AC$315,'Unit Ledger'!$Q$2:$Q$315,"Renewed",'Unit Ledger'!$V$2:$V$315,"<>Y",'Unit Ledger'!$B$2:$B$315,"A2_Seas"),"") -> 0.0019972039 | J3: =IFERROR(AVERAGEIFS('Unit Ledger'!$AD$2:$AD$315,'Unit Ledger'!$Q$2:$Q$315,"Renewed",'Unit Ledger'!$V$2:$V$315,"<>Y",'Unit Ledger'!$B$2:$B$315,"A2_Seas"),"") -> 0.06283904 | K3: =IFERROR(AVERAGEIFS('Unit Ledger'!$AM$2:$AM$315,'Unit Ledger'!$Q$2:$Q$315,"Moved Out",'Unit Ledger'!$V$2:$V$315,"<>Y",'Unit Ledger'!$B$2:$B$315,"A2_Seas"),"") -> 0.014428815 | L3: =IFERROR(AVERAGEIFS('Unit Ledger'!$AN$2:$AN$315,'Unit Ledger'!$Q$2:$Q$315,"Moved Out",'Unit Ledger'!$V$2:$V$315,"<>Y",'Unit Ledger'!$B$2:$B$315,"A2_Seas"),"") -> 0.079321835
A4: B1_Seas | B4: =COUNTIF('Unit Ledger'!$B$2:$B$315,"B1_Seas") -> 25 | C4: =D4+E4+F4 -> 10 | D4: =COUNTIFS('Unit Ledger'!$B$2:$B$315,"B1_Seas",'Unit Ledger'!$S$2:$S$315,"Y",'Unit Ledger'!$Q$2:$Q$315,"Renewed") -> 6 | E4: =COUNTIFS('Unit Ledger'!$B$2:$B$315,"B1_Seas",'Unit Ledger'!$S$2:$S$315,"Y",'Unit Ledger'!$Q$2:$Q$315,"Moved Out") -> 4 | F4: =COUNTIFS('Unit Ledger'!$B$2:$B$315,"B1_Seas",'Unit Ledger'!$S$2:$S$315,"Y",'Unit Ledger'!$Q$2:$Q$315,"MTM Holdover") -> 0 | G4: =IF(C4=0,"",D4/C4) -> 0.6 | H4: =IFERROR(AVERAGEIFS('Unit Ledger'!$L$2:$L$315,'Unit Ledger'!$Q$2:$Q$315,"<>zz",'Unit Ledger'!$B$2:$B$315,"B1_Seas"),"") -> 1782.72 | I4: =IFERROR(AVERAGEIFS('Unit Ledger'!$AC$2:$AC$315,'Unit Ledger'!$Q$2:$Q$315,"Renewed",'Unit Ledger'!$V$2:$V$315,"<>Y",'Unit Ledger'!$B$2:$B$315,"B1_Seas"),"") -> 0.016704199 | J4: =IFERROR(AVERAGEIFS('Unit Ledger'!$AD$2:$AD$315,'Unit Ledger'!$Q$2:$Q$315,"Renewed",'Unit Ledger'!$V$2:$V$315,"<>Y",'Unit Ledger'!$B$2:$B$315,"B1_Seas"),"") -> 0.06839647 | K4: =IFERROR(AVERAGEIFS('Unit Ledger'!$AM$2:$AM$315,'Unit Ledger'!$Q$2:$Q$315,"Moved Out",'Unit Ledger'!$V$2:$V$315,"<>Y",'Unit Ledger'!$B$2:$B$315,"B1_Seas"),"") -> 0.03812016 | L4: =IFERROR(AVERAGEIFS('Unit Ledger'!$AN$2:$AN$315,'Unit Ledger'!$Q$2:$Q$315,"Moved Out",'Unit Ledger'!$V$2:$V$315,"<>Y",'Unit Ledger'!$B$2:$B$315,"B1_Seas"),"") -> 0.045162692
A5: B2_Seas | B5: =COUNTIF('Unit Ledger'!$B$2:$B$315,"B2_Seas") -> 70 | C5: =D5+E5+F5 -> 35 | D5: =COUNTIFS('Unit Ledger'!$B$2:$B$315,"B2_Seas",'Unit Ledger'!$S$2:$S$315,"Y",'Unit Ledger'!$Q$2:$Q$315,"Renewed") -> 12 | E5: =COUNTIFS('Unit Ledger'!$B$2:$B$315,"B2_Seas",'Unit Ledger'!$S$2:$S$315,"Y",'Unit Ledger'!$Q$2:$Q$315,"Moved Out") -> 22 | F5: =COUNTIFS('Unit Ledger'!$B$2:$B$315,"B2_Seas",'Unit Ledger'!$S$2:$S$315,"Y",'Unit Ledger'!$Q$2:$Q$315,"MTM Holdover") -> 1 | G5: =IF(C5=0,"",D5/C5) -> 0.34285714 | H5: =IFERROR(AVERAGEIFS('Unit Ledger'!$L$2:$L$315,'Unit Ledger'!$Q$2:$Q$315,"<>zz",'Unit Ledger'!$B$2:$B$315,"B2_Seas"),"") -> 1959.6429 | I5: =IFERROR(AVERAGEIFS('Unit Ledger'!$AC$2:$AC$315,'Unit Ledger'!$Q$2:$Q$315,"Renewed",'Unit Ledger'!$V$2:$V$315,"<>Y",'Unit Ledger'!$B$2:$B$315,"B2_Seas"),"") -> 0.010533404 | J5: =IFERROR(AVERAGEIFS('Unit Ledger'!$AD$2:$AD$315,'Unit Ledger'!$Q$2:$Q$315,"Renewed",'Unit Ledger'!$V$2:$V$315,"<>Y",'Unit Ledger'!$B$2:$B$315,"B2_Seas"),"") -> 0.10736541 | K5: =IFERROR(AVERAGEIFS('Unit Ledger'!$AM$2:$AM$315,'Unit Ledger'!$Q$2:$Q$315,"Moved Out",'Unit Ledger'!$V$2:$V$315,"<>Y",'Unit Ledger'!$B$2:$B$315,"B2_Seas"),"") -> 0.019674464 | L5: =IFERROR(AVERAGEIFS('Unit Ledger'!$AN$2:$AN$315,'Unit Ledger'!$Q$2:$Q$315,"Moved Out",'Unit Ledger'!$V$2:$V$315,"<>Y",'Unit Ledger'!$B$2:$B$315,"B2_Seas"),"") -> 0.065979197
A6: B3a_Seas | B6: =COUNTIF('Unit Ledger'!$B$2:$B$315,"B3a_Seas") -> 15 | C6: =D6+E6+F6 -> 9 | D6: =COUNTIFS('Unit Ledger'!$B$2:$B$315,"B3a_Seas",'Unit Ledger'!$S$2:$S$315,"Y",'Unit Ledger'!$Q$2:$Q$315,"Renewed") -> 4 | E6: =COUNTIFS('Unit Ledger'!$B$2:$B$315,"B3a_Seas",'Unit Ledger'!$S$2:$S$315,"Y",'Unit Ledger'!$Q$2:$Q$315,"Moved Out") -> 5 | F6: =COUNTIFS('Unit Ledger'!$B$2:$B$315,"B3a_Seas",'Unit Ledger'!$S$2:$S$315,"Y",'Unit Ledger'!$Q$2:$Q$315,"MTM Holdover") -> 0 | G6: =IF(C6=0,"",D6/C6) -> 0.44444444 | H6: =IFERROR(AVERAGEIFS('Unit Ledger'!$L$2:$L$315,'Unit Ledger'!$Q$2:$Q$315,"<>zz",'Unit Ledger'!$B$2:$B$315,"B3a_Seas"),"") -> 1867.3333 | I6: =IFERROR(AVERAGEIFS('Unit Ledger'!$AC$2:$AC$315,'Unit Ledger'!$Q$2:$Q$315,"Renewed",'Unit Ledger'!$V$2:$V$315,"<>Y",'Unit Ledger'!$B$2:$B$315,"B3a_Seas"),"") -> 0.023491167 | J6: =IFERROR(AVERAGEIFS('Unit Ledger'!$AD$2:$AD$315,'Unit Ledger'!$Q$2:$Q$315,"Renewed",'Unit Ledger'!$V$2:$V$315,"<>Y",'Unit Ledger'!$B$2:$B$315,"B3a_Seas"),"") -> 0.10547941 | K6: =IFERROR(AVERAGEIFS('Unit Ledger'!$AM$2:$AM$315,'Unit Ledger'!$Q$2:$Q$315,"Moved Out",'Unit Ledger'!$V$2:$V$315,"<>Y",'Unit Ledger'!$B$2:$B$315,"B3a_Seas"),"") -> 0.086813187 | L6: =IFERROR(AVERAGEIFS('Unit Ledger'!$AN$2:$AN$315,'Unit Ledger'!$Q$2:$Q$315,"Moved Out",'Unit Ledger'!$V$2:$V$315,"<>Y",'Unit Ledger'!$B$2:$B$315,"B3a_Seas"),"") -> 0.2199285
A7: B3b_Seas | B7: =COUNTIF('Unit Ledger'!$B$2:$B$315,"B3b_Seas") -> 26 | C7: =D7+E7+F7 -> 11 | D7: =COUNTIFS('Unit Ledger'!$B$2:$B$315,"B3b_Seas",'Unit Ledger'!$S$2:$S$315,"Y",'Unit Ledger'!$Q$2:$Q$315,"Renewed") -> 4 | E7: =COUNTIFS('Unit Ledger'!$B$2:$B$315,"B3b_Seas",'Unit Ledger'!$S$2:$S$315,"Y",'Unit Ledger'!$Q$2:$Q$315,"Moved Out") -> 6 | F7: =COUNTIFS('Unit Ledger'!$B$2:$B$315,"B3b_Seas",'Unit Ledger'!$S$2:$S$315,"Y",'Unit Ledger'!$Q$2:$Q$315,"MTM Holdover") -> 1 | G7: =IF(C7=0,"",D7/C7) -> 0.36363636 | H7: =IFERROR(AVERAGEIFS('Unit Ledger'!$L$2:$L$315,'Unit Ledger'!$Q$2:$Q$315,"<>zz",'Unit Ledger'!$B$2:$B$315,"B3b_Seas"),"") -> 1873.8846 | I7: =IFERROR(AVERAGEIFS('Unit Ledger'!$AC$2:$AC$315,'Unit Ledger'!$Q$2:$Q$315,"Renewed",'Unit Ledger'!$V$2:$V$315,"<>Y",'Unit Ledger'!$B$2:$B$315,"B3b_Seas"),"") -> 0.025428796 | J7: =IFERROR(AVERAGEIFS('Unit Ledger'!$AD$2:$AD$315,'Unit Ledger'!$Q$2:$Q$315,"Renewed",'Unit Ledger'!$V$2:$V$315,"<>Y",'Unit Ledger'!$B$2:$B$315,"B3b_Seas"),"") -> 0.12991612 | K7: =IFERROR(AVERAGEIFS('Unit Ledger'!$AM$2:$AM$315,'Unit Ledger'!$Q$2:$Q$315,"Moved Out",'Unit Ledger'!$V$2:$V$315,"<>Y",'Unit Ledger'!$B$2:$B$315,"B3b_Seas"),"") -> 0.090925763 | L7: =IFERROR(AVERAGEIFS('Unit Ledger'!$AN$2:$AN$315,'Unit Ledger'!$Q$2:$Q$315,"Moved Out",'Unit Ledger'!$V$2:$V$315,"<>Y",'Unit Ledger'!$B$2:$B$315,"B3b_Seas"),"") -> 0.1316302
A8: C1a_Seas | B8: =COUNTIF('Unit Ledger'!$B$2:$B$315,"C1a_Seas") -> 10 | C8: =D8+E8+F8 -> 7 | D8: =COUNTIFS('Unit Ledger'!$B$2:$B$315,"C1a_Seas",'Unit Ledger'!$S$2:$S$315,"Y",'Unit Ledger'!$Q$2:$Q$315,"Renewed") -> 3 | E8: =COUNTIFS('Unit Ledger'!$B$2:$B$315,"C1a_Seas",'Unit Ledger'!$S$2:$S$315,"Y",'Unit Ledger'!$Q$2:$Q$315,"Moved Out") -> 3 | F8: =COUNTIFS('Unit Ledger'!$B$2:$B$315,"C1a_Seas",'Unit Ledger'!$S$2:$S$315,"Y",'Unit Ledger'!$Q$2:$Q$315,"MTM Holdover") -> 1 | G8: =IF(C8=0,"",D8/C8) -> 0.42857143 | H8: =IFERROR(AVERAGEIFS('Unit Ledger'!$L$2:$L$315,'Unit Ledger'!$Q$2:$Q$315,"<>zz",'Unit Ledger'!$B$2:$B$315,"C1a_Seas"),"") -> 2253.1 | I8: =IFERROR(AVERAGEIFS('Unit Ledger'!$AC$2:$AC$315,'Unit Ledger'!$Q$2:$Q$315,"Renewed",'Unit Ledger'!$V$2:$V$315,"<>Y",'Unit Ledger'!$B$2:$B$315,"C1a_Seas"),"") -> 0.027803048 | J8: =IFERROR(AVERAGEIFS('Unit Ledger'!$AD$2:$AD$315,'Unit Ledger'!$Q$2:$Q$315,"Renewed",'Unit Ledger'!$V$2:$V$315,"<>Y",'Unit Ledger'!$B$2:$B$315,"C1a_Seas"),"") -> 0.12729331 | K8: =IFERROR(AVERAGEIFS('Unit Ledger'!$AM$2:$AM$315,'Unit Ledger'!$Q$2:$Q$315,"Moved Out",'Unit Ledger'!$V$2:$V$315,"<>Y",'Unit Ledger'!$B$2:$B$315,"C1a_Seas"),"") -> 0.088312576 | L8: =IFERROR(AVERAGEIFS('Unit Ledger'!$AN$2:$AN$315,'Unit Ledger'!$Q$2:$Q$315,"Moved Out",'Unit Ledger'!$V$2:$V$315,"<>Y",'Unit Ledger'!$B$2:$B$315,"C1a_Seas"),"") -> 0.092767527
A9: C1b_Seas | B9: =COUNTIF('Unit Ledger'!$B$2:$B$315,"C1b_Seas") -> 15 | C9: =D9+E9+F9 -> 9 | D9: =COUNTIFS('Unit Ledger'!$B$2:$B$315,"C1b_Seas",'Unit Ledger'!$S$2:$S$315,"Y",'Unit Ledger'!$Q$2:$Q$315,"Renewed") -> 3 | E9: =COUNTIFS('Unit Ledger'!$B$2:$B$315,"C1b_Seas",'Unit Ledger'!$S$2:$S$315,"Y",'Unit Ledger'!$Q$2:$Q$315,"Moved Out") -> 4 | F9: =COUNTIFS('Unit Ledger'!$B$2:$B$315,"C1b_Seas",'Unit Ledger'!$S$2:$S$315,"Y",'Unit Ledger'!$Q$2:$Q$315,"MTM Holdover") -> 2 | G9: =IF(C9=0,"",D9/C9) -> 0.33333333 | H9: =IFERROR(AVERAGEIFS('Unit Ledger'!$L$2:$L$315,'Unit Ledger'!$Q$2:$Q$315,"<>zz",'Unit Ledger'!$B$2:$B$315,"C1b_Seas"),"") -> 2237.3333 | I9: =IFERROR(AVERAGEIFS('Unit Ledger'!$AC$2:$AC$315,'Unit Ledger'!$Q$2:$Q$315,"Renewed",'Unit Ledger'!$V$2:$V$315,"<>Y",'Unit Ledger'!$B$2:$B$315,"C1b_Seas"),"") -> 0.01135442 | J9: =IFERROR(AVERAGEIFS('Unit Ledger'!$AD$2:$AD$315,'Unit Ledger'!$Q$2:$Q$315,"Renewed",'Unit Ledger'!$V$2:$V$315,"<>Y",'Unit Ledger'!$B$2:$B$315,"C1b_Seas"),"") -> 0.022940571 | K9: =IFERROR(AVERAGEIFS('Unit Ledger'!$AM$2:$AM$315,'Unit Ledger'!$Q$2:$Q$315,"Moved Out",'Unit Ledger'!$V$2:$V$315,"<>Y",'Unit Ledger'!$B$2:$B$315,"C1b_Seas"),"") -> 0.081109712 | L9: =IFERROR(AVERAGEIFS('Unit Ledger'!$AN$2:$AN$315,'Unit Ledger'!$Q$2:$Q$315,"Moved Out",'Unit Ledger'!$V$2:$V$315,"<>Y",'Unit Ledger'!$B$2:$B$315,"C1b_Seas"),"") -> 0.097188613
A10: S1_Seas | B10: =COUNTIF('Unit Ledger'!$B$2:$B$315,"S1_Seas") -> 13 | C10: =D10+E10+F10 -> 10 | D10: =COUNTIFS('Unit Ledger'!$B$2:$B$315,"S1_Seas",'Unit Ledger'!$S$2:$S$315,"Y",'Unit Ledger'!$Q$2:$Q$315,"Renewed") -> 4 | E10: =COUNTIFS('Unit Ledger'!$B$2:$B$315,"S1_Seas",'Unit Ledger'!$S$2:$S$315,"Y",'Unit Ledger'!$Q$2:$Q$315,"Moved Out") -> 6 | F10: =COUNTIFS('Unit Ledger'!$B$2:$B$315,"S1_Seas",'Unit Ledger'!$S$2:$S$315,"Y",'Unit Ledger'!$Q$2:$Q$315,"MTM Holdover") -> 0 | G10: =IF(C10=0,"",D10/C10) -> 0.4 | H10: =IFERROR(AVERAGEIFS('Unit Ledger'!$L$2:$L$315,'Unit Ledger'!$Q$2:$Q$315,"<>zz",'Unit Ledger'!$B$2:$B$315,"S1_Seas"),"") -> 1355 | I10: =IFERROR(AVERAGEIFS('Unit Ledger'!$AC$2:$AC$315,'Unit Ledger'!$Q$2:$Q$315,"Renewed",'Unit Ledger'!$V$2:$V$315,"<>Y",'Unit Ledger'!$B$2:$B$315,"S1_Seas"),"") -> 0.012426548 | J10: =IFERROR(AVERAGEIFS('Unit Ledger'!$AD$2:$AD$315,'Unit Ledger'!$Q$2:$Q$315,"Renewed",'Unit Ledger'!$V$2:$V$315,"<>Y",'Unit Ledger'!$B$2:$B$315,"S1_Seas"),"") -> 0.072240757 | K10: =IFERROR(AVERAGEIFS('Unit Ledger'!$AM$2:$AM$315,'Unit Ledger'!$Q$2:$Q$315,"Moved Out",'Unit Ledger'!$V$2:$V$315,"<>Y",'Unit Ledger'!$B$2:$B$315,"S1_Seas"),"") -> 0.084197784 | L10: =IFERROR(AVERAGEIFS('Unit Ledger'!$AN$2:$AN$315,'Unit Ledger'!$Q$2:$Q$315,"Moved Out",'Unit Ledger'!$V$2:$V$315,"<>Y",'Unit Ledger'!$B$2:$B$315,"S1_Seas"),"") -> 0.15931241
A12: Studio | B12: =COUNTIF('Unit Ledger'!$C$2:$C$315,"Studio") -> 13 | C12: =D12+E12+F12 -> 10 | D12: =COUNTIFS('Unit Ledger'!$C$2:$C$315,"Studio",'Unit Ledger'!$S$2:$S$315,"Y",'Unit Ledger'!$Q$2:$Q$315,"Renewed") -> 4 | E12: =COUNTIFS('Unit Ledger'!$C$2:$C$315,"Studio",'Unit Ledger'!$S$2:$S$315,"Y",'Unit Ledger'!$Q$2:$Q$315,"Moved Out") -> 6 | F12: =COUNTIFS('Unit Ledger'!$C$2:$C$315,"Studio",'Unit Ledger'!$S$2:$S$315,"Y",'Unit Ledger'!$Q$2:$Q$315,"MTM Holdover") -> 0 | G12: =IF(C12=0,"",D12/C12) -> 0.4 | H12: =IFERROR(AVERAGEIFS('Unit Ledger'!$L$2:$L$315,'Unit Ledger'!$Q$2:$Q$315,"<>zz",'Unit Ledger'!$C$2:$C$315,"Studio"),"") -> 1355 | I12: =IFERROR(AVERAGEIFS('Unit Ledger'!$AC$2:$AC$315,'Unit Ledger'!$Q$2:$Q$315,"Renewed",'Unit Ledger'!$V$2:$V$315,"<>Y",'Unit Ledger'!$C$2:$C$315,"Studio"),"") -> 0.012426548 | J12: =IFERROR(AVERAGEIFS('Unit Ledger'!$AD$2:$AD$315,'Unit Ledger'!$Q$2:$Q$315,"Renewed",'Unit Ledger'!$V$2:$V$315,"<>Y",'Unit Ledger'!$C$2:$C$315,"Studio"),"") -> 0.072240757 | K12: =IFERROR(AVERAGEIFS('Unit Ledger'!$AM$2:$AM$315,'Unit Ledger'!$Q$2:$Q$315,"Moved Out",'Unit Ledger'!$V$2:$V$315,"<>Y",'Unit Ledger'!$C$2:$C$315,"Studio"),"") -> 0.084197784 | L12: =IFERROR(AVERAGEIFS('Unit Ledger'!$AN$2:$AN$315,'Unit Ledger'!$Q$2:$Q$315,"Moved Out",'Unit Ledger'!$V$2:$V$315,"<>Y",'Unit Ledger'!$C$2:$C$315,"Studio"),"") -> 0.15931241
A13: 1x1 | B13: =COUNTIF('Unit Ledger'!$C$2:$C$315,"1x1") -> 140 | C13: =D13+E13+F13 -> 63 | D13: =COUNTIFS('Unit Ledger'!$C$2:$C$315,"1x1",'Unit Ledger'!$S$2:$S$315,"Y",'Unit Ledger'!$Q$2:$Q$315,"Renewed") -> 28 | E13: =COUNTIFS('Unit Ledger'!$C$2:$C$315,"1x1",'Unit Ledger'!$S$2:$S$315,"Y",'Unit Ledger'!$Q$2:$Q$315,"Moved Out") -> 33 | F13: =COUNTIFS('Unit Ledger'!$C$2:$C$315,"1x1",'Unit Ledger'!$S$2:$S$315,"Y",'Unit Ledger'!$Q$2:$Q$315,"MTM Holdover") -> 2 | G13: =IF(C13=0,"",D13/C13) -> 0.44444444 | H13: =IFERROR(AVERAGEIFS('Unit Ledger'!$L$2:$L$315,'Unit Ledger'!$Q$2:$Q$315,"<>zz",'Unit Ledger'!$C$2:$C$315,"1x1"),"") -> 1500.95 | I13: =IFERROR(AVERAGEIFS('Unit Ledger'!$AC$2:$AC$315,'Unit Ledger'!$Q$2:$Q$315,"Renewed",'Unit Ledger'!$V$2:$V$315,"<>Y",'Unit Ledger'!$C$2:$C$315,"1x1"),"") -> 0.014065166 | J13: =IFERROR(AVERAGEIFS('Unit Ledger'!$AD$2:$AD$315,'Unit Ledger'!$Q$2:$Q$315,"Renewed",'Unit Ledger'!$V$2:$V$315,"<>Y",'Unit Ledger'!$C$2:$C$315,"1x1"),"") -> 0.097135816 | K13: =IFERROR(AVERAGEIFS('Unit Ledger'!$AM$2:$AM$315,'Unit Ledger'!$Q$2:$Q$315,"Moved Out",'Unit Ledger'!$V$2:$V$315,"<>Y",'Unit Ledger'!$C$2:$C$315,"1x1"),"") -> 0.045422565 | L13: =IFERROR(AVERAGEIFS('Unit Ledger'!$AN$2:$AN$315,'Unit Ledger'!$Q$2:$Q$315,"Moved Out",'Unit Ledger'!$V$2:$V$315,"<>Y",'Unit Ledger'!$C$2:$C$315,"1x1"),"") -> 0.11399548
A14: 2x2 | B14: =COUNTIF('Unit Ledger'!$C$2:$C$315,"2x2") -> 136 | C14: =D14+E14+F14 -> 65 | D14: =COUNTIFS('Unit Ledger'!$C$2:$C$315,"2x2",'Unit Ledger'!$S$2:$S$315,"Y",'Unit Ledger'!$Q$2:$Q$315,"Renewed") -> 26 | E14: =COUNTIFS('Unit Ledger'!$C$2:$C$315,"2x2",'Unit Ledger'!$S$2:$S$315,"Y",'Unit Ledger'!$Q$2:$Q$315,"Moved Out") -> 37 | F14: =COUNTIFS('Unit Ledger'!$C$2:$C$315,"2x2",'Unit Ledger'!$S$2:$S$315,"Y",'Unit Ledger'!$Q$2:$Q$315,"MTM Holdover") -> 2 | G14: =IF(C14=0,"",D14/C14) -> 0.4 | H14: =IFERROR(AVERAGEIFS('Unit Ledger'!$L$2:$L$315,'Unit Ledger'!$Q$2:$Q$315,"<>zz",'Unit Ledger'!$C$2:$C$315,"2x2"),"") -> 1900.5441 | I14: =IFERROR(AVERAGEIFS('Unit Ledger'!$AC$2:$AC$315,'Unit Ledger'!$Q$2:$Q$315,"Renewed",'Unit Ledger'!$V$2:$V$315,"<>Y",'Unit Ledger'!$C$2:$C$315,"2x2"),"") -> 0.016242534 | J14: =IFERROR(AVERAGEIFS('Unit Ledger'!$AD$2:$AD$315,'Unit Ledger'!$Q$2:$Q$315,"Renewed",'Unit Ledger'!$V$2:$V$315,"<>Y",'Unit Ledger'!$C$2:$C$315,"2x2"),"") -> 0.10155176 | K14: =IFERROR(AVERAGEIFS('Unit Ledger'!$AM$2:$AM$315,'Unit Ledger'!$Q$2:$Q$315,"Moved Out",'Unit Ledger'!$V$2:$V$315,"<>Y",'Unit Ledger'!$C$2:$C$315,"2x2"),"") -> 0.046152296 | L14: =IFERROR(AVERAGEIFS('Unit Ledger'!$AN$2:$AN$315,'Unit Ledger'!$Q$2:$Q$315,"Moved Out",'Unit Ledger'!$V$2:$V$315,"<>Y",'Unit Ledger'!$C$2:$C$315,"2x2"),"") -> 0.092329875
A15: 3x2 | B15: =COUNTIF('Unit Ledger'!$C$2:$C$315,"3x2") -> 25 | C15: =D15+E15+F15 -> 16 | D15: =COUNTIFS('Unit Ledger'!$C$2:$C$315,"3x2",'Unit Ledger'!$S$2:$S$315,"Y",'Unit Ledger'!$Q$2:$Q$315,"Renewed") -> 6 | E15: =COUNTIFS('Unit Ledger'!$C$2:$C$315,"3x2",'Unit Ledger'!$S$2:$S$315,"Y",'Unit Ledger'!$Q$2:$Q$315,"Moved Out") -> 7 | F15: =COUNTIFS('Unit Ledger'!$C$2:$C$315,"3x2",'Unit Ledger'!$S$2:$S$315,"Y",'Unit Ledger'!$Q$2:$Q$315,"MTM Holdover") -> 3 | G15: =IF(C15=0,"",D15/C15) -> 0.375 | H15: =IFERROR(AVERAGEIFS('Unit Ledger'!$L$2:$L$315,'Unit Ledger'!$Q$2:$Q$315,"<>zz",'Unit Ledger'!$C$2:$C$315,"3x2"),"") -> 2243.64 | I15: =IFERROR(AVERAGEIFS('Unit Ledger'!$AC$2:$AC$315,'Unit Ledger'!$Q$2:$Q$315,"Renewed",'Unit Ledger'!$V$2:$V$315,"<>Y",'Unit Ledger'!$C$2:$C$315,"3x2"),"") -> 0.019578734 | J15: =IFERROR(AVERAGEIFS('Unit Ledger'!$AD$2:$AD$315,'Unit Ledger'!$Q$2:$Q$315,"Renewed",'Unit Ledger'!$V$2:$V$315,"<>Y",'Unit Ledger'!$C$2:$C$315,"3x2"),"") -> 0.075116942 | K15: =IFERROR(AVERAGEIFS('Unit Ledger'!$AM$2:$AM$315,'Unit Ledger'!$Q$2:$Q$315,"Moved Out",'Unit Ledger'!$V$2:$V$315,"<>Y",'Unit Ledger'!$C$2:$C$315,"3x2"),"") -> 0.085611502 | L15: =IFERROR(AVERAGEIFS('Unit Ledger'!$AN$2:$AN$315,'Unit Ledger'!$Q$2:$Q$315,"Moved Out",'Unit Ledger'!$V$2:$V$315,"<>Y",'Unit Ledger'!$C$2:$C$315,"3x2"),"") -> 0.094662278
A17: TOTAL | B17: =COUNTA('Unit Ledger'!$A$2:$A$315) -> 314 | C17: =D17+E17+F17 -> 154 | D17: =COUNTIFS('Unit Ledger'!$S$2:$S$315,"Y",'Unit Ledger'!$Q$2:$Q$315,"Renewed") -> 64 | E17: =COUNTIFS('Unit Ledger'!$S$2:$S$315,"Y",'Unit Ledger'!$Q$2:$Q$315,"Moved Out") -> 83 | F17: =COUNTIFS('Unit Ledger'!$S$2:$S$315,"Y",'Unit Ledger'!$Q$2:$Q$315,"MTM Holdover") -> 7 | G17: =IF(C17=0,"",D17/C17) -> 0.41558442 | H17: =IFERROR(AVERAGEIFS('Unit Ledger'!$L$2:$L$315,'Unit Ledger'!$Q$2:$Q$315,"<>zz"),"") -> 1727.1115 | I17: =IFERROR(AVERAGEIFS('Unit Ledger'!$AC$2:$AC$315,'Unit Ledger'!$Q$2:$Q$315,"Renewed",'Unit Ledger'!$V$2:$V$315,"<>Y"),"") -> 0.015364205 | J17: =IFERROR(AVERAGEIFS('Unit Ledger'!$AD$2:$AD$315,'Unit Ledger'!$Q$2:$Q$315,"Renewed",'Unit Ledger'!$V$2:$V$315,"<>Y"),"") -> 0.095309584 | K17: =IFERROR(AVERAGEIFS('Unit Ledger'!$AM$2:$AM$315,'Unit Ledger'!$Q$2:$Q$315,"Moved Out",'Unit Ledger'!$V$2:$V$315,"<>Y"),"") -> 0.051747484 | L17: =IFERROR(AVERAGEIFS('Unit Ledger'!$AN$2:$AN$315,'Unit Ledger'!$Q$2:$Q$315,"Moved Out",'Unit Ledger'!$V$2:$V$315,"<>Y"),"") -> 0.1066842

Sheet By Month
A1: First-Expiration Month | B1: Expirations Due | C1: Renewed | D1: Moved Out | E1: MTM | F1: Retention % | G1: Renewal TO Gross % | H1: Renewal TO Eff % | I1: New-Lease TO Gross % | J1: New-Lease TO Eff % | K1: Coming Due (not yet expired)
A2: 2025-08 | B2: =C2+D2+E2 -> 1 | C2: =COUNTIFS('Unit Ledger'!$J$2:$J$315,"2025-08",'Unit Ledger'!$S$2:$S$315,"Y",'Unit Ledger'!$Q$2:$Q$315,"Renewed") -> 1 | D2: =COUNTIFS('Unit Ledger'!$J$2:$J$315,"2025-08",'Unit Ledger'!$S$2:$S$315,"Y",'Unit Ledger'!$Q$2:$Q$315,"Moved Out") -> 0 | E2: =COUNTIFS('Unit Ledger'!$J$2:$J$315,"2025-08",'Unit Ledger'!$S$2:$S$315,"Y",'Unit Ledger'!$Q$2:$Q$315,"MTM Holdover") -> 0 | F2: =IF(B2=0,"",C2/B2) -> 1 | G2: =IFERROR(AVERAGEIFS('Unit Ledger'!$AC$2:$AC$315,'Unit Ledger'!$J$2:$J$315,"2025-08",'Unit Ledger'!$Q$2:$Q$315,"Renewed",'Unit Ledger'!$V$2:$V$315,"<>Y"),"") -> 0.014336918 | H2: =IFERROR(AVERAGEIFS('Unit Ledger'!$AD$2:$AD$315,'Unit Ledger'!$J$2:$J$315,"2025-08",'Unit Ledger'!$Q$2:$Q$315,"Renewed",'Unit Ledger'!$V$2:$V$315,"<>Y"),"") -> 0.014336918 | I2: =IFERROR(AVERAGEIFS('Unit Ledger'!$AM$2:$AM$315,'Unit Ledger'!$J$2:$J$315,"2025-08",'Unit Ledger'!$Q$2:$Q$315,"Moved Out",'Unit Ledger'!$V$2:$V$315,"<>Y"),"") | J2: =IFERROR(AVERAGEIFS('Unit Ledger'!$AN$2:$AN$315,'Unit Ledger'!$J$2:$J$315,"2025-08",'Unit Ledger'!$Q$2:$Q$315,"Moved Out",'Unit Ledger'!$V$2:$V$315,"<>Y"),"") | K2: =COUNTIFS('Unit Ledger'!$J$2:$J$315,"2025-08",'Unit Ledger'!$Q$2:$Q$315,"Not Yet Expired") -> 0
A3: 2025-10 | B3: =C3+D3+E3 -> 2 | C3: =COUNTIFS('Unit Ledger'!$J$2:$J$315,"2025-10",'Unit Ledger'!$S$2:$S$315,"Y",'Unit Ledger'!$Q$2:$Q$315,"Renewed") -> 2 | D3: =COUNTIFS('Unit Ledger'!$J$2:$J$315,"2025-10",'Unit Ledger'!$S$2:$S$315,"Y",'Unit Ledger'!$Q$2:$Q$315,"Moved Out") -> 0 | E3: =COUNTIFS('Unit Ledger'!$J$2:$J$315,"2025-10",'Unit Ledger'!$S$2:$S$315,"Y",'Unit Ledger'!$Q$2:$Q$315,"MTM Holdover") -> 0 | F3: =IF(B3=0,"",C3/B3) -> 1 | G3: =IFERROR(AVERAGEIFS('Unit Ledger'!$AC$2:$AC$315,'Unit Ledger'!$J$2:$J$315,"2025-10",'Unit Ledger'!$Q$2:$Q$315,"Renewed",'Unit Ledger'!$V$2:$V$315,"<>Y"),"") -> 0.0090252708 | H3: =IFERROR(AVERAGEIFS('Unit Ledger'!$AD$2:$AD$315,'Unit Ledger'!$J$2:$J$315,"2025-10",'Unit Ledger'!$Q$2:$Q$315,"Renewed",'Unit Ledger'!$V$2:$V$315,"<>Y"),"") -> 0.11354536 | I3: =IFERROR(AVERAGEIFS('Unit Ledger'!$AM$2:$AM$315,'Unit Ledger'!$J$2:$J$315,"2025-10",'Unit Ledger'!$Q$2:$Q$315,"Moved Out",'Unit Ledger'!$V$2:$V$315,"<>Y"),"") | J3: =IFERROR(AVERAGEIFS('Unit Ledger'!$AN$2:$AN$315,'Unit Ledger'!$J$2:$J$315,"2025-10",'Unit Ledger'!$Q$2:$Q$315,"Moved Out",'Unit Ledger'!$V$2:$V$315,"<>Y"),"") | K3: =COUNTIFS('Unit Ledger'!$J$2:$J$315,"2025-10",'Unit Ledger'!$Q$2:$Q$315,"Not Yet Expired") -> 0
A4: 2025-11 | B4: =C4+D4+E4 -> 4 | C4: =COUNTIFS('Unit Ledger'!$J$2:$J$315,"2025-11",'Unit Ledger'!$S$2:$S$315,"Y",'Unit Ledger'!$Q$2:$Q$315,"Renewed") -> 4 | D4: =COUNTIFS('Unit Ledger'!$J$2:$J$315,"2025-11",'Unit Ledger'!$S$2:$S$315,"Y",'Unit Ledger'!$Q$2:$Q$315,"Moved Out") -> 0 | E4: =COUNTIFS('Unit Ledger'!$J$2:$J$315,"2025-11",'Unit Ledger'!$S$2:$S$315,"Y",'Unit Ledger'!$Q$2:$Q$315,"MTM Holdover") -> 0 | F4: =IF(B4=0,"",C4/B4) -> 1 | G4: =IFERROR(AVERAGEIFS('Unit Ledger'!$AC$2:$AC$315,'Unit Ledger'!$J$2:$J$315,"2025-11",'Unit Ledger'!$Q$2:$Q$315,"Renewed",'Unit Ledger'!$V$2:$V$315,"<>Y"),"") -> -0.0076261741 | H4: =IFERROR(AVERAGEIFS('Unit Ledger'!$AD$2:$AD$315,'Unit Ledger'!$J$2:$J$315,"2025-11",'Unit Ledger'!$Q$2:$Q$315,"Renewed",'Unit Ledger'!$V$2:$V$315,"<>Y"),"") -> 0.16708954 | I4: =IFERROR(AVERAGEIFS('Unit Ledger'!$AM$2:$AM$315,'Unit Ledger'!$J$2:$J$315,"2025-11",'Unit Ledger'!$Q$2:$Q$315,"Moved Out",'Unit Ledger'!$V$2:$V$315,"<>Y"),"") | J4: =IFERROR(AVERAGEIFS('Unit Ledger'!$AN$2:$AN$315,'Unit Ledger'!$J$2:$J$315,"2025-11",'Unit Ledger'!$Q$2:$Q$315,"Moved Out",'Unit Ledger'!$V$2:$V$315,"<>Y"),"") | K4: =COUNTIFS('Unit Ledger'!$J$2:$J$315,"2025-11",'Unit Ledger'!$Q$2:$Q$315,"Not Yet Expired") -> 0
A5: 2025-12 | B5: =C5+D5+E5 -> 6 | C5: =COUNTIFS('Unit Ledger'!$J$2:$J$315,"2025-12",'Unit Ledger'!$S$2:$S$315,"Y",'Unit Ledger'!$Q$2:$Q$315,"Renewed") -> 5 | D5: =COUNTIFS('Unit Ledger'!$J$2:$J$315,"2025-12",'Unit Ledger'!$S$2:$S$315,"Y",'Unit Ledger'!$Q$2:$Q$315,"Moved Out") -> 1 | E5: =COUNTIFS('Unit Ledger'!$J$2:$J$315,"2025-12",'Unit Ledger'!$S$2:$S$315,"Y",'Unit Ledger'!$Q$2:$Q$315,"MTM Holdover") -> 0 | F5: =IF(B5=0,"",C5/B5) -> 0.83333333 | G5: =IFERROR(AVERAGEIFS('Unit Ledger'!$AC$2:$AC$315,'Unit Ledger'!$J$2:$J$315,"2025-12",'Unit Ledger'!$Q$2:$Q$315,"Renewed",'Unit Ledger'!$V$2:$V$315,"<>Y"),"") -> 0.0064654773 | H5: =IFERROR(AVERAGEIFS('Unit Ledger'!$AD$2:$AD$315,'Unit Ledger'!$J$2:$J$315,"2025-12",'Unit Ledger'!$Q$2:$Q$315,"Renewed",'Unit Ledger'!$V$2:$V$315,"<>Y"),"") -> 0.092349584 | I5: =IFERROR(AVERAGEIFS('Unit Ledger'!$AM$2:$AM$315,'Unit Ledger'!$J$2:$J$315,"2025-12",'Unit Ledger'!$Q$2:$Q$315,"Moved Out",'Unit Ledger'!$V$2:$V$315,"<>Y"),"") -> 0.1061246 | J5: =IFERROR(AVERAGEIFS('Unit Ledger'!$AN$2:$AN$315,'Unit Ledger'!$J$2:$J$315,"2025-12",'Unit Ledger'!$Q$2:$Q$315,"Moved Out",'Unit Ledger'!$V$2:$V$315,"<>Y"),"") -> 0.20679724 | K5: =COUNTIFS('Unit Ledger'!$J$2:$J$315,"2025-12",'Unit Ledger'!$Q$2:$Q$315,"Not Yet Expired") -> 0
