Workbook

Sheet Comparison
B1: SEASONS AT MERIDIAN Y1 UW vs PRELUDE AT PARAMOUNT Y1 UW vs PRELUDE ACTUALS
B2: Blue = hard-coded from source (Seasons v3 model CF(Annual) col K · Prelude Final Model Rev&Exp col H · Yardi accrual statement) · Black = formula · Green = link to Detail tab. "Actual" = 7 true post-close months (Jan–Jul 2026) annualized ×12/7; T3 = May–Jul 2026 ×4. Prepared 2026-08-14.
C4: Seasons at Meridian Y1 UW ($/U/yr) | D4: Prelude Y1 UW ($/U/yr) | E4: Prelude Actual 7-mo ann. ($/U/yr) | F4: Prelude Actual T3 ann. ($/U/yr) | G4: Prelude Act vs UW ($/U) | H4: Prelude Act vs UW (%) | I4: Seasons UW vs Prelude Act ($/U) | J4: Seasons Y1 UW Total ($) | K4: Prelude Y1 UW Total ($) | L4: Prelude Actual Ann. Total ($) | M4: Notes
B5: PROPERTY SNAPSHOT
C6: Seasons at Meridian | D6: Prelude UW | E6: Prelude Actual
B7: Units | C7: 360 | D7: 280 | E7: 280
B8: Average unit SF | C8: 932.46 | D8: 1016.38 | E8: 1016.38 | M8: Seasons: model unit mix wtd avg. Prelude: Rev&Exp tab.
B9: Year built | C9: 2024 | D9: 2018 | E9: 2018
B10: Location | C10: Meridian (Overland Rd) | D10: Meridian (Paramount)
B11: Status / period | C11: UW Y1 (Dec-26 – Nov-27) | D11: UW Y1 (CY 2026) | E11: Owned; Jan–Jul-26 ann. | M11: Seasons: acquisition target, close 10/31/26, $118.5M ($329K/U). Prelude: closed 12/31/25, $79.75M ($285K/U).
B12: Basis: purchase price ($) | C12: 118500000 | D12: 79750000 | E12: 79750000
B13: Price per unit ($) | C13: =C12/C7 -> 329166.67 | D13: =D12/D7 -> 284821.43 | E13: =E12/E7 -> 284821.43
B14: Market rent ($/U/mo) | C14: 1915 | D14: 1729.64 | E14: 1723.5 | M14: Seasons = Y1 UW avg (CF K4). Prelude UW = Y1 avg. Actual = PM market rent, held flat $1,723.50 since close (RR 8/13/26).
B15: Market rent ($/SF/mo) | C15: =C14/C8 -> 2.0537074 | D15: =D14/D8 -> 1.7017651 | E15: =E14/E8 -> 1.695724
B16: In-place rent ($/U/mo, occupied) | D16: 1668 | E16: 1680.44 | M16: Prelude UW Y1 rent/occupied unit; Actual = RR 8/13/26 (271 of 280 units paying = 96.8%). L5 new leases (May–Aug 26, n=56): $1,731 face; latest L5 $1,811.
B17: REVENUE ($/yr)
B18: Market Rent (GPR) | C18: =J18/$C$7 -> 22980 | D18: =K18/$D$7 -> 20755.686 | E18: =L18/$E$7 -> 20682 | F18: =SUMIF('Prelude Actuals Detail'!$D$5:$D$133,"GPR",'Prelude Actuals Detail'!$N$5:$N$133)/$E$7 -> 20682 | G18: =E18-D18 -> -73.6865 | H18: =IF(D18=0,"n/a",(E18-D18)/ABS(D18)) -> -0.0035501837 | I18: =C18-E18 -> 2298 | J18: 8272800 | K18: 5811592.2 | L18: =SUMIF('Prelude Actuals Detail'!$D$5:$D$133,"GPR",'Prelude Actuals Detail'!$M$5:$M$133) -> 5790960 | M18: Prelude PM market-rent line flat at $1,723.50/U all 7 months — no pushes taken yet in Yardi.
B19: Value-Add Revenue | C19: =J19/$C$7 -> 0 | D19: =K19/$D$7 -> 14.464286 | E19: =L19/$E$7 -> 0 | F19: 0 | G19: =E19-D19 -> -14.464286 | H19: =IF(D19=0,"n/a",(E19-D19)/ABS(D19)) -> -1 | I19: =C19-E19 -> 0 | J19: 0 | K19: 4050 | L19: 0 | M19: No VA program in either UW (Prelude token $4K).
B20: Gain / (Loss) to Lease | C20: =J20/$C$7 -> -911.26036 | D20: =K20/$D$7 -> -205.15336 | E20: =L20/$E$7 -> -580.93469 | F20: =SUMIF('Prelude Actuals Detail'!$D$5:$D$133,"LTL",'Prelude Actuals Detail'!$N$5:$N$133)/$E$7 -> -519.15714 | G20: =E20-D20 -> -375.78134 | H20: =IF(D20=0,"n/a",(E20-D20)/ABS(D20)) -> -1.8317094 | I20: =C20-E20 -> -330.32567 | J20: -328053.73 | K20: -57442.94 | L20: =SUMIF('Prelude Actuals Detail'!$D$5:$D$133,"LTL",'Prelude Actuals Detail'!$M$5:$M$133) -> -162661.71 | M20: Prelude actual LTL running ~2.8x UW but shrinking monthly (-3.2% of GPR Jan → -2.3% Jul).
B21: Adjusted GPR | C21: =J21/$C$7 -> 22068.74 | D21: =K21/$D$7 -> 20564.997 | E21: =L21/$E$7 -> 20101.065 | F21: =SUM(F18:F20) -> 20162.843 | G21: =E21-D21 -> -463.93212 | H21: =IF(D21=0,"n/a",(E21-D21)/ABS(D21)) -> -0.022559309 | I21: =C21-E21 -> 1967.6743 | J21: =SUM(J18:J20) -> 7944746.3 | K21: =SUM(K18:K20) -> 5758199.3 | L21: =SUM(L18:L20) -> 5628298.3
B22: Vacancy | C22: =J22/$C$7 -> -1213.7807 | D22: =K22/$D$7 -> -1439.5498 | E22: =L22/$E$7 -> -1822.8015 | F22: =SUMIF('Prelude Actuals Detail'!$D$5:$D$133,"Vacancy",'Prelude Actuals Detail'!$N$5:$N$133)/$E$7 -> -1230.2236 | G22: =E22-D22 -> -383.25165 | H22: =IF(D22=0,"n/a",(E22-D22)/ABS(D22)) -> -0.26623021 | I22: =C22-E22 -> 609.0208 | J22: -436961.04 | K22: -403073.95 | L22: =SUMIF('Prelude Actuals Detail'!$D$5:$D$133,"Vacancy",'Prelude Actuals Detail'!$M$5:$M$133) -> -510384.41 | M22: Prelude vacancy burned from ~11% econ (Jan–Apr) to 6.1% T3 — absorption thesis tracking.
B23: Bad Debt / Uncollectables | C23: =J23/$C$7 -> -55.171861 | D23: =K23/$D$7 -> -102.825 | E23: =L23/$E$7 -> 6.5739184 | F23: =SUMIF('Prelude Actuals Detail'!$D$5:$D$133,"BadDebt",'Prelude Actuals Detail'!$N$5:$N$133)/$E$7 -> 11.378857 | G23: =E23-D23 -> 109.39892 | H23: =IF(D23=0,"n/a",(E23-D23)/ABS(D23)) -> 1.0639331 | I23: =C23-E23 -> -61.745779 | J23: -19861.87 | K23: -28791 | L23: =SUMIF('Prelude Actuals Detail'!$D$5:$D$133,"BadDebt",'Prelude Actuals Detail'!$M$5:$M$133) -> 1840.6971 | M23: Prelude actual net recovery (+$1.1K) — far better than 0.5% UW allowance.
B24: Model / Employee Units | C24: =J24/$C$7 -> -61.302056 | D24: =K24/$D$7 -> -88.952929 | E24: =L24/$E$7 -> -30.771429 | F24: =SUMIF('Prelude Actuals Detail'!$D$5:$D$133,"ModelEmp",'Prelude Actuals Detail'!$N$5:$N$133)/$E$7 -> -30.771429 | G24: =E24-D24 -> 58.1815 | H24: =IF(D24=0,"n/a",(E24-D24)/ABS(D24)) -> 0.65407065 | I24: =C24-E24 -> -30.530627 | J24: -22068.74 | K24: -24906.82 | L24: =SUMIF('Prelude Actuals Detail'!$D$5:$D$133,"ModelEmp",'Prelude Actuals Detail'!$M$5:$M$133) -> -8616
B25: Concessions | C25: =J25/$C$7 -> -220.68739 | D25: =K25/$D$7 -> -514.12493 | E25: =L25/$E$7 -> -855.97378 | F25: =SUMIF('Prelude Actuals Detail'!$D$5:$D$133,"Concessions",'Prelude Actuals Detail'!$N$5:$N$133)/$E$7 -> -1153.7729 | G25: =E25-D25 -> -341.84885 | H25: =IF(D25=0,"n/a",(E25-D25)/ABS(D25)) -> -0.66491397 | I25: =C25-E25 -> 635.28639 | J25: -79447.46 | K25: -143954.98 | L25: =SUMIF('Prelude Actuals Detail'!$D$5:$D$133,"Concessions",'Prelude Actuals Detail'!$M$5:$M$133) -> -239672.66 | M25: RED FLAG: Prelude actual ~1.7x UW and accelerating — T3 pace ~$1,154/U (5.6% of GPR) vs $514/U UW. One-time (upfront) concessions on new signings; winter-cohort burn-off underway. Seasons UW assumes only 1.0% of AGPR in Y1.
B26: Net Rental Income | C26: =J26/$C$7 -> 20517.798 | D26: =K26/$D$7 -> 18419.545 | E26: =L26/$E$7 -> 17398.093 | F26: =F21+SUM(F22:F25) -> 17759.454 | G26: =E26-D26 -> -1021.4522 | H26: =IF(D26=0,"n/a",(E26-D26)/ABS(D26)) -> -0.055454802 | I26: =C26-E26 -> 3119.7051 | J26: =J21+SUM(J22:J25) -> 7386407.2 | K26: =K21+SUM(K22:K25) -> 5157472.5 | L26: =L21+SUM(L22:L25) -> 4871465.9
B27: Other Income (misc & fees) | C27: =J27/$C$7 -> 623.71639 | D27: =K27/$D$7 -> 920.61282 | E27: =L27/$E$7 -> 744.31543 | F27: =SUMIF('Prelude Actuals Detail'!$D$5:$D$133,"OIMisc",'Prelude Actuals Detail'!$N$5:$N$133)/$E$7 -> 890.62729 | G27: =E27-D27 -> -176.29739 | H27: =IF(D27=0,"n/a",(E27-D27)/ABS(D27)) -> -0.19150004 | I27: =C27-E27 -> -120.59904 | J27: 224537.9 | K27: 257771.59 | L27: =SUMIF('Prelude Actuals Detail'!$D$5:$D$133,"OIMisc",'Prelude Actuals Detail'!$M$5:$M$133) -> 208408.32 | M27: Prelude actual incl. smart-home $250/U ann. UW also carried bulk-wifi at $100.8K income offset by $100.8K expense (net $0) — excluded both sides here.
B28: RUBS / Utility Billbacks | C28: =J28/$C$7 -> 697.74411 | D28: =K28/$D$7 -> 762.95725 | E28: =L28/$E$7 -> 946.8892 | F28: =SUMIF('Prelude Actuals Detail'!$D$5:$D$133,"RUBS",'Prelude Actuals Detail'!$N$5:$N$133)/$E$7 -> 699.82986 | G28: =E28-D28 -> 183.93195 | H28: =IF(D28=0,"n/a",(E28-D28)/ABS(D28)) -> 0.24107767 | I28: =C28-E28 -> -249.14509 | J28: 251187.88 | K28: 213628.03 | L28: =SUMIF('Prelude Actuals Detail'!$D$5:$D$133,"RUBS",'Prelude Actuals Detail'!$M$5:$M$133) -> 265128.98 | M28: Prelude billbacks ramped from ~$0 (Jan) as TMG RUBS program took over billing.
B29: Parking, Garages & Carports | C29: =J29/$C$7 -> 360.24167 | D29: =K29/$D$7 -> 759.41932 | E29: =L29/$E$7 -> 630.63692 | F29: =SUMIF('Prelude Actuals Detail'!$D$5:$D$133,"Parking",'Prelude Actuals Detail'!$N$5:$N$133)/$E$7 -> 620.619 | G29: =E29-D29 -> -128.7824 | H29: =IF(D29=0,"n/a",(E29-D29)/ABS(D29)) -> -0.1695801 | I29: =C29-E29 -> -270.39525 | J29: 129687 | K29: 212637.41 | L29: =SUMIF('Prelude Actuals Detail'!$D$5:$D$133,"Parking",'Prelude Actuals Detail'!$M$5:$M$133) -> 176578.34 | M29: Prelude UW pushed detached garages $75→$100/mo; actual garage income $609/U ann. vs $759/U UW.
B30: Revenue Share (internet/cable) | C30: =J30/$C$7 -> 1077.3 | D30: =K30/$D$7 -> 0 | E30: =L30/$E$7 -> 25.350918 | F30: =SUMIF('Prelude Actuals Detail'!$D$5:$D$133,"RevShare",'Prelude Actuals Detail'!$N$5:$N$133)/$E$7 -> 46.927429 | G30: =E30-D30 -> 25.350918 | H30: =IF(D30=0,"n/a",(E30-D30)/ABS(D30)) -> n/a | I30: =C30-E30 -> 1051.9491 | J30: 387828 | K30: 0 | L30: =SUMIF('Prelude Actuals Detail'!$D$5:$D$133,"RevShare",'Prelude Actuals Detail'!$M$5:$M$133) -> 7098.2571 | M30: KEY DELTA: Seasons UW carries $1,077/U bulk-internet revenue share — supported by in-place contract ($834/U in Seasons T12). Prelude has no program (actual $15/U).
B31: Total Other Income | C31: =J31/$C$7 -> 2759.0022 | D31: =K31/$D$7 -> 2442.9894 | E31: =L31/$E$7 -> 2347.1925 | F31: =SUM(F27:F30) -> 2258.0036 | G31: =E31-D31 -> -95.796923 | H31: =IF(D31=0,"n/a",(E31-D31)/ABS(D31)) -> -0.039212992 | I31: =C31-E31 -> 411.8097 | J31: =SUM(J27:J30) -> 993240.78 | K31: =SUM(K27:K30) -> 684037.03 | L31: =SUM(L27:L30) -> 657213.89
B32: EFFECTIVE GROSS INCOME | C32: =J32/$C$7 -> 23276.8 | D32: =K32/$D$7 -> 20862.534 | E32: =L32/$E$7 -> 19745.285 | F32: =F26+F31 -> 20017.457 | G32: =E32-D32 -> -1117.2491 | H32: =IF(D32=0,"n/a",(E32-D32)/ABS(D32)) -> -0.053552896 | I32: =C32-E32 -> 3531.5148 | J32: =J26+J31 -> 8379647.9 | K32: =K26+K31 -> 5841509.6 | L32: =L26+L31 -> 5528679.8
B33: OPERATING EXPENSES ($/yr)
B34: Payroll & Benefits | C34: =J34/$C$7 -> 1670.9059 | D34: =K34/$D$7 -> 1796.9228 | E34: =L34/$E$7 -> 1460.6066 | F34: =SUMIF('Prelude Actuals Detail'!$D$5:$D$133,"Payroll",'Prelude Actuals Detail'!$N$5:$N$133)/$E$7 -> 1436.3567 | G34: =E34-D34 -> -336.31615 | H34: =IF(D34=0,"n/a",(E34-D34)/ABS(D34)) -> -0.18716227 | I34: =C34-E34 -> 210.29926 | J34: 601526.12 | K34: 503138.38 | L34: =SUMIF('Prelude Actuals Detail'!$D$5:$D$133,"Payroll",'Prelude Actuals Detail'!$M$5:$M$133) -> 408969.86 | M34: Prelude running ~$300/U favorable to UW.
B35: Advertising & Promotion | C35: =J35/$C$7 -> 366.91689 | D35: =K35/$D$7 -> 347.14257 | E35: =L35/$E$7 -> 364.50061 | F35: =SUMIF('Prelude Actuals Detail'!$D$5:$D$133,"Advertising",'Prelude Actuals Detail'!$N$5:$N$133)/$E$7 -> 481.465 | G35: =E35-D35 -> 17.358041 | H35: =IF(D35=0,"n/a",(E35-D35)/ABS(D35)) -> 0.050002628 | I35: =C35-E35 -> 2.4162766 | J35: 132090.08 | K35: 97199.92 | L35: =SUMIF('Prelude Actuals Detail'!$D$5:$D$133,"Advertising",'Prelude Actuals Detail'!$M$5:$M$133) -> 102060.17 | M35: Prelude T3 elevated (~$481/U ann.) — leasing push.
B36: General & Administrative | C36: =J36/$C$7 -> 349.13733 | D36: =K36/$D$7 -> 398.67618 | E36: =L36/$E$7 -> 421.14937 | F36: =SUMIF('Prelude Actuals Detail'!$D$5:$D$133,"GA",'Prelude Actuals Detail'!$N$5:$N$133)/$E$7 -> 405.269 | G36: =E36-D36 -> 22.473189 | H36: =IF(D36=0,"n/a",(E36-D36)/ABS(D36)) -> 0.05636953 | I36: =C36-E36 -> -72.012034 | J36: 125689.44 | K36: 111629.33 | L36: =SUMIF('Prelude Actuals Detail'!$D$5:$D$133,"GA",'Prelude Actuals Detail'!$M$5:$M$133) -> 117921.82
B37: Turnover (make-ready & amenities) | C37: =J37/$C$7 -> 175 | D37: =K37/$D$7 -> 227.61646 | E37: =L37/$E$7 -> 141.52127 | F37: =SUMIF('Prelude Actuals Detail'!$D$5:$D$133,"Turnover",'Prelude Actuals Detail'!$N$5:$N$133)/$E$7 -> 180.29643 | G37: =E37-D37 -> -86.095199 | H37: =IF(D37=0,"n/a",(E37-D37)/ABS(D37)) -> -0.3782468 | I37: =C37-E37 -> 33.478735 | J37: 63000 | K37: 63732.61 | L37: =SUMIF('Prelude Actuals Detail'!$D$5:$D$133,"Turnover",'Prelude Actuals Detail'!$M$5:$M$133) -> 39625.954 | M37: Actual favorable; 2018 vintage still young.
B38: Repairs & Maintenance | C38: =J38/$C$7 -> 175 | D38: =K38/$D$7 -> 157.06918 | E38: =L38/$E$7 -> 120.42129 | F38: =SUMIF('Prelude Actuals Detail'!$D$5:$D$133,"RM",'Prelude Actuals Detail'!$N$5:$N$133)/$E$7 -> 169.02143 | G38: =E38-D38 -> -36.647893 | H38: =IF(D38=0,"n/a",(E38-D38)/ABS(D38)) -> -0.23332326 | I38: =C38-E38 -> 54.578714 | J38: 63000 | K38: 43979.37 | L38: =SUMIF('Prelude Actuals Detail'!$D$5:$D$133,"RM",'Prelude Actuals Detail'!$M$5:$M$133) -> 33717.96
B39: Contracts | C39: =J39/$C$7 -> 634.42881 | D39: =K39/$D$7 -> 715.69136 | E39: =L39/$E$7 -> 710.19165 | F39: =SUMIF('Prelude Actuals Detail'!$D$5:$D$133,"Contracts",'Prelude Actuals Detail'!$N$5:$N$133)/$E$7 -> 830.36086 | G39: =E39-D39 -> -5.4997041 | H39: =IF(D39=0,"n/a",(E39-D39)/ABS(D39)) -> -0.0076844635 | I39: =C39-E39 -> -75.762848 | J39: 228394.37 | K39: 200393.58 | L39: =SUMIF('Prelude Actuals Detail'!$D$5:$D$133,"Contracts",'Prelude Actuals Detail'!$M$5:$M$133) -> 198853.66
B40: Utilities | C40: =J40/$C$7 -> 759.58717 | D40: =K40/$D$7 -> 552.28857 | E40: =L40/$E$7 -> 583.97455 | F40: =SUMIF('Prelude Actuals Detail'!$D$5:$D$133,"Utilities",'Prelude Actuals Detail'!$N$5:$N$133)/$E$7 -> 600.39071 | G40: =E40-D40 -> 31.68598 | H40: =IF(D40=0,"n/a",(E40-D40)/ABS(D40)) -> 0.057372144 | I40: =C40-E40 -> 175.61262 | J40: 273451.38 | K40: 154640.8 | L40: =SUMIF('Prelude Actuals Detail'!$D$5:$D$133,"Utilities",'Prelude Actuals Detail'!$M$5:$M$133) -> 163512.87 | M40: Seasons UW $760/U vs Prelude $553-600/U — Seasons is a larger-common-area 2024 asset.
B41: Management Fee | C41: =J41/$C$7 -> 581.92 | D41: =K41/$D$7 -> 521.56336 | E41: =L41/$E$7 -> 475.3159 | F41: =SUMIF('Prelude Actuals Detail'!$D$5:$D$133,"MgmtFee",'Prelude Actuals Detail'!$N$5:$N$133)/$E$7 -> 470.18214 | G41: =E41-D41 -> -46.247459 | H41: =IF(D41=0,"n/a",(E41-D41)/ABS(D41)) -> -0.088670837 | I41: =C41-E41 -> 106.6041 | J41: 209491.2 | K41: 146037.74 | L41: =SUMIF('Prelude Actuals Detail'!$D$5:$D$133,"MgmtFee",'Prelude Actuals Detail'!$M$5:$M$133) -> 133088.45 | M41: Both ~2.5% of EGI underwritten; Prelude actual ~2.4%.
...

Sheet Prelude Actuals Detail
B1: Prelude at Paramount — Post-Close Actuals Detail (TMG ownership: Jan–Jul 2026)
B2: Source: Yardi 12-month accrual statement (idprepar), period Aug 2025–Jul 2026. Aug–Nov 2025 columns are zero (pre-acquisition); Dec 2025 contains takeover/proration entries only and is excluded. Category = TMG standardized bucket. Blue = statement values; black = formulas.
B4: Acct | C4: Line Item | D4: Category | E4: Jan-26 | F4: Feb-26 | G4: Mar-26 | H4: Apr-26 | I4: May-26 | J4: Jun-26 | K4: Jul-26 | L4: 7-Mo Total | M4: Annualized (x12/7) | N4: T3 Ann. (May-Jul x4)
B5: 41000-000 | C5: Market Rent | D5: GPR | E5: 482580 | F5: 482580 | G5: 482580 | H5: 482580 | I5: 482580 | J5: 482580 | K5: 482580 | L5: =SUM(E5:K5) -> 3378060 | M5: =L5*12/7 -> 5790960 | N5: =SUM(I5:K5)*4 -> 5790960
B6: 41010-000 | C6: Gain / Loss To Lease | D6: LTL | E6: -15414 | F6: -15099 | G6: -14336 | H6: -13696 | I6: -13623 | J6: -11561 | K6: -11157 | L6: =SUM(E6:K6) -> -94886 | M6: =L6*12/7 -> -162661.71 | N6: =SUM(I6:K6)*4 -> -145364
B7: 41091-000 | C7: One-Time Concessions | D7: Concessions | E7: -2154.11 | F7: -5842.14 | G7: -16444.5 | H7: -34604.2 | I7: -46159.45 | J7: -15665.45 | K7: -18939.2 | L7: =SUM(E7:K7) -> -139809.05 | M7: =L7*12/7 -> -239672.66 | N7: =SUM(I7:K7)*4 -> -323056.4
B8: 41092-000 | C8: Renewal Concessions | D8: Concessions | E8: 0 | F8: -3000 | G8: 3000 | H8: 0 | I8: 0 | J8: 0 | K8: 0 | L8: =SUM(E8:K8) -> 0 | M8: =L8*12/7 -> 0 | N8: =SUM(I8:K8)*4 -> 0
B9: 41100-000 | C9: Vacancy Loss | D9: Vacancy | E9: -44866.61 | F9: -57387.96 | G9: -57935.52 | H9: -51418.5 | I9: -27505.94 | J9: -35839.09 | K9: -22770.62 | L9: =SUM(E9:K9) -> -297724.24 | M9: =L9*12/7 -> -510384.41 | N9: =SUM(I9:K9)*4 -> -344462.6
B10: 41110-000 | C10: Employee Units | D10: ModelEmp | E10: -1072.06 | F10: -363.94 | G10: -718 | H10: -718 | I10: -718 | J10: -718 | K10: -718 | L10: =SUM(E10:K10) -> -5026 | M10: =L10*12/7 -> -8616 | N10: =SUM(I10:K10)*4 -> -8616
B11: 41150-000 | C11: Bad Debt - Rent | D11: BadDebt | E11: 0 | F11: 0 | G11: 277.22 | H11: 0 | I11: 0 | J11: -364.5 | K11: 0 | L11: =SUM(E11:K11) -> -87.28 | M11: =L11*12/7 -> -149.62286 | N11: =SUM(I11:K11)*4 -> -1458
B12: 41155-000 | C12: Bad Debt Recovery - Rent | D12: BadDebt | E12: 0 | F12: 0 | G12: 0 | H12: 0 | I12: 0 | J12: 58.5 | K12: 1102.52 | L12: =SUM(E12:K12) -> 1161.02 | M12: =L12*12/7 -> 1990.32 | N12: =SUM(I12:K12)*4 -> 4644.08
B13: 43010-000 | C13: Administrative Fees | D13: OIMisc | E13: 200 | F13: 1200 | G13: 3000 | H13: 6800 | I13: 2140 | J13: 4200 | K13: 1800 | L13: =SUM(E13:K13) -> 19340 | M13: =L13*12/7 -> 33154.286 | N13: =SUM(I13:K13)*4 -> 32560
B14: 43018-600 | C14: Smart Home Income | D14: OIMisc | E14: 3893.87 | F14: 3800.37 | G14: 4004.51 | H14: 4489.98 | I14: 5077.56 | J14: 5331.48 | K14: 5453.49 | L14: =SUM(E14:K14) -> 32051.26 | M14: =L14*12/7 -> 54945.017 | N14: =SUM(I14:K14)*4 -> 63450.12
B15: 43020-000 | C15: Application Fees | D15: OIMisc | E15: 60 | F15: 420 | G15: 660 | H15: 1740 | I15: 660 | J15: 960 | K15: 420 | L15: =SUM(E15:K15) -> 4920 | M15: =L15*12/7 -> 8434.2857 | N15: =SUM(I15:K15)*4 -> 8160
B16: 43055-000 | C16: Cable TV Commissions | D16: RevShare | E16: 0 | F16: 0 | G16: 855.73 | H16: 0 | I16: 0 | J16: 0 | K16: 0 | L16: =SUM(E16:K16) -> 855.73 | M16: =L16*12/7 -> 1466.9657 | N16: =SUM(I16:K16)*4 -> 0
... B133: 63010-000 | C133: Property Insurance | D133: Insurance | E133: 15013.63 | F133: 15013.63 | G133: 15013.63 | H133: 11206.95 | I133: 11206.95 | J133: 11206.95 | K133: 11288.21 | L133: =SUM(E133:K133) -> 89949.95 | M133: =L133*12/7 -> 154199.91 | N133: =SUM(I133:K133)*4 -> 134808.44
C134: TOTAL (NOI basis: all mapped lines) | L134: =SUM(L5:L133) -> 4208222.9 | M134: =SUM(M5:M133) -> 7214096.4 | N134: =SUM(N5:N133) -> 7353698.2

Sheet Sources & Method
B2: Sources & Method
B4: SEASONS AT MERIDIAN Y1 UW — TMG_Acquisitions_model_7.26___Seasons_at_Meridian_v3.xlsm, Cash Flow (Annual) column K (Year 1 = Dec-2026–Nov-2027, 8/14/26 model refresh: Y1 market-rent basis $1,915/U/mo). NOI before $250/U capital reserves. Purchase price $118.5M per Assumptions H5.
B5: PRELUDE AT PARAMOUNT Y1 UW — Prelude_at_Paramount_Final_Model.xlsm (Dec-2025 acquisition model), Revenue & Expense tab column H (Y1 = CY 2026). Bulk-wifi program was modeled at $100,800 income offset by $100,800 expense (net $0 Y1, I&E AA35:AD37); both sides excluded here. The knowledge-base exhibit (Boise_Deals_Normalized_Underwriting_v2, tab 2b) shows OI at $2,803/U because it moves that gross-up into Other Income — NOI is identical.
B6: PRELUDE ACTUALS — Yardi 12-month accrual statement (idprepar), Aug-2025–Jul-2026, tree ysi_cf. TMG closed 12/31/2025: Aug–Nov-25 columns are zero and Dec-25 contains only takeover/proration entries (excluded: takeover rents $41.5K, damages $17.2K, tax/insurance stubs). "Actual" = Jan–Jul-2026 (7 months) x 12/7; "T3" = May–Jul-2026 x 4. Below-NOI routine-replacement lines (-$84 net) excluded. Rent roll w/ lease charges as of 8/13/2026 for occupancy and in-place rent.
B8: CATEGORY MAPPING (statement → TMG buckets) — see Prelude Actuals Detail tab, column D. Notable choices: smart-home income → Other Income; cable TV commissions + satellite/internet → Revenue Share; utility set-up/admin fees → RUBS; make-ready + recreational-amenities → Turnover; smart-home WiFi expense stays in G&A; storage rent → Other Income (misc).
B9: ANNUALIZATION CAVEATS — (1) Concessions are one-time credits taken at signing: the 7-mo annualization embeds the heavy winter cohort; T3 shows the current (worse) pace. (2) RUBS billbacks ramped from ~$0 in January as TMG took over billing — 7-mo annualized understates the run rate; T3 is the better read. (3) Taxes and insurance accrue at level monthly amounts — annualization is exact.
B10: COMPARABILITY — Assets differ: Seasons is 2024-built, 360 units, 932 SF avg, in lease-up stabilization; Prelude is 2018-built, 280 units, 1,016 SF avg, stabilized-recovering. Both Meridian (Ada County, ~0.45% levy). Compare $/unit and ratios, not totals. Cap rates are comparable; $/unit price is not (larger avg SF at Prelude).
B12: Related repo exhibits: knowledge/exhibits/Boise_Deals_Normalized_Underwriting_v2.xlsx (tabs 2_ProFormas, 2b_Prelude_Actuals), knowledge/deal_metrics.json (branch seasons-meridian-underwriting-woep67). Prepared 2026-08-14 from user-supplied source files.
