Workbook

Sheet UW Comparison
B2: TMG UW COMPARISON — BOISE MSA
B3: Canyon Ridge (288u, SE Boise · Direct · model 6.2026) vs. Seasons at Meridian (360u, Meridian · JV · model 7.26) · 5-yr hold · 4.75% exit cap · values as of Jul 2026
B4: Blue = hard-coded from model — relink via 'Link Map' tab. Black = formula (recalcs off this sheet). Δ = CR vs SaM: dollars/counts as % difference, rates as bps, multiples as Δx.
B6: Metric | C6: Canyon Ridge | D6: Seasons at Meridian | E6: Δ CR vs SaM | F6: Notes
B8: PROPERTY SNAPSHOT
B9: Location | C9: Boise · 2552 E Gowen Rd | D9: Meridian · 2700 E Overland Rd | F9: Both Ada County, Boise MSA
B10: Year Built | C10: 2024 | D10: 2024 | F10: Both 2024 deliveries — new-vintage, in/near lease-up
B11: Units | C11: 288 | D11: 360 | E11: =IFERROR(C11/D11-1,"")
B12: Avg Unit SF | C12: 888.9375 | D12: 932.45833 | E12: =IFERROR(C12/D12-1,"")
B13: Total NRSF | C13: =C11*C12 | D13: =D11*D12 | E13: =IFERROR(C13/D13-1,"")
B14: Deal Structure | C14: Direct | D14: JV | F14: Drives investor-level return comparability (see Returns)
B15: Seller | C15: — | D15: Carlyle Group
B16: Target Close | C16: Aug 31, 2026 | D16: Oct 31, 2026
B18: MARKET — 3-MILE DEMOGRAPHICS
B19: Avg Household Income | C19: 142348 | D19: 108532.27 | E19: =IFERROR(C19/D19-1,"") | F19: Placer.ai
B20: Median Home Value | C20: 671987 | D20: 570090.81 | E20: =IFERROR(C20/D20-1,"") | F20: Placer.ai
B21: Avg Market Rent | E21: =IFERROR(C21/D21-1,"") | F21: CoStar — to be added
B23: PRICING & BASIS
B24: Whisper / Guidance Price | C24: 110000000 | D24: 125000000 | E24: =IFERROR(C24/D24-1,"")
B25: TMG Purchase Price | C25: 95000000 | D25: 110000000 | E25: =IFERROR(C25/D25-1,"")
B26: per Unit | C26: =C25/C11 | D26: =D25/D11 | E26: =IFERROR(C26/D26-1,"")
B27: per SF | C27: =C25/C13 | D27: =D25/D13 | E27: =IFERROR(C27/D27-1,"")
B28: Discount to Whisper | C28: =C25/C24-1 | D28: =D25/D24-1 | E28: =IF(OR(C28="",D28=""),"",(C28-D28)*10000)
B29: Budgeted CapEx per Unit | C29: 6885.4167 | D29: 7138.8889 | E29: =IFERROR(C29/D29-1,"") | F29: 5-yr program incl. $250/U/yr reserves; $0 value-add capex in either base UW
B30: TMG Total Basis | C30: 97345481 | D30: 1.1300603e+08 | E30: =IFERROR(C30/D30-1,"") | F30: Price + closing + financing fees + capex
B31: per Unit | C31: =C30/C11 | D31: =D30/D11 | E31: =IFERROR(C31/D31-1,"")
B32: per SF | C32: =C30/C13 | D32: =D30/D13 | E32: =IFERROR(C32/D32-1,"")
B34: RENTS & OCCUPANCY
B35: In-Place Contract Rent ($/mo) | C35: 1994.8244 | D35: 1735.1513 | E35: =IFERROR(C35/D35-1,"")
B36: per SF | C36: =C35/C12 | D36: =D35/D12 | E36: =IFERROR(C36/D36-1,"")
B37: T12 Market Rent ($/mo) | C37: 2008.6724 | D37: 1743.2632 | E37: =IFERROR(C37/D37-1,"") | F37: Hellodata
B38: T3 Market Rent ($/mo) | C38: 2201.1689 | D38: 1837.6891 | E38: =IFERROR(C38/D38-1,"") | F38: Hellodata
B39: per SF | C39: =C38/C12 | D39: =D38/D12 | E39: =IFERROR(C39/D39-1,"")
B40: TMG Y1 Market Rent ($/mo) | C40: 2052.0281 | D40: 1761.1786 | E40: =IFERROR(C40/D40-1,"")
B41: In-Place vs T3 Market (LTL) | C41: =C35/C38-1 | D41: =D35/D38-1 | E41: =IF(OR(C41="",D41=""),"",(C41-D41)*10000) | F41: Loss-to-lease = mark-to-market upside embedded in T3 rents
B42: T12 Physical Occupancy | C42: 0.77093296 | D42: 0.80318463 | E42: =IF(OR(C42="",D42=""),"",(C42-D42)*10000) | F42: Both in lease-up during T12 — T3 is the cleaner read
B43: T3 Physical Occupancy | C43: 0.97863474 | D43: 0.94946822 | E43: =IF(OR(C43="",D43=""),"",(C43-D43)*10000)
B44: T3 Economic Occupancy | C44: 0.92632513 | D44: 0.91926151 | E44: =IF(OR(C44="",D44=""),"",(C44-D44)*10000)
B45: TMG Y1 Economic Occupancy | C45: 0.93652778 | D45: 0.91972222 | E45: =IF(OR(C45="",D45=""),"",(C45-D45)*10000) | F45: Y1 physical UW'd at 94.5% for both
B46: T3 Concessions (% of GPR) | C46: 0.042014977 | D46: 0.019174393 | E46: =IF(OR(C46="",D46=""),"",(C46-D46)*10000) | F46: Burn-off tailwind as lease-up concessions roll off
...

Sheet Link Map
B2: LINK MAP — WHERE EVERY HARD-CODED VALUE COMES FROM
B3: Replace each blue value on 'UW Comparison' with an external link to the cell below. CAUTION: the two models are different template versions — Assumptions-sheet addresses differ between them (returns block is column M on Canyon Ridge but column L on Seasons; pricing cells also differ). 'Cash Flow (Annual)' addresses are identical in both.
B4: [CR] = Canyon_Ridge_UWv2 (TMG Acquisition Model 6.2026).xlsm [SaM] = TMG_Acquisitions_model_7.26 Seasons_at_Meridian_v02.xlsm
B6: Metric | C6: Cells | D6: Canyon Ridge source [CR] | E6: Seasons source [SaM] | F6: Definition
B7: Location | C7: C9 / D9 | D7: Assumptions!C5 | E7: Assumptions!C4
B8: Year Built | C8: C10 / D10 | D8: Assumptions!C7 | E8: Assumptions!C6
B9: Units | C9: C11 / D11 | D9: Assumptions!F100 | E9: Assumptions!F100
B10: Avg Unit SF | C10: C12 / D12 | D10: Assumptions!H100 | E10: Assumptions!H100
B11: Total NRSF | C11: C13 / D13 | D11: formula — do not link | E11: formula — do not link | F11: =Units × Avg SF
B12: Deal Structure | C12: C14 / D14 | D12: Assumptions!E4 | E12: Assumptions!E3
B13: Seller | C13: C15 / D15 | D13: Assumptions!E7 (blank in model) | E13: Assumptions!E6
B14: Target Close | C14: C16 / D16 | D14: Assumptions!C33 | E14: Assumptions!H4
B15: Avg Household Income | C15: C19 / D19 | D15: External — Placer.ai | E15: External — Placer.ai
B16: Median Home Value | C16: C20 / D20 | D16: External — Placer.ai | E16: External — Placer.ai
B17: Avg Market Rent | C17: C21 / D21 | D17: External — CoStar | E17: External — CoStar
B18: Whisper / Guidance Price | C18: C24 / D24 | D18: Assumptions!C35 | E18: Assumptions!H6
B19: TMG Purchase Price | C19: C25 / D25 | D19: Assumptions!C34 | E19: Assumptions!H5
B20: per Unit | C20: C26 / D26 | D20: formula — do not link | E20: formula — do not link
B21: per SF | C21: C27 / D27 | D21: formula — do not link | E21: formula — do not link
B22: Discount to Whisper | C22: C28 / D28 | D22: formula — do not link | E22: formula — do not link
B23: Budgeted CapEx per Unit | C23: C29 / D29 | D23: Assumptions!G46 | E23: Assumptions!G46
... B37: TMG Y1 Economic Occupancy | C37: C45 / D45 | D37: 'Cash Flow (Annual)'!K15 | E37: 'Cash Flow (Annual)'!K15
B38: T3 Concessions (% of GPR) | C38: C46 / D46 | D38: =-'Cash Flow (Annual)'!I25 / 'Cash Flow (Annual)'!I16 | E38: =-'Cash Flow (Annual)'!I25 / 'Cash Flow (Annual)'!I16
B39: T3 Revenue (annualized) | C39: C49 / D49 | D39: 'Cash Flow (Annual)'!I35 | E39: 'Cash Flow (Annual)'!I35
B40: TMG Y1 Revenue | C40: C50 / D50 | D40: 'Cash Flow (Annual)'!K35 | E40: 'Cash Flow (Annual)'!K35
B41: Y1 Other Income ($/U/mo) | C41: C51 / D51 | D41: =SUM('Cash Flow (Annual)'!K29:K32)/Units/12 | E41: =SUM('Cash Flow (Annual)'!K29:K32)/Units/12
B42: Y1 OpEx per Unit (incl. reserves) | C42: C52 / D52 | D42: =('Cash Flow (Annual)'!K53+'Cash Flow (Annual)'!K63)/Units | E42: =('Cash Flow (Annual)'!K53+'Cash Flow (Annual)'!K63)/Units
B43: RE Taxes per Unit | C43: C53 / D53 | D43: ='Cash Flow (Annual)'!K50/Units | E43: ='Cash Flow (Annual)'!K50/Units
B44: Insurance per Unit | C44: C54 / D54 | D44: ='Cash Flow (Annual)'!K49/Units | E44: ='Cash Flow (Annual)'!K49/Units
B45: All Other OpEx per Unit | C45: C55 / D55 | D45: formula — do not link | E45: formula — do not link
B46: Y1 Expense Ratio | C46: C56 / D56 | D46: 'Cash Flow (Annual)'!K55 | E46: 'Cash Flow (Annual)'!K55
B47: Current Taxable Value | C47: C57 / D57 | D47: Assumptions!K42 | E47: Assumptions!K42
B48: Stabilized NOI (T3 Rev @ TMG Y1 Exp) | C48: C60 / D60 | D48: formula — do not link | E48: formula — do not link
B49: Cap Rate on Price | C49: C61 / D61 | D49: formula — do not link | E49: formula — do not link
B50: TMG Y1 NOI (net of reserves) | C50: C62 / D62 | D50: ='Cash Flow (Annual)'!K59-'Cash Flow (Annual)'!K63 | E50: ='Cash Flow (Annual)'!K59-'Cash Flow (Annual)'!K63
B51: Cap Rate on Price | C51: C63 / D63 | D51: formula — do not link | E51: formula — do not link
B52: Y1 Economic Cap (w/ CapEx Adj) | C52: C64 / D64 | D52: Assumptions!E41 | E52: Assumptions!E35
B53: Unlevered Return on Cost | C53: C65 / D65 | D53: Assumptions!K39 | E53: Assumptions!K39
B54: Units Upgraded (%) | C54: C68 / D68 | D54: Assumptions!G32 | E54: Assumptions!G32
B55: Cost per Unit | C55: C69 / D69 | D55: Assumptions!G35 | E55: Assumptions!G35
...
